{"type": "depth", "ts": 1783008103314, "U": 96863169001, "u": 96863169226, "bids": [["61605.99000000", "6.14275000"], ["61605.98000000", "0.97479000"], ["61604.87000000", "0.38956000"], ["61604.86000000", "0.54436000"], ["61604.84000000", "1.48845000"], ["61604.76000000", "0.00000000"], ["61604.74000000", "0.00000000"], ["61604.59000000", "0.16232000"], ["61604.50000000", "0.00018000"], ["61604.00000000", "0.07527000"], ["61603.99000000", "0.09045000"], ["61603.98000000", "0.04235000"], ["61602.57000000", "1.36722000"], ["61602.55000000", "0.34959000"], ["61602.00000000", "0.07509000"], ["61601.99000000", "0.08044000"], ["61601.98000000", "0.00009000"], ["61601.47000000", "0.00009000"], ["61601.11000000", "0.00896000"], ["61600.50000000", "0.00009000"], ["61600.45000000", "0.00995000"], ["61600.00000000", "0.12027000"], ["61599.99000000", "0.00000000"], ["61599.40000000", "0.18909000"], ["61599.39000000", "0.56531000"], ["61599.22000000", "0.01117000"], ["61598.30000000", "0.00000000"], ["61598.29000000", "0.00009000"], ["61597.99000000", "0.04720000"], ["61597.98000000", "0.00000000"], ["61597.07000000", "0.01000000"], ["61597.02000000", "0.01000000"], ["61596.85000000", "1.18360000"], ["61594.25000000", "0.01000000"], ["61593.00000000", "0.08759000"], ["61591.46000000", "0.08895000"], ["61589.73000000", "0.00000000"], ["61588.19000000", "0.00000000"], ["61587.97000000", "0.00000000"], ["61587.66000000", "0.00000000"], ["61587.15000000", "0.01009000"], ["61585.53000000", "0.00000000"], ["61582.98000000", "0.00419000"], ["61582.06000000", "0.00012000"], ["61581.47000000", "0.00193000"], ["61579.08000000", "0.00000000"], ["61579.03000000", "0.64219000"], ["61575.64000000", "0.00000000"], ["61573.00000000", "0.01000000"], ["61572.84000000", "0.00000000"], ["61571.51000000", "0.00000000"], ["61571.00000000", "0.00000000"], ["61565.31000000", "0.00428000"], ["61565.02000000", "0.00617000"], ["61564.40000000", "0.00425000"], ["61562.90000000", "0.00430000"], ["61553.37000000", "0.00000000"], ["61553.27000000", "0.00000000"], ["61553.18000000", "0.01139000"], ["61551.91000000", "0.00000000"], ["61512.70000000", "0.04636000"], ["61494.53000000", "0.00000000"], ["61430.77000000", "0.00000000"], ["55445.40000000", "0.00060000"]], "asks": [["61606.00000000", "0.02500000"], ["61606.01000000", "0.00432000"], ["61606.48000000", "0.00000000"], ["61608.00000000", "0.02418000"], ["61608.34000000", "0.00000000"], ["61608.83000000", "0.00000000"], ["61609.26000000", "0.00000000"], ["61609.27000000", "0.00018000"], ["61610.00000000", "0.02418000"], ["61610.06000000", "0.00000000"], ["61610.49000000", "0.00800000"], ["61611.06000000", "0.00000000"], ["61611.07000000", "0.00018000"], ["61611.59000000", "0.00179000"], ["61611.96000000", "0.00034000"], ["61612.00000000", "0.02418000"], ["61612.02000000", "0.00000000"], ["61612.03000000", "0.00018000"], ["61612.07000000", "0.00000000"], ["61612.56000000", "0.00000000"], ["61612.82000000", "0.00995000"], ["61613.26000000", "0.00902000"], ["61613.91000000", "0.00009000"], ["61614.97000000", "0.00000000"], ["61615.23000000", "0.00009000"], ["61615.59000000", "0.00000000"], ["61615.98000000", "0.00009000"], ["61615.99000000", "0.09113000"], ["61616.03000000", "0.00069000"], ["61616.43000000", "0.00048000"], ["61616.86000000", "0.00000000"], ["61617.42000000", "0.00000000"], ["61617.90000000", "0.00009000"], ["61618.26000000", "0.00000000"], ["61618.33000000", "0.00326000"], ["61618.40000000", "0.00000000"], ["61618.54000000", "0.00000000"], ["61619.24000000", "0.03000000"], ["61619.76000000", "0.00047000"], ["61620.02000000", "0.00048000"], ["61620.64000000", "0.00000000"], ["61621.34000000", "0.00000000"], ["61621.96000000", "0.00000000"], ["61621.98000000", "0.14096000"], ["61621.99000000", "0.26594000"], ["61622.14000000", "0.04000000"], ["61623.14000000", "0.08000000"], ["61624.85000000", "1.08461000"], ["61624.86000000", "1.36330000"], ["61624.87000000", "0.00000000"], ["61624.88000000", "0.00000000"], ["61625.89000000", "0.00000000"], ["61625.95000000", "0.00000000"], ["61626.50000000", "0.01300000"], ["61628.97000000", "0.00000000"], ["61637.16000000", "0.64159000"], ["61637.47000000", "0.00000000"], ["61641.00000000", "0.00400000"], ["61643.20000000", "0.00617000"], ["61643.51000000", "0.00428000"], ["61645.65000000", "0.00379000"], ["61646.80000000", "0.00425000"], ["61647.02000000", "0.00430000"], ["61647.20000000", "0.00000000"], ["61649.94000000", "0.00000000"], ["61654.56000000", "0.00400000"], ["61657.33000000", "0.01300000"], ["61659.87000000", "0.02200000"], ["61660.95000000", "0.09341000"], ["61662.48000000", "0.00400000"], ["61662.65000000", "0.01000000"], ["61663.12000000", "0.00230000"], ["61668.47000000", "0.00000000"], ["61669.30000000", "0.00000000"], ["61669.39000000", "0.00000000"], ["61670.59000000", "0.97494000"], ["61707.99000000", "0.00152000"], ["61778.50000000", "0.00009000"], ["61781.58000000", "0.00000000"], ["63000.00000000", "43.10237000"]]}
{"type": "depth", "ts": 1783008103414, "U": 96863169227, "u": 96863169694, "bids": [["61607.99000000", "5.14355000"], ["61607.98000000", "2.34585000"], ["61607.97000000", "0.00017000"], ["61607.80000000", "0.00009000"], ["61607.79000000", "0.00000000"], ["61607.69000000", "0.00000000"], ["61607.44000000", "0.04217000"], ["61607.04000000", "0.00400000"], ["61606.66000000", "0.00000000"], ["61606.52000000", "0.16231000"], ["61606.33000000", "0.00000000"], ["61606.18000000", "0.00009000"], ["61606.15000000", "0.15374000"], ["61606.02000000", "2.19932000"], ["61606.01000000", "0.07500000"], ["61606.00000000", "0.40283000"], ["61605.99000000", "0.40899000"], ["61605.98000000", "0.00045000"], ["61605.97000000", "0.00000000"], ["61604.87000000", "0.38974000"], ["61604.86000000", "0.00027000"], ["61604.84000000", "1.48845000"], ["61604.59000000", "0.00018000"], ["61604.50000000", "0.00000000"], ["61603.99000000", "0.09036000"], ["61603.98000000", "0.04217000"], ["61602.57000000", "0.99773000"], ["61602.56000000", "0.00010000"], ["61602.55000000", "0.10209000"], ["61602.00000000", "0.00009000"], ["61601.83000000", "0.00010000"], ["61600.51000000", "0.00000000"], ["61600.29000000", "0.00009000"], ["61600.00000000", "0.04027000"], ["61599.83000000", "0.00000000"], ["61598.02000000", "0.00000000"], ["61597.99000000", "0.04711000"], ["61596.75000000", "0.08758000"], ["61595.67000000", "0.00010000"], ["61595.21000000", "0.08895000"], ["61593.93000000", "0.01000000"], ["61593.00000000", "0.00000000"], ["61592.59000000", "0.00010000"], ["61592.53000000", "0.00009000"], ["61591.67000000", "0.00982000"], ["61591.46000000", "0.00000000"], ["61589.51000000", "0.00010000"], ["61588.59000000", "0.00000000"], ["61586.71000000", "0.00324000"], ["61586.43000000", "0.00010000"], ["61585.66000000", "0.00009000"], ["61585.51000000", "0.00000000"], ["61584.32000000", "0.00010000"], ["61583.35000000", "0.00010000"], ["61582.43000000", "0.00000000"], ["61582.35000000", "0.00000000"], ["61581.68000000", "0.00300000"], ["61580.27000000", "0.00010000"], ["61579.35000000", "0.00000000"], ["61577.67000000", "0.00000000"], ["61577.65000000", "0.00000000"], ["61577.19000000", "0.00010000"], ["61576.88000000", "0.00000000"], ["61576.78000000", "0.00000000"], ["61576.27000000", "0.00000000"], ["61575.35000000", "0.00000000"], ["61575.00000000", "0.01000000"], ["61573.19000000", "0.00000000"], ["61573.00000000", "0.00000000"], ["61569.22000000", "0.77918000"], ["61568.70000000", "0.00000000"], ["61564.86000000", "0.01000000"], ["61563.27000000", "0.00000000"], ["61561.63000000", "1.50230000"], ["61557.82000000", "0.00000000"], ["61509.50000000", "0.00161000"], ["61498.41000000", "0.00000000"], ["61487.50000000", "0.00024000"], ["61461.96000000", "0.00035000"], ["61432.60000000", "0.00000000"], ["61420.76000000", "0.00000000"], ["55445.40000000", "0.00000000"]], "asks": [["61606.00000000", "0.00000000"], ["61606.01000000", "0.00000000"], ["61606.02000000", "0.00000000"], ["61606.16000000", "0.00000000"], ["61606.34000000", "0.00000000"], ["61607.70000000", "0.00000000"], ["61607.80000000", "0.00000000"], ["61607.99000000", "0.00000000"], ["61608.00000000", "0.02545000"], ["61608.01000000", "0.00045000"], ["61609.27000000", "0.00000000"], ["61610.00000000", "0.02418000"], ["61610.49000000", "0.00018000"], ["61611.07000000", "0.00000000"], ["61612.00000000", "0.02418000"], ["61612.03000000", "0.00000000"], ["61612.16000000", "0.00000000"], ["61612.47000000", "0.00859000"], ["61612.81000000", "0.00000000"], ["61612.82000000", "0.00018000"], ["61613.26000000", "0.00018000"], ["61613.31000000", "0.00000000"], ["61613.91000000", "0.00000000"], ["61613.92000000", "0.00018000"], ["61614.00000000", "0.02418000"], ["61614.16000000", "0.00010000"], ["61614.35000000", "0.00009000"], ["61614.36000000", "0.08777000"], ["61614.62000000", "0.00000000"], ["61614.70000000", "0.02018000"], ["61614.74000000", "0.00031000"], ["61614.97000000", "0.00000000"], ["61615.23000000", "0.00000000"], ["61615.24000000", "0.00009000"], ["61616.32000000", "0.00009000"], ["61616.96000000", "0.00009000"], ["61617.40000000", "0.00000000"], ["61618.33000000", "0.00000000"], ["61618.34000000", "0.00000000"], ["61619.25000000", "0.00000000"], ["61619.40000000", "0.00000000"], ["61619.74000000", "0.09172000"], ["61620.32000000", "0.00010000"], ["61621.97000000", "0.00000000"], ["61622.48000000", "0.00013000"], ["61622.78000000", "0.00009000"], ["61623.13000000", "0.08860000"], ["61623.40000000", "0.00010000"], ["61624.70000000", "0.08754000"], ["61624.84000000", "0.09172000"], ["61625.56000000", "0.00000000"], ["61626.24000000", "0.08890000"], ["61626.48000000", "0.00010000"], ["61626.56000000", "0.00000000"], ["61628.64000000", "0.00000000"], ["61629.56000000", "0.00010000"], ["61631.72000000", "0.00000000"], ["61632.64000000", "0.00010000"], ["61634.80000000", "0.00000000"], ["61635.72000000", "0.00010000"], ["61637.00000000", "0.00000000"], ["61637.30000000", "0.00009000"], ["61638.80000000", "0.00010000"], ["61639.00000000", "0.01000000"], ["61643.43000000", "1.50031000"], ["61655.19000000", "0.41689000"], ["61662.95000000", "0.02200000"], ["61668.79000000", "0.00000000"], ["61683.19000000", "0.00000000"], ["61705.99000000", "0.00000000"], ["61716.33000000", "0.00162000"], ["61730.93000000", "0.00000000"], ["61781.25000000", "0.01247000"], ["61784.33000000", "0.00000000"], ["61789.50000000", "0.00000000"], ["61915.84000000", "0.00009000"], ["62530.09000000", "0.00000000"]]}
{"type": "depth", "ts": 1783008103514, "U": 96863169695, "u": 96863169820, "bids": [["61607.99000000", "5.23813000"], ["61607.98000000", "2.34603000"], ["61607.45000000", "0.06226000"], ["61607.44000000", "0.04235000"], ["61606.52000000", "0.16249000"], ["61606.15000000", "0.15410000"], ["61606.02000000", "0.73994000"], ["61606.01000000", "0.07518000"], ["61605.99000000", "0.30796000"], ["61605.98000000", "0.00018000"], ["61604.87000000", "0.38956000"], ["61604.86000000", "0.00000000"], ["61604.84000000", "1.48827000"], ["61604.59000000", "0.00000000"], ["61604.00000000", "0.07509000"], ["61603.65000000", "0.00979000"], ["61601.99000000", "0.08035000"], ["61601.98000000", "0.00000000"], ["61601.47000000", "0.00000000"], ["61600.00000000", "0.04027000"], ["61595.23000000", "0.01000000"], ["61593.99000000", "0.01200000"], ["61590.34000000", "0.00649000"], ["61584.07000000", "0.00000000"], ["61559.68000000", "0.00000000"], ["61552.80000000", "0.00000000"], ["61551.07000000", "0.01000000"], ["61550.01000000", "1.25331000"], ["61504.96000000", "0.05233000"], ["61420.75000000", "0.00000000"], ["55447.20000000", "0.00040000"], ["55445.00000000", "0.00000000"]], "asks": [["61608.00000000", "0.02527000"], ["61608.01000000", "0.00045000"], ["61610.00000000", "0.02418000"], ["61610.49000000", "0.00000000"], ["61612.00000000", "0.02418000"], ["61612.47000000", "0.00877000"], ["61612.82000000", "0.00000000"], ["61613.26000000", "0.00000000"], ["61613.92000000", "0.00000000"], ["61614.00000000", "0.02418000"], ["61614.36000000", "0.08795000"], ["61614.70000000", "0.02018000"], ["61614.97000000", "0.00009000"], ["61615.98000000", "0.09181000"], ["61615.99000000", "0.09131000"], ["61616.00000000", "0.02427000"], ["61616.97000000", "0.00000000"], ["61617.12000000", "0.00000000"], ["61617.40000000", "0.00009000"], ["61617.58000000", "0.00000000"], ["61617.74000000", "0.00000000"], ["61620.05000000", "0.00000000"], ["61621.14000000", "0.00000000"], ["61623.14000000", "0.00000000"], ["61623.96000000", "0.00000000"], ["61624.84000000", "0.00000000"], ["61625.24000000", "0.08000000"], ["61632.37000000", "1.00000000"], ["61647.48000000", "0.01230000"], ["61656.62000000", "0.01100000"], ["61662.90000000", "0.01000000"], ["61663.12000000", "0.00000000"], ["61689.77000000", "0.05036000"], ["61690.34000000", "0.00016000"], ["61968.60000000", "3.00000000"]]}
{"type": "depth", "ts": 1783008103614, "U": 96863169821, "u": 96863170168, "bids": [["61609.99000000", "4.08942000"], ["61609.98000000", "0.00035000"], ["61609.97000000", "0.00017000"], ["61609.94000000", "0.15365000"], ["61609.24000000", "4.79528000"], ["61609.23000000", "1.12088000"], ["61609.22000000", "0.00000000"], ["61609.21000000", "0.00000000"], ["61609.11000000", "0.00009000"], ["61608.64000000", "0.00010000"], ["61608.32000000", "0.16231000"], ["61608.00000000", "0.07500000"], ["61607.99000000", "0.15484000"], ["61607.98000000", "1.36348000"], ["61607.97000000", "0.00000000"], ["61607.45000000", "0.00000000"], ["61607.44000000", "0.00018000"], ["61606.52000000", "0.00018000"], ["61606.01000000", "0.07500000"], ["61606.00000000", "0.08033000"], ["61605.99000000", "0.04046000"], ["61604.00000000", "0.00009000"], ["61603.83000000", "0.00010000"], ["61602.55000000", "0.02209000"], ["61602.19000000", "0.00013000"], ["61601.99000000", "0.00035000"], ["61601.83000000", "0.00000000"], ["61601.46000000", "0.00009000"], ["61601.45000000", "1.36827000"], ["61600.12000000", "0.01000000"], ["61600.00000000", "0.04018000"], ["61599.50000000", "0.01300000"], ["61597.99000000", "0.00000000"], ["61596.26000000", "0.58503000"], ["61588.63000000", "0.36504000"], ["61585.30000000", "0.00000000"], ["61584.01000000", "0.01051000"], ["61578.30000000", "0.00000000"], ["61577.00000000", "0.01000000"], ["61575.00000000", "0.00000000"], ["61556.32000000", "0.00000000"], ["61550.01000000", "0.43254000"], ["61531.99000000", "0.20282000"], ["61513.95000000", "0.00000000"], ["61504.96000000", "0.00000000"], ["61497.80000000", "0.04639000"], ["61474.45000000", "1.20000000"], ["61460.49000000", "0.00000000"], ["55447.20000000", "0.00000000"]], "asks": [["61608.00000000", "0.00000000"], ["61608.01000000", "0.00000000"], ["61609.24000000", "0.00000000"], ["61609.25000000", "0.00000000"], ["61609.26000000", "0.00000000"], ["61609.95000000", "0.00000000"], ["61609.99000000", "0.00000000"], ["61610.00000000", "0.13059000"], ["61610.01000000", "0.00063000"], ["61610.47000000", "0.00000000"], ["61610.88000000", "0.08777000"], ["61611.70000000", "0.00000000"], ["61612.04000000", "0.00000000"], ["61612.47000000", "0.00018000"], ["61613.29000000", "0.00000000"], ["61613.49000000", "0.00000000"], ["61613.70000000", "0.00009000"], ["61613.95000000", "0.00555000"], ["61614.16000000", "0.00000000"], ["61614.36000000", "0.00027000"], ["61614.70000000", "0.02018000"], ["61615.95000000", "0.00000000"], ["61615.97000000", "0.00009000"], ["61615.98000000", "0.00027000"], ["61615.99000000", "0.00027000"], ["61616.00000000", "0.02427000"], ["61616.16000000", "0.00010000"], ["61616.96000000", "0.00000000"], ["61617.99000000", "0.00009000"], ["61620.33000000", "0.00000000"], ["61621.57000000", "0.00000000"], ["61622.32000000", "0.00000000"], ["61622.33000000", "0.00000000"], ["61623.96000000", "0.09173000"], ["61624.69000000", "0.09172000"], ["61630.89000000", "0.55793000"], ["61639.00000000", "0.00000000"], ["61640.25000000", "0.00009000"], ["61641.00000000", "0.01400000"], ["61641.32000000", "0.00000000"], ["61644.27000000", "0.00000000"], ["61644.75000000", "0.00000000"], ["61649.38000000", "1.08063000"], ["61654.05000000", "0.01623000"], ["61657.48000000", "0.01623000"], ["61668.60000000", "0.01100000"], ["61669.21000000", "0.01000000"], ["61669.44000000", "0.00010000"], ["61689.77000000", "0.00000000"], ["61703.37000000", "0.00000000"], ["61718.80000000", "0.00000000"]]}
{"type": "depth", "ts": 1783008103714, "U": 96863170169, "u": 96863170524, "bids": [["61610.87000000", "4.38222000"], ["61610.86000000", "0.00035000"], ["61610.85000000", "0.00017000"], ["61610.75000000", "0.00009000"], ["61610.74000000", "0.00000000"], ["61610.32000000", "0.00000000"], ["61610.01000000", "1.10269000"], ["61610.00000000", "0.22865000"], ["61609.99000000", "1.33040000"], ["61609.98000000", "0.00000000"], ["61609.97000000", "0.00000000"], ["61609.94000000", "0.00036000"], ["61609.68000000", "0.00400000"], ["61609.34000000", "0.00009000"], ["61609.25000000", "0.00000000"], ["61609.24000000", "0.55581000"], ["61609.23000000", "0.04969000"], ["61609.13000000", "0.11712000"], ["61608.44000000", "0.00000000"], ["61608.32000000", "0.00018000"], ["61608.27000000", "0.00000000"], ["61608.00000000", "0.07518000"], ["61607.99000000", "0.13301000"], ["61607.98000000", "1.36330000"], ["61607.44000000", "0.00000000"], ["61606.84000000", "0.00034000"], ["61606.52000000", "0.00000000"], ["61606.15000000", "0.15383000"], ["61606.02000000", "0.73976000"], ["61606.01000000", "0.00000000"], ["61602.57000000", "0.74291000"], ["61602.29000000", "0.00009000"], ["61601.99000000", "0.00018000"], ["61601.82000000", "0.00300000"], ["61601.45000000", "1.36818000"], ["61600.50000000", "0.00000000"], ["61600.00000000", "0.04009000"], ["61596.12000000", "0.00009000"], ["61595.65000000", "0.00300000"], ["61587.84000000", "0.24750000"], ["61586.89000000", "0.00000000"], ["61584.73000000", "0.00000000"], ["61582.28000000", "0.00000000"], ["61581.68000000", "0.00000000"], ["61579.81000000", "0.00000000"], ["61579.00000000", "0.01000000"], ["61578.00000000", "0.02400000"], ["61577.00000000", "0.00000000"], ["61567.44000000", "0.00000000"], ["61564.47000000", "0.13639000"], ["61551.53000000", "0.00000000"], ["61549.26000000", "0.00010000"], ["61542.39000000", "0.00000000"], ["61511.98000000", "0.05721000"], ["61487.65000000", "0.00010000"], ["61486.40000000", "0.00000000"], ["61480.78000000", "0.00000000"], ["61434.14000000", "0.00000000"], ["61426.04000000", "0.00010000"], ["61419.18000000", "0.00000000"], ["61364.43000000", "0.00010000"], ["61357.57000000", "0.00019000"], ["61302.82000000", "0.00010000"], ["61295.97000000", "0.00000000"], ["61241.20000000", "0.00010000"], ["61234.37000000", "0.00015000"], ["61179.59000000", "0.00010000"], ["61172.76000000", "0.00000000"], ["61117.98000000", "0.00010000"], ["61111.16000000", "0.00000000"], ["55449.79000000", "0.00020000"], ["55449.00000000", "0.00000000"], ["49287.99000000", "0.00000000"]], "asks": [["61610.00000000", "0.00000000"], ["61610.01000000", "0.00000000"], ["61610.33000000", "0.00000000"], ["61610.75000000", "0.00000000"], ["61610.87000000", "0.00000000"], ["61610.88000000", "0.33493000"], ["61610.89000000", "0.00081000"], ["61611.59000000", "0.00000000"], ["61611.96000000", "0.00000000"], ["61612.00000000", "0.02418000"], ["61612.47000000", "0.00000000"], ["61613.26000000", "0.00034000"], ["61613.95000000", "0.00018000"], ["61614.00000000", "0.02418000"], ["61614.35000000", "0.00000000"], ["61614.36000000", "0.00000000"], ["61614.70000000", "0.02018000"], ["61614.74000000", "0.00031000"], ["61614.75000000", "0.00000000"], ["61615.15000000", "0.00000000"], ["61615.29000000", "0.02861000"], ["61615.97000000", "0.00000000"], ["61615.98000000", "0.00000000"], ["61615.99000000", "0.00009000"], ["61616.26000000", "0.00018000"], ["61616.35000000", "0.00931000"], ["61616.64000000", "0.00009000"], ["61616.65000000", "0.09080000"], ["61616.66000000", "0.01009000"], ["61618.13000000", "0.00000000"], ["61618.38000000", "0.00009000"], ["61618.47000000", "0.00009000"], ["61618.95000000", "0.00812000"], ["61619.33000000", "0.00400000"], ["61620.33000000", "0.00300000"], ["61622.40000000", "0.00000000"], ["61622.81000000", "0.00000000"], ["61623.96000000", "0.00000000"], ["61625.49000000", "0.00400000"], ["61627.26000000", "0.00649000"], ["61628.48000000", "0.00162000"], ["61641.00000000", "0.00400000"], ["61642.00000000", "0.03400000"], ["61651.10000000", "0.00000000"], ["61657.60000000", "0.00405000"], ["61665.60000000", "0.00000000"], ["61669.76000000", "0.13563000"], ["61672.49000000", "0.00010000"], ["61693.57000000", "0.00024000"], ["61696.80000000", "0.05036000"], ["61697.88000000", "0.00040000"], ["61727.21000000", "0.00000000"], ["61734.10000000", "0.00010000"], ["61773.78000000", "0.00000000"], ["61775.22000000", "0.02543000"], ["61784.01000000", "0.00009000"], ["61787.09000000", "0.00009000"], ["61788.81000000", "0.00000000"], ["61795.71000000", "0.00010000"], ["61850.42000000", "0.00000000"], ["61857.32000000", "0.00010000"], ["61912.02000000", "0.00000000"], ["61918.93000000", "0.00010000"], ["61973.62000000", "0.00000000"], ["61980.55000000", "0.00010000"], ["62035.23000000", "0.00000000"], ["62042.16000000", "0.00010000"], ["62096.83000000", "0.00000000"], ["62103.77000000", "0.00010000"]]}
{"type": "depth", "ts": 1783008103814, "U": 96863170525, "u": 96863170615, "bids": [["61610.87000000", "4.90028000"], ["61610.01000000", "0.63279000"], ["61610.00000000", "0.22883000"], ["61609.99000000", "1.33040000"], ["61609.94000000", "0.00009000"], ["61609.24000000", "0.55581000"], ["61609.23000000", "0.04969000"], ["61609.18000000", "0.16133000"], ["61609.13000000", "0.00000000"], ["61608.32000000", "0.00000000"], ["61601.99000000", "0.00009000"], ["61601.46000000", "0.23675000"], ["61589.88000000", "0.00324000"], ["61586.71000000", "0.00000000"], ["61580.00000000", "0.03416000"], ["61579.00000000", "0.00000000"], ["61578.01000000", "0.71162000"], ["61575.46000000", "0.00000000"], ["61551.68000000", "0.00000000"], ["61489.01000000", "0.03115000"], ["61454.94000000", "0.01001000"], ["55449.79000000", "0.00060000"], ["49288.70000000", "0.00020000"]], "asks": [["61610.88000000", "0.15888000"], ["61610.89000000", "0.00099000"], ["61612.00000000", "0.02418000"], ["61612.04000000", "0.00009000"], ["61613.95000000", "0.00000000"], ["61614.67000000", "0.00009000"], ["61614.68000000", "0.01400000"], ["61614.70000000", "0.02018000"], ["61615.28000000", "0.00000000"], ["61615.29000000", "0.00018000"], ["61615.56000000", "0.00009000"], ["61615.57000000", "0.02278000"], ["61616.00000000", "0.02427000"], ["61616.26000000", "0.00000000"], ["61616.35000000", "0.00931000"], ["61616.65000000", "0.09098000"], ["61618.47000000", "0.00000000"], ["61623.21000000", "0.00325000"], ["61775.22000000", "0.00000000"]]}
{"type": "depth", "ts": 1783008103914, "U": 96863170616, "u": 96863170657, "bids": [["61610.87000000", "4.92840000"], ["61610.01000000", "0.24727000"], ["61609.99000000", "1.06290000"], ["61609.23000000", "0.04157000"], ["61603.08000000", "0.00009000"], ["61590.34000000", "0.00000000"], ["61505.66000000", "0.00016000"], ["61497.67000000", "0.00000000"], ["61487.50000000", "0.00000000"], ["55449.79000000", "0.00100000"], ["49288.70000000", "0.00000000"]], "asks": [["61610.88000000", "0.09503000"], ["61614.00000000", "0.02418000"], ["61614.68000000", "0.00018000"], ["61614.70000000", "0.02018000"], ["61615.29000000", "0.00000000"], ["61615.57000000", "0.02296000"], ["61616.47000000", "0.00179000"], ["61616.66000000", "0.00991000"], ["61627.26000000", "0.00000000"], ["61690.34000000", "0.00000000"], ["61693.57000000", "0.00000000"], ["61697.88000000", "0.00000000"], ["62064.96000000", "0.00273000"]]}
{"type": "depth", "ts": 1783008104014, "U": 96863170658, "u": 96863170686, "bids": [["61610.87000000", "5.06107000"], ["61610.01000000", "0.38159000"], ["61601.46000000", "0.00000000"], ["61592.34000000", "0.00649000"], ["61592.01000000", "0.00000000"], ["61553.50000000", "0.00404000"], ["61539.47000000", "0.00000000"], ["61492.10000000", "0.00162000"], ["61475.26000000", "0.00000000"], ["60677.43000000", "0.00000000"], ["56682.01000000", "0.00018000"], ["55449.79000000", "0.00140000"], ["49289.00000000", "0.00402000"], ["49288.70000000", "0.00040000"]], "asks": [["61610.88000000", "0.09494000"], ["61610.89000000", "0.00090000"], ["61612.04000000", "0.00009000"], ["61614.00000000", "0.02418000"], ["61614.67000000", "0.00000000"], ["61614.68000000", "0.00000000"], ["61614.79000000", "0.00883000"], ["61616.66000000", "0.01009000"], ["62535.05000000", "0.00030000"]]}
{"type": "depth", "ts": 1783008104114, "U": 96863170687, "u": 96863171106, "bids": [["61611.99000000", "3.86673000"], ["61611.98000000", "0.00035000"], ["61611.97000000", "0.00017000"], ["61611.79000000", "0.00000000"], ["61611.71000000", "0.04000000"], ["61610.89000000", "0.64263000"], ["61610.88000000", "1.36818000"], ["61610.87000000", "1.08256000"], ["61610.86000000", "0.00000000"], ["61610.85000000", "0.00000000"], ["61610.32000000", "0.00000000"], ["61610.27000000", "0.12763000"], ["61610.25000000", "0.00000000"], ["61610.07000000", "0.00000000"], ["61610.01000000", "0.00018000"], ["61610.00000000", "0.15383000"], ["61609.99000000", "0.04909000"], ["61609.73000000", "0.03000000"], ["61609.24000000", "0.55572000"], ["61609.23000000", "0.04036000"], ["61609.18000000", "0.00000000"], ["61608.00000000", "0.00018000"], ["61607.99000000", "0.04506000"], ["61606.53000000", "0.12000000"], ["61605.83000000", "0.00010000"], ["61604.84000000", "1.36827000"], ["61604.44000000", "0.00009000"], ["61604.29000000", "0.00009000"], ["61603.99000000", "0.00036000"], ["61603.83000000", "0.00000000"], ["61602.55000000", "0.02191000"], ["61602.13000000", "0.00000000"], ["61602.00000000", "0.00000000"], ["61601.99000000", "0.00000000"], ["61601.42000000", "0.00009000"], ["61600.00000000", "0.00009000"], ["61599.71000000", "0.35910000"], ["61599.70000000", "0.00000000"], ["61599.67000000", "0.00010000"], ["61599.40000000", "0.00000000"], ["61597.48000000", "0.00009000"], ["61596.59000000", "0.00010000"], ["61595.67000000", "0.00000000"], ["61594.00000000", "0.01848000"], ["61593.73000000", "0.00000000"], ["61593.51000000", "0.00010000"], ["61592.59000000", "0.00000000"], ["61591.77000000", "0.01624000"], ["61590.66000000", "0.00000000"], ["61590.43000000", "0.00010000"], ["61589.51000000", "0.00000000"], ["61587.35000000", "0.00010000"], ["61586.43000000", "0.00000000"], ["61584.37000000", "0.00000000"], ["61584.26000000", "0.00010000"], ["61584.01000000", "0.04280000"], ["61583.35000000", "0.00000000"], ["61581.86000000", "0.58516000"], ["61581.18000000", "0.00010000"], ["61581.00000000", "0.01000000"], ["61580.27000000", "0.00000000"], ["61580.00000000", "0.02416000"], ["61577.19000000", "0.00000000"], ["61577.15000000", "0.00000000"], ["61571.90000000", "0.00000000"], ["61561.63000000", "0.00000000"], ["61533.41000000", "0.00030000"], ["61520.54000000", "0.00000000"], ["61510.61000000", "0.22405000"], ["61508.91000000", "0.00000000"], ["61497.80000000", "0.04639000"], ["61454.94000000", "0.00000000"], ["61450.01000000", "0.01001000"], ["61436.61000000", "0.00000000"], ["61352.47000000", "0.00000000"], ["60687.81000000", "0.00030000"], ["55450.80000000", "0.00020000"], ["55449.79000000", "0.00010000"], ["55438.20000000", "0.00000000"], ["49289.00000000", "0.00202000"]], "asks": [["61610.88000000", "0.00000000"], ["61610.89000000", "0.00000000"], ["61611.80000000", "0.00000000"], ["61611.99000000", "0.00000000"], ["61612.00000000", "0.78100000"], ["61612.01000000", "0.00072000"], ["61612.04000000", "0.00000000"], ["61612.85000000", "0.00009000"], ["61612.86000000", "0.08775000"], ["61613.26000000", "0.00000000"], ["61614.04000000", "0.00009000"], ["61614.05000000", "0.05000000"], ["61614.09000000", "0.00009000"], ["61614.10000000", "0.05000000"], ["61614.70000000", "0.02018000"], ["61614.74000000", "0.00000000"], ["61614.79000000", "0.00018000"], ["61614.87000000", "0.00009000"], ["61615.56000000", "0.00000000"], ["61615.57000000", "0.00018000"], ["61615.61000000", "0.00000000"], ["61616.00000000", "0.02418000"], ["61616.16000000", "0.00000000"], ["61616.50000000", "0.02690000"], ["61616.64000000", "0.00000000"], ["61616.65000000", "0.00027000"], ["61616.66000000", "0.01009000"], ["61616.81000000", "0.00009000"], ["61616.82000000", "0.00000000"], ["61617.32000000", "0.08440000"], ["61617.40000000", "0.00000000"], ["61617.41000000", "0.00000000"], ["61618.16000000", "0.00010000"], ["61618.38000000", "0.00000000"], ["61618.39000000", "0.00000000"], ["61618.47000000", "0.00000000"], ["61618.48000000", "0.00009000"], ["61618.64000000", "0.00009000"], ["61618.65000000", "0.08483000"], ["61618.95000000", "0.00000000"], ["61619.24000000", "0.00000000"], ["61619.33000000", "0.00000000"], ["61619.72000000", "0.14278000"], ["61619.73000000", "0.09172000"], ["61619.74000000", "0.00000000"], ["61620.32000000", "0.00000000"], ["61620.52000000", "0.00000000"], ["61621.31000000", "0.09172000"], ["61621.83000000", "0.12522000"], ["61621.97000000", "1.36330000"], ["61621.98000000", "0.00191000"], ["61621.99000000", "0.00000000"], ["61622.14000000", "0.00000000"], ["61622.77000000", "0.00812000"], ["61622.86000000", "0.00000000"], ["61623.21000000", "0.00000000"], ["61623.40000000", "0.00000000"], ["61623.44000000", "0.00000000"], ["61623.89000000", "0.00400000"], ["61623.97000000", "0.00000000"], ["61624.32000000", "0.00010000"], ["61624.53000000", "0.09172000"], ["61624.54000000", "0.07000000"], ["61624.67000000", "1.11014000"], ["61624.68000000", "1.36330000"], ["61624.69000000", "0.00000000"], ["61624.85000000", "0.00000000"], ["61624.86000000", "0.00000000"], ["61625.17000000", "0.00000000"], ["61625.24000000", "0.00000000"], ["61625.49000000", "0.00000000"], ["61626.44000000", "0.08000000"], ["61626.48000000", "0.00000000"], ["61627.40000000", "0.00010000"], ["61629.33000000", "0.08636000"], ["61629.56000000", "0.00000000"], ["61629.57000000", "0.00400000"], ["61629.60000000", "1.36330000"], ["61629.61000000", "0.00000000"], ["61629.69000000", "0.00000000"], ["61630.08000000", "0.97390000"], ["61630.09000000", "0.00000000"], ["61630.47000000", "0.00000000"], ["61630.48000000", "0.00010000"], ["61630.89000000", "0.00000000"], ["61632.36000000", "0.81233000"], ["61632.64000000", "0.00000000"], ["61633.56000000", "0.00010000"], ["61635.18000000", "0.00400000"], ["61635.72000000", "0.00000000"], ["61636.64000000", "0.00010000"], ["61638.80000000", "0.00000000"], ["61639.73000000", "0.00010000"], ["61640.57000000", "0.00000000"], ["61640.81000000", "0.38956000"], ["61642.00000000", "0.02400000"], ["61642.81000000", "0.00010000"], ["61643.00000000", "0.01000000"], ["61643.07000000", "0.58458000"], ["61643.43000000", "0.00000000"], ["61645.65000000", "0.00000000"], ["61648.02000000", "0.00000000"], ["61649.25000000", "0.00000000"], ["61649.38000000", "0.00000000"], ["61651.91000000", "0.00379000"], ["61652.50000000", "0.00000000"], ["61663.81000000", "0.00542000"], ["61669.76000000", "0.00000000"], ["61674.54000000", "0.00000000"], ["61674.80000000", "0.13967000"], ["61687.43000000", "0.00030000"], ["61707.99000000", "0.00000000"], ["61713.29000000", "0.00152000"], ["61789.82000000", "0.00009000"], ["61792.90000000", "0.00000000"], ["62535.05000000", "0.00000000"]]}
{"type": "depth", "ts": 1783008104214, "U": 96863171107, "u": 96863171341, "bids": [["61611.99000000", "3.78741000"], ["61611.72000000", "0.00009000"], ["61611.71000000", "0.04018000"], ["61611.18000000", "0.00009000"], ["61610.90000000", "0.00009000"], ["61610.89000000", "1.44561000"], ["61610.88000000", "1.36348000"], ["61610.87000000", "0.08857000"], ["61610.27000000", "0.00018000"], ["61610.01000000", "0.00000000"], ["61609.99000000", "0.04900000"], ["61609.83000000", "0.09069000"], ["61609.73000000", "0.00000000"], ["61609.35000000", "0.00812000"], ["61609.34000000", "0.00000000"], ["61609.25000000", "0.00000000"], ["61609.24000000", "0.48081000"], ["61609.23000000", "0.00009000"], ["61608.23000000", "0.08775000"], ["61608.00000000", "0.00000000"], ["61607.99000000", "0.00506000"], ["61607.83000000", "0.00000000"], ["61607.59000000", "0.01000000"], ["61607.53000000", "0.01000000"], ["61606.97000000", "0.01000000"], ["61606.92000000", "0.01000000"], ["61606.88000000", "0.00034000"], ["61606.84000000", "0.00000000"], ["61606.83000000", "0.03000000"], ["61606.15000000", "0.15392000"], ["61606.03000000", "0.97390000"], ["61606.00000000", "0.04033000"], ["61605.98000000", "0.00009000"], ["61604.51000000", "0.01000000"], ["61604.00000000", "0.00000000"], ["61603.99000000", "0.00000000"], ["61603.83000000", "0.01000000"], ["61602.81000000", "0.00895000"], ["61599.71000000", "0.18448000"], ["61596.26000000", "0.00000000"], ["61595.22000000", "0.00649000"], ["61592.34000000", "0.00000000"], ["61587.33000000", "0.58511000"], ["61579.81000000", "0.00009000"], ["61495.49000000", "0.00024000"], ["61362.53000000", "0.00093000"], ["61359.64000000", "0.00046000"], ["59701.00000000", "0.26010000"], ["55450.80000000", "0.00060000"], ["49288.70000000", "0.00000000"]], "asks": [["61612.00000000", "0.68382000"], ["61612.01000000", "0.00063000"], ["61612.86000000", "0.08811000"], ["61613.30000000", "0.00034000"], ["61614.00000000", "0.02418000"], ["61614.04000000", "0.00000000"], ["61614.05000000", "0.00027000"], ["61614.09000000", "0.00000000"], ["61614.10000000", "0.00018000"], ["61614.70000000", "0.02018000"], ["61614.79000000", "0.00000000"], ["61615.57000000", "0.00000000"], ["61615.98000000", "0.00000000"], ["61615.99000000", "0.00018000"], ["61616.03000000", "0.00000000"], ["61616.22000000", "0.00009000"], ["61616.23000000", "0.00000000"], ["61616.35000000", "0.00931000"], ["61616.43000000", "0.00000000"], ["61616.49000000", "0.00000000"], ["61616.50000000", "0.00018000"], ["61616.65000000", "0.00009000"], ["61616.66000000", "0.00991000"], ["61616.81000000", "0.00000000"], ["61617.31000000", "0.00009000"], ["61617.99000000", "0.00009000"], ["61618.17000000", "0.00000000"], ["61618.64000000", "0.00009000"], ["61619.46000000", "0.00400000"], ["61621.18000000", "0.00029000"], ["61621.83000000", "0.51616000"], ["61623.13000000", "0.00000000"], ["61623.26000000", "0.40100000"], ["61623.89000000", "0.00000000"], ["61623.97000000", "0.00000000"], ["61624.33000000", "0.00326000"], ["61624.36000000", "0.01800000"], ["61624.41000000", "0.01400000"], ["61624.53000000", "0.00000000"], ["61624.94000000", "0.97390000"], ["61624.97000000", "0.01200000"], ["61625.03000000", "0.01100000"], ["61627.44000000", "0.01000000"], ["61627.99000000", "0.58473000"], ["61629.26000000", "0.00000000"], ["61644.72000000", "0.00000000"], ["61658.90000000", "0.01741000"], ["61660.22000000", "0.00109000"], ["61674.62000000", "0.01800000"], ["61674.67000000", "0.01400000"], ["61675.23000000", "0.01200000"], ["61675.29000000", "0.01100000"], ["61677.70000000", "0.01000000"], ["61698.35000000", "0.00016000"], ["61701.59000000", "0.00024000"]]}
{"type": "depth", "ts": 1783008104314, "U": 96863171342, "u": 96863171421, "bids": [["61611.99000000", "3.78536000"], ["61610.89000000", "1.44552000"], ["61610.87000000", "0.08857000"], ["61610.27000000", "0.00000000"], ["61610.00000000", "0.15392000"], ["61609.99000000", "0.04900000"], ["61609.83000000", "0.09087000"], ["61609.25000000", "0.00009000"], ["61609.24000000", "0.48072000"], ["61606.97000000", "0.02000000"], ["61606.91000000", "0.01000000"], ["61604.14000000", "0.01000000"], ["61602.81000000", "0.00000000"], ["61602.69000000", "0.00000000"], ["61602.67000000", "0.00893000"], ["61600.73000000", "0.00009000"], ["61597.07000000", "0.00000000"], ["61597.02000000", "0.00000000"], ["61564.72000000", "1.50222000"], ["61547.61000000", "0.00000000"], ["61547.05000000", "0.00000000"], ["61522.69000000", "3.24118000"], ["55450.80000000", "0.00100000"]], "asks": [["61612.00000000", "0.68373000"], ["61612.01000000", "0.00072000"], ["61612.86000000", "0.08802000"], ["61613.30000000", "0.00000000"], ["61614.00000000", "0.02418000"], ["61614.05000000", "0.00000000"], ["61614.10000000", "0.00000000"], ["61615.98000000", "0.00009000"], ["61615.99000000", "0.09182000"], ["61616.12000000", "0.00009000"], ["61616.13000000", "0.03816000"], ["61616.22000000", "0.00000000"], ["61616.35000000", "0.00931000"], ["61616.50000000", "0.00000000"], ["61616.66000000", "0.01009000"], ["61617.32000000", "0.08467000"], ["61618.00000000", "0.02418000"], ["61639.82000000", "0.57390000"], ["61646.52000000", "1.50023000"], ["61658.96000000", "1.06470000"], ["61659.87000000", "0.03858000"], ["61670.82000000", "0.00829000"], ["61674.67000000", "0.00000000"], ["61675.23000000", "0.00000000"], ["63142.01000000", "0.00000000"]]}
{"type": "depth", "ts": 1783008104414, "U": 96863171422, "u": 96863171468, "bids": [["61611.99000000", "3.44624000"], ["61610.91000000", "0.00009000"], ["61610.90000000", "0.59283000"], ["61610.89000000", "0.97417000"], ["61609.83000000", "0.00018000"], ["61608.38000000", "0.10703000"], ["61603.83000000", "0.02191000"], ["61594.25000000", "0.00000000"], ["61591.65000000", "0.00009000"], ["61585.66000000", "0.00000000"], ["61579.81000000", "0.00000000"], ["55450.80000000", "0.00140000"]], "asks": [["61612.00000000", "1.21263000"], ["61612.01000000", "0.00081000"], ["61612.86000000", "0.08811000"], ["61614.70000000", "0.02018000"], ["61615.97000000", "0.00009000"], ["61615.98000000", "0.08796000"], ["61615.99000000", "0.09200000"], ["61616.00000000", "0.02418000"], ["61616.10000000", "0.04974000"], ["61616.13000000", "0.00018000"], ["61617.32000000", "0.08449000"], ["61618.00000000", "0.02400000"], ["61618.64000000", "0.00000000"], ["61622.78000000", "0.00000000"], ["61628.62000000", "0.00009000"], ["61635.48000000", "0.00428000"], ["61642.67000000", "0.03136000"], ["61705.89000000", "0.00040000"], ["62536.18000000", "0.00030000"]]}
{"type": "depth", "ts": 1783008104514, "U": 96863171469, "u": 96863171545, "bids": [["61611.99000000", "3.17874000"], ["61611.71000000", "0.04018000"], ["61610.90000000", "0.59301000"], ["61610.00000000", "0.15383000"], ["61609.99000000", "0.04900000"], ["61609.83000000", "0.00000000"], ["61609.24000000", "0.48081000"], ["61607.99000000", "0.00515000"], ["61605.82000000", "0.24750000"], ["61605.02000000", "0.01000000"], ["61603.89000000", "0.01200000"], ["61602.00000000", "0.00500000"], ["61600.00000000", "0.00509000"], ["61598.00000000", "0.00500000"], ["61596.00000000", "0.00571000"], ["61594.00000000", "0.02348000"], ["61593.99000000", "0.00000000"], ["61553.11000000", "0.00000000"], ["61552.80000000", "0.00000000"], ["61551.07000000", "0.01000000"], ["61461.96000000", "0.00000000"], ["55450.80000000", "0.00180000"]], "asks": [["61612.00000000", "1.67529000"], ["61612.01000000", "0.00054000"], ["61614.70000000", "0.02018000"], ["61615.98000000", "0.08814000"], ["61616.00000000", "0.02418000"], ["61616.09000000", "0.00009000"], ["61616.10000000", "0.04992000"], ["61616.12000000", "0.00000000"], ["61616.13000000", "0.00000000"], ["61616.66000000", "0.00991000"], ["61617.31000000", "0.00000000"], ["61617.99000000", "0.00000000"], ["61623.23000000", "0.01600000"], ["61661.46000000", "0.00400000"], ["61662.48000000", "0.00000000"], ["61675.29000000", "0.00000000"]]}
{"type": "depth", "ts": 1783008104614, "U": 96863171546, "u": 96863171717, "bids": [["61611.99000000", "2.05120000"], ["61610.92000000", "0.39608000"], ["61610.91000000", "1.36330000"], ["61610.90000000", "0.00018000"], ["61610.89000000", "0.00018000"], ["61610.88000000", "0.00027000"], ["61610.00000000", "0.00018000"], ["61609.35000000", "0.00000000"], ["61609.24000000", "0.48063000"], ["61608.39000000", "0.00000000"], ["61608.38000000", "0.00000000"], ["61608.24000000", "0.00000000"], ["61608.23000000", "0.00000000"], ["61608.10000000", "0.00000000"], ["61608.09000000", "0.08273000"], ["61607.99000000", "0.00515000"], ["61606.88000000", "0.00000000"], ["61606.85000000", "0.00034000"], ["61606.84000000", "0.00812000"], ["61606.83000000", "0.00000000"], ["61606.53000000", "0.00000000"], ["61606.04000000", "0.00000000"], ["61606.03000000", "0.97390000"], ["61606.00000000", "0.00033000"], ["61605.82000000", "0.25150000"], ["61604.85000000", "0.00009000"], ["61603.98000000", "0.00000000"], ["61603.93000000", "0.03000000"], ["61603.65000000", "0.00000000"], ["61603.62000000", "0.01018000"], ["61603.43000000", "0.12000000"], ["61602.67000000", "0.00000000"], ["61598.67000000", "0.00000000"], ["61595.23000000", "0.00000000"], ["61593.93000000", "0.00000000"], ["61584.01000000", "0.01051000"], ["61581.41000000", "0.00000000"], ["61579.95000000", "0.00000000"], ["61579.81000000", "0.00009000"], ["61578.67000000", "0.58519000"], ["61578.30000000", "0.03174000"], ["61568.79000000", "1.18366000"], ["61566.74000000", "0.61734000"], ["61551.07000000", "0.00000000"], ["61538.29000000", "1.47729000"], ["61538.28000000", "4.87986000"], ["61538.01000000", "0.00000000"], ["61501.61000000", "0.00016000"], ["61488.57000000", "0.04217000"], ["56682.01000000", "0.00000000"], ["55450.80000000", "0.00220000"]], "asks": [["61612.00000000", "1.71774000"], ["61612.01000000", "0.00036000"], ["61612.84000000", "0.00009000"], ["61612.85000000", "0.00009000"], ["61612.86000000", "0.08820000"], ["61613.25000000", "0.00034000"], ["61614.65000000", "0.00009000"], ["61614.66000000", "0.00009000"], ["61614.69000000", "0.00009000"], ["61615.86000000", "0.00009000"], ["61615.87000000", "0.06629000"], ["61615.97000000", "0.00009000"], ["61615.98000000", "0.08814000"], ["61615.99000000", "0.09200000"], ["61616.09000000", "0.00000000"], ["61616.10000000", "0.00018000"], ["61620.94000000", "0.04217000"], ["61624.53000000", "0.00000000"], ["61624.91000000", "0.58476000"], ["61631.92000000", "0.00230000"], ["61632.14000000", "0.00649000"], ["61637.44000000", "1.57004000"], ["61639.48000000", "1.60771000"], ["61643.07000000", "0.00000000"], ["61647.48000000", "0.01000000"], ["61652.16000000", "0.60681000"], ["61658.80000000", "0.00400000"], ["61661.46000000", "0.00000000"], ["61681.13000000", "0.83777000"], ["61703.03000000", "0.48669000"], ["61737.56000000", "0.00000000"]]}
{"type": "depth", "ts": 1783008104714, "U": 96863171718, "u": 96863171804, "bids": [["61611.99000000", "2.05061000"], ["61611.71000000", "0.04018000"], ["61610.93000000", "0.00009000"], ["61610.92000000", "0.39626000"], ["61610.91000000", "1.36348000"], ["61610.90000000", "0.00000000"], ["61610.89000000", "0.00000000"], ["61610.88000000", "0.00009000"], ["61610.87000000", "0.08848000"], ["61610.00000000", "0.00000000"], ["61609.99000000", "0.04900000"], ["61609.24000000", "0.48081000"], ["61608.09000000", "0.08291000"], ["61596.34000000", "0.00649000"], ["61595.22000000", "0.00000000"], ["61593.51000000", "0.00026000"], ["61575.52000000", "0.00000000"], ["61575.02000000", "0.00016000"], ["61557.04000000", "0.00000000"], ["61556.54000000", "0.00016000"], ["61550.81000000", "0.00000000"], ["61547.67000000", "0.00000000"], ["61538.57000000", "0.00000000"], ["61538.06000000", "0.00016000"], ["61520.09000000", "0.00000000"], ["61519.57000000", "0.00016000"], ["61501.61000000", "0.00000000"], ["61466.52000000", "0.00000000"], ["55450.80000000", "0.00260000"], ["49289.59000000", "0.00000000"]], "asks": [["61612.00000000", "1.71783000"], ["61612.49000000", "0.00000000"], ["61612.84000000", "0.00000000"], ["61613.02000000", "0.00009000"], ["61613.25000000", "0.00000000"], ["61614.65000000", "0.00000000"], ["61614.70000000", "0.02018000"], ["61615.87000000", "0.06647000"], ["61616.00000000", "0.02418000"], ["61616.10000000", "0.00000000"], ["61624.33000000", "0.00626000"], ["61630.48000000", "0.00026000"], ["61630.97000000", "0.00000000"], ["61632.14000000", "0.00000000"], ["61648.97000000", "0.00016000"], ["61649.44000000", "0.00000000"], ["61667.45000000", "0.00016000"], ["61667.92000000", "0.00000000"], ["61674.62000000", "0.00000000"], ["61677.70000000", "0.00000000"], ["61685.93000000", "0.00016000"], ["61686.40000000", "0.00000000"], ["61704.42000000", "0.00016000"]]}
{"type": "depth", "ts": 1783008104814, "U": 96863171805, "u": 96863171943, "bids": [["61611.99000000", "0.77825000"], ["61610.94000000", "0.00000000"], ["61610.93000000", "0.00009000"], ["61610.92000000", "0.00027000"], ["61610.91000000", "0.00018000"], ["61610.88000000", "0.00000000"], ["61610.87000000", "0.00045000"], ["61609.68000000", "0.00000000"], ["61609.24000000", "0.00036000"], ["61609.11000000", "0.00000000"], ["61608.66000000", "0.04848000"], ["61608.09000000", "0.00018000"], ["61607.99000000", "0.00045000"], ["61606.85000000", "0.00000000"], ["61606.84000000", "0.00000000"], ["61606.15000000", "0.00027000"], ["61606.05000000", "0.00009000"], ["61606.04000000", "0.00000000"], ["61606.03000000", "0.00009000"], ["61606.02000000", "0.73985000"], ["61605.82000000", "0.24750000"], ["61605.35000000", "0.00009000"], ["61604.85000000", "0.00018000"], ["61604.84000000", "1.36339000"], ["61604.24000000", "0.08775000"], ["61604.08000000", "0.00047000"], ["61603.93000000", "0.00000000"], ["61603.90000000", "0.00812000"], ["61603.43000000", "0.01000000"], ["61603.04000000", "0.00048000"], ["61598.43000000", "0.14000000"], ["61594.50000000", "0.00000000"], ["61593.31000000", "0.00000000"], ["61591.77000000", "0.00000000"], ["61590.66000000", "0.00400000"], ["61580.14000000", "0.58518000"], ["61576.88000000", "0.00009000"], ["61563.04000000", "0.00409000"], ["61549.77000000", "0.00000000"], ["61549.61000000", "0.97494000"], ["61524.75000000", "0.01658000"], ["55450.80000000", "0.00280000"], ["55450.00000000", "0.40804000"]], "asks": [["61612.00000000", "1.77642000"], ["61612.01000000", "0.00018000"], ["61612.84000000", "0.00009000"], ["61612.85000000", "0.08550000"], ["61612.86000000", "0.08829000"], ["61613.18000000", "0.00898000"], ["61613.32000000", "0.08840000"], ["61613.33000000", "0.00000000"], ["61613.39000000", "0.00034000"], ["61613.99000000", "0.00000000"], ["61614.65000000", "0.00000000"], ["61614.66000000", "0.08891000"], ["61614.69000000", "0.00000000"], ["61614.70000000", "0.00018000"], ["61614.88000000", "0.00000000"], ["61614.89000000", "0.07188000"], ["61615.86000000", "0.00000000"], ["61615.87000000", "0.00018000"], ["61615.97000000", "0.00000000"], ["61615.98000000", "0.08805000"], ["61615.99000000", "0.09191000"], ["61616.24000000", "0.00400000"], ["61618.24000000", "0.03000000"], ["61619.76000000", "0.00000000"], ["61620.02000000", "0.00000000"], ["61623.22000000", "0.00000000"], ["61624.53000000", "0.00000000"], ["61624.54000000", "0.04000000"], ["61639.40000000", "0.03157000"], ["61642.67000000", "0.00000000"], ["61656.14000000", "0.00400000"], ["61657.20000000", "0.00000000"], ["61658.80000000", "0.00000000"]]}
{"type": "depth", "ts": 1783008104914, "U": 96863171944, "u": 96863172070, "bids": [["61611.99000000", "0.77959000"], ["61611.71000000", "0.00018000"], ["61610.93000000", "0.00000000"], ["61610.92000000", "0.00000000"], ["61610.91000000", "0.00000000"], ["61610.87000000", "0.00027000"], ["61610.00000000", "0.00009000"], ["61609.99000000", "0.04738000"], ["61609.94000000", "0.00000000"], ["61609.25000000", "0.00000000"], ["61609.24000000", "0.00000000"], ["61608.67000000", "0.00009000"], ["61608.66000000", "0.04866000"], ["61608.09000000", "0.00000000"], ["61608.00000000", "0.00009000"], ["61607.99000000", "0.42637000"], ["61607.98000000", "1.36348000"], ["61607.59000000", "0.01018000"], ["61607.53000000", "0.01018000"], ["61607.04000000", "0.00000000"], ["61606.99000000", "0.00000000"], ["61606.97000000", "0.02018000"], ["61606.92000000", "0.01018000"], ["61606.87000000", "0.00034000"], ["61606.18000000", "0.00000000"], ["61606.05000000", "0.00000000"], ["61606.03000000", "0.00009000"], ["61605.83000000", "0.00019000"], ["61604.88000000", "0.00009000"], ["61604.37000000", "0.00069000"], ["61604.24000000", "0.00000000"], ["61603.01000000", "0.00153000"], ["61598.43000000", "0.00000000"], ["61597.73000000", "0.14000000"], ["61565.70000000", "0.00400000"], ["61549.61000000", "0.00000000"], ["61548.88000000", "0.00000000"], ["61548.09000000", "0.97494000"], ["61511.98000000", "0.00000000"], ["61505.01000000", "0.05396000"], ["61470.85000000", "0.00000000"], ["61467.91000000", "0.00039000"], ["55450.80000000", "0.00320000"], ["55450.00000000", "0.40784000"], ["49289.59000000", "0.00000000"]], "asks": [["61612.00000000", "1.77831000"], ["61612.85000000", "0.08568000"], ["61612.86000000", "0.08829000"], ["61613.18000000", "0.00916000"], ["61613.32000000", "0.08858000"], ["61614.00000000", "0.02418000"], ["61614.66000000", "0.08900000"], ["61614.70000000", "0.00000000"], ["61614.89000000", "0.07206000"], ["61615.87000000", "0.00000000"], ["61615.99000000", "0.09173000"], ["61616.00000000", "0.02400000"], ["61616.35000000", "0.00913000"], ["61617.54000000", "0.04016000"], ["61621.64000000", "0.58479000"], ["61621.98000000", "0.00000000"], ["61623.21000000", "0.08940000"], ["61624.32000000", "0.00333000"], ["61624.33000000", "0.00300000"], ["61639.55000000", "0.00000000"], ["61689.81000000", "0.05037000"], ["61696.80000000", "0.00000000"]]}
{"type": "depth", "ts": 1783008105014, "U": 96863172071, "u": 96863172113, "bids": [["61611.99000000", "0.77685000"], ["61611.72000000", "0.00000000"], ["61611.71000000", "0.00000000"], ["61610.00000000", "0.04365000"], ["61609.49000000", "0.00009000"], ["61609.48000000", "0.09854000"], ["61608.86000000", "0.00243000"], ["61608.66000000", "0.04866000"], ["61606.03000000", "0.97399000"], ["61604.88000000", "0.00497000"], ["61604.44000000", "0.00009000"], ["61604.40000000", "0.00448000"], ["61599.22000000", "0.00874000"], ["61548.09000000", "0.00000000"], ["61507.04000000", "0.03691000"], ["61399.50000000", "0.00000000"], ["55450.80000000", "0.00360000"], ["49289.60000000", "0.00040000"]], "asks": [["61612.00000000", "1.77840000"], ["61612.84000000", "0.00000000"], ["61612.85000000", "0.08559000"], ["61613.39000000", "0.00000000"], ["61621.62000000", "0.09173000"], ["61621.63000000", "0.80476000"], ["61621.83000000", "0.00000000"], ["61621.84000000", "0.00000000"], ["61623.21000000", "0.00000000"]]}
{"type": "depth", "ts": 1783008105114, "U": 96863172114, "u": 96863172145, "bids": [["61611.99000000", "0.77751000"], ["61611.12000000", "0.09645000"], ["61610.01000000", "0.00009000"], ["61610.00000000", "0.04383000"], ["61609.99000000", "0.04738000"], ["61609.48000000", "0.00000000"], ["61606.97000000", "0.02000000"], ["61606.92000000", "0.01000000"], ["61606.04000000", "0.00009000"], ["61605.83000000", "0.00010000"], ["61604.40000000", "0.00400000"], ["61598.41000000", "0.00009000"], ["61589.26000000", "0.01624000"], ["61548.08000000", "0.00000000"], ["61548.06000000", "0.97494000"], ["61509.55000000", "0.12000000"], ["60687.81000000", "0.00030000"], ["55450.80000000", "0.00400000"]], "asks": [["61612.00000000", "1.78815000"], ["61654.05000000", "0.00000000"], ["61701.10000000", "0.00009000"]]}
{"type": "depth", "ts": 1783008105214, "U": 96863172146, "u": 96863172184, "bids": [["61611.99000000", "0.77752000"], ["61611.13000000", "0.00009000"], ["61610.01000000", "0.00000000"], ["61610.00000000", "0.00027000"], ["61609.99000000", "0.04720000"], ["61609.49000000", "0.00000000"], ["61608.98000000", "0.00009000"], ["61608.97000000", "0.02191000"], ["61604.88000000", "0.00488000"], ["61604.85000000", "0.00009000"], ["61604.49000000", "0.00000000"], ["61602.55000000", "0.00000000"], ["61548.06000000", "0.00000000"], ["61548.04000000", "0.97494000"], ["61497.07000000", "0.00034000"], ["61468.94000000", "0.00050000"], ["61467.91000000", "0.00000000"], ["61450.01000000", "0.00000000"], ["61442.87000000", "0.01002000"], ["55450.80000000", "0.00440000"], ["55450.79000000", "0.00010000"], ["55449.79000000", "0.00000000"], ["49289.60000000", "0.00000000"]], "asks": [["61612.00000000", "1.78832000"], ["61612.01000000", "0.00035000"], ["61612.02000000", "0.00017000"], ["61613.32000000", "0.00018000"], ["61633.26000000", "0.00649000"], ["61686.39000000", "0.00000000"]]}
{"type": "depth", "ts": 1783008105314, "U": 96863172185, "u": 96863172216, "bids": [["61611.18000000", "0.00000000"], ["61611.12000000", "0.09663000"], ["61610.00000000", "0.00009000"], ["61606.00000000", "0.00833000"], ["61604.88000000", "0.00497000"], ["61604.00000000", "0.00800000"], ["61589.00000000", "0.01000000"], ["61588.95000000", "0.01000000"], ["61586.18000000", "0.01000000"], ["61554.61000000", "0.00000000"], ["55450.80000000", "0.00460000"]], "asks": [["61612.00000000", "1.80685000"], ["61612.86000000", "0.08820000"], ["61613.18000000", "0.00916000"], ["61613.32000000", "0.00000000"], ["61613.63000000", "0.00009000"], ["61615.99000000", "0.09191000"], ["61658.96000000", "0.00000000"], ["61688.84000000", "0.05294000"], ["61689.81000000", "0.00000000"]]}
{"type": "depth", "ts": 1783008105414, "U": 96863172217, "u": 96863172236, "bids": [["61611.12000000", "0.00018000"], ["61604.88000000", "0.00497000"], ["61602.00000000", "0.01300000"], ["61600.00000000", "0.01309000"], ["61598.00000000", "0.01300000"], ["61596.34000000", "0.00000000"], ["61596.33000000", "0.00649000"], ["61596.00000000", "0.01371000"], ["61591.65000000", "0.00000000"], ["61585.87000000", "0.01000000"], ["61549.45000000", "0.00000000"], ["61542.01000000", "0.82065000"], ["55450.80000000", "0.00440000"]], "asks": [["61623.79000000", "0.00009000"], ["61628.62000000", "0.00000000"], ["61633.26000000", "0.00000000"], ["62536.18000000", "0.00030000"]]}
{"type": "depth", "ts": 1783008105514, "U": 96863172237, "u": 96863172268, "bids": [["61611.99000000", "0.77812000"], ["61611.13000000", "0.00000000"], ["61611.12000000", "0.00000000"], ["61609.99000000", "0.04738000"], ["61608.00000000", "0.00497000"], ["61604.88000000", "0.00488000"], ["61604.85000000", "0.00009000"], ["61604.37000000", "0.00000000"], ["61591.65000000", "0.00009000"], ["61587.16000000", "0.01000000"], ["61585.93000000", "0.01200000"], ["61553.20000000", "0.00000000"], ["61552.80000000", "0.00000000"], ["61551.07000000", "0.00000000"], ["55450.80000000", "0.00420000"]], "asks": [["61612.00000000", "1.80846000"], ["61612.84000000", "0.00009000"], ["61612.85000000", "0.08568000"], ["61613.99000000", "0.00009000"], ["61614.65000000", "0.00009000"], ["61614.88000000", "0.00009000"], ["61628.62000000", "0.00009000"], ["61633.25000000", "0.00649000"], ["61717.23000000", "0.00000000"]]}
{"type": "depth", "ts": 1783008105614, "U": 96863172269, "u": 96863172277, "bids": [["61610.00000000", "0.00609000"], ["61564.47000000", "0.00000000"], ["61560.58000000", "0.00000000"], ["61560.30000000", "0.13532000"], ["55450.80000000", "0.00420000"]], "asks": []}
{"type": "depth", "ts": 1783008105714, "U": 96863172278, "u": 96863172314, "bids": [["61611.28000000", "0.08109000"], ["61608.01000000", "0.09163000"], ["61608.00000000", "0.01097000"], ["61606.00000000", "0.01433000"], ["61604.00000000", "0.01400000"], ["61602.00000000", "0.01900000"], ["61600.00000000", "0.01909000"], ["61598.00000000", "0.01900000"], ["61596.00000000", "0.01922000"], ["61580.15000000", "0.55097000"], ["61555.85000000", "0.53135000"], ["61522.94000000", "1.97318000"], ["61469.95000000", "0.00037000"], ["61468.94000000", "0.00012000"], ["55450.80000000", "0.00420000"]], "asks": [["61612.00000000", "1.80864000"], ["61612.01000000", "0.00044000"], ["61631.54000000", "0.55934000"], ["61633.92000000", "0.55085000"], ["61674.87000000", "0.82951000"], ["61675.40000000", "0.00000000"], ["61693.31000000", "0.40824000"], ["61715.76000000", "1.58601000"]]}
{"type": "depth", "ts": 1783008105815, "U": 96863172315, "u": 96863172355, "bids": [["61611.99000000", "0.77839000"], ["61611.30000000", "0.05257000"], ["61611.29000000", "0.00009000"], ["61611.28000000", "0.08136000"], ["61610.57000000", "0.00009000"], ["61610.00000000", "0.00627000"], ["61609.96000000", "0.00009000"], ["61608.97000000", "0.02209000"], ["61608.66000000", "0.04848000"], ["61608.02000000", "1.36339000"], ["61607.98000000", "0.00000000"], ["61607.59000000", "0.01000000"], ["61607.53000000", "0.01000000"], ["61606.03000000", "0.00009000"], ["61589.26000000", "0.00000000"], ["61580.15000000", "0.30186000"], ["61551.06000000", "0.00000000"], ["55450.80000000", "0.00440000"], ["49289.59000000", "0.00000000"]], "asks": [["61612.00000000", "1.81846000"], ["61612.01000000", "0.00035000"]]}
{"type": "depth", "ts": 1783008105914, "U": 96863172356, "u": 96863172388, "bids": [["61611.99000000", "0.77839000"], ["61611.31000000", "0.00000000"], ["61611.30000000", "0.00000000"], ["61611.28000000", "0.08136000"], ["61608.04000000", "0.00009000"], ["61608.03000000", "0.45581000"], ["61608.02000000", "1.36330000"], ["61608.01000000", "0.00000000"], ["61608.00000000", "0.01088000"], ["61607.99000000", "0.00009000"], ["61606.04000000", "0.00009000"], ["61606.03000000", "0.97399000"], ["61605.83000000", "0.00010000"], ["55450.80000000", "0.00440000"], ["49289.59000000", "0.00000000"]], "asks": [["61613.29000000", "0.00035000"], ["61628.40000000", "0.00009000"]]}
{"type": "depth", "ts": 1783008106014, "U": 96863172389, "u": 96863172398, "bids": [["61611.99000000", "0.77757000"], ["61611.28000000", "0.08145000"], ["61608.05000000", "0.00009000"], ["61608.04000000", "0.09182000"], ["55450.80000000", "0.00440000"], ["55450.00000000", "0.40804000"], ["49289.60000000", "0.00040000"]], "asks": []}
{"type": "depth", "ts": 1783008106114, "U": 96863172399, "u": 96863172414, "bids": [["61606.18000000", "0.00009000"], ["61603.70000000", "0.08775000"], ["61534.53000000", "0.00030000"], ["61533.41000000", "0.00000000"], ["60687.81000000", "0.00030000"], ["55450.80000000", "0.00420000"], ["55450.00000000", "0.40784000"], ["33000.00000000", "37.44360000"]], "asks": [["61687.43000000", "0.00000000"], ["61688.56000000", "0.00030000"], ["61698.08000000", "0.00009000"], ["61701.36000000", "0.00009000"], ["62481.58000000", "0.00352000"]]}
{"type": "depth", "ts": 1783008106214, "U": 96863172415, "u": 96863172449, "bids": [["61611.99000000", "0.77847000"], ["61611.98000000", "0.00071000"], ["61611.30000000", "0.00009000"], ["61611.29000000", "0.04058000"], ["61610.87000000", "0.00036000"], ["61610.86000000", "0.04000000"], ["61606.03000000", "0.97390000"], ["61605.99000000", "0.00046000"], ["61587.87000000", "0.01624000"], ["61470.95000000", "0.00036000"], ["61469.95000000", "0.00000000"], ["55450.80000000", "0.00420000"], ["49289.60000000", "0.00000000"], ["33000.00000000", "37.44300000"]], "asks": []}
{"type": "depth", "ts": 1783008106314, "U": 96863172450, "u": 96863172468, "bids": [["61611.99000000", "1.02606000"], ["61611.28000000", "0.08127000"], ["61609.96000000", "0.00000000"], ["61606.04000000", "0.00000000"], ["61604.36000000", "0.00400000"], ["55450.80000000", "0.00420000"]], "asks": [["61612.00000000", "1.81657000"], ["61614.66000000", "0.00027000"], ["61615.97000000", "0.00009000"], ["61615.98000000", "0.08814000"], ["61615.99000000", "0.09200000"], ["61620.37000000", "0.00190000"]]}
{"type": "depth", "ts": 1783008106414, "U": 96863172469, "u": 96863172661, "bids": [["61611.99000000", "2.67095000"], ["61611.98000000", "0.00035000"], ["61611.30000000", "0.00000000"], ["61611.29000000", "0.10209000"], ["61611.28000000", "0.08154000"], ["61610.87000000", "0.00027000"], ["61610.86000000", "0.04018000"], ["61610.66000000", "0.00018000"], ["61610.00000000", "0.00618000"], ["61609.91000000", "0.00000000"], ["61609.33000000", "0.09182000"], ["61609.11000000", "0.00009000"], ["61608.98000000", "0.00000000"], ["61608.67000000", "0.00000000"], ["61608.66000000", "0.08793000"], ["61608.26000000", "0.00400000"], ["61608.05000000", "0.00000000"], ["61608.04000000", "0.09191000"], ["61608.03000000", "0.39516000"], ["61608.00000000", "0.01588000"], ["61604.08000000", "0.00000000"], ["61603.70000000", "0.00000000"], ["61603.04000000", "0.00000000"], ["61602.21000000", "0.04217000"], ["61593.21000000", "0.58506000"], ["61587.87000000", "0.00000000"], ["61580.24000000", "1.60925000"], ["61580.15000000", "0.00000000"], ["61580.14000000", "0.00000000"], ["61579.81000000", "0.00000000"], ["61578.67000000", "0.00000000"], ["61576.88000000", "0.00000000"], ["61568.36000000", "0.00400000"], ["61565.70000000", "0.00000000"], ["61563.04000000", "0.00009000"], ["61538.29000000", "0.00000000"], ["61538.28000000", "0.00000000"], ["61488.57000000", "0.00000000"], ["61442.87000000", "0.01017000"], ["55450.80000000", "0.00430000"], ["55450.79000000", "0.00000000"]], "asks": [["61612.00000000", "0.20990000"], ["61612.01000000", "0.00080000"], ["61612.84000000", "0.00000000"], ["61612.85000000", "0.00027000"], ["61613.72000000", "0.00000000"], ["61613.73000000", "0.00000000"], ["61614.00000000", "0.02418000"], ["61614.65000000", "0.00000000"], ["61614.66000000", "0.00009000"], ["61614.88000000", "0.00000000"], ["61614.89000000", "0.00018000"], ["61615.97000000", "0.00000000"], ["61615.98000000", "0.00018000"], ["61615.99000000", "0.00027000"], ["61616.00000000", "0.02418000"], ["61616.22000000", "0.00009000"], ["61616.23000000", "0.00000000"], ["61617.31000000", "0.00009000"], ["61617.32000000", "0.08458000"], ["61617.53000000", "0.00009000"], ["61617.54000000", "0.06016000"], ["61617.99000000", "0.00009000"], ["61618.23000000", "0.00009000"], ["61618.64000000", "0.00009000"], ["61619.46000000", "0.00000000"], ["61620.66000000", "0.00400000"], ["61620.94000000", "0.00000000"], ["61621.47000000", "0.00048000"], ["61621.63000000", "0.16942000"], ["61621.64000000", "0.00000000"], ["61621.72000000", "0.00048000"], ["61621.97000000", "0.00000000"], ["61623.22000000", "0.08536000"], ["61624.32000000", "0.00010000"], ["61624.33000000", "0.00625000"], ["61624.66000000", "0.08547000"], ["61624.91000000", "0.00000000"], ["61624.94000000", "0.00000000"], ["61636.21000000", "0.58465000"], ["61643.83000000", "0.59858000"], ["62536.18000000", "0.00030000"]]}
{"type": "depth", "ts": 1783008106514, "U": 96863172662, "u": 96863172745, "bids": [["61611.99000000", "2.67284000"], ["61611.28000000", "0.08163000"], ["61610.66000000", "0.00009000"], ["61610.25000000", "0.16230000"], ["61610.10000000", "0.00000000"], ["61609.99000000", "0.04738000"], ["61608.04000000", "0.09173000"], ["61606.00000000", "0.01933000"], ["61604.00000000", "0.01900000"], ["61603.83000000", "0.02000000"], ["61602.00000000", "0.02400000"], ["61600.00000000", "0.02409000"], ["61598.00000000", "0.02400000"], ["61596.00000000", "0.02422000"], ["61594.00000000", "0.02409000"], ["61591.65000000", "0.00009000"], ["55450.80000000", "0.00450000"]], "asks": [["61612.00000000", "0.04912000"], ["61612.01000000", "0.00098000"], ["61612.85000000", "0.00000000"], ["61612.86000000", "0.00027000"], ["61613.17000000", "0.00009000"], ["61614.00000000", "0.02418000"], ["61614.66000000", "0.00000000"], ["61614.89000000", "0.00000000"], ["61614.97000000", "0.00000000"], ["61615.98000000", "0.00000000"], ["61615.99000000", "0.00009000"], ["61616.22000000", "0.00000000"], ["61616.24000000", "0.00000000"], ["61616.35000000", "0.00931000"], ["61616.50000000", "0.00000000"], ["61616.51000000", "0.00009000"], ["61616.65000000", "0.00018000"], ["61616.66000000", "0.01009000"], ["61616.98000000", "0.00009000"], ["61616.99000000", "0.02036000"], ["61617.32000000", "0.08476000"], ["61617.54000000", "0.06034000"], ["61628.62000000", "0.00009000"], ["61630.81000000", "1.37392000"], ["61631.92000000", "0.00000000"], ["61642.45000000", "0.02812000"], ["61664.12000000", "0.05023000"]]}
{"type": "depth", "ts": 1783008106614, "U": 96863172746, "u": 96863172792, "bids": [["61610.86000000", "0.04018000"], ["61609.33000000", "0.09173000"], ["61609.02000000", "0.04217000"], ["61608.66000000", "0.00000000"], ["61596.36000000", "0.58503000"], ["61497.80000000", "0.00000000"], ["55450.80000000", "0.00450000"]], "asks": [["61612.00000000", "0.04882000"], ["61612.86000000", "0.00009000"], ["61616.66000000", "0.01009000"], ["61616.99000000", "0.02054000"], ["61617.90000000", "0.00000000"], ["61619.68000000", "0.00048000"], ["61619.72000000", "0.00000000"], ["61620.83000000", "0.00000000"], ["61621.63000000", "0.00000000"], ["61623.21000000", "0.18394000"], ["61623.76000000", "0.00000000"], ["61624.67000000", "1.02881000"], ["61624.68000000", "0.00000000"], ["61624.94000000", "1.36330000"], ["61626.69000000", "0.00000000"], ["61627.87000000", "0.74913000"], ["61629.62000000", "0.00000000"], ["61630.07000000", "0.97390000"], ["61630.08000000", "0.00000000"], ["61632.55000000", "0.00000000"], ["61635.48000000", "0.00419000"], ["61638.41000000", "0.00000000"], ["61641.34000000", "0.00000000"]]}
{"type": "depth", "ts": 1783008106714, "U": 96863172793, "u": 96863172845, "bids": [["61611.28000000", "0.08172000"], ["61610.66000000", "0.00000000"], ["61610.32000000", "0.08775000"], ["61610.25000000", "0.00018000"], ["61610.09000000", "0.11771000"], ["61609.33000000", "0.00000000"], ["61608.97000000", "0.02191000"], ["61580.25000000", "0.75582000"], ["61553.26000000", "0.31427000"], ["61471.93000000", "0.00035000"], ["61470.95000000", "0.00000000"], ["55450.80000000", "0.00470000"]], "asks": [["61612.00000000", "0.21300000"], ["61612.01000000", "0.00098000"], ["61613.51000000", "0.00009000"], ["61613.52000000", "0.08775000"], ["61614.97000000", "0.00009000"], ["61616.27000000", "0.00000000"], ["61616.49000000", "0.00009000"], ["61616.50000000", "0.03117000"], ["61616.65000000", "0.00009000"], ["61616.98000000", "0.00000000"], ["61616.99000000", "0.00018000"], ["61617.90000000", "0.00009000"], ["61619.68000000", "0.00000000"], ["61619.72000000", "0.14446000"], ["61620.83000000", "0.00009000"], ["61623.76000000", "0.00009000"], ["61624.93000000", "1.36330000"], ["61624.94000000", "0.00000000"], ["61626.69000000", "0.00009000"], ["61629.62000000", "0.00009000"], ["61632.55000000", "0.00009000"], ["61635.48000000", "0.00428000"], ["61638.41000000", "0.00009000"], ["61641.34000000", "0.00009000"], ["61646.51000000", "1.30614000"], ["61684.19000000", "0.48850000"], ["61710.18000000", "0.07388000"]]}
{"type": "depth", "ts": 1783008106814, "U": 96863172846, "u": 96863172887, "bids": [["61611.28000000", "0.08163000"], ["61610.86000000", "0.04018000"], ["61610.32000000", "0.08793000"], ["61610.25000000", "0.00000000"], ["61610.09000000", "0.11789000"], ["61609.99000000", "0.04720000"], ["61519.57000000", "0.00061000"], ["61442.87000000", "0.00000000"], ["55450.80000000", "0.00450000"], ["55450.79000000", "0.00010000"], ["49289.59000000", "0.00000000"]], "asks": [["61613.18000000", "0.00916000"], ["61613.52000000", "0.08793000"], ["61616.35000000", "0.00931000"], ["61616.50000000", "0.03135000"], ["61616.66000000", "0.01009000"], ["61616.99000000", "0.00000000"], ["61617.54000000", "0.06016000"], ["63854.68000000", "0.00016000"]]}
{"type": "depth", "ts": 1783008106914, "U": 96863172888, "u": 96863172907, "bids": [["61611.99000000", "2.66179000"], ["61609.99000000", "0.04738000"], ["61609.02000000", "0.04235000"], ["55450.80000000", "0.00450000"], ["55450.79000000", "0.00000000"], ["49289.59000000", "0.00000000"]], "asks": [["61612.00000000", "0.21273000"], ["61612.01000000", "0.00107000"], ["61613.02000000", "0.00000000"]]}
{"type": "depth", "ts": 1783008107014, "U": 96863172908, "u": 96863173032, "bids": [["61611.99000000", "1.25663000"], ["61611.98000000", "0.00071000"], ["61611.30000000", "0.00009000"], ["61611.29000000", "0.10218000"], ["61610.87000000", "0.00036000"], ["61610.33000000", "0.00009000"], ["61610.32000000", "0.00027000"], ["61610.10000000", "0.00000000"], ["61610.09000000", "0.00018000"], ["61610.00000000", "0.00627000"], ["61609.43000000", "0.00000000"], ["61609.42000000", "0.00000000"], ["61609.02000000", "0.00018000"], ["61608.98000000", "0.00009000"], ["61608.80000000", "0.00009000"], ["61608.79000000", "0.06103000"], ["61608.05000000", "0.00000000"], ["61608.04000000", "0.09182000"], ["61608.03000000", "0.39525000"], ["61605.99000000", "0.00028000"], ["61605.98000000", "0.00000000"], ["61602.93000000", "0.00192000"], ["61596.36000000", "0.00000000"], ["61594.57000000", "0.01624000"], ["61578.82000000", "0.58919000"], ["61497.80000000", "0.04639000"], ["61488.81000000", "0.00045000"], ["55450.80000000", "0.00450000"], ["49290.00000000", "0.01823000"], ["49289.60000000", "0.00040000"]], "asks": [["61612.00000000", "1.24637000"], ["61612.01000000", "0.00116000"], ["61613.52000000", "0.08802000"], ["61614.65000000", "0.00009000"], ["61614.66000000", "0.00009000"], ["61615.36000000", "0.00009000"], ["61615.37000000", "0.06554000"], ["61615.96000000", "0.00000000"], ["61615.97000000", "0.00009000"], ["61615.98000000", "0.10339000"], ["61615.99000000", "0.09182000"], ["61616.49000000", "0.00000000"], ["61616.50000000", "0.00018000"], ["61617.31000000", "0.00009000"], ["61617.53000000", "0.00000000"], ["61617.99000000", "0.00000000"], ["61618.23000000", "0.00000000"], ["61618.64000000", "0.00000000"], ["61621.09000000", "0.04217000"], ["61624.92000000", "0.97390000"], ["61639.82000000", "0.00000000"], ["61659.87000000", "0.02200000"]]}
{"type": "depth", "ts": 1783008107115, "U": 96863173033, "u": 96863173112, "bids": [["61611.99000000", "1.25654000"], ["61611.98000000", "0.00062000"], ["61611.29000000", "0.07504000"], ["61611.28000000", "0.08163000"], ["61610.86000000", "0.04018000"], ["61610.33000000", "0.00000000"], ["61610.32000000", "0.00009000"], ["61610.09000000", "0.00000000"], ["61609.99000000", "0.04738000"], ["61609.34000000", "0.00009000"], ["61609.33000000", "0.09173000"], ["61609.02000000", "0.00000000"], ["61608.97000000", "0.02209000"], ["61608.79000000", "0.06121000"], ["61608.05000000", "0.00000000"], ["61608.04000000", "0.09191000"], ["61608.03000000", "0.39516000"], ["61512.74000000", "0.12000000"], ["61448.76000000", "0.01001000"], ["60687.81000000", "0.00030000"], ["59600.00000000", "12.91260000"], ["55450.80000000", "0.00450000"], ["49290.00000000", "0.01623000"]], "asks": [["61612.00000000", "1.00296000"], ["61614.00000000", "0.02418000"], ["61614.65000000", "0.00000000"], ["61615.37000000", "0.06572000"], ["61615.98000000", "0.10357000"], ["61615.99000000", "0.09200000"], ["61616.35000000", "0.00931000"], ["61616.50000000", "0.00000000"], ["61616.66000000", "0.00991000"], ["61617.32000000", "0.08458000"], ["61617.53000000", "0.00009000"], ["61628.33000000", "0.00000000"], ["61661.46000000", "0.00400000"], ["61664.12000000", "0.04623000"]]}
{"type": "depth", "ts": 1783008107214, "U": 96863173113, "u": 96863173150, "bids": [["61609.99000000", "0.04738000"], ["61609.33000000", "0.09191000"], ["61608.05000000", "0.00009000"], ["61608.04000000", "0.09182000"], ["61608.03000000", "0.39525000"], ["61606.60000000", "0.25000000"], ["61595.00000000", "0.00000000"], ["61499.56000000", "0.00000000"], ["61472.64000000", "0.00034000"], ["61471.93000000", "0.00000000"], ["55450.80000000", "0.00470000"], ["55450.00000000", "0.40784000"], ["49289.60000000", "0.00000000"]], "asks": [["61612.00000000", "1.24618000"], ["61624.32000000", "0.00337000"], ["61624.33000000", "0.00300000"]]}
{"type": "depth", "ts": 1783008107314, "U": 96863173151, "u": 96863173255, "bids": [["61611.99000000", "1.25649000"], ["61611.98000000", "0.00071000"], ["61611.29000000", "0.04076000"], ["61609.34000000", "0.00000000"], ["61609.33000000", "0.00018000"], ["61608.03000000", "0.39534000"], ["61606.96000000", "0.08775000"], ["61580.25000000", "0.00000000"], ["61580.24000000", "0.00000000"], ["61579.81000000", "0.00009000"], ["61539.52000000", "4.87976000"], ["55450.80000000", "0.00470000"]], "asks": [["61612.00000000", "1.45484000"], ["61612.01000000", "0.00044000"], ["61613.51000000", "0.00191000"], ["61614.65000000", "0.00009000"], ["61614.66000000", "0.08492000"], ["61615.97000000", "0.00009000"], ["61615.98000000", "0.10357000"], ["61615.99000000", "0.09200000"], ["61617.31000000", "0.00000000"], ["61617.53000000", "0.00000000"], ["61623.21000000", "0.33501000"], ["61624.64000000", "0.58485000"], ["61643.78000000", "0.01658000"], ["61643.83000000", "0.01400000"], ["61704.41000000", "0.00114000"]]}
{"type": "depth", "ts": 1783008107414, "U": 96863173256, "u": 96863173298, "bids": [["61611.99000000", "1.25613000"], ["61611.28000000", "0.08154000"], ["61609.99000000", "0.04738000"], ["61609.33000000", "0.00000000"], ["61608.04000000", "0.09200000"], ["61608.03000000", "0.39543000"], ["61448.76000000", "0.00000000"], ["61442.87000000", "0.01002000"], ["55450.80000000", "0.00450000"]], "asks": [["61612.00000000", "1.45565000"], ["61612.01000000", "0.00089000"], ["61614.00000000", "0.02418000"], ["61614.66000000", "0.08510000"], ["61616.35000000", "0.00913000"], ["61653.15000000", "1.05315000"], ["62536.18000000", "0.00030000"]]}
{"type": "depth", "ts": 1783008107614, "U": 96863173311, "u": 96863173320, "bids": [["61611.99000000", "1.25521000"], ["61611.98000000", "0.00062000"], ["61579.81000000", "0.00000000"], ["55450.80000000", "0.00440000"]], "asks": [["61612.00000000", "1.45574000"], ["61612.01000000", "0.00098000"], ["61735.26000000", "0.00114000"]]}
{"type": "depth", "ts": 1783008107714, "U": 96863173321, "u": 96863173334, "bids": [["61580.24000000", "0.45014000"], ["61557.39000000", "0.07391000"], ["61541.22000000", "2.85923000"], ["55450.80000000", "0.00440000"]], "asks": [["61612.00000000", "1.44337000"], ["61640.80000000", "0.14337000"], ["61688.84000000", "0.00000000"], ["61696.23000000", "0.05819000"]]}
{"type": "depth", "ts": 1783008107814, "U": 96863173335, "u": 96863173342, "bids": [["55450.80000000", "0.00460000"], ["49289.59000000", "0.00000000"]], "asks": [["61612.00000000", "1.45509000"], ["61695.40000000", "0.05294000"]]}
{"type": "depth", "ts": 1783008107914, "U": 96863173343, "u": 96863173365, "bids": [["61611.29000000", "0.07488000"], ["61611.28000000", "0.08163000"], ["61609.34000000", "0.00009000"], ["61609.33000000", "0.09129000"], ["61608.04000000", "0.09191000"], ["61608.03000000", "0.39534000"], ["61604.00000000", "0.02400000"], ["61486.64000000", "0.00000000"], ["55450.80000000", "0.00440000"], ["49289.59000000", "0.00000000"]], "asks": [["61612.00000000", "1.32975000"], ["61614.65000000", "0.00000000"], ["61614.66000000", "0.00027000"], ["61617.31000000", "0.00009000"], ["61617.53000000", "0.00009000"], ["61628.40000000", "0.00009000"], ["77803.32000000", "0.00072000"]]}
{"type": "depth", "ts": 1783008108014, "U": 96863173366, "u": 96863173414, "bids": [["61611.99000000", "1.50271000"], ["61609.99000000", "0.04738000"], ["61609.33000000", "0.09147000"], ["61608.05000000", "0.00000000"], ["61608.04000000", "0.09173000"], ["61580.24000000", "0.38872000"], ["61580.12000000", "0.01658000"], ["61524.75000000", "0.00000000"], ["55450.80000000", "0.00440000"], ["49289.60000000", "0.00040000"]], "asks": [["61612.00000000", "1.24007000"], ["61612.01000000", "0.00098000"], ["61614.00000000", "0.02418000"], ["61614.66000000", "0.00009000"], ["61615.98000000", "0.07604000"], ["61615.99000000", "0.00027000"], ["61616.35000000", "0.00931000"], ["61617.99000000", "0.00009000"], ["61624.32000000", "0.00010000"], ["61624.33000000", "0.00624000"], ["61628.40000000", "0.00009000"], ["61628.41000000", "0.09750000"]]}
{"type": "depth", "ts": 1783008108114, "U": 96863173415, "u": 96863173432, "bids": [["61580.12000000", "0.00000000"], ["61442.87000000", "0.01017000"], ["60687.81000000", "0.00030000"], ["55450.80000000", "0.00420000"]], "asks": [["61612.00000000", "0.99242000"], ["61615.98000000", "0.07604000"], ["61615.99000000", "0.00009000"], ["61616.66000000", "0.01009000"], ["61628.41000000", "0.00000000"]]}
{"type": "depth", "ts": 1783008108214, "U": 96863173433, "u": 96863173547, "bids": [["61611.99000000", "2.49497000"], ["61611.98000000", "0.00035000"], ["61611.29000000", "0.12291000"], ["61611.28000000", "0.08172000"], ["61610.87000000", "0.00027000"], ["61610.66000000", "0.09138000"], ["61610.07000000", "0.11762000"], ["61610.00000000", "0.00618000"], ["61609.34000000", "0.00000000"], ["61608.98000000", "0.00000000"], ["61608.80000000", "0.00000000"], ["61608.79000000", "0.00018000"], ["61608.03000000", "0.49907000"], ["61596.10000000", "0.58503000"], ["61584.72000000", "0.00000000"], ["61579.80000000", "1.60926000"], ["61578.82000000", "0.00400000"], ["61541.22000000", "1.43910000"], ["61539.52000000", "0.00000000"], ["61412.61000000", "0.02543000"], ["55450.80000000", "0.00420000"], ["49289.60000000", "0.00000000"]], "asks": [["61612.00000000", "0.20228000"], ["61612.01000000", "0.00098000"], ["61615.36000000", "0.00000000"], ["61615.37000000", "0.00027000"], ["61615.93000000", "0.00009000"], ["61615.94000000", "0.00000000"], ["61615.97000000", "0.00000000"], ["61615.98000000", "0.00018000"], ["61616.51000000", "0.03194000"], ["61618.23000000", "0.00009000"], ["61621.09000000", "0.00000000"], ["61623.21000000", "0.18394000"], ["61624.64000000", "0.00009000"], ["61624.66000000", "0.09129000"], ["61624.92000000", "0.00000000"], ["61628.45000000", "0.09759000"], ["61641.82000000", "0.58460000"], ["61660.44000000", "0.10000000"], ["61735.50000000", "0.02543000"], ["61849.20000000", "3.00000000"], ["61908.90000000", "3.00000000"], ["61968.60000000", "3.00000000"]]}
{"type": "depth", "ts": 1783008108314, "U": 96863173548, "u": 96863173620, "bids": [["61611.99000000", "2.49685000"], ["61611.98000000", "0.00035000"], ["61611.29000000", "0.05294000"], ["61611.28000000", "0.08163000"], ["61610.86000000", "0.04018000"], ["61610.66000000", "0.00027000"], ["61610.32000000", "0.00000000"], ["61610.07000000", "0.11787000"], ["61609.34000000", "0.00000000"], ["61609.33000000", "0.00018000"], ["61608.97000000", "0.02191000"], ["61608.79000000", "0.00000000"], ["61608.03000000", "0.49898000"], ["61606.96000000", "0.00000000"], ["61602.93000000", "0.00000000"], ["55450.80000000", "0.00420000"], ["55450.00000000", "0.40804000"]], "asks": [["61612.00000000", "0.20228000"], ["61612.01000000", "0.00098000"], ["61613.52000000", "0.08793000"], ["61614.00000000", "0.02418000"], ["61614.66000000", "0.00000000"], ["61615.37000000", "0.00000000"], ["61615.93000000", "0.00000000"], ["61615.94000000", "0.00000000"], ["61615.98000000", "0.00000000"], ["61616.35000000", "0.00931000"], ["61616.50000000", "0.00009000"], ["61616.51000000", "0.03212000"], ["61617.32000000", "0.08476000"], ["61628.45000000", "0.00009000"]]}
{"type": "depth", "ts": 1783008108414, "U": 96863173621, "u": 96863173671, "bids": [["61611.99000000", "2.49524000"], ["61611.98000000", "0.00053000"], ["61611.29000000", "0.08134000"], ["61611.28000000", "0.08163000"], ["61610.86000000", "0.04018000"], ["61610.66000000", "0.00009000"], ["61610.07000000", "0.00018000"], ["61609.99000000", "0.04738000"], ["61609.34000000", "0.08414000"], ["61609.33000000", "0.00000000"], ["61608.97000000", "0.02209000"], ["61608.04000000", "0.09191000"], ["61567.62000000", "0.01827000"], ["61545.12000000", "0.00000000"], ["55450.80000000", "0.00420000"], ["55450.00000000", "0.40784000"]], "asks": [["61612.00000000", "0.77451000"], ["61612.01000000", "0.00107000"], ["61615.93000000", "0.00009000"], ["61615.94000000", "0.04589000"], ["61616.50000000", "0.00000000"], ["61616.51000000", "0.00027000"], ["61618.64000000", "0.00009000"], ["62536.18000000", "0.00030000"]]}
{"type": "depth", "ts": 1783008108514, "U": 96863173672, "u": 96863173702, "bids": [["61611.28000000", "0.08154000"], ["61610.86000000", "0.04018000"], ["61610.66000000", "0.00000000"], ["61610.07000000", "0.00000000"], ["61609.99000000", "0.04738000"], ["61609.34000000", "0.08432000"], ["61603.88000000", "0.00187000"], ["61591.65000000", "0.00000000"], ["55450.80000000", "0.00440000"]], "asks": [["61614.00000000", "0.02418000"], ["61615.94000000", "0.04607000"], ["61616.35000000", "0.00931000"], ["61616.51000000", "0.00009000"], ["61628.62000000", "0.00000000"]]}
{"type": "depth", "ts": 1783008108715, "U": 96863173713, "u": 96863173741, "bids": [["61611.99000000", "2.49497000"], ["61611.98000000", "0.00035000"], ["61610.07000000", "0.11656000"], ["61609.35000000", "0.09129000"], ["61609.34000000", "0.00018000"], ["61580.24000000", "0.70613000"], ["61550.01000000", "0.77267000"], ["61504.38000000", "0.09222000"], ["55450.80000000", "0.00440000"]], "asks": [["61612.00000000", "0.20785000"], ["61615.94000000", "0.00018000"], ["61616.50000000", "0.03214000"], ["61621.18000000", "0.00000000"], ["61628.42000000", "0.09750000"], ["61640.80000000", "0.29955000"], ["61712.64000000", "0.94484000"]]}
{"type": "depth", "ts": 1783008108814, "U": 96863173742, "u": 96863173853, "bids": [["61611.99000000", "1.52134000"], ["61611.98000000", "0.00053000"], ["61611.28000000", "0.08163000"], ["61610.87000000", "0.00036000"], ["61610.86000000", "0.04018000"], ["61610.08000000", "0.00000000"], ["61610.07000000", "0.00027000"], ["61610.00000000", "0.00627000"], ["61609.99000000", "0.04738000"], ["61609.36000000", "0.00000000"], ["61609.35000000", "0.00018000"], ["61609.34000000", "0.09138000"], ["61609.33000000", "0.00000000"], ["61608.98000000", "0.00009000"], ["61608.79000000", "0.06899000"], ["61608.04000000", "0.09173000"], ["61607.62000000", "0.08775000"], ["61603.88000000", "0.00000000"], ["61603.69000000", "0.00188000"], ["61579.81000000", "0.00009000"], ["55450.80000000", "0.00430000"], ["55450.79000000", "0.00000000"], ["49289.59000000", "0.00000000"]], "asks": [["61612.00000000", "1.27361000"], ["61612.01000000", "0.00116000"], ["61614.00000000", "0.02418000"], ["61614.84000000", "0.00028000"], ["61615.55000000", "0.06122000"], ["61615.93000000", "0.00009000"], ["61615.94000000", "0.00000000"], ["61615.98000000", "0.00009000"], ["61615.99000000", "0.09147000"], ["61616.35000000", "0.00931000"], ["61616.48000000", "0.00009000"], ["61616.49000000", "0.07503000"], ["61616.50000000", "0.00018000"], ["61618.23000000", "0.00000000"], ["61618.64000000", "0.00000000"], ["61624.64000000", "0.09138000"], ["61624.65000000", "0.97390000"], ["61624.66000000", "0.00000000"], ["61628.42000000", "0.00000000"], ["61628.44000000", "0.00000000"], ["62275.95000000", "0.00000000"]]}
{"type": "depth", "ts": 1783008108914, "U": 96863173854, "u": 96863173971, "bids": [["61611.99000000", "2.49497000"], ["61611.98000000", "0.00035000"], ["61611.30000000", "0.00000000"], ["61611.29000000", "0.13173000"], ["61611.28000000", "0.08163000"], ["61610.87000000", "0.00027000"], ["61610.86000000", "0.04018000"], ["61610.66000000", "0.09138000"], ["61610.07000000", "0.00000000"], ["61610.06000000", "0.11676000"], ["61610.00000000", "0.00618000"], ["61609.99000000", "0.04738000"], ["61609.35000000", "0.00000000"], ["61609.34000000", "0.09156000"], ["61608.98000000", "0.00000000"], ["61608.97000000", "0.02209000"], ["61608.80000000", "0.00000000"], ["61608.79000000", "0.00018000"], ["61608.03000000", "0.37260000"], ["61603.69000000", "0.00000000"], ["61579.81000000", "0.00000000"], ["55450.80000000", "0.00430000"], ["49289.59000000", "0.00000000"]], "asks": [["61612.00000000", "0.20710000"], ["61612.01000000", "0.00107000"], ["61613.52000000", "0.08802000"], ["61614.00000000", "0.02418000"], ["61615.54000000", "0.00000000"], ["61615.55000000", "0.00018000"], ["61615.93000000", "0.00000000"], ["61615.98000000", "0.00000000"], ["61615.99000000", "0.00036000"], ["61616.35000000", "0.00931000"], ["61616.48000000", "0.00000000"], ["61616.49000000", "0.00027000"], ["61616.50000000", "0.03214000"], ["61616.66000000", "0.00991000"], ["61617.32000000", "0.08458000"], ["61618.23000000", "0.00009000"], ["61624.65000000", "0.00000000"], ["61628.44000000", "0.00000000"]]}
{"type": "depth", "ts": 1783008109014, "U": 96863173972, "u": 96863174046, "bids": [["61611.99000000", "2.49524000"], ["61611.98000000", "0.00053000"], ["61611.29000000", "0.07809000"], ["61611.28000000", "0.08172000"], ["61610.86000000", "0.04018000"], ["61610.66000000", "0.00027000"], ["61610.06000000", "0.00018000"], ["61609.34000000", "0.00018000"], ["61609.32000000", "0.08455000"], ["61608.97000000", "0.02191000"], ["61608.79000000", "0.00000000"], ["61603.66000000", "0.00188000"], ["61596.10000000", "0.00000000"], ["61581.69000000", "0.97473000"], ["55450.80000000", "0.00430000"], ["49289.60000000", "0.00040000"]], "asks": [["61612.00000000", "1.27395000"], ["61612.01000000", "0.00107000"], ["61613.52000000", "0.08793000"], ["61614.00000000", "0.02418000"], ["61615.55000000", "0.00000000"], ["61615.93000000", "0.00009000"], ["61615.94000000", "0.04608000"], ["61615.99000000", "0.00009000"], ["61616.35000000", "0.00931000"], ["61616.49000000", "0.00000000"], ["61616.50000000", "0.00018000"], ["61616.66000000", "0.01009000"], ["61617.32000000", "0.08476000"]]}
{"type": "depth", "ts": 1783008109114, "U": 96863174047, "u": 96863174093, "bids": [["61611.28000000", "0.08154000"], ["61610.86000000", "0.04018000"], ["61610.66000000", "0.00000000"], ["61610.06000000", "0.00000000"], ["61609.99000000", "0.04738000"], ["61609.34000000", "0.00000000"], ["61609.32000000", "0.08473000"], ["61608.97000000", "0.02209000"], ["61608.04000000", "0.09191000"], ["61580.12000000", "0.01658000"], ["61566.26000000", "0.01658000"], ["61521.12000000", "0.00000000"], ["60687.81000000", "0.00030000"], ["55450.80000000", "0.00450000"]], "asks": [["61612.00000000", "1.27505000"], ["61613.51000000", "0.00009000"], ["61614.00000000", "0.02418000"], ["61615.94000000", "0.04626000"], ["61616.35000000", "0.00931000"], ["61616.50000000", "0.00000000"]]}
{"type": "depth", "ts": 1783008109214, "U": 96863174094, "u": 96863174113, "bids": [["61611.30000000", "0.00009000"], ["61611.29000000", "0.07818000"], ["61610.87000000", "0.00036000"], ["61610.00000000", "0.00627000"], ["61609.33000000", "0.00009000"], ["61608.98000000", "0.00009000"], ["61580.12000000", "0.00000000"], ["61566.26000000", "0.00000000"], ["61504.02000000", "0.00000000"], ["55450.80000000", "0.00470000"], ["49289.60000000", "0.00000000"]], "asks": [["61612.00000000", "1.02864000"], ["61612.01000000", "0.00098000"], ["61788.99000000", "0.00000000"]]}
{"type": "depth", "ts": 1783008109314, "U": 96863174114, "u": 96863174164, "bids": [["61611.99000000", "2.50198000"], ["61611.98000000", "0.00035000"], ["61611.28000000", "0.08163000"], ["61610.87000000", "0.00027000"], ["61610.06000000", "0.00000000"], ["61610.00000000", "0.00618000"], ["61609.33000000", "0.09129000"], ["61609.32000000", "0.00018000"], ["61609.31000000", "0.08489000"], ["61608.98000000", "0.00000000"], ["61575.50000000", "0.02708000"], ["55450.80000000", "0.00470000"]], "asks": [["61612.00000000", "0.20559000"], ["61615.94000000", "0.04642000"], ["61616.50000000", "0.00000000"], ["61628.26000000", "0.00000000"], ["61652.60000000", "0.00000000"], ["61656.02000000", "0.06731000"]]}
{"type": "depth", "ts": 1783008109414, "U": 96863174165, "u": 96863174215, "bids": [["61611.99000000", "2.50388000"], ["61611.28000000", "0.08163000"], ["61610.06000000", "0.11738000"], ["61609.99000000", "0.04738000"], ["61609.33000000", "0.09156000"], ["61609.32000000", "0.00000000"], ["61609.31000000", "0.00018000"], ["61608.04000000", "0.09173000"], ["61608.03000000", "0.37251000"], ["61607.62000000", "0.00000000"], ["61603.66000000", "0.00000000"], ["61596.57000000", "0.58502000"], ["61581.69000000", "0.38956000"], ["61575.50000000", "0.00000000"], ["61512.88000000", "0.05233000"], ["61507.04000000", "0.02027000"], ["61505.01000000", "0.00000000"], ["55450.80000000", "0.00450000"]], "asks": [["61612.00000000", "0.20481000"], ["61612.01000000", "0.00098000"], ["61613.51000000", "0.00000000"], ["61613.52000000", "0.00018000"], ["61614.97000000", "0.00000000"], ["61615.93000000", "0.00000000"], ["61615.94000000", "0.00018000"], ["61616.50000000", "0.00009000"], ["61616.51000000", "0.03219000"], ["61618.64000000", "0.00009000"], ["61637.54000000", "0.00000000"], ["61651.47000000", "0.04710000"], ["62275.95000000", "0.00042000"], ["62536.18000000", "0.00030000"]]}
{"type": "depth", "ts": 1783008109514, "U": 96863174216, "u": 96863174285, "bids": [["61611.99000000", "2.50371000"], ["61611.98000000", "0.00035000"], ["61610.86000000", "0.04018000"], ["61610.06000000", "0.00018000"], ["61609.33000000", "0.00018000"], ["61609.31000000", "0.00000000"], ["61608.79000000", "0.09068000"], ["61536.03000000", "0.00000000"], ["61475.27000000", "0.00000000"], ["55450.80000000", "0.00450000"], ["55450.00000000", "0.40784000"]], "asks": [["61612.00000000", "0.20472000"], ["61613.18000000", "0.00916000"], ["61613.52000000", "0.00000000"], ["61614.00000000", "0.02418000"], ["61614.97000000", "0.00009000"], ["61615.90000000", "0.05088000"], ["61615.94000000", "0.00000000"], ["61616.35000000", "0.00931000"], ["61616.51000000", "0.00027000"], ["61617.54000000", "0.06034000"], ["61619.57000000", "0.00000000"], ["61643.78000000", "0.00000000"]]}
{"type": "depth", "ts": 1783008109614, "U": 96863174286, "u": 96863174387, "bids": [["61611.99000000", "2.50407000"], ["61611.98000000", "0.00062000"], ["61611.29000000", "0.10843000"], ["61611.28000000", "0.08163000"], ["61610.87000000", "0.00036000"], ["61610.86000000", "0.04018000"], ["61610.07000000", "0.00009000"], ["61610.06000000", "0.00000000"], ["61610.00000000", "0.00627000"], ["61609.99000000", "0.04738000"], ["61609.33000000", "0.00000000"], ["61609.31000000", "0.00000000"], ["61608.98000000", "0.00009000"], ["61608.97000000", "0.02209000"], ["61608.79000000", "0.00018000"], ["61608.05000000", "0.00009000"], ["61608.04000000", "0.00018000"], ["61608.03000000", "0.37251000"], ["61607.93000000", "0.09634000"], ["61591.65000000", "0.00009000"], ["56682.01000000", "0.00018000"], ["55450.80000000", "0.00450000"]], "asks": [["61612.00000000", "1.02981000"], ["61612.01000000", "0.00107000"], ["61614.00000000", "0.02418000"], ["61615.89000000", "0.00000000"], ["61615.90000000", "0.00018000"], ["61615.94000000", "0.00000000"], ["61615.99000000", "0.06114000"], ["61616.35000000", "0.00931000"], ["61616.50000000", "0.00009000"], ["61616.51000000", "0.00009000"], ["61618.23000000", "0.00000000"], ["61618.64000000", "0.00000000"], ["61619.51000000", "0.00000000"], ["61628.62000000", "0.00009000"]]}
{"type": "depth", "ts": 1783008109714, "U": 96863174388, "u": 96863174440, "bids": [["61611.99000000", "2.50217000"], ["61611.98000000", "0.00062000"], ["61611.29000000", "0.05286000"], ["61611.28000000", "0.08136000"], ["61610.07000000", "0.00000000"], ["61609.63000000", "0.08775000"], ["61608.97000000", "0.02209000"], ["61608.79000000", "0.00000000"], ["61608.05000000", "0.00000000"], ["61608.04000000", "0.00000000"], ["61608.03000000", "0.37278000"], ["61608.02000000", "1.36348000"], ["61603.74000000", "0.00188000"], ["61571.89000000", "0.67823000"], ["61544.23000000", "0.27536000"], ["55450.80000000", "0.00450000"]], "asks": [["61612.00000000", "1.02963000"], ["61612.01000000", "0.00098000"], ["61612.71000000", "0.08775000"], ["61614.00000000", "0.02418000"], ["61615.90000000", "0.00000000"], ["61615.98000000", "0.00009000"], ["61615.99000000", "0.06132000"], ["61616.50000000", "0.00000000"], ["61618.23000000", "0.00009000"], ["61618.64000000", "0.00009000"]]}
{"type": "depth", "ts": 1783008109814, "U": 96863174441, "u": 96863174498, "bids": [["61611.99000000", "1.28077000"], ["61611.28000000", "0.08145000"], ["61609.99000000", "0.04738000"], ["61609.64000000", "0.00009000"], ["61609.63000000", "0.08793000"], ["61608.86000000", "0.06556000"], ["61608.04000000", "0.00009000"], ["61608.03000000", "0.37287000"], ["61608.02000000", "1.36330000"], ["61607.93000000", "0.00000000"], ["61606.61000000", "0.00009000"], ["61596.57000000", "0.00000000"], ["61579.65000000", "0.58519000"], ["55450.80000000", "0.00470000"], ["49290.00000000", "0.01823000"], ["49289.59000000", "0.00000000"]], "asks": [["61612.00000000", "1.47254000"], ["61612.70000000", "0.00009000"], ["61612.71000000", "0.08802000"], ["61613.17000000", "0.00000000"], ["61615.42000000", "0.06312000"], ["61615.97000000", "0.12151000"], ["61615.98000000", "0.09138000"], ["61615.99000000", "0.00027000"], ["61617.31000000", "0.00000000"], ["61617.53000000", "0.00000000"], ["61617.54000000", "0.06016000"], ["61617.99000000", "0.00000000"], ["61618.23000000", "0.00000000"], ["61618.64000000", "0.00000000"], ["61620.68000000", "0.04217000"], ["61623.21000000", "0.47841000"], ["61624.53000000", "0.97390000"]]}
{"type": "depth", "ts": 1783008109914, "U": 96863174499, "u": 96863174608, "bids": [["61611.99000000", "1.28122000"], ["61611.98000000", "0.00071000"], ["61609.63000000", "0.00027000"], ["61608.97000000", "0.02209000"], ["61608.87000000", "0.00009000"], ["61608.86000000", "0.06574000"], ["61608.03000000", "0.37260000"], ["61603.62000000", "0.00000000"], ["61579.81000000", "0.00009000"], ["61544.01000000", "0.82065000"], ["61542.01000000", "0.00000000"], ["55450.80000000", "0.00470000"], ["49290.00000000", "0.01623000"], ["49289.59000000", "0.00000000"]], "asks": [["61612.00000000", "1.45891000"], ["61612.01000000", "0.00035000"], ["61612.71000000", "0.08811000"], ["61614.00000000", "0.02418000"], ["61614.66000000", "0.09129000"], ["61615.41000000", "0.00000000"], ["61615.42000000", "0.06339000"], ["61615.96000000", "0.00000000"], ["61615.97000000", "0.12160000"], ["61615.98000000", "0.09147000"], ["61615.99000000", "0.00000000"], ["61616.66000000", "0.00991000"], ["61617.32000000", "0.08458000"], ["61617.54000000", "0.04016000"], ["61624.03000000", "0.58476000"], ["61624.32000000", "0.00334000"], ["61624.33000000", "0.00300000"], ["61641.82000000", "0.00000000"], ["61659.84000000", "0.00400000"], ["61661.46000000", "0.00000000"]]}
{"type": "depth", "ts": 1783008110014, "U": 96863174609, "u": 96863174647, "bids": [["61609.99000000", "0.04738000"], ["61609.64000000", "0.00000000"], ["61609.63000000", "0.00009000"], ["61609.11000000", "0.00000000"], ["61608.03000000", "0.37278000"], ["61606.18000000", "0.00000000"], ["61603.25000000", "0.00000000"], ["61580.25000000", "1.36330000"], ["55450.80000000", "0.00470000"], ["49289.60000000", "0.00040000"]], "asks": [["61612.00000000", "1.49723000"], ["61612.01000000", "0.00044000"], ["61612.71000000", "0.08820000"], ["61614.00000000", "0.02418000"], ["61614.65000000", "0.00009000"], ["61614.66000000", "0.09147000"], ["61615.24000000", "0.00000000"], ["61615.41000000", "0.00009000"], ["61615.96000000", "0.00009000"], ["61616.35000000", "0.00913000"], ["61623.99000000", "0.09153000"], ["61624.64000000", "0.00009000"], ["61640.80000000", "0.14337000"]]}
{"type": "depth", "ts": 1783008110114, "U": 96863174648, "u": 96863174708, "bids": [["61611.99000000", "1.24245000"], ["61611.98000000", "0.00071000"], ["61609.11000000", "0.00009000"], ["61608.26000000", "0.00000000"], ["61606.87000000", "0.00000000"], ["61606.86000000", "0.00034000"], ["61606.18000000", "0.00009000"], ["61604.04000000", "0.00048000"], ["61603.84000000", "0.00047000"], ["61603.56000000", "0.01007000"], ["61603.43000000", "0.00000000"], ["61603.25000000", "0.00009000"], ["61602.83000000", "0.01000000"], ["61600.13000000", "0.03248000"], ["61598.01000000", "0.00000000"], ["61594.57000000", "0.00000000"], ["61590.17000000", "0.01624000"], ["61580.24000000", "0.43029000"], ["61579.80000000", "0.00000000"], ["61562.16000000", "0.00400000"], ["61544.01000000", "0.00000000"], ["61537.98000000", "4.87988000"], ["61512.88000000", "0.00000000"], ["55450.80000000", "0.00450000"]], "asks": [["61612.00000000", "1.52925000"], ["61612.01000000", "0.00035000"], ["61612.69000000", "0.00009000"], ["61612.70000000", "0.06415000"], ["61612.71000000", "0.08820000"], ["61613.32000000", "0.00000000"], ["61613.33000000", "0.00000000"], ["61613.36000000", "0.00034000"], ["61614.65000000", "0.00009000"], ["61615.41000000", "0.00009000"], ["61615.96000000", "0.00000000"], ["61617.60000000", "0.00400000"], ["61621.47000000", "0.00000000"], ["61621.72000000", "0.00000000"], ["61659.84000000", "0.00000000"], ["61664.23000000", "0.01658000"]]}
{"type": "depth", "ts": 1783008110214, "U": 96863174709, "u": 96863174848, "bids": [["61611.99000000", "0.84386000"], ["61611.30000000", "0.00000000"], ["61611.29000000", "0.00018000"], ["61611.28000000", "0.00036000"], ["61611.18000000", "0.00009000"], ["61609.11000000", "0.00000000"], ["61608.86000000", "0.06583000"], ["61608.05000000", "0.00009000"], ["61608.04000000", "0.09138000"], ["61608.00000000", "0.01100000"], ["61607.00000000", "0.00034000"], ["61606.86000000", "0.00000000"], ["61606.60000000", "0.25018000"], ["61606.15000000", "0.00018000"], ["61606.06000000", "0.00009000"], ["61606.05000000", "0.83854000"], ["61606.04000000", "0.97390000"], ["61606.03000000", "0.00000000"], ["61606.02000000", "0.00009000"], ["61605.83000000", "0.00010000"], ["61605.82000000", "0.24759000"], ["61605.07000000", "0.08775000"], ["61604.87000000", "0.00000000"], ["61604.36000000", "0.00000000"], ["61602.83000000", "0.00000000"], ["61602.73000000", "0.01000000"], ["61602.21000000", "0.00000000"], ["61602.02000000", "0.38956000"], ["61601.78000000", "0.00400000"], ["61600.13000000", "0.00000000"], ["61598.01000000", "0.03248000"], ["61593.33000000", "0.00000000"], ["61590.17000000", "0.00000000"], ["61580.24000000", "0.38872000"], ["61576.88000000", "0.00009000"], ["61571.89000000", "0.52328000"], ["61544.23000000", "0.03269000"], ["61507.82000000", "0.05396000"], ["61488.57000000", "0.04217000"], ["60687.81000000", "0.00030000"], ["56682.01000000", "0.00000000"], ["55450.80000000", "0.00450000"], ["49290.00000000", "0.01623000"], ["49289.60000000", "0.00000000"]], "asks": [["61612.00000000", "1.56218000"], ["61612.70000000", "0.06433000"], ["61613.26000000", "0.00034000"], ["61613.33000000", "0.00000000"], ["61613.36000000", "0.00000000"], ["61613.99000000", "0.00009000"], ["61614.65000000", "0.00009000"], ["61614.96000000", "0.00400000"], ["61615.41000000", "0.00009000"], ["61616.00000000", "0.02400000"], ["61619.72000000", "0.31293000"], ["61620.26000000", "0.00825000"], ["61620.37000000", "0.00000000"], ["61621.21000000", "0.58479000"], ["61622.11000000", "1.08474000"], ["61622.12000000", "1.36330000"], ["61622.77000000", "0.00000000"], ["61623.21000000", "0.00000000"], ["61623.22000000", "0.00000000"], ["61623.99000000", "0.00024000"], ["61626.97000000", "0.00230000"], ["61627.06000000", "0.58474000"], ["61627.72000000", "0.00009000"], ["61630.81000000", "0.91285000"], ["61632.37000000", "0.00000000"], ["61633.34000000", "0.00000000"], ["61636.21000000", "0.00000000"], ["61642.45000000", "0.02582000"], ["61656.14000000", "0.00000000"]]}
{"type": "depth", "ts": 1783008110314, "U": 96863174849, "u": 96863174912, "bids": [["61611.99000000", "0.84407000"], ["61611.98000000", "0.00080000"], ["61611.29000000", "0.00000000"], ["61611.28000000", "0.00018000"], ["61610.88000000", "0.00009000"], ["61610.87000000", "0.02845000"], ["61608.86000000", "0.06583000"], ["61608.05000000", "0.00497000"], ["61608.04000000", "0.09156000"], ["61608.02000000", "1.36348000"], ["61606.60000000", "0.25009000"], ["61606.06000000", "1.08873000"], ["61606.05000000", "0.00000000"], ["61576.88000000", "0.00000000"], ["55450.80000000", "0.00430000"], ["43128.39000000", "0.00000000"]], "asks": [["61612.00000000", "1.55400000"], ["61612.01000000", "0.00071000"], ["61613.26000000", "0.00000000"], ["61614.64000000", "0.00812000"], ["61615.96000000", "0.00009000"], ["61615.97000000", "0.12169000"], ["61615.99000000", "0.00009000"], ["61620.45000000", "0.00190000"], ["61627.72000000", "0.00009000"], ["61712.41000000", "0.02543000"]]}
{"type": "depth", "ts": 1783008110414, "U": 96863174913, "u": 96863174959, "bids": [["61611.99000000", "0.93662000"], ["61610.87000000", "0.02863000"], ["61608.04000000", "0.00027000"], ["61608.02000000", "1.36330000"], ["61606.61000000", "0.00009000"], ["55450.80000000", "0.00430000"]], "asks": [["61612.00000000", "1.55355000"], ["61612.01000000", "0.00035000"], ["61614.00000000", "0.02418000"], ["61614.64000000", "0.00830000"], ["61614.65000000", "0.00000000"], ["61615.41000000", "0.00000000"], ["61615.96000000", "0.00000000"], ["61615.97000000", "0.12160000"], ["61615.98000000", "0.09129000"], ["61615.99000000", "0.00000000"], ["61621.62000000", "0.00000000"], ["61622.10000000", "0.09129000"], ["62536.18000000", "0.00030000"]]}
{"type": "depth", "ts": 1783008110514, "U": 96863174960, "u": 96863175069, "bids": [["61611.99000000", "0.00000000"], ["61611.98000000", "0.00000000"], ["61611.97000000", "0.00000000"], ["61611.28000000", "0.00000000"], ["61611.18000000", "0.00000000"], ["61610.88000000", "0.00000000"], ["61610.87000000", "0.07766000"], ["61608.86000000", "0.06583000"], ["61608.64000000", "0.00000000"], ["61608.05000000", "0.00000000"], ["61608.04000000", "0.00009000"], ["61608.03000000", "0.09628000"], ["61608.02000000", "0.00018000"], ["61607.00000000", "0.00000000"], ["61606.95000000", "0.00000000"], ["61606.60000000", "0.25000000"], ["61606.07000000", "0.87281000"], ["61606.06000000", "0.00000000"], ["61606.05000000", "0.00000000"], ["61606.04000000", "0.00000000"], ["61605.83000000", "0.00019000"], ["61605.82000000", "0.00009000"], ["61604.85000000", "0.00018000"], ["61604.84000000", "0.00009000"], ["61602.73000000", "0.00000000"], ["61601.78000000", "0.00000000"], ["61601.57000000", "0.00000000"], ["61599.83000000", "0.01000000"], ["61599.65000000", "0.24750000"], ["61594.00000000", "0.02400000"], ["61593.21000000", "0.00000000"], ["61576.88000000", "0.00009000"], ["61576.23000000", "0.58522000"], ["61564.72000000", "0.00000000"], ["61522.84000000", "0.01658000"], ["61359.64000000", "0.00000000"], ["55450.80000000", "0.00450000"], ["55450.00000000", "0.40804000"]], "asks": [["61610.88000000", "1.19157000"], ["61611.29000000", "0.40000000"], ["61611.99000000", "0.40000000"], ["61612.00000000", "1.74901000"], ["61612.69000000", "0.00000000"], ["61612.70000000", "0.06424000"], ["61612.71000000", "0.08829000"], ["61612.86000000", "0.00043000"], ["61613.33000000", "0.09129000"], ["61613.99000000", "0.00000000"], ["61614.02000000", "0.08000000"], ["61614.64000000", "0.00018000"], ["61620.45000000", "0.00000000"], ["61626.44000000", "0.00000000"], ["61628.14000000", "0.00419000"], ["61646.52000000", "0.00000000"]]}
{"type": "depth", "ts": 1783008110614, "U": 96863175070, "u": 96863175831, "bids": [["61610.87000000", "0.00000000"], ["61610.86000000", "0.00000000"], ["61610.85000000", "0.00000000"], ["61610.84000000", "0.00000000"], ["61610.75000000", "0.00000000"], ["61610.57000000", "0.00000000"], ["61610.00000000", "0.00718000"], ["61609.99000000", "0.04801000"], ["61608.98000000", "0.00000000"], ["61608.97000000", "0.00018000"], ["61608.87000000", "0.00000000"], ["61608.86000000", "0.00027000"], ["61608.04000000", "0.00000000"], ["61608.03000000", "0.00027000"], ["61608.02000000", "0.00000000"], ["61608.01000000", "0.00009000"], ["61608.00000000", "0.01118000"], ["61607.59000000", "0.00018000"], ["61607.53000000", "0.00018000"], ["61607.36000000", "0.00000000"], ["61607.28000000", "0.00009000"], ["61607.27000000", "0.00000000"], ["61606.98000000", "0.00000000"], ["61606.97000000", "0.00018000"], ["61606.96000000", "0.00000000"], ["61606.94000000", "0.00000000"], ["61606.92000000", "0.00000000"], ["61606.91000000", "0.00000000"], ["61606.62000000", "0.00000000"], ["61606.61000000", "0.00009000"], ["61606.60000000", "0.25018000"], ["61606.54000000", "0.00000000"], ["61606.18000000", "0.00000000"], ["61606.15000000", "0.00009000"], ["61606.10000000", "0.00000000"], ["61606.09000000", "0.00009000"], ["61606.08000000", "0.00000000"], ["61606.07000000", "0.00000000"], ["61606.05000000", "0.00000000"], ["61606.02000000", "0.00000000"], ["61606.01000000", "0.00009000"], ["61606.00000000", "0.01909000"], ["61605.95000000", "0.00009000"], ["61605.94000000", "0.00000000"], ["61605.83000000", "0.00000000"], ["61605.82000000", "0.00000000"], ["61605.34000000", "0.00959000"], ["61605.08000000", "0.00000000"], ["61605.07000000", "0.00000000"], ["61605.02000000", "0.00000000"], ["61604.88000000", "0.00000000"], ["61604.85000000", "0.00009000"], ["61604.51000000", "0.00000000"], ["61604.40000000", "0.00000000"], ["61604.22000000", "0.00009000"], ["61604.21000000", "0.00009000"], ["61604.14000000", "0.00000000"], ["61604.01000000", "0.00009000"], ["61603.95000000", "0.00009000"], ["61603.94000000", "0.00000000"], ["61603.93000000", "0.00000000"], ["61603.90000000", "0.00000000"], ["61603.89000000", "0.00000000"], ["61603.84000000", "0.00057000"], ["61603.83000000", "0.00000000"], ["61603.56000000", "0.00000000"], ["61603.35000000", "0.08451000"], ["61603.25000000", "0.00000000"], ["61603.01000000", "0.00000000"], ["61602.88000000", "0.00000000"], ["61602.62000000", "0.09129000"], ["61602.61000000", "0.02434000"], ["61602.58000000", "0.00009000"], ["61602.57000000", "0.42910000"], ["61602.50000000", "0.00000000"], ["61602.49000000", "0.00000000"], ["61602.03000000", "1.36330000"], ["61602.02000000", "0.00000000"], ["61602.01000000", "0.00000000"], ["61601.46000000", "0.00000000"], ["61601.45000000", "0.00000000"], ["61601.43000000", "0.00034000"], ["61601.11000000", "0.00000000"], ["61601.05000000", "0.00000000"], ["61600.67000000", "0.00000000"], ["61600.45000000", "0.00000000"], ["61600.32000000", "0.00000000"], ["61600.28000000", "0.00000000"], ["61600.13000000", "0.00812000"], ["61599.83000000", "0.00000000"], ["61599.81000000", "0.00000000"], ["61599.71000000", "0.28556000"], ["61599.40000000", "1.36330000"], ["61599.22000000", "0.00000000"], ["61599.11000000", "0.00000000"], ["61598.64000000", "0.00000000"], ["61598.61000000", "0.00000000"], ["61598.49000000", "0.00400000"], ["61598.33000000", "0.00000000"], ["61598.01000000", "0.00000000"], ["61597.73000000", "0.00000000"], ["61597.39000000", "0.00000000"], ["61596.88000000", "0.97878000"], ["61596.87000000", "0.00000000"], ["61596.84000000", "1.36330000"], ["61596.38000000", "0.00000000"], ["61596.19000000", "0.00153000"], ["61595.83000000", "0.15000000"], ["61595.04000000", "0.02000000"], ["61594.40000000", "0.39444000"], ["61594.39000000", "0.00000000"], ["61593.26000000", "0.00400000"], ["61592.01000000", "0.03249000"], ["61591.65000000", "0.00000000"], ["61590.66000000", "0.00000000"], ["61590.37000000", "0.00000000"], ["61589.66000000", "0.01009000"], ["61588.00000000", "0.02800000"], ["61587.33000000", "0.00000000"], ["61584.59000000", "0.58514000"], ["61582.98000000", "0.00000000"], ["61581.00000000", "0.00000000"], ["61580.00000000", "0.02416000"], ["61579.00000000", "0.01000000"], ["61578.30000000", "0.00000000"], ["61573.95000000", "0.00009000"], ["61572.75000000", "0.58525000"], ["61571.02000000", "0.00009000"], ["61568.85000000", "0.00024000"], ["61560.30000000", "0.00000000"], ["61557.58000000", "1.50240000"], ["61556.88000000", "0.00409000"], ["61550.01000000", "0.00701000"], ["61548.04000000", "0.00000000"], ["61538.70000000", "0.97499000"], ["61445.15000000", "0.00250000"], ["61351.27000000", "0.00040000"], ["60687.81000000", "0.00000000"], ["55450.80000000", "0.00010000"], ["55450.00000000", "0.40784000"], ["55449.78000000", "0.00000000"], ["55449.00000000", "0.00020000"]], "asks": [["61610.01000000", "4.45912000"], ["61610.02000000", "0.00017000"], ["61610.03000000", "0.00017000"], ["61610.58000000", "0.00018000"], ["61610.75000000", "0.00009000"], ["61610.76000000", "0.00009000"], ["61610.85000000", "0.70244000"], ["61610.86000000", "0.05100000"], ["61610.87000000", "0.46581000"], ["61610.88000000", "0.10088000"], ["61610.89000000", "0.00000000"], ["61610.90000000", "0.00000000"], ["61611.19000000", "0.00000000"], ["61611.28000000", "0.00000000"], ["61611.29000000", "0.00027000"], ["61611.50000000", "0.16231000"], ["61611.98000000", "0.00000000"], ["61611.99000000", "0.20516000"], ["61612.00000000", "0.02771000"], ["61612.01000000", "0.00000000"], ["61612.02000000", "0.00000000"], ["61612.04000000", "0.00009000"], ["61612.32000000", "0.00409000"], ["61612.51000000", "0.00000000"], ["61612.55000000", "0.09659000"], ["61612.56000000", "0.00000000"], ["61612.70000000", "0.00018000"], ["61612.71000000", "0.00036000"], ["61613.18000000", "0.00916000"], ["61613.26000000", "0.00000000"], ["61613.33000000", "0.00009000"], ["61614.00000000", "0.02400000"], ["61614.01000000", "0.00000000"], ["61614.39000000", "0.04217000"], ["61614.64000000", "0.00000000"], ["61614.66000000", "0.00000000"], ["61615.20000000", "0.00000000"], ["61615.41000000", "0.58485000"], ["61615.42000000", "0.00009000"], ["61615.97000000", "0.20589000"], ["61615.98000000", "0.00000000"], ["61616.17000000", "0.00010000"], ["61616.27000000", "0.00013000"], ["61616.48000000", "1.36330000"], ["61617.05000000", "0.00400000"], ["61617.32000000", "0.00009000"], ["61617.52000000", "0.00000000"], ["61618.16000000", "0.00000000"], ["61618.22000000", "0.00000000"], ["61618.23000000", "0.58482000"], ["61618.24000000", "0.00000000"], ["61618.65000000", "0.00000000"], ["61619.37000000", "0.00150000"], ["61619.39000000", "0.97659000"], ["61619.40000000", "1.36330000"], ["61619.71000000", "0.97390000"], ["61619.72000000", "0.00000000"], ["61619.73000000", "0.00000000"], ["61621.31000000", "0.00000000"], ["61622.10000000", "0.00000000"], ["61622.33000000", "0.00000000"], ["61622.50000000", "0.00000000"], ["61623.20000000", "0.00000000"], ["61624.05000000", "0.02576000"], ["61624.32000000", "0.00010000"], ["61624.54000000", "0.00000000"], ["61626.30000000", "0.00000000"], ["61626.63000000", "0.00009000"], ["61627.99000000", "0.00000000"], ["61628.62000000", "0.00000000"], ["61629.57000000", "0.00000000"], ["61632.97000000", "1.60788000"], ["61633.48000000", "0.00000000"], ["61634.12000000", "0.04710000"], ["61635.48000000", "0.00009000"], ["61635.95000000", "0.00000000"], ["61639.40000000", "0.00000000"], ["61639.47000000", "2.47430000"], ["61641.34000000", "0.00000000"], ["61642.00000000", "0.03400000"], ["61643.00000000", "0.00000000"], ["61646.51000000", "0.85832000"], ["61651.47000000", "0.00000000"], ["61653.51000000", "0.00016000"], ["61654.56000000", "0.00000000"], ["61656.24000000", "0.00000000"], ["61658.20000000", "0.97499000"], ["61660.44000000", "0.00000000"], ["61670.59000000", "0.00000000"], ["61712.65000000", "0.00000000"], ["61715.76000000", "0.00000000"], ["61784.14000000", "0.00030000"], ["62048.84000000", "0.00250000"], ["62536.18000000", "0.00000000"]]}
{"type": "depth", "ts": 1783008110714, "U": 96863175832, "u": 96863176000, "bids": [["61610.00000000", "0.18986000"], ["61609.99000000", "0.04792000"], ["61608.97000000", "0.00000000"], ["61608.86000000", "0.00009000"], ["61608.03000000", "0.00009000"], ["61608.00000000", "0.01118000"], ["61607.59000000", "0.00000000"], ["61607.53000000", "0.00000000"], ["61607.28000000", "0.00000000"], ["61607.16000000", "0.00009000"], ["61607.15000000", "0.08377000"], ["61606.97000000", "0.00000000"], ["61606.60000000", "0.25045000"], ["61606.09000000", "0.00000000"], ["61606.00000000", "0.01927000"], ["61605.95000000", "0.00000000"], ["61605.55000000", "0.00009000"], ["61605.54000000", "0.02655000"], ["61605.34000000", "0.00018000"], ["61604.66000000", "0.00009000"], ["61604.65000000", "0.05871000"], ["61604.64000000", "0.08584000"], ["61604.22000000", "0.00000000"], ["61604.21000000", "0.00000000"], ["61604.01000000", "0.00000000"], ["61604.00000000", "0.02418000"], ["61603.95000000", "0.00000000"], ["61603.94000000", "0.00009000"], ["61603.74000000", "0.00000000"], ["61603.36000000", "0.00009000"], ["61603.35000000", "0.08478000"], ["61602.63000000", "0.00009000"], ["61602.62000000", "0.09147000"], ["61602.58000000", "0.00000000"], ["61602.04000000", "0.00488000"], ["61601.76000000", "0.00000000"], ["61599.71000000", "0.62666000"], ["61599.41000000", "0.00488000"], ["61596.33000000", "0.00000000"], ["61595.23000000", "0.00189000"], ["61595.21000000", "0.09544000"], ["61587.45000000", "0.58511000"], ["61580.26000000", "0.86010000"], ["61580.24000000", "0.00000000"], ["61572.75000000", "0.00000000"], ["61564.80000000", "0.00400000"], ["61557.59000000", "0.52357000"], ["61557.39000000", "0.00000000"], ["61537.99000000", "1.46982000"], ["61507.82000000", "0.00000000"], ["61472.64000000", "0.00000000"], ["55449.00000000", "0.00060000"]], "asks": [["61610.01000000", "4.55915000"], ["61610.58000000", "0.00000000"], ["61610.85000000", "0.30394000"], ["61610.86000000", "0.05118000"], ["61610.87000000", "0.46599000"], ["61610.88000000", "0.08950000"], ["61611.29000000", "0.00009000"], ["61611.50000000", "0.00018000"], ["61611.75000000", "0.13413000"], ["61611.95000000", "0.04039000"], ["61611.99000000", "0.20516000"], ["61612.00000000", "0.02762000"], ["61612.55000000", "0.04815000"], ["61612.70000000", "0.00000000"], ["61612.71000000", "0.00018000"], ["61612.86000000", "0.00034000"], ["61613.18000000", "0.00898000"], ["61614.02000000", "0.08009000"], ["61615.97000000", "0.59309000"], ["61617.32000000", "0.00000000"], ["61617.54000000", "0.00000000"], ["61622.33000000", "0.00326000"], ["61632.14000000", "0.03168000"], ["61633.25000000", "0.00000000"], ["61641.00000000", "0.01400000"], ["61642.00000000", "0.02400000"], ["61652.47000000", "0.00532000"], ["61663.81000000", "0.00000000"], ["61695.40000000", "0.00000000"], ["61712.64000000", "0.00000000"]]}
{"type": "depth", "ts": 1783008110814, "U": 96863176001, "u": 96863176070, "bids": [["61610.00000000", "0.00727000"], ["61609.99000000", "0.04792000"], ["61608.00000000", "0.01118000"], ["61607.50000000", "0.00009000"], ["61607.16000000", "0.00000000"], ["61607.15000000", "0.00018000"], ["61606.00000000", "0.01927000"], ["61605.54000000", "0.00018000"], ["61605.35000000", "0.00000000"], ["61605.34000000", "0.00000000"], ["61605.19000000", "0.00851000"], ["61604.65000000", "0.05889000"], ["61604.64000000", "0.08602000"], ["61604.01000000", "0.00009000"], ["61604.00000000", "0.02400000"], ["61603.35000000", "0.08460000"], ["61602.63000000", "0.38965000"], ["61602.62000000", "0.09129000"], ["61600.32000000", "0.00009000"], ["61597.39000000", "0.00009000"], ["61571.02000000", "0.00000000"], ["61504.38000000", "0.12970000"], ["61503.88000000", "0.05351000"], ["61442.87000000", "0.00000000"], ["55449.00000000", "0.00080000"], ["49288.00000000", "0.05700000"]], "asks": [["61610.01000000", "5.56100000"], ["61610.87000000", "0.21849000"], ["61610.88000000", "0.08941000"], ["61611.36000000", "0.16231000"], ["61611.50000000", "0.00000000"], ["61611.75000000", "0.00018000"], ["61611.79000000", "0.00009000"], ["61613.63000000", "0.00000000"], ["61614.87000000", "0.00000000"], ["61649.00000000", "0.00111000"], ["61658.90000000", "0.00000000"], ["61660.22000000", "0.00000000"], ["61687.73000000", "0.69527000"], ["61688.68000000", "0.05037000"]]}
{"type": "depth", "ts": 1783008110914, "U": 96863176071, "u": 96863176131, "bids": [["61610.00000000", "0.01089000"], ["61608.00000000", "0.01118000"], ["61607.15000000", "0.00000000"], ["61606.00000000", "0.01927000"], ["61605.55000000", "0.00000000"], ["61605.54000000", "0.00000000"], ["61605.19000000", "0.00869000"], ["61604.65000000", "0.03315000"], ["61604.64000000", "0.00018000"], ["61603.35000000", "0.08460000"], ["61602.64000000", "0.00009000"], ["61602.63000000", "0.38956000"], ["61602.62000000", "0.00000000"], ["61602.58000000", "0.00009000"], ["61587.45000000", "0.00000000"], ["61571.02000000", "0.00009000"], ["61570.61000000", "0.58527000"], ["61565.00000000", "0.00000000"], ["61527.95000000", "0.00000000"], ["61509.49000000", "0.00000000"], ["61470.65000000", "0.00034000"], ["55449.00000000", "0.00120000"]], "asks": [["61610.01000000", "5.56140000"], ["61610.85000000", "0.17756000"], ["61610.88000000", "0.08941000"], ["61611.36000000", "0.16249000"], ["61611.75000000", "0.00000000"], ["61611.95000000", "0.04057000"], ["61615.41000000", "0.58494000"], ["61615.42000000", "0.00000000"], ["61615.95000000", "1.01369000"], ["61615.96000000", "0.97390000"], ["61615.97000000", "0.00000000"], ["61623.23000000", "0.00000000"], ["61635.71000000", "0.00432000"], ["61643.51000000", "0.00000000"], ["61647.68000000", "0.01716000"]]}
{"type": "depth", "ts": 1783008111014, "U": 96863176132, "u": 96863176159, "bids": [["61606.60000000", "0.25036000"], ["61604.65000000", "0.03315000"], ["61604.64000000", "0.00000000"], ["61604.00000000", "0.02418000"], ["61602.64000000", "0.14611000"], ["61602.57000000", "0.00000000"], ["61602.03000000", "0.00000000"], ["61599.72000000", "0.09197000"], ["61596.27000000", "0.00000000"], ["61489.02000000", "0.02543000"], ["61426.21000000", "0.00045000"], ["55449.00000000", "0.00160000"], ["49288.00000000", "0.05740000"]], "asks": [["61610.01000000", "5.56232000"], ["61612.71000000", "0.00009000"], ["61643.20000000", "0.00000000"]]}
{"type": "depth", "ts": 1783008111114, "U": 96863176160, "u": 96863176185, "bids": [["61610.00000000", "0.01098000"], ["61603.94000000", "0.00000000"], ["61603.35000000", "0.08469000"], ["61602.65000000", "0.00009000"], ["61602.58000000", "0.00000000"], ["61600.62000000", "0.09197000"], ["61592.40000000", "0.03249000"], ["61592.01000000", "0.00000000"], ["61586.63000000", "0.00040000"], ["61582.81000000", "0.01624000"], ["61564.40000000", "0.00000000"], ["61559.82000000", "0.13895000"], ["61554.33000000", "0.00434000"], ["61521.92000000", "0.00000000"], ["61514.73000000", "0.00309000"], ["61496.28000000", "0.00986000"], ["61420.75000000", "0.01002000"], ["55449.00000000", "0.00200000"]], "asks": [["61610.01000000", "5.56435000"], ["61622.46000000", "0.04792000"], ["61635.48000000", "0.00633000"], ["61653.51000000", "0.00000000"], ["61674.80000000", "0.00000000"]]}
{"type": "depth", "ts": 1783008111214, "U": 96863176186, "u": 96863176222, "bids": [["61606.60000000", "0.25045000"], ["61605.64000000", "0.10579000"], ["61604.65000000", "0.06049000"], ["61604.17000000", "0.00009000"], ["61604.16000000", "0.00000000"], ["61602.65000000", "0.09084000"], ["61599.74000000", "0.03249000"], ["61599.73000000", "0.00000000"], ["61597.78000000", "0.01000000"], ["61597.73000000", "0.01000000"], ["61597.16000000", "0.01000000"], ["61594.03000000", "0.01000000"], ["61592.51000000", "0.00000000"], ["61592.40000000", "0.00000000"], ["61574.65000000", "0.00419000"], ["61553.10000000", "0.01000000"], ["61551.07000000", "0.01000000"], ["61550.80000000", "0.01000000"], ["61547.66000000", "0.01000000"], ["61547.60000000", "0.01000000"], ["61547.04000000", "0.01000000"], ["61420.75000000", "0.00000000"], ["61058.54000000", "0.00201000"], ["60997.48000000", "0.00044000"], ["60685.85000000", "0.00030000"], ["55449.00000000", "0.00240000"], ["49288.00000000", "0.05700000"]], "asks": [["61610.01000000", "5.56510000"], ["61615.26000000", "0.01800000"], ["61615.32000000", "0.01400000"], ["61615.88000000", "0.01200000"], ["61615.93000000", "0.01100000"], ["61618.35000000", "0.01000000"], ["61619.01000000", "0.01200000"], ["61625.03000000", "0.00000000"]]}
{"type": "depth", "ts": 1783008111314, "U": 96863176223, "u": 96863176274, "bids": [["61610.00000000", "0.19357000"], ["61609.99000000", "0.04801000"], ["61609.95000000", "0.00009000"], ["61606.60000000", "0.25045000"], ["61606.00000000", "0.01927000"], ["61605.65000000", "0.00009000"], ["61605.43000000", "0.00009000"], ["61605.42000000", "0.02304000"], ["61605.19000000", "0.00018000"], ["61604.65000000", "0.03315000"], ["61604.17000000", "0.00000000"], ["61603.35000000", "0.08478000"], ["61602.66000000", "0.00009000"], ["61602.65000000", "0.09075000"], ["61602.64000000", "0.14602000"], ["61597.16000000", "0.02000000"], ["61597.11000000", "0.01000000"], ["61596.21000000", "0.00897000"], ["61594.34000000", "0.01000000"], ["61589.00000000", "0.00000000"], ["61588.95000000", "0.00000000"], ["61587.76000000", "0.00000000"], ["61587.71000000", "0.00000000"], ["61587.15000000", "0.00009000"], ["61554.61000000", "0.01000000"], ["61553.20000000", "0.01000000"], ["61549.44000000", "0.01000000"], ["61547.04000000", "0.00000000"], ["55449.00000000", "0.00280000"]], "asks": [["61610.01000000", "5.56566000"], ["61610.88000000", "0.08950000"], ["61611.36000000", "0.00018000"], ["61611.62000000", "0.15758000"], ["61615.88000000", "0.02500000"], ["61615.94000000", "0.01100000"], ["61618.71000000", "0.01000000"], ["61624.36000000", "0.00000000"], ["61624.41000000", "0.00000000"], ["61624.97000000", "0.00000000"], ["61626.50000000", "0.00000000"], ["61626.57000000", "0.00000000"], ["61627.44000000", "0.00000000"], ["61659.81000000", "0.00000000"]]}
{"type": "depth", "ts": 1783008111414, "U": 96863176275, "u": 96863176673, "bids": [["61610.00000000", "0.00000000"], ["61609.99000000", "0.00000000"], ["61609.95000000", "0.00000000"], ["61609.63000000", "0.00000000"], ["61609.23000000", "0.00000000"], ["61608.86000000", "0.00000000"], ["61608.03000000", "0.00000000"], ["61608.01000000", "0.00000000"], ["61608.00000000", "0.00000000"], ["61607.99000000", "0.00000000"], ["61607.80000000", "0.00000000"], ["61607.50000000", "0.00000000"], ["61606.61000000", "0.00000000"], ["61606.60000000", "0.40304000"], ["61606.59000000", "0.00062000"], ["61606.58000000", "0.00017000"], ["61605.65000000", "0.00000000"], ["61605.64000000", "0.00018000"], ["61605.43000000", "0.00000000"], ["61605.42000000", "0.00018000"], ["61605.32000000", "0.00000000"], ["61605.19000000", "0.00000000"], ["61604.66000000", "0.00000000"], ["61604.65000000", "0.00018000"], ["61604.29000000", "0.00000000"], ["61604.04000000", "0.00000000"], ["61603.84000000", "0.00000000"], ["61603.36000000", "0.00000000"], ["61603.35000000", "0.00018000"], ["61602.67000000", "0.00009000"], ["61602.66000000", "0.00009000"], ["61602.65000000", "0.03562000"], ["61602.64000000", "0.00018000"], ["61602.63000000", "0.00000000"], ["61602.62000000", "0.00009000"], ["61602.61000000", "0.00000000"], ["61602.04000000", "0.00000000"], ["61602.01000000", "0.00009000"], ["61600.64000000", "0.00009000"], ["61600.63000000", "0.09206000"], ["61600.62000000", "0.00000000"], ["61600.44000000", "0.00010000"], ["61600.32000000", "0.00000000"], ["61600.13000000", "0.00000000"], ["61600.12000000", "0.00000000"], ["61600.01000000", "0.00009000"], ["61599.74000000", "0.00000000"], ["61599.73000000", "0.00009000"], ["61599.72000000", "0.09215000"], ["61599.67000000", "0.00000000"], ["61599.50000000", "0.00000000"], ["61599.41000000", "1.36818000"], ["61599.40000000", "0.00000000"], ["61599.27000000", "0.04710000"], ["61598.49000000", "0.00000000"], ["61597.39000000", "0.00000000"], ["61597.11000000", "0.01000000"], ["61596.90000000", "1.38451000"], ["61596.89000000", "2.34208000"], ["61596.88000000", "0.00000000"], ["61596.86000000", "0.00000000"], ["61596.85000000", "0.00000000"], ["61596.84000000", "0.00000000"], ["61596.59000000", "0.00000000"], ["61596.32000000", "0.00812000"], ["61596.21000000", "0.00000000"], ["61595.90000000", "0.00000000"], ["61595.86000000", "0.02434000"], ["61595.83000000", "0.00000000"], ["61595.80000000", "0.00400000"], ["61595.74000000", "0.00000000"], ["61595.72000000", "0.01008000"], ["61594.93000000", "0.15000000"], ["61594.67000000", "0.00000000"], ["61594.59000000", "0.00000000"], ["61594.58000000", "0.00905000"], ["61594.41000000", "1.75286000"], ["61594.40000000", "0.00488000"], ["61594.37000000", "0.00000000"], ["61594.28000000", "0.00010000"], ["61594.03000000", "0.02000000"], ["61593.51000000", "0.00016000"], ["61593.26000000", "0.00000000"], ["61592.51000000", "0.03249000"], ["61592.36000000", "0.00000000"], ["61591.65000000", "0.70036000"], ["61591.64000000", "0.97878000"], ["61591.63000000", "0.00000000"], ["61591.62000000", "0.00000000"], ["61591.20000000", "0.00010000"], ["61590.43000000", "0.00000000"], ["61589.64000000", "0.00400000"], ["61588.12000000", "0.00044000"], ["61588.00000000", "0.02400000"], ["61587.35000000", "0.00000000"], ["61586.20000000", "0.00800000"], ["61586.18000000", "0.00000000"], ["61585.04000000", "0.00010000"], ["61584.59000000", "0.00000000"], ["61584.26000000", "0.00000000"], ["61584.01000000", "0.00051000"], ["61581.96000000", "0.00010000"], ["61581.18000000", "0.00000000"], ["61579.00000000", "0.00000000"], ["61578.88000000", "0.00010000"], ["61578.30000000", "0.00009000"], ["61575.80000000", "0.00010000"], ["61575.10000000", "0.00000000"], ["61575.00000000", "0.01000000"], ["61573.48000000", "0.00000000"], ["61568.08000000", "0.58530000"], ["61559.82000000", "0.00000000"], ["61559.02000000", "0.00000000"], ["61553.50000000", "0.00000000"], ["61551.06000000", "0.01000000"], ["61549.45000000", "0.00405000"], ["61548.77000000", "1.61008000"], ["61515.21000000", "0.01658000"], ["61513.48000000", "0.00009000"], ["61108.65000000", "0.00000000"], ["60936.48000000", "0.00025000"], ["60685.85000000", "0.00000000"], ["55450.80000000", "0.00000000"], ["55449.00000000", "0.00010000"]], "asks": [["61606.61000000", "3.24902000"], ["61606.62000000", "0.00035000"], ["61606.63000000", "0.00017000"], ["61607.80000000", "0.00009000"], ["61607.95000000", "0.00000000"], ["61608.00000000", "0.00000000"], ["61608.01000000", "0.00000000"], ["61608.04000000", "0.00000000"], ["61608.71000000", "0.09337000"], ["61608.87000000", "0.00000000"], ["61609.11000000", "0.00009000"], ["61609.24000000", "0.00000000"], ["61609.64000000", "0.00000000"], ["61609.96000000", "0.00000000"], ["61610.00000000", "3.22580000"], ["61610.01000000", "1.69935000"], ["61610.02000000", "0.00000000"], ["61610.03000000", "0.00000000"], ["61610.85000000", "0.00027000"], ["61610.87000000", "0.13074000"], ["61610.88000000", "0.08950000"], ["61611.36000000", "0.00000000"], ["61611.42000000", "0.00000000"], ["61611.62000000", "0.00018000"], ["61612.00000000", "0.02744000"], ["61612.55000000", "0.03363000"], ["61612.77000000", "0.00010000"], ["61613.49000000", "0.00009000"], ["61614.02000000", "0.00009000"], ["61616.17000000", "0.00000000"], ["61618.93000000", "0.00010000"], ["61619.17000000", "0.00009000"], ["61620.27000000", "0.00400000"], ["61621.76000000", "0.60500000"], ["61622.01000000", "0.00010000"], ["61622.26000000", "0.00000000"], ["61622.33000000", "0.00000000"], ["61624.32000000", "0.00000000"], ["61625.09000000", "0.00010000"], ["61627.40000000", "0.00000000"], ["61628.17000000", "0.00010000"], ["61629.34000000", "0.00000000"], ["61629.65000000", "0.00000000"], ["61630.48000000", "0.00016000"], ["61631.25000000", "0.00010000"], ["61633.56000000", "0.00000000"], ["61634.33000000", "0.00010000"], ["61635.18000000", "0.00000000"], ["61636.64000000", "0.00000000"], ["61637.41000000", "0.00010000"], ["61638.41000000", "0.00000000"], ["61639.24000000", "0.00009000"], ["61639.73000000", "0.00000000"], ["61640.25000000", "0.00000000"], ["61642.81000000", "0.00000000"], ["61646.80000000", "0.00000000"], ["61647.02000000", "0.00000000"], ["61666.89000000", "0.13386000"], ["61669.31000000", "0.00016000"], ["61701.36000000", "0.00000000"], ["61915.84000000", "0.00000000"], ["61943.78000000", "0.00829000"], ["62530.71000000", "0.00030000"]]}
{"type": "depth", "ts": 1783008111514, "U": 96863176674, "u": 96863176828, "bids": [["61606.60000000", "0.98227000"], ["61606.59000000", "0.00062000"], ["61606.00000000", "0.01927000"], ["61605.64000000", "0.00000000"], ["61605.42000000", "0.00000000"], ["61604.65000000", "0.00000000"], ["61604.00000000", "0.02418000"], ["61603.35000000", "0.00000000"], ["61602.85000000", "0.04637000"], ["61602.67000000", "0.00000000"], ["61602.66000000", "0.00018000"], ["61602.65000000", "0.00018000"], ["61602.64000000", "0.00000000"], ["61602.62000000", "0.00000000"], ["61602.00000000", "0.02418000"], ["61600.66000000", "0.09207000"], ["61600.65000000", "0.15126000"], ["61600.64000000", "0.38956000"], ["61600.63000000", "0.00027000"], ["61600.01000000", "0.00000000"], ["61600.00000000", "0.02427000"], ["61599.72000000", "0.09233000"], ["61599.71000000", "0.62693000"], ["61599.66000000", "0.00009000"], ["61599.65000000", "0.24759000"], ["61596.91000000", "1.75654000"], ["61596.90000000", "0.00000000"], ["61596.75000000", "0.00000000"], ["61595.72000000", "0.00000000"], ["61595.60000000", "0.00048000"], ["61595.41000000", "0.00048000"], ["61595.28000000", "0.01003000"], ["61595.21000000", "0.00649000"], ["61594.58000000", "0.00000000"], ["61594.33000000", "0.01034000"], ["61593.10000000", "0.01200000"], ["61565.31000000", "0.00000000"], ["61565.02000000", "0.00000000"], ["61562.90000000", "0.00000000"], ["61555.91000000", "0.00434000"], ["61555.56000000", "0.00621000"], ["61552.80000000", "0.00000000"], ["61551.07000000", "0.01000000"], ["61435.66000000", "0.00009000"], ["61432.58000000", "0.00009000"], ["61420.75000000", "0.00975000"], ["60875.54000000", "0.00028000"], ["55445.94000000", "0.00040000"]], "asks": [["61606.61000000", "3.27153000"], ["61607.82000000", "0.00400000"], ["61608.70000000", "0.02790000"], ["61608.71000000", "0.00027000"], ["61609.63000000", "0.09133000"], ["61609.68000000", "0.00400000"], ["61609.99000000", "0.91633000"], ["61610.00000000", "1.41448000"], ["61610.01000000", "1.68360000"], ["61610.85000000", "0.00009000"], ["61610.88000000", "0.08914000"], ["61611.62000000", "0.00000000"], ["61614.30000000", "0.00009000"], ["61614.84000000", "0.00000000"], ["61618.80000000", "0.08731000"], ["61618.93000000", "0.00334000"], ["61620.34000000", "0.08891000"], ["61624.70000000", "0.00000000"], ["61626.24000000", "0.00000000"], ["61638.00000000", "0.03400000"], ["61638.02000000", "0.00432000"], ["61638.18000000", "0.00435000"], ["61641.00000000", "0.00400000"], ["61648.60000000", "0.00000000"], ["61651.15000000", "0.09352000"], ["61651.92000000", "0.00000000"], ["61660.95000000", "0.00000000"], ["61703.03000000", "0.00000000"], ["61706.80000000", "0.00000000"], ["61710.18000000", "0.00000000"], ["61789.82000000", "0.00000000"]]}
{"type": "depth", "ts": 1783008111614, "U": 96863176829, "u": 96863176915, "bids": [["61606.60000000", "0.98346000"], ["61606.59000000", "0.00062000"], ["61604.00000000", "0.02418000"], ["61602.86000000", "0.00009000"], ["61602.85000000", "0.04655000"], ["61602.66000000", "0.00009000"], ["61602.65000000", "0.00000000"], ["61602.00000000", "0.02418000"], ["61600.67000000", "0.00009000"], ["61600.66000000", "0.09225000"], ["61600.65000000", "0.15144000"], ["61600.64000000", "0.38974000"], ["61600.63000000", "0.00009000"], ["61599.73000000", "0.00000000"], ["61599.72000000", "0.00018000"], ["61599.71000000", "0.62675000"], ["61597.39000000", "0.00009000"], ["61595.09000000", "0.08775000"], ["61593.71000000", "0.01000000"], ["61593.09000000", "0.01300000"], ["61589.66000000", "0.01000000"], ["61587.16000000", "0.00000000"], ["61585.93000000", "0.00000000"], ["61585.87000000", "0.00000000"], ["61568.09000000", "0.00009000"], ["61552.80000000", "0.00433000"], ["61551.69000000", "0.01000000"], ["61551.53000000", "0.01300000"], ["61432.58000000", "0.00000000"], ["60682.50000000", "0.00039000"], ["55445.94000000", "0.00080000"]], "asks": [["61606.61000000", "3.36021000"], ["61607.79000000", "0.00029000"], ["61608.70000000", "0.00018000"], ["61608.71000000", "0.00009000"], ["61609.63000000", "0.09151000"], ["61610.01000000", "1.43610000"], ["61611.91000000", "0.00158000"], ["61611.95000000", "0.04039000"], ["61611.99000000", "0.20507000"], ["61612.55000000", "0.10321000"], ["61612.78000000", "0.24750000"], ["61615.41000000", "0.58485000"], ["61618.35000000", "0.02100000"], ["61618.97000000", "0.01000000"], ["61619.37000000", "0.00000000"], ["61626.63000000", "0.00000000"], ["61669.31000000", "0.00000000"], ["61787.09000000", "0.00000000"]]}
{"type": "depth", "ts": 1783008111714, "U": 96863176916, "u": 96863176951, "bids": [["61606.60000000", "0.98346000"], ["61606.59000000", "0.00053000"], ["61603.71000000", "0.00009000"], ["61603.70000000", "0.08309000"], ["61600.00000000", "0.02409000"], ["61586.26000000", "0.00009000"], ["61583.57000000", "0.00000000"], ["61575.10000000", "0.15925000"], ["61551.53000000", "0.00000000"], ["61548.78000000", "1.00512000"], ["61531.99000000", "0.42186000"], ["61530.01000000", "0.82067000"], ["61505.66000000", "0.00000000"], ["61495.49000000", "0.00000000"], ["61470.65000000", "0.00000000"], ["55445.94000000", "0.00120000"], ["33000.00000000", "37.44300000"]], "asks": [["61606.61000000", "3.36039000"], ["61608.70000000", "0.00000000"], ["61609.99000000", "0.91651000"], ["61612.78000000", "0.25050000"], ["61623.23000000", "0.00009000"], ["61624.33000000", "0.00000000"], ["61627.01000000", "0.00000000"], ["61655.65000000", "1.42214000"], ["61669.21000000", "0.00000000"], ["61698.35000000", "0.00000000"], ["61701.59000000", "0.00000000"], ["61705.89000000", "0.00000000"]]}
{"type": "depth", "ts": 1783008111814, "U": 96863176952, "u": 96863176981, "bids": [["61606.60000000", "0.98183000"], ["61605.65000000", "0.00009000"], ["61604.00000000", "0.02418000"], ["61603.81000000", "0.00009000"], ["61595.28000000", "0.00000000"], ["61584.19000000", "0.00000000"], ["61420.75000000", "0.01002000"], ["60814.66000000", "0.00031000"], ["55445.94000000", "0.00160000"], ["55445.00000000", "0.00000000"]], "asks": [["61606.61000000", "3.36003000"], ["61609.99000000", "0.93956000"], ["61610.88000000", "0.08932000"], ["61611.79000000", "0.00000000"], ["61611.95000000", "0.04057000"], ["61626.41000000", "0.00000000"], ["61653.15000000", "0.00000000"], ["67767.27000000", "0.00009000"]]}
{"type": "depth", "ts": 1783008111914, "U": 96863176982, "u": 96863177000, "bids": [["61606.60000000", "0.98192000"], ["61606.59000000", "0.00062000"], ["61600.73000000", "0.00000000"], ["61594.86000000", "0.00987000"], ["61558.34000000", "0.13667000"], ["61502.26000000", "0.00016000"], ["61492.10000000", "0.00186000"], ["55445.94000000", "0.00200000"], ["49285.28000000", "0.00000000"]], "asks": [["61606.61000000", "3.03963000"], ["61609.70000000", "0.00913000"], ["61628.40000000", "0.00000000"], ["67767.27000000", "0.00000000"]]}
{"type": "depth", "ts": 1783008112014, "U": 96863177001, "u": 96863177028, "bids": [["61606.60000000", "0.97113000"], ["61605.35000000", "0.00009000"], ["61605.34000000", "0.09016000"], ["61603.71000000", "0.00000000"], ["61603.70000000", "0.00000000"], ["61601.24000000", "0.09198000"], ["61592.51000000", "0.00000000"], ["61592.07000000", "0.03249000"], ["61584.56000000", "0.58514000"], ["61568.08000000", "0.00000000"], ["61467.25000000", "0.00034000"], ["61261.29000000", "0.00040000"], ["60753.84000000", "0.00038000"], ["55445.94000000", "0.00240000"], ["49285.28000000", "0.00040000"]], "asks": [["61606.61000000", "2.99963000"], ["61609.63000000", "0.09151000"], ["61609.70000000", "0.00931000"], ["61611.95000000", "0.04039000"]]}
{"type": "depth", "ts": 1783008112114, "U": 96863177029, "u": 96863177061, "bids": [["61606.60000000", "0.97122000"], ["61606.59000000", "0.00071000"], ["61606.00000000", "0.01927000"], ["61605.34000000", "0.09043000"], ["61604.00000000", "0.02418000"], ["61602.00000000", "0.02418000"], ["61601.25000000", "0.00009000"], ["61600.64000000", "0.38956000"], ["61599.66000000", "0.00000000"], ["61595.09000000", "0.00000000"], ["61570.54000000", "0.03131000"], ["61568.09000000", "0.00000000"], ["61534.53000000", "0.00000000"], ["61529.14000000", "0.00030000"], ["61420.75000000", "0.01017000"], ["55445.94000000", "0.00260000"]], "asks": [["61606.61000000", "2.87199000"], ["61609.62000000", "0.00009000"], ["61663.31000000", "0.00829000"], ["61683.16000000", "0.00039000"], ["61688.56000000", "0.00000000"]]}
{"type": "depth", "ts": 1783008112214, "U": 96863177062, "u": 96863177073, "bids": [["61581.38000000", "0.01000000"], ["61581.32000000", "0.01000000"], ["61580.76000000", "0.01000000"], ["61547.04000000", "0.01000000"], ["55445.94000000", "0.00300000"], ["49285.28000000", "0.00000000"]], "asks": [["61623.72000000", "0.54842000"], ["61659.81000000", "0.01200000"], ["61694.95000000", "0.00016000"], ["61698.19000000", "0.00024000"], ["61702.49000000", "0.00040000"]]}
{"type": "depth", "ts": 1783008112314, "U": 96863177074, "u": 96863177174, "bids": [["61606.60000000", "1.78769000"], ["61606.59000000", "0.00062000"], ["61605.35000000", "0.12642000"], ["61605.34000000", "0.00027000"], ["61604.01000000", "0.00000000"], ["61603.92000000", "0.09205000"], ["61602.86000000", "0.00000000"], ["61602.58000000", "0.09205000"], ["61602.01000000", "0.00000000"], ["61601.25000000", "0.00000000"], ["61600.67000000", "0.97390000"], ["61600.66000000", "0.09216000"], ["61600.65000000", "0.15135000"], ["61599.72000000", "0.09214000"], ["61596.92000000", "0.03258000"], ["61592.07000000", "0.00000000"], ["61587.65000000", "0.58511000"], ["61580.71000000", "0.01000000"], ["61579.65000000", "0.00000000"], ["61573.52000000", "1.60943000"], ["61570.61000000", "0.00000000"], ["61566.54000000", "0.00400000"], ["61556.88000000", "0.00009000"], ["61547.60000000", "0.00000000"], ["61547.04000000", "0.00000000"], ["61540.69000000", "0.00000000"], ["55445.94000000", "0.00340000"]], "asks": [["61606.61000000", "1.93725000"], ["61607.82000000", "0.00000000"], ["61609.11000000", "0.02009000"], ["61609.98000000", "0.00009000"], ["61609.99000000", "0.00027000"], ["61610.00000000", "0.00027000"], ["61610.01000000", "1.20610000"], ["61610.74000000", "0.00000000"], ["61610.86000000", "0.00018000"], ["61610.87000000", "0.00027000"], ["61610.88000000", "0.00932000"], ["61611.99000000", "0.05142000"], ["61612.52000000", "0.12000000"], ["61612.78000000", "0.25450000"], ["61612.86000000", "0.00000000"], ["61614.39000000", "0.00000000"], ["61615.40000000", "0.00018000"], ["61615.41000000", "0.00000000"], ["61615.96000000", "0.00000000"], ["61616.48000000", "0.00000000"], ["61618.23000000", "0.00000000"], ["61619.40000000", "0.00000000"], ["61619.71000000", "0.00000000"], ["61620.27000000", "0.00000000"], ["61620.66000000", "0.00000000"], ["61623.12000000", "0.00400000"], ["61629.33000000", "0.00000000"], ["61632.36000000", "0.00000000"], ["61651.91000000", "0.00000000"], ["61654.26000000", "0.00400000"], ["61713.29000000", "0.00000000"]]}
{"type": "depth", "ts": 1783008112414, "U": 96863177175, "u": 96863177861, "bids": [["61609.10000000", "6.50574000"], ["61609.09000000", "0.00017000"], ["61609.08000000", "0.00017000"], ["61609.01000000", "0.00018000"], ["61608.70000000", "0.00000000"], ["61608.52000000", "0.00034000"], ["61607.82000000", "0.00400000"], ["61607.80000000", "0.00009000"], ["61607.79000000", "0.00000000"], ["61607.78000000", "0.00000000"], ["61606.63000000", "1.36818000"], ["61606.62000000", "0.00000000"], ["61606.61000000", "1.15726000"], ["61606.60000000", "1.21495000"], ["61606.59000000", "0.00000000"], ["61606.58000000", "0.00000000"], ["61606.18000000", "0.00009000"], ["61606.01000000", "0.00000000"], ["61606.00000000", "0.01927000"], ["61605.38000000", "0.13374000"], ["61605.37000000", "0.00000000"], ["61605.36000000", "0.00009000"], ["61605.35000000", "0.00027000"], ["61605.34000000", "0.00009000"], ["61605.24000000", "0.00400000"], ["61604.84000000", "0.16241000"], ["61604.78000000", "0.04217000"], ["61604.66000000", "0.00000000"], ["61604.00000000", "0.02418000"], ["61603.92000000", "0.00027000"], ["61603.67000000", "0.00000000"], ["61603.25000000", "0.00009000"], ["61603.23000000", "0.03000000"], ["61603.17000000", "0.00000000"], ["61602.99000000", "0.00000000"], ["61602.94000000", "0.00010000"], ["61602.93000000", "0.00400000"], ["61602.85000000", "0.00018000"], ["61602.66000000", "0.00409000"], ["61602.58000000", "0.00018000"], ["61601.95000000", "0.02000000"], ["61601.24000000", "0.00027000"], ["61601.08000000", "0.00986000"], ["61600.69000000", "0.40687000"], ["61600.68000000", "0.38956000"], ["61600.66000000", "0.00000000"], ["61600.65000000", "0.00000000"], ["61600.64000000", "0.00000000"], ["61600.47000000", "0.04217000"], ["61600.44000000", "0.00000000"], ["61600.32000000", "0.00009000"], ["61599.85000000", "0.00912000"], ["61599.72000000", "0.00009000"], ["61599.65000000", "0.24750000"], ["61599.17000000", "0.00000000"], ["61597.26000000", "0.00911000"], ["61596.92000000", "0.00009000"], ["61596.91000000", "1.65860000"], ["61596.77000000", "0.58502000"], ["61596.32000000", "0.00000000"], ["61596.19000000", "0.00000000"], ["61595.60000000", "0.00000000"], ["61595.41000000", "0.00000000"], ["61595.23000000", "0.00000000"], ["61595.04000000", "0.00000000"], ["61594.93000000", "0.12000000"], ["61594.64000000", "0.00892000"], ["61589.64000000", "0.00000000"], ["61588.02000000", "0.01625000"], ["61582.81000000", "0.00000000"], ["61581.86000000", "0.00000000"], ["61581.81000000", "0.00419000"], ["61579.77000000", "1.60927000"], ["61576.88000000", "0.00000000"], ["61576.86000000", "0.00400000"], ["61576.23000000", "0.00000000"], ["61573.95000000", "0.00000000"], ["61573.67000000", "0.00000000"], ["61571.02000000", "0.00000000"], ["61570.54000000", "0.00000000"], ["61568.36000000", "0.00000000"], ["61566.54000000", "0.00000000"], ["61564.80000000", "0.00000000"], ["61562.16000000", "0.00000000"], ["61558.34000000", "0.00000000"], ["61552.37000000", "0.97506000"], ["61549.44000000", "0.00000000"], ["61548.78000000", "0.00000000"], ["61548.77000000", "0.00000000"], ["61538.70000000", "0.00000000"], ["61497.80000000", "0.00000000"], ["61488.57000000", "0.00000000"], ["61467.25000000", "0.00000000"], ["61461.13000000", "0.00040000"], ["60682.50000000", "0.00009000"], ["55449.00000000", "0.00000000"], ["55445.94000000", "0.00010000"]], "asks": [["61606.61000000", "0.00000000"], ["61606.62000000", "0.00000000"], ["61606.63000000", "0.00000000"], ["61607.02000000", "0.00000000"], ["61607.79000000", "0.00000000"], ["61607.80000000", "0.00000000"], ["61608.10000000", "0.00000000"], ["61608.53000000", "0.00000000"], ["61608.54000000", "0.00000000"], ["61608.71000000", "0.00000000"], ["61609.01000000", "0.00000000"], ["61609.02000000", "0.00000000"], ["61609.10000000", "0.00000000"], ["61609.11000000", "0.04114000"], ["61609.12000000", "0.00080000"], ["61609.13000000", "0.00017000"], ["61609.62000000", "0.00000000"], ["61609.63000000", "0.00018000"], ["61609.68000000", "0.00000000"], ["61609.69000000", "0.00000000"], ["61609.70000000", "0.00018000"], ["61609.93000000", "0.00000000"], ["61609.98000000", "0.00000000"], ["61609.99000000", "0.00000000"], ["61610.00000000", "0.00009000"], ["61610.01000000", "1.08583000"], ["61610.28000000", "0.00000000"], ["61610.29000000", "0.00000000"], ["61610.85000000", "0.00000000"], ["61610.86000000", "0.00000000"], ["61610.87000000", "0.00009000"], ["61610.88000000", "0.00036000"], ["61610.95000000", "0.00000000"], ["61611.14000000", "0.00000000"], ["61611.16000000", "0.00904000"], ["61611.59000000", "0.02033000"], ["61611.91000000", "0.00000000"], ["61611.95000000", "0.04057000"], ["61611.98000000", "0.00000000"], ["61611.99000000", "0.00051000"], ["61612.00000000", "0.02744000"], ["61612.03000000", "0.00000000"], ["61612.04000000", "0.00000000"], ["61612.32000000", "0.00009000"], ["61612.51000000", "0.00000000"], ["61612.52000000", "0.00018000"], ["61612.54000000", "0.00000000"], ["61612.55000000", "0.00000000"], ["61612.71000000", "0.00000000"], ["61612.77000000", "0.00000000"], ["61612.78000000", "0.25050000"], ["61613.33000000", "0.00000000"], ["61613.43000000", "0.02000000"], ["61614.02000000", "0.00000000"], ["61614.56000000", "0.00009000"], ["61614.92000000", "0.00000000"], ["61614.96000000", "0.00000000"], ["61614.97000000", "0.00000000"], ["61615.00000000", "0.00000000"], ["61615.27000000", "0.00010000"], ["61615.40000000", "0.00009000"], ["61615.92000000", "0.00000000"], ["61615.94000000", "0.01100000"], ["61615.95000000", "0.00000000"], ["61616.71000000", "0.00048000"], ["61616.89000000", "0.00048000"], ["61617.05000000", "0.00000000"], ["61617.11000000", "0.00028000"], ["61617.33000000", "0.00000000"], ["61617.41000000", "0.00009000"], ["61617.42000000", "0.15000000"], ["61617.53000000", "0.00000000"], ["61618.41000000", "0.00221000"], ["61618.67000000", "0.09205000"], ["61618.79000000", "0.58639000"], ["61618.93000000", "0.00010000"], ["61618.94000000", "0.00000000"], ["61619.38000000", "0.00000000"], ["61619.39000000", "0.00000000"], ["61619.60000000", "0.00009000"], ["61619.82000000", "0.00400000"], ["61619.87000000", "0.00000000"], ["61620.36000000", "0.00166000"], ["61620.68000000", "0.00000000"], ["61621.17000000", "0.08422000"], ["61621.19000000", "0.09205000"], ["61621.20000000", "0.00000000"], ["61621.21000000", "0.00000000"], ["61621.35000000", "0.00000000"], ["61621.44000000", "0.00323000"], ["61621.73000000", "1.03310000"], ["61621.74000000", "0.00000000"], ["61621.75000000", "0.00000000"], ["61622.11000000", "0.00000000"], ["61622.12000000", "0.00000000"], ["61622.45000000", "0.00000000"], ["61622.46000000", "0.00000000"], ["61623.12000000", "0.00000000"], ["61623.69000000", "0.00000000"], ["61623.71000000", "1.36330000"], ["61624.03000000", "0.00000000"], ["61624.51000000", "0.00000000"], ["61624.53000000", "0.00000000"], ["61624.84000000", "0.00000000"], ["61624.85000000", "0.00000000"], ["61624.92000000", "0.00000000"], ["61624.93000000", "0.00000000"], ["61625.25000000", "0.09750000"], ["61626.95000000", "0.00400000"], ["61626.97000000", "0.00000000"], ["61627.33000000", "0.00000000"], ["61628.57000000", "0.58472000"], ["61630.81000000", "0.60812000"], ["61632.14000000", "0.00400000"], ["61632.97000000", "0.00000000"], ["61634.66000000", "0.58466000"], ["61638.00000000", "0.02400000"], ["61638.34000000", "0.00000000"], ["61638.41000000", "0.00009000"], ["61639.24000000", "0.00000000"], ["61640.00000000", "0.03400000"], ["61641.34000000", "0.00009000"], ["61649.10000000", "0.00400000"], ["61651.18000000", "0.00230000"], ["61658.20000000", "0.00000000"], ["61658.46000000", "0.00000000"], ["61659.04000000", "0.00000000"], ["61659.42000000", "0.00400000"], ["61661.04000000", "0.00000000"], ["61662.00000000", "0.02800000"], ["61663.31000000", "0.00000000"], ["61664.23000000", "0.00000000"], ["61666.89000000", "0.00000000"], ["61669.83000000", "0.00000000"], ["61670.00000000", "0.15972000"], ["61671.89000000", "0.97506000"], ["61687.99000000", "0.01170000"], ["61706.80000000", "0.11631000"], ["61726.62000000", "4.86497000"], ["61784.14000000", "0.24780000"], ["61915.84000000", "0.00009000"], ["62530.71000000", "0.00000000"]]}
{"type": "depth", "ts": 1783008112514, "U": 96863177862, "u": 96863178037, "bids": [["61609.10000000", "6.50902000"], ["61609.01000000", "0.00000000"], ["61608.64000000", "0.00010000"], ["61607.97000000", "0.08775000"], ["61607.64000000", "0.16240000"], ["61606.64000000", "1.11653000"], ["61606.63000000", "1.36836000"], ["61606.61000000", "0.22883000"], ["61606.60000000", "1.21373000"], ["61606.00000000", "0.01927000"], ["61605.38000000", "0.04021000"], ["61605.35000000", "0.00000000"], ["61604.84000000", "0.00027000"], ["61604.78000000", "0.04235000"], ["61604.00000000", "0.02418000"], ["61603.92000000", "0.00000000"], ["61603.24000000", "0.03248000"], ["61602.85000000", "0.00000000"], ["61602.66000000", "0.00400000"], ["61602.58000000", "0.00000000"], ["61602.00000000", "0.02400000"], ["61600.63000000", "0.00000000"], ["61599.72000000", "0.00000000"], ["61599.71000000", "0.62666000"], ["61596.45000000", "0.08734000"], ["61594.91000000", "0.08895000"], ["61588.02000000", "0.00000000"], ["61578.88000000", "0.03156000"], ["61578.00000000", "0.03400000"], ["61575.00000000", "0.00000000"], ["61574.65000000", "0.00000000"], ["61565.56000000", "0.14068000"], ["61555.56000000", "0.00000000"], ["61552.80000000", "0.01433000"], ["61551.08000000", "0.01200000"], ["61441.24000000", "0.00009000"], ["55448.19000000", "0.00040000"]], "asks": [["61609.11000000", "0.04239000"], ["61609.12000000", "0.00089000"], ["61609.63000000", "0.00000000"], ["61609.70000000", "0.00000000"], ["61610.01000000", "1.08583000"], ["61610.08000000", "0.08775000"], ["61610.88000000", "0.00018000"], ["61611.16000000", "0.00922000"], ["61611.59000000", "0.00018000"], ["61611.94000000", "0.01300000"], ["61611.95000000", "0.04057000"], ["61611.99000000", "0.00033000"], ["61612.00000000", "0.02744000"], ["61612.52000000", "0.00000000"], ["61612.77000000", "0.00009000"], ["61612.78000000", "0.25068000"], ["61613.18000000", "0.00916000"], ["61613.43000000", "0.02018000"], ["61614.17000000", "0.01211000"], ["61614.97000000", "0.00009000"], ["61618.49000000", "0.08347000"], ["61618.79000000", "0.15248000"], ["61618.80000000", "0.00000000"], ["61620.34000000", "0.00000000"], ["61620.36000000", "0.00000000"], ["61625.25000000", "0.00000000"], ["61626.76000000", "0.00000000"], ["61630.81000000", "0.00000000"], ["61631.54000000", "0.00000000"], ["61635.48000000", "0.00009000"], ["61638.02000000", "0.00000000"], ["61638.18000000", "0.00000000"], ["61643.71000000", "0.00632000"], ["61646.57000000", "0.00424000"], ["61646.94000000", "0.00430000"], ["61651.15000000", "0.00000000"], ["61687.73000000", "0.50078000"], ["61786.61000000", "0.00009000"], ["61789.69000000", "0.00009000"]]}
{"type": "depth", "ts": 1783008112614, "U": 96863178038, "u": 96863178140, "bids": [["61610.00000000", "1.67291000"], ["61609.11000000", "0.00000000"], ["61609.10000000", "6.55774000"], ["61609.09000000", "0.00035000"], ["61608.52000000", "0.00000000"], ["61607.97000000", "0.08793000"], ["61607.64000000", "0.16258000"], ["61606.64000000", "1.11671000"], ["61606.60000000", "1.21220000"], ["61605.38000000", "0.04003000"], ["61604.84000000", "0.00009000"], ["61604.78000000", "0.04217000"], ["61604.00000000", "0.02400000"], ["61599.27000000", "0.00000000"], ["61593.85000000", "0.58505000"], ["61565.92000000", "0.00433000"], ["61563.94000000", "0.00426000"], ["61555.91000000", "0.00000000"], ["61552.80000000", "0.01000000"], ["61551.53000000", "0.01300000"], ["61435.66000000", "0.00000000"], ["60684.96000000", "0.00030000"], ["55448.19000000", "0.00080000"]], "asks": [["61609.11000000", "0.00000000"], ["61609.12000000", "0.00000000"], ["61609.13000000", "0.00000000"], ["61610.00000000", "0.00000000"], ["61610.01000000", "1.08583000"], ["61610.07000000", "0.00009000"], ["61610.08000000", "0.08793000"], ["61611.16000000", "0.00922000"], ["61611.59000000", "0.00000000"], ["61611.94000000", "0.01318000"], ["61612.04000000", "0.00009000"], ["61613.43000000", "0.02000000"], ["61615.26000000", "0.00000000"], ["61615.32000000", "0.00000000"], ["61615.88000000", "0.00000000"], ["61615.93000000", "0.00000000"], ["61615.94000000", "0.00000000"], ["61617.14000000", "0.00048000"], ["61617.68000000", "0.00069000"], ["61618.35000000", "0.00000000"], ["61618.71000000", "0.00000000"], ["61618.97000000", "0.00000000"], ["61619.01000000", "0.00000000"], ["61626.96000000", "0.00000000"], ["61627.03000000", "0.00000000"], ["61627.04000000", "0.04239000"], ["61627.55000000", "0.00166000"], ["61635.71000000", "0.00000000"], ["61637.57000000", "0.58464000"], ["61638.18000000", "0.58463000"], ["61644.04000000", "0.00433000"], ["61660.92000000", "0.09387000"], ["61669.21000000", "0.01000000"], ["61789.69000000", "0.00000000"]]}
{"type": "depth", "ts": 1783008112714, "U": 96863178141, "u": 96863178367, "bids": [["61610.00000000", "4.13814000"], ["61609.99000000", "0.00035000"], ["61609.98000000", "0.00017000"], ["61609.11000000", "1.81347000"], ["61609.10000000", "3.06007000"], ["61609.09000000", "0.00000000"], ["61609.08000000", "0.00000000"], ["61608.05000000", "0.00000000"], ["61607.64000000", "0.00027000"], ["61606.64000000", "0.00018000"], ["61606.60000000", "1.08690000"], ["61605.39000000", "0.00812000"], ["61603.83000000", "0.00400000"], ["61603.24000000", "0.00000000"], ["61602.93000000", "0.00000000"], ["61599.72000000", "0.03248000"], ["61598.75000000", "0.00400000"], ["61597.68000000", "0.00010000"], ["61595.80000000", "0.00000000"], ["61594.60000000", "0.00010000"], ["61594.28000000", "0.00000000"], ["61591.52000000", "0.00010000"], ["61591.20000000", "0.00000000"], ["61589.66000000", "0.01009000"], ["61588.44000000", "0.00010000"], ["61588.12000000", "0.00034000"], ["61586.26000000", "0.00000000"], ["61585.36000000", "0.00010000"], ["61585.04000000", "0.00000000"], ["61582.28000000", "0.00010000"], ["61581.96000000", "0.00000000"], ["61579.20000000", "0.00010000"], ["61579.00000000", "0.01000000"], ["61578.88000000", "0.03146000"], ["61578.30000000", "0.00000000"], ["61578.00000000", "0.02400000"], ["61575.80000000", "0.00000000"], ["61575.10000000", "0.61504000"], ["61548.45000000", "0.52152000"], ["61547.66000000", "0.00000000"], ["61513.48000000", "0.00000000"], ["61502.26000000", "0.00000000"], ["61492.10000000", "0.00162000"], ["61461.13000000", "0.00000000"], ["55449.00000000", "0.00020000"], ["55448.19000000", "0.00000000"]], "asks": [["61610.01000000", "1.33485000"], ["61610.02000000", "0.00098000"], ["61610.03000000", "0.00017000"], ["61611.93000000", "0.00009000"], ["61611.94000000", "0.01327000"], ["61611.99000000", "0.00076000"], ["61612.78000000", "0.24768000"], ["61613.42000000", "0.00009000"], ["61613.43000000", "0.02018000"], ["61613.97000000", "0.00000000"], ["61613.99000000", "0.00009000"], ["61614.17000000", "0.00000000"], ["61614.18000000", "0.00009000"], ["61614.19000000", "0.04673000"], ["61615.87000000", "0.00000000"], ["61615.99000000", "0.00009000"], ["61617.14000000", "0.00000000"], ["61617.68000000", "0.00000000"], ["61617.99000000", "0.09203000"], ["61618.93000000", "0.00000000"], ["61620.73000000", "0.09203000"], ["61621.44000000", "0.00000000"], ["61621.73000000", "0.71904000"], ["61621.76000000", "0.00000000"], ["61622.01000000", "0.00000000"], ["61622.33000000", "0.00010000"], ["61622.34000000", "0.00624000"], ["61623.23000000", "0.00000000"], ["61625.09000000", "0.00000000"], ["61625.41000000", "0.00010000"], ["61626.63000000", "0.00009000"], ["61627.04000000", "0.00000000"], ["61627.67000000", "0.00000000"], ["61628.17000000", "0.00000000"], ["61628.49000000", "0.00010000"], ["61631.25000000", "0.00000000"], ["61631.57000000", "0.00010000"], ["61634.33000000", "0.00000000"], ["61634.65000000", "0.00010000"], ["61637.41000000", "0.00000000"], ["61637.73000000", "0.00010000"], ["61640.00000000", "0.02400000"], ["61640.25000000", "0.00009000"], ["61640.82000000", "0.00010000"], ["61641.00000000", "0.01400000"], ["61671.66000000", "0.61487000"], ["61694.95000000", "0.00000000"], ["61698.19000000", "0.00000000"], ["61701.36000000", "0.00009000"], ["61702.49000000", "0.00000000"], ["61703.03000000", "0.48708000"]]}
{"type": "depth", "ts": 1783008112814, "U": 96863178368, "u": 96863178396, "bids": [["61610.00000000", "4.13872000"], ["61609.11000000", "1.81365000"], ["61607.97000000", "0.08793000"], ["61607.64000000", "0.00009000"], ["61606.64000000", "0.00000000"], ["61606.00000000", "0.01927000"], ["61420.75000000", "0.00000000"], ["55449.00000000", "0.00040000"]], "asks": [["61610.01000000", "1.24224000"], ["61612.00000000", "0.03944000"], ["61617.41000000", "0.08416000"], ["61627.68000000", "0.09750000"]]}
{"type": "depth", "ts": 1783008112914, "U": 96863178397, "u": 96863178420, "bids": [["61610.00000000", "4.04744000"], ["61609.99000000", "0.00044000"], ["61607.50000000", "0.00009000"], ["61606.61000000", "0.15383000"], ["61605.65000000", "0.00000000"], ["61603.81000000", "0.00000000"], ["61505.66000000", "0.00016000"], ["61495.50000000", "0.00024000"], ["55449.00000000", "0.00060000"], ["49288.00000000", "0.05700000"]], "asks": [["61610.01000000", "1.26985000"], ["61611.17000000", "0.00009000"], ["61616.71000000", "0.09252000"], ["61617.41000000", "0.08407000"], ["61621.16000000", "1.36330000"], ["61624.94000000", "0.97390000"], ["61627.05000000", "1.36330000"], ["61635.33000000", "0.00230000"], ["61650.29000000", "1.28116000"], ["61650.69000000", "1.03995000"], ["61651.18000000", "0.00000000"]]}
{"type": "depth", "ts": 1783008113014, "U": 96863178421, "u": 96863178461, "bids": [["61610.00000000", "4.04557000"], ["61609.12000000", "0.00009000"], ["61609.11000000", "1.81365000"], ["61609.10000000", "3.02007000"], ["61607.97000000", "0.00018000"], ["61606.64000000", "0.00009000"], ["61606.61000000", "0.15392000"], ["61601.64000000", "0.00191000"], ["61601.24000000", "0.00018000"], ["61600.73000000", "0.00009000"], ["61590.61000000", "0.58508000"], ["61552.37000000", "0.00000000"], ["61551.92000000", "0.00000000"], ["61551.91000000", "0.97490000"], ["61465.93000000", "0.00039000"], ["55449.00000000", "0.00100000"], ["49288.00000000", "0.05940000"]], "asks": [["61610.01000000", "1.51735000"], ["61610.02000000", "0.00098000"], ["61612.77000000", "0.00000000"], ["61612.78000000", "0.00018000"], ["61614.56000000", "0.00000000"], ["61618.79000000", "0.55935000"], ["61621.15000000", "0.09204000"], ["61621.17000000", "0.00000000"], ["61621.19000000", "0.00000000"], ["61624.32000000", "0.58476000"], ["61638.18000000", "0.00000000"], ["61640.14000000", "0.03198000"], ["61641.34000000", "0.00000000"], ["61651.68000000", "0.00400000"], ["61662.00000000", "0.02400000"]]}
{"type": "depth", "ts": 1783008113114, "U": 96863178462, "u": 96863178626, "bids": [["61610.00000000", "2.04669000"], ["61609.99000000", "0.00080000"], ["61609.12000000", "0.00000000"], ["61609.11000000", "0.00027000"], ["61609.10000000", "0.13195000"], ["61607.97000000", "0.00000000"], ["61607.82000000", "0.00000000"], ["61606.64000000", "0.00009000"], ["61606.63000000", "1.36348000"], ["61606.61000000", "0.00027000"], ["61606.60000000", "0.11300000"], ["61606.18000000", "0.00000000"], ["61605.39000000", "0.00018000"], ["61605.38000000", "0.01870000"], ["61604.78000000", "0.00000000"], ["61603.92000000", "0.08775000"], ["61603.83000000", "0.00000000"], ["61603.23000000", "0.00000000"], ["61602.53000000", "0.00000000"], ["61601.95000000", "0.00000000"], ["61601.85000000", "0.00400000"], ["61601.83000000", "0.00812000"], ["61601.51000000", "0.00153000"], ["61601.24000000", "0.00009000"], ["61600.47000000", "0.00000000"], ["61599.84000000", "0.02000000"], ["61599.72000000", "0.00000000"], ["61598.83000000", "0.03000000"], ["61598.75000000", "0.00000000"], ["61598.20000000", "0.12500000"], ["61598.17000000", "0.12458000"], ["61598.01000000", "0.00000000"], ["61597.27000000", "0.00000000"], ["61596.77000000", "0.00000000"], ["61594.94000000", "0.03249000"], ["61594.76000000", "0.00400000"], ["61593.85000000", "0.00000000"], ["61589.41000000", "0.01625000"], ["61581.73000000", "0.58517000"], ["61579.77000000", "0.00000000"], ["61577.05000000", "0.58521000"], ["61576.88000000", "0.00009000"], ["61565.56000000", "0.00631000"], ["61561.38000000", "1.36730000"], ["61554.88000000", "1.60992000"], ["61551.91000000", "0.00000000"], ["61550.84000000", "0.00000000"], ["61549.88000000", "0.00000000"], ["61548.84000000", "0.97490000"], ["61497.80000000", "0.04639000"], ["61488.57000000", "0.04217000"], ["55449.00000000", "0.00160000"], ["49288.00000000", "0.05740000"]], "asks": [["61610.01000000", "1.66493000"], ["61610.02000000", "0.00035000"], ["61610.06000000", "0.00009000"], ["61610.07000000", "0.05740000"], ["61610.08000000", "0.08811000"], ["61611.99000000", "0.00067000"], ["61612.00000000", "0.03944000"], ["61612.69000000", "0.09204000"], ["61612.78000000", "0.00000000"], ["61613.42000000", "0.00000000"], ["61613.43000000", "0.00018000"], ["61613.97000000", "0.00009000"], ["61613.98000000", "0.07631000"], ["61613.99000000", "0.09202000"], ["61614.00000000", "0.02418000"], ["61614.18000000", "0.00009000"], ["61615.37000000", "0.09204000"], ["61615.56000000", "0.00400000"], ["61615.99000000", "0.00000000"], ["61616.70000000", "0.00000000"], ["61618.65000000", "0.98812000"], ["61618.66000000", "1.36330000"], ["61618.67000000", "0.00000000"], ["61618.79000000", "0.00000000"], ["61620.61000000", "0.04217000"], ["61620.73000000", "0.00000000"], ["61621.14000000", "0.97390000"], ["61621.15000000", "0.00000000"], ["61621.38000000", "0.58479000"], ["61637.57000000", "0.00000000"], ["61656.84000000", "0.00000000"], ["61659.42000000", "0.00000000"]]}
{"type": "depth", "ts": 1783008113214, "U": 96863178627, "u": 96863178966, "bids": [["61610.00000000", "0.00153000"], ["61609.99000000", "0.00080000"], ["61609.11000000", "0.00009000"], ["61609.10000000", "0.04755000"], ["61608.64000000", "0.00000000"], ["61607.64000000", "0.00000000"], ["61606.65000000", "0.00009000"], ["61606.64000000", "0.00018000"], ["61606.63000000", "0.00018000"], ["61606.61000000", "0.05643000"], ["61606.60000000", "0.01372000"], ["61606.12000000", "0.00009000"], ["61606.11000000", "0.00009000"], ["61606.10000000", "0.00000000"], ["61606.00000000", "0.01927000"], ["61605.39000000", "0.00000000"], ["61605.38000000", "0.00018000"], ["61605.24000000", "0.00000000"], ["61604.01000000", "0.00000000"], ["61604.00000000", "0.02418000"], ["61603.92000000", "0.00018000"], ["61603.35000000", "0.09136000"], ["61603.25000000", "0.00000000"], ["61602.02000000", "0.09136000"], ["61602.01000000", "0.00000000"], ["61602.00000000", "0.02418000"], ["61601.85000000", "0.00000000"], ["61601.52000000", "0.00048000"], ["61601.47000000", "0.00047000"], ["61601.43000000", "0.00000000"], ["61601.08000000", "0.00000000"], ["61600.70000000", "0.12462000"], ["61600.69000000", "0.40696000"], ["61600.68000000", "0.08791000"], ["61600.67000000", "0.00000000"], ["61600.50000000", "0.00034000"], ["61600.32000000", "0.00000000"], ["61599.85000000", "0.00000000"], ["61599.84000000", "0.00000000"], ["61599.63000000", "0.00000000"], ["61599.58000000", "0.00000000"], ["61599.42000000", "0.00488000"], ["61599.41000000", "0.00000000"], ["61599.33000000", "0.00000000"], ["61599.04000000", "0.01000000"], ["61598.83000000", "0.00000000"], ["61598.32000000", "0.00400000"], ["61598.02000000", "0.01016000"], ["61597.43000000", "0.03000000"], ["61597.26000000", "0.00000000"], ["61596.92000000", "1.36339000"], ["61596.89000000", "0.97878000"], ["61596.80000000", "0.00908000"], ["61596.64000000", "0.01000000"], ["61595.84000000", "0.02000000"], ["61594.94000000", "0.00000000"], ["61594.76000000", "0.00000000"], ["61592.35000000", "0.00400000"], ["61592.06000000", "0.00000000"], ["61590.61000000", "0.00000000"], ["61589.41000000", "0.00000000"], ["61573.95000000", "0.00009000"], ["61573.58000000", "0.58524000"], ["61566.54000000", "0.00400000"], ["61562.66000000", "0.00000000"], ["61561.14000000", "0.00000000"], ["61548.84000000", "0.00000000"], ["61541.07000000", "0.97490000"], ["61495.50000000", "0.00000000"], ["55449.00000000", "0.00180000"], ["49288.00000000", "0.05700000"]], "asks": [["61610.01000000", "2.45594000"], ["61610.02000000", "0.00035000"], ["61610.06000000", "0.00000000"], ["61610.07000000", "0.05749000"], ["61610.08000000", "0.08829000"], ["61611.34000000", "0.00000000"], ["61611.35000000", "0.00000000"], ["61611.93000000", "0.00000000"], ["61611.94000000", "0.01318000"], ["61611.99000000", "0.00058000"], ["61612.00000000", "0.03944000"], ["61612.66000000", "0.08764000"], ["61612.67000000", "0.00000000"], ["61612.68000000", "0.08611000"], ["61612.69000000", "0.00027000"], ["61612.98000000", "0.00400000"], ["61613.18000000", "0.00916000"], ["61613.30000000", "0.07324000"], ["61613.43000000", "0.00000000"], ["61613.86000000", "0.00000000"], ["61613.87000000", "0.00000000"], ["61613.97000000", "0.00000000"], ["61613.98000000", "0.00000000"], ["61613.99000000", "0.09193000"], ["61614.00000000", "0.02400000"], ["61614.18000000", "0.00000000"], ["61614.19000000", "0.00000000"], ["61614.52000000", "0.04217000"], ["61615.33000000", "0.09136000"], ["61615.36000000", "1.36330000"], ["61616.71000000", "0.09204000"], ["61616.89000000", "0.00000000"], ["61617.23000000", "0.58483000"], ["61617.40000000", "0.97390000"], ["61617.99000000", "0.00000000"], ["61618.41000000", "0.00034000"], ["61619.11000000", "0.00142000"], ["61621.13000000", "0.00000000"], ["61622.66000000", "0.01800000"], ["61622.71000000", "0.01400000"], ["61623.28000000", "0.01200000"], ["61623.33000000", "0.01100000"], ["61625.74000000", "0.01000000"], ["61626.41000000", "0.01200000"], ["61627.55000000", "0.00000000"], ["61634.66000000", "0.00000000"], ["61654.26000000", "0.00000000"], ["61660.58000000", "0.97490000"], ["61671.66000000", "0.38092000"], ["61671.89000000", "0.00000000"], ["61674.62000000", "0.01800000"], ["61674.67000000", "0.01400000"], ["61675.01000000", "0.00000000"], ["61675.23000000", "0.01200000"], ["61675.29000000", "0.01100000"], ["61677.70000000", "0.01000000"], ["61678.37000000", "0.01213000"], ["61692.77000000", "0.01827000"], ["61698.36000000", "0.00016000"], ["61701.60000000", "0.00000000"], ["61705.90000000", "0.00000000"]]}
{"type": "depth", "ts": 1783008113314, "U": 96863178967, "u": 96863179453, "bids": [["61610.00000000", "0.00000000"], ["61609.99000000", "0.00000000"], ["61609.98000000", "0.00000000"], ["61609.11000000", "0.00000000"], ["61609.10000000", "0.11101000"], ["61609.09000000", "0.00036000"], ["61606.65000000", "0.00000000"], ["61606.64000000", "0.00000000"], ["61606.63000000", "0.00000000"], ["61606.62000000", "0.00000000"], ["61606.61000000", "0.00036000"], ["61606.60000000", "0.01354000"], ["61606.12000000", "0.00000000"], ["61606.11000000", "0.00000000"], ["61606.01000000", "0.00009000"], ["61606.00000000", "0.01927000"], ["61605.66000000", "0.00000000"], ["61605.65000000", "0.00000000"], ["61605.41000000", "0.04197000"], ["61605.38000000", "0.00000000"], ["61605.34000000", "0.00000000"], ["61604.62000000", "0.04342000"], ["61604.61000000", "0.00000000"], ["61604.01000000", "0.00009000"], ["61604.00000000", "0.02418000"], ["61603.92000000", "0.00000000"], ["61603.80000000", "0.00009000"], ["61603.79000000", "0.09145000"], ["61603.36000000", "0.00000000"], ["61603.35000000", "0.00027000"], ["61602.66000000", "0.00000000"], ["61602.47000000", "0.00009000"], ["61602.46000000", "0.09145000"], ["61602.04000000", "0.61723000"], ["61602.03000000", "0.00009000"], ["61602.02000000", "0.09163000"], ["61602.01000000", "0.00000000"], ["61601.83000000", "0.00018000"], ["61601.24000000", "0.00000000"], ["61600.75000000", "0.00034000"], ["61600.73000000", "0.00018000"], ["61600.72000000", "0.09136000"], ["61600.71000000", "0.97390000"], ["61600.70000000", "0.00000000"], ["61600.69000000", "0.00000000"], ["61600.68000000", "0.00000000"], ["61600.50000000", "0.00000000"], ["61600.32000000", "0.00009000"], ["61599.73000000", "1.18617000"], ["61599.72000000", "1.36330000"], ["61599.71000000", "0.00000000"], ["61598.32000000", "0.00000000"], ["61598.02000000", "0.00000000"], ["61597.66000000", "0.08775000"], ["61597.43000000", "0.00000000"], ["61597.39000000", "0.00009000"], ["61597.05000000", "0.00000000"], ["61596.91000000", "0.84727000"], ["61596.80000000", "0.00000000"], ["61595.94000000", "0.00400000"], ["61595.84000000", "0.00000000"], ["61594.93000000", "0.00000000"], ["61593.44000000", "0.02000000"], ["61593.23000000", "0.15000000"], ["61592.93000000", "0.03249000"], ["61592.50000000", "0.00000000"], ["61592.35000000", "0.00000000"], ["61591.66000000", "0.00000000"], ["61589.78000000", "0.00400000"], ["61589.66000000", "0.00009000"], ["61587.65000000", "0.00000000"], ["61581.81000000", "0.00000000"], ["61579.00000000", "0.00000000"], ["61578.88000000", "0.00000000"], ["61578.30000000", "0.00009000"], ["61578.00000000", "0.03400000"], ["61575.10000000", "0.15925000"], ["61574.05000000", "0.00419000"], ["61573.52000000", "0.00000000"], ["61571.02000000", "0.00009000"], ["61560.94000000", "0.00000000"], ["61559.32000000", "0.13728000"], ["61556.22000000", "0.00400000"], ["61548.23000000", "1.61009000"], ["61531.99000000", "0.20282000"], ["61530.01000000", "0.00000000"], ["61513.48000000", "0.00009000"], ["61479.34000000", "0.04217000"], ["61450.01000000", "0.01001000"], ["55449.00000000", "0.00000000"], ["55448.20000000", "0.00000000"]], "asks": [["61609.11000000", "4.49132000"], ["61609.12000000", "1.21344000"], ["61609.13000000", "0.00017000"], ["61609.14000000", "0.00000000"], ["61609.25000000", "0.00000000"], ["61609.61000000", "0.01000000"], ["61609.99000000", "0.00000000"], ["61610.00000000", "0.20489000"], ["61610.01000000", "1.22593000"], ["61610.02000000", "0.00000000"], ["61610.03000000", "0.00000000"], ["61610.07000000", "0.00018000"], ["61610.08000000", "0.08820000"], ["61610.40000000", "0.00400000"], ["61610.69000000", "0.04217000"], ["61610.99000000", "0.00000000"], ["61611.34000000", "0.00000000"], ["61611.73000000", "0.08462000"], ["61612.00000000", "0.03944000"], ["61612.08000000", "0.00009000"], ["61612.64000000", "0.99553000"], ["61612.65000000", "1.36330000"], ["61612.66000000", "0.00000000"], ["61612.68000000", "0.00000000"], ["61612.69000000", "0.00000000"], ["61613.18000000", "0.00898000"], ["61613.30000000", "0.00000000"], ["61613.99000000", "0.00000000"], ["61615.29000000", "0.00400000"], ["61615.33000000", "0.00000000"], ["61615.37000000", "0.00000000"], ["61616.71000000", "0.00000000"], ["61617.11000000", "0.00000000"], ["61617.22000000", "0.52132000"], ["61617.41000000", "0.00000000"], ["61617.42000000", "0.00000000"], ["61618.49000000", "0.00000000"], ["61618.64000000", "0.00230000"], ["61621.44000000", "0.00325000"], ["61622.34000000", "0.00300000"], ["61623.27000000", "0.01300000"], ["61623.33000000", "0.02200000"], ["61626.11000000", "0.01000000"], ["61626.95000000", "0.00000000"], ["61628.57000000", "0.00000000"], ["61632.03000000", "1.60790000"], ["61635.33000000", "0.00000000"], ["61635.70000000", "0.03208000"], ["61635.82000000", "0.00431000"], ["61640.00000000", "0.03400000"], ["61640.14000000", "0.00000000"], ["61640.25000000", "0.00000000"], ["61641.00000000", "0.00400000"], ["61644.04000000", "0.00000000"], ["61644.88000000", "0.00000000"], ["61651.68000000", "0.00000000"], ["61672.75000000", "0.00000000"], ["61674.67000000", "0.00000000"], ["61675.23000000", "0.00000000"], ["61675.29000000", "0.02200000"], ["61678.07000000", "0.01009000"], ["61701.36000000", "0.00000000"], ["61726.62000000", "0.00000000"], ["61784.14000000", "0.00030000"]]}
{"type": "depth", "ts": 1783008113414, "U": 96863179454, "u": 96863179621, "bids": [["61609.10000000", "0.94279000"], ["61609.09000000", "0.00054000"], ["61607.50000000", "0.00000000"], ["61606.61000000", "0.00018000"], ["61606.27000000", "0.00009000"], ["61606.00000000", "0.01927000"], ["61605.42000000", "0.00000000"], ["61605.41000000", "0.00018000"], ["61605.20000000", "0.00009000"], ["61605.19000000", "0.04018000"], ["61604.82000000", "0.00000000"], ["61604.81000000", "0.00000000"], ["61604.63000000", "0.00009000"], ["61604.62000000", "0.04351000"], ["61604.58000000", "0.00000000"], ["61604.00000000", "0.02418000"], ["61603.79000000", "0.09163000"], ["61603.35000000", "0.00009000"], ["61602.46000000", "0.09181000"], ["61602.20000000", "1.36330000"], ["61602.07000000", "0.00000000"], ["61602.06000000", "0.04710000"], ["61602.05000000", "0.55141000"], ["61602.04000000", "0.00018000"], ["61602.03000000", "0.00000000"], ["61602.02000000", "0.09145000"], ["61602.00000000", "0.02400000"], ["61601.83000000", "0.00000000"], ["61600.73000000", "0.38965000"], ["61600.32000000", "0.00000000"], ["61596.24000000", "0.00878000"], ["61571.12000000", "0.58527000"], ["61495.49000000", "0.00024000"], ["55448.19000000", "0.00030000"], ["55445.94000000", "0.00000000"]], "asks": [["61609.11000000", "3.54735000"], ["61609.12000000", "0.26107000"], ["61609.61000000", "0.01018000"], ["61609.99000000", "0.00009000"], ["61610.00000000", "0.20516000"], ["61610.01000000", "1.22584000"], ["61610.07000000", "0.00000000"], ["61610.08000000", "0.08820000"], ["61610.69000000", "0.04235000"], ["61610.87000000", "0.00009000"], ["61611.16000000", "0.00922000"], ["61611.61000000", "0.09253000"], ["61611.73000000", "0.00018000"], ["61611.94000000", "0.01300000"], ["61611.95000000", "0.04039000"], ["61611.99000000", "0.00024000"], ["61612.00000000", "0.03926000"], ["61612.65000000", "0.00000000"], ["61615.36000000", "0.00000000"], ["61617.40000000", "0.00000000"], ["61621.43000000", "0.00326000"], ["61621.44000000", "0.00000000"], ["61631.21000000", "0.58470000"], ["61636.05000000", "0.00623000"], ["61643.71000000", "0.00000000"], ["61675.29000000", "0.01100000"], ["62533.25000000", "0.00030000"]]}
{"type": "depth", "ts": 1783008113514, "U": 96863179622, "u": 96863179794, "bids": [["61609.10000000", "1.22444000"], ["61609.09000000", "0.00027000"], ["61607.11000000", "0.00034000"], ["61606.61000000", "0.00009000"], ["61606.44000000", "0.08964000"], ["61606.00000000", "0.01927000"], ["61605.41000000", "0.00000000"], ["61605.38000000", "0.00009000"], ["61605.37000000", "0.05320000"], ["61605.20000000", "0.00000000"], ["61605.19000000", "0.00018000"], ["61605.13000000", "0.00009000"], ["61605.12000000", "0.07513000"], ["61605.11000000", "0.09136000"], ["61604.63000000", "0.00000000"], ["61604.62000000", "0.00018000"], ["61604.01000000", "0.00000000"], ["61603.80000000", "0.00000000"], ["61603.35000000", "0.00000000"], ["61603.25000000", "0.00009000"], ["61602.47000000", "0.00000000"], ["61602.46000000", "0.09172000"], ["61602.21000000", "0.94960000"], ["61602.20000000", "1.36348000"], ["61602.18000000", "0.02434000"], ["61602.05000000", "0.00488000"], ["61602.04000000", "0.00000000"], ["61602.02000000", "0.00000000"], ["61601.51000000", "0.00553000"], ["61600.74000000", "0.38956000"], ["61600.73000000", "0.00009000"], ["61600.72000000", "0.00000000"], ["61600.32000000", "0.00009000"], ["61599.84000000", "0.02000000"], ["61597.66000000", "0.00000000"], ["61595.94000000", "0.00000000"], ["61595.86000000", "0.00000000"], ["61594.42000000", "0.38956000"], ["61594.41000000", "1.36330000"], ["61593.44000000", "0.00000000"], ["61589.60000000", "0.58509000"], ["61574.64000000", "0.03170000"], ["61573.36000000", "1.60943000"], ["61571.12000000", "0.00000000"], ["61571.02000000", "0.00000000"], ["61563.96000000", "0.00400000"], ["61556.22000000", "0.00000000"], ["61548.23000000", "0.00000000"], ["61538.01000000", "0.82067000"], ["55448.19000000", "0.00070000"]], "asks": [["61609.11000000", "2.57769000"], ["61609.12000000", "0.01402000"], ["61609.61000000", "0.00018000"], ["61609.94000000", "0.00009000"], ["61610.00000000", "0.00051000"], ["61610.01000000", "1.08584000"], ["61610.07000000", "0.00009000"], ["61610.08000000", "0.08820000"], ["61610.69000000", "0.00018000"], ["61611.16000000", "0.00922000"], ["61611.31000000", "0.03000000"], ["61611.60000000", "0.00000000"], ["61611.61000000", "0.00027000"], ["61611.62000000", "0.00000000"], ["61611.73000000", "0.00000000"], ["61612.00000000", "0.04426000"], ["61612.53000000", "0.07588000"], ["61612.54000000", "0.08984000"], ["61612.63000000", "0.00000000"], ["61612.64000000", "0.00000000"], ["61614.42000000", "0.00000000"], ["61615.72000000", "0.12000000"], ["61615.99000000", "0.02477000"], ["61617.22000000", "0.00000000"], ["61617.23000000", "0.00000000"], ["61618.64000000", "1.44783000"], ["61618.66000000", "0.00000000"], ["61621.14000000", "0.00000000"], ["61629.14000000", "0.00230000"], ["61632.03000000", "0.00000000"], ["61675.29000000", "0.00000000"], ["61678.07000000", "0.00009000"], ["61701.59000000", "0.00024000"], ["61705.89000000", "0.00040000"], ["61724.71000000", "4.86512000"]]}
{"type": "depth", "ts": 1783008113614, "U": 96863179795, "u": 96863179945, "bids": [["61609.10000000", "1.43176000"], ["61609.09000000", "0.00018000"], ["61606.60000000", "0.01354000"], ["61606.46000000", "0.09090000"], ["61606.45000000", "0.02687000"], ["61606.44000000", "0.00018000"], ["61606.18000000", "0.00009000"], ["61606.00000000", "0.01927000"], ["61605.38000000", "0.00009000"], ["61605.37000000", "0.05338000"], ["61605.19000000", "0.00000000"], ["61605.13000000", "0.00009000"], ["61605.12000000", "0.07531000"], ["61605.11000000", "0.09154000"], ["61604.62000000", "0.00000000"], ["61604.01000000", "0.00000000"], ["61603.80000000", "0.00000000"], ["61602.66000000", "0.00400000"], ["61602.46000000", "0.09163000"], ["61602.30000000", "0.00000000"], ["61602.20000000", "1.36330000"], ["61601.51000000", "0.00153000"], ["61601.29000000", "0.00400000"], ["61600.75000000", "0.38990000"], ["61600.74000000", "0.00000000"], ["61578.82000000", "0.03522000"], ["61574.64000000", "0.00000000"], ["61573.95000000", "0.00000000"], ["61569.60000000", "0.13541000"], ["61561.38000000", "1.36330000"], ["60684.96000000", "0.00030000"], ["55448.19000000", "0.00110000"]], "asks": [["61609.11000000", "2.32599000"], ["61609.12000000", "0.01402000"], ["61609.61000000", "0.00000000"], ["61609.99000000", "0.00000000"], ["61610.00000000", "0.00033000"], ["61610.08000000", "0.08811000"], ["61610.40000000", "0.00000000"], ["61610.69000000", "0.00000000"], ["61611.16000000", "0.00922000"], ["61611.31000000", "0.00018000"], ["61611.61000000", "0.00000000"], ["61611.62000000", "0.00000000"], ["61611.94000000", "0.01318000"], ["61611.95000000", "0.04057000"], ["61612.00000000", "0.04444000"], ["61612.08000000", "0.00000000"], ["61612.52000000", "0.00000000"], ["61612.53000000", "0.05200000"], ["61612.54000000", "0.08993000"], ["61613.32000000", "0.01000000"], ["61614.82000000", "0.02000000"], ["61615.29000000", "0.00000000"], ["61615.71000000", "0.06068000"], ["61615.99000000", "0.00000000"], ["61617.26000000", "0.00189000"], ["61617.83000000", "0.00400000"], ["61618.42000000", "0.00000000"], ["61618.62000000", "0.09138000"], ["61618.63000000", "2.48278000"], ["61618.64000000", "0.00000000"], ["61618.65000000", "0.00000000"], ["61620.44000000", "0.01100000"], ["61621.05000000", "0.01000000"], ["61634.05000000", "0.58867000"], ["61635.70000000", "0.00000000"], ["61635.86000000", "0.01109000"], ["61636.47000000", "0.01000000"], ["61640.09000000", "0.03220000"], ["61656.84000000", "0.00400000"], ["61660.58000000", "0.00000000"], ["61660.59000000", "0.97502000"], ["61678.37000000", "0.00013000"], ["61684.02000000", "0.01100000"], ["61684.63000000", "0.01000000"], ["61784.14000000", "0.24780000"]]}
{"type": "depth", "ts": 1783008113714, "U": 96863179946, "u": 96863180113, "bids": [["61609.10000000", "1.43053000"], ["61609.09000000", "0.00018000"], ["61607.77000000", "0.09138000"], ["61606.61000000", "0.00000000"], ["61606.60000000", "0.01354000"], ["61606.49000000", "0.02746000"], ["61606.48000000", "0.09138000"], ["61606.47000000", "0.00000000"], ["61606.46000000", "0.00018000"], ["61606.45000000", "0.00018000"], ["61606.44000000", "0.00000000"], ["61606.06000000", "0.06671000"], ["61606.01000000", "0.00000000"], ["61605.38000000", "0.00000000"], ["61605.37000000", "0.00018000"], ["61605.13000000", "0.00000000"], ["61605.12000000", "0.07522000"], ["61604.01000000", "0.00000000"], ["61603.80000000", "0.00000000"], ["61603.79000000", "0.09145000"], ["61602.46000000", "0.09154000"], ["61602.22000000", "0.38956000"], ["61601.52000000", "0.00000000"], ["61601.47000000", "0.00000000"], ["61600.75000000", "0.00034000"], ["61599.53000000", "0.03000000"], ["61593.23000000", "0.12000000"], ["61592.65000000", "0.58506000"], ["61589.66000000", "0.00000000"], ["61589.32000000", "0.58509000"], ["61588.76000000", "0.00009000"], ["61577.05000000", "0.00000000"], ["61575.10000000", "0.79099000"], ["61573.58000000", "0.00000000"], ["61569.60000000", "0.00000000"], ["61555.85000000", "0.94826000"], ["61505.66000000", "0.00000000"], ["61495.49000000", "0.00000000"], ["61465.93000000", "0.00000000"], ["61450.01000000", "0.00000000"], ["61420.75000000", "0.01002000"], ["55448.19000000", "0.00150000"]], "asks": [["61609.11000000", "1.34195000"], ["61611.16000000", "0.00922000"], ["61611.31000000", "0.00000000"], ["61612.53000000", "0.00027000"], ["61612.54000000", "0.00009000"], ["61612.63000000", "0.05921000"], ["61613.62000000", "0.00000000"], ["61614.32000000", "0.04000000"], ["61615.28000000", "0.00300000"], ["61615.71000000", "0.06059000"], ["61615.72000000", "0.00000000"], ["61615.74000000", "0.02000000"], ["61617.09000000", "0.00047000"], ["61617.19000000", "0.00048000"], ["61617.42000000", "0.08000000"], ["61617.83000000", "0.00000000"], ["61618.42000000", "0.08824000"], ["61618.60000000", "1.21917000"], ["61618.61000000", "0.00000000"], ["61618.62000000", "0.00000000"], ["61618.63000000", "0.00000000"], ["61620.32000000", "0.00400000"], ["61622.34000000", "0.00000000"], ["61625.73000000", "0.00009000"], ["61626.63000000", "0.00000000"], ["61631.20000000", "0.59480000"], ["61660.59000000", "0.00000000"], ["61661.32000000", "0.00000000"], ["61661.36000000", "0.97502000"], ["61669.21000000", "0.00000000"], ["61674.62000000", "0.00000000"], ["61677.70000000", "0.00000000"], ["61684.63000000", "0.00000000"], ["61698.36000000", "0.00000000"], ["61701.59000000", "0.00000000"], ["61705.89000000", "0.00000000"]]}
{"type": "depth", "ts": 1783008113814, "U": 96863180114, "u": 96863180205, "bids": [["61609.10000000", "1.43071000"], ["61607.79000000", "0.00009000"], ["61607.78000000", "0.05895000"], ["61607.77000000", "0.09156000"], ["61606.61000000", "0.00009000"], ["61606.60000000", "0.01354000"], ["61606.49000000", "0.00027000"], ["61606.48000000", "0.09165000"], ["61606.46000000", "0.00000000"], ["61606.45000000", "0.00000000"], ["61606.07000000", "0.00009000"], ["61606.06000000", "0.06698000"], ["61606.01000000", "0.00009000"], ["61606.00000000", "0.01909000"], ["61605.97000000", "0.00009000"], ["61605.96000000", "0.08775000"], ["61605.37000000", "0.00000000"], ["61605.24000000", "0.00400000"], ["61604.00000000", "0.02400000"], ["61602.46000000", "0.09163000"], ["61599.01000000", "0.04217000"], ["61598.78000000", "0.01010000"], ["61576.88000000", "0.00000000"], ["61563.96000000", "0.00000000"], ["61479.34000000", "0.00000000"], ["61398.00000000", "0.00488000"], ["55448.19000000", "0.00190000"]], "asks": [["61609.11000000", "1.58954000"], ["61609.13000000", "0.00017000"], ["61610.01000000", "1.00059000"], ["61610.08000000", "0.08811000"], ["61610.75000000", "0.00181000"], ["61612.00000000", "0.04444000"], ["61612.43000000", "0.02000000"], ["61612.53000000", "0.00000000"], ["61612.62000000", "0.00009000"], ["61612.63000000", "0.05939000"], ["61612.98000000", "0.00000000"], ["61614.52000000", "0.00000000"], ["61615.70000000", "0.00000000"], ["61615.71000000", "0.48100000"], ["61615.74000000", "0.00000000"], ["61618.41000000", "1.36364000"], ["61618.42000000", "0.00000000"], ["61618.59000000", "0.69476000"], ["61618.60000000", "0.00000000"], ["61621.43000000", "0.00000000"], ["61621.44000000", "0.00325000"], ["61629.14000000", "0.00000000"], ["61638.90000000", "0.00230000"], ["61654.26000000", "0.00400000"], ["61661.36000000", "0.00000000"], ["61662.53000000", "0.00000000"], ["61663.45000000", "0.97502000"], ["61668.60000000", "0.00000000"], ["61684.02000000", "0.00000000"]]}
{"type": "depth", "ts": 1783008113914, "U": 96863180206, "u": 96863180293, "bids": [["61609.10000000", "1.43089000"], ["61607.78000000", "0.03171000"], ["61607.77000000", "0.00018000"], ["61607.11000000", "0.00000000"], ["61606.60000000", "0.01354000"], ["61606.49000000", "0.00009000"], ["61606.48000000", "0.00027000"], ["61605.13000000", "0.00009000"], ["61605.12000000", "0.07531000"], ["61605.11000000", "0.09136000"], ["61604.01000000", "0.00009000"], ["61598.60000000", "0.00000000"], ["61592.65000000", "0.00000000"], ["61581.63000000", "0.58517000"], ["61504.76000000", "0.00016000"], ["61494.60000000", "0.00024000"], ["55448.19000000", "0.00230000"], ["49287.28000000", "0.00000000"]], "asks": [["61609.11000000", "1.69487000"], ["61609.12000000", "0.01402000"], ["61612.00000000", "0.04444000"], ["61612.07000000", "0.00034000"], ["61612.43000000", "0.00018000"], ["61612.62000000", "0.04967000"], ["61612.63000000", "0.05921000"], ["61615.69000000", "0.97633000"], ["61615.70000000", "1.36330000"], ["61615.71000000", "0.00000000"], ["61618.40000000", "0.00000000"], ["61621.15000000", "0.97390000"], ["61621.38000000", "0.00000000"], ["61621.43000000", "0.00326000"], ["61621.44000000", "0.00000000"], ["61624.32000000", "0.00000000"], ["61627.06000000", "0.00000000"], ["61636.99000000", "0.58464000"], ["61641.66000000", "0.58460000"], ["61644.20000000", "0.05008000"], ["61661.11000000", "0.00000000"], ["61713.92000000", "0.07512000"], ["61726.42000000", "0.00000000"]]}
{"type": "depth", "ts": 1783008114014, "U": 96863180294, "u": 96863180343, "bids": [["61609.10000000", "1.43080000"], ["61607.79000000", "0.00000000"], ["61607.78000000", "0.00018000"], ["61607.77000000", "0.00000000"], ["61607.49000000", "0.00009000"], ["61606.60000000", "0.01354000"], ["61606.49000000", "0.00000000"], ["61606.48000000", "0.00009000"], ["61606.00000000", "0.01927000"], ["61605.96000000", "0.08793000"], ["61602.23000000", "0.03248000"], ["61597.80000000", "0.00897000"], ["61592.93000000", "0.00000000"], ["61576.88000000", "0.00009000"], ["61466.05000000", "0.00038000"], ["55448.19000000", "0.00270000"], ["49287.28000000", "0.00040000"]], "asks": [["61609.11000000", "1.69487000"], ["61609.12000000", "0.01402000"], ["61609.94000000", "0.00000000"], ["61610.08000000", "0.08802000"], ["61611.94000000", "0.00018000"], ["61612.00000000", "0.04444000"], ["61612.43000000", "0.00000000"], ["61612.54000000", "0.00000000"], ["61612.62000000", "0.04985000"], ["61612.63000000", "0.05930000"], ["61627.50000000", "0.58473000"], ["61632.13000000", "0.00649000"], ["61697.46000000", "0.00016000"]]}
{"type": "depth", "ts": 1783008114114, "U": 96863180344, "u": 96863180366, "bids": [["61609.10000000", "1.43071000"], ["61607.78000000", "0.00000000"], ["61605.96000000", "0.00018000"], ["61605.11000000", "0.09154000"], ["61604.01000000", "0.00000000"], ["61582.87000000", "0.01625000"], ["61531.64000000", "0.00030000"], ["61529.14000000", "0.00000000"], ["55448.19000000", "0.00290000"]], "asks": [["61610.75000000", "0.00009000"], ["61611.16000000", "0.00922000"], ["61611.94000000", "0.00000000"], ["61612.63000000", "0.05948000"], ["61683.16000000", "0.00009000"], ["61685.66000000", "0.00030000"], ["61781.29000000", "0.09711000"]]}
{"type": "depth", "ts": 1783008114214, "U": 96863180367, "u": 96863180402, "bids": [["61609.10000000", "1.43097000"], ["61609.09000000", "0.00035000"], ["61609.08000000", "0.00017000"], ["61606.06000000", "0.06689000"], ["61606.00000000", "0.01927000"], ["61605.97000000", "0.00000000"], ["61605.96000000", "0.00000000"], ["61604.00000000", "0.02418000"], ["61595.21000000", "0.00000000"], ["61593.45000000", "0.00649000"], ["61496.72000000", "0.09756000"], ["61494.60000000", "0.00000000"], ["61466.05000000", "0.00000000"], ["55448.19000000", "0.00330000"], ["49287.28000000", "0.00000000"], ["49287.00000000", "0.00000000"]], "asks": [["61632.13000000", "0.00000000"], ["61700.69000000", "0.00024000"], ["61704.99000000", "0.00040000"], ["61754.68000000", "0.00000000"]]}
{"type": "depth", "ts": 1783008114414, "U": 96863180407, "u": 96863180419, "bids": [["61606.18000000", "0.00000000"], ["61494.59000000", "0.00024000"], ["55448.19000000", "0.00410000"], ["49287.00000000", "0.00000000"]], "asks": [["61758.64000000", "6.69348000"], ["62533.25000000", "0.00030000"]]}
{"type": "depth", "ts": 1783008114614, "U": 96863180427, "u": 96863180453, "bids": [["61609.10000000", "1.43060000"], ["61607.49000000", "0.00000000"], ["61606.27000000", "0.00000000"], ["60684.96000000", "0.00030000"], ["55448.19000000", "0.00470000"], ["55448.00000000", "0.00045000"]], "asks": [["61609.11000000", "1.44737000"], ["61609.12000000", "0.01402000"], ["61610.56000000", "0.00009000"], ["61610.75000000", "0.00172000"], ["61610.76000000", "0.00009000"], ["61611.16000000", "0.00922000"], ["61611.94000000", "0.01618000"], ["61612.62000000", "0.00027000"], ["61612.63000000", "0.05930000"]]}
{"type": "depth", "ts": 1783008114714, "U": 96863180454, "u": 96863180481, "bids": [["61609.10000000", "1.43069000"], ["61606.45000000", "0.02737000"], ["61606.44000000", "0.09138000"], ["61605.13000000", "0.00000000"], ["61605.12000000", "0.07522000"], ["61592.79000000", "0.58506000"], ["61588.76000000", "0.00000000"], ["61581.73000000", "0.00000000"], ["61442.87000000", "0.00954000"], ["61420.75000000", "0.00000000"], ["55448.19000000", "0.00470000"]], "asks": [["61612.00000000", "0.04444000"], ["61612.62000000", "0.00009000"], ["61612.63000000", "0.05948000"], ["61615.68000000", "0.00009000"], ["61615.69000000", "0.45644000"], ["61615.70000000", "0.00000000"], ["61625.73000000", "0.00000000"], ["61640.80000000", "0.29585000"]]}
{"type": "depth", "ts": 1783008114814, "U": 96863180482, "u": 96863180515, "bids": [["61609.10000000", "1.43042000"], ["61607.78000000", "0.06693000"], ["61607.77000000", "0.09138000"], ["61606.60000000", "0.01354000"], ["61606.45000000", "0.00027000"], ["61606.44000000", "0.09156000"], ["61606.18000000", "0.00009000"], ["61606.07000000", "0.00000000"], ["61606.01000000", "0.00000000"], ["61588.76000000", "0.00009000"], ["61584.79000000", "0.00250000"], ["61496.72000000", "0.00000000"], ["61420.75000000", "0.00015000"], ["55448.19000000", "0.00450000"]], "asks": [["61609.11000000", "1.18159000"], ["61610.75000000", "0.00009000"], ["61611.47000000", "0.02000000"], ["61621.43000000", "0.00000000"], ["61621.44000000", "0.00326000"], ["61625.73000000", "0.00009000"], ["61781.29000000", "0.00000000"]]}
{"type": "depth", "ts": 1783008114914, "U": 96863180516, "u": 96863180556, "bids": [["61609.10000000", "1.43051000"], ["61607.78000000", "0.06711000"], ["61607.77000000", "0.09156000"], ["61606.61000000", "0.00000000"], ["61606.60000000", "0.01354000"], ["61606.45000000", "0.00000000"], ["61604.00000000", "0.02400000"], ["61468.06000000", "0.00036000"], ["61467.07000000", "0.00000000"], ["55448.19000000", "0.00450000"], ["49287.28000000", "0.00000000"]], "asks": [["61609.11000000", "1.18168000"], ["61609.12000000", "0.01411000"], ["61611.16000000", "0.00922000"], ["61611.47000000", "0.02018000"], ["61612.63000000", "0.05930000"]]}
{"type": "depth", "ts": 1783008115014, "U": 96863180557, "u": 96863180624, "bids": [["61609.10000000", "2.40419000"], ["61607.78000000", "0.03166000"], ["61607.77000000", "0.00018000"], ["61606.06000000", "0.06698000"], ["61605.17000000", "0.08775000"], ["61605.12000000", "0.34322000"], ["61605.11000000", "0.09163000"], ["61604.48000000", "0.97390000"], ["61603.79000000", "0.00009000"], ["61602.21000000", "0.85824000"], ["61599.37000000", "0.00883000"], ["61595.50000000", "0.58503000"], ["61584.56000000", "0.00000000"], ["61582.87000000", "0.00000000"], ["61576.88000000", "0.00000000"], ["55448.19000000", "0.00450000"], ["49287.28000000", "0.00040000"], ["49287.00000000", "0.00000000"]], "asks": [["61609.11000000", "1.01676000"], ["61609.12000000", "0.00522000"], ["61610.00000000", "0.00009000"], ["61610.07000000", "0.00000000"], ["61610.08000000", "0.00027000"], ["61611.16000000", "0.00018000"], ["61611.47000000", "0.00018000"], ["61611.99000000", "0.00033000"], ["61612.04000000", "0.00000000"], ["61612.47000000", "0.02000000"], ["61612.63000000", "0.05921000"], ["61614.97000000", "0.00000000"], ["61615.68000000", "0.00000000"], ["61615.69000000", "0.00000000"], ["61616.34000000", "0.04224000"], ["61617.41000000", "0.00009000"], ["61617.90000000", "0.00000000"], ["61618.41000000", "0.00034000"], ["61618.49000000", "0.08914000"], ["61620.08000000", "0.00000000"], ["61620.83000000", "0.00000000"], ["61621.13000000", "0.09206000"], ["61621.14000000", "1.36330000"], ["61621.15000000", "0.00000000"], ["61621.16000000", "0.00000000"], ["61623.76000000", "0.00000000"], ["61626.69000000", "0.00000000"], ["61639.48000000", "0.00000000"], ["61647.29000000", "0.00024000"], ["61713.29000000", "0.09147000"], ["61732.27000000", "4.86453000"], ["77803.32000000", "0.00053000"]]}
