{"type": "depth", "ts": 1783008086914, "U": 96863148685, "u": 96863148716, "bids": [["61618.33000000", "0.00000000"], ["61613.64000000", "0.00000000"], ["61609.64000000", "0.00009000"], ["55467.00000000", "0.09357000"], ["55466.99000000", "0.00000000"]], "asks": [["61630.00000000", "3.41557000"], ["61630.66000000", "0.01027000"], ["61631.89000000", "0.00894000"], ["61633.33000000", "0.09433000"], ["61633.94000000", "0.00000000"], ["61634.34000000", "0.04046000"], ["61634.63000000", "0.00009000"], ["61637.83000000", "0.97390000"], ["61646.63000000", "0.00009000"], ["61650.63000000", "0.00000000"], ["61651.73000000", "0.00000000"], ["61655.26000000", "0.00000000"], ["61849.20000000", "0.00000000"], ["61908.90000000", "0.00000000"], ["61968.60000000", "0.00000000"]]}
{"type": "snapshot", "last_update_id": 96863149391, "bids": [["61629.70000000", "0.25051000"], ["61629.69000000", "0.00072000"], ["61629.63000000", "0.00009000"], ["61628.45000000", "0.00009000"], ["61628.44000000", "0.00026000"], ["61628.40000000", "0.00009000"], ["61628.01000000", "0.00009000"], ["61628.00000000", "0.01730000"], ["61627.99000000", "0.00009000"], ["61627.72000000", "0.00009000"], ["61627.47000000", "0.00009000"], ["61627.02000000", "0.00009000"], ["61626.33000000", "0.00177000"], ["61626.01000000", "0.00009000"], ["61626.00000000", "0.01918000"], ["61625.90000000", "0.00009000"], ["61625.89000000", "0.03389000"], ["61625.50000000", "0.00009000"], ["61625.00000000", "0.00324000"], ["61624.74000000", "0.00009000"], ["61624.73000000", "0.04727000"], ["61624.64000000", "0.00009000"], ["61624.47000000", "0.00009000"], ["61624.34000000", "0.00009000"], ["61624.33000000", "0.08276000"], ["61624.13000000", "0.00024000"], ["61624.01000000", "0.00009000"], ["61624.00000000", "0.02427000"], ["61623.99000000", "0.02491000"], ["61623.83000000", "0.00019000"], ["61623.82000000", "0.00300000"], ["61623.07000000", "0.00034000"], ["61622.56000000", "0.00009000"], ["61622.55000000", "0.00009000"], ["61622.54000000", "0.00031000"], ["61622.29000000", "0.00009000"], ["61622.05000000", "0.01018000"], ["61622.01000000", "0.00009000"], ["61622.00000000", "0.02418000"], ["61621.66000000", "0.00300000"], ["61621.56000000", "0.00009000"], ["61621.41000000", "0.00009000"], ["61621.40000000", "0.02190000"], ["61621.06000000", "0.00048000"], ["61620.89000000", "0.00400000"], ["61620.87000000", "0.60917000"], ["61620.86000000", "0.00009000"], ["61620.85000000", "0.08574000"], ["61620.82000000", "0.01200000"], ["61620.81000000", "0.38956000"], ["61620.80000000", "0.00010000"], ["61620.79000000", "0.51849000"], ["61620.76000000", "0.00013000"], ["61620.59000000", "0.00153000"], ["61620.29000000", "0.00009000"], ["61620.12000000", "0.00243000"], ["61620.03000000", "1.36818000"], ["61620.00000000", "0.02400000"], ["61619.84000000", "0.00936000"], ["61619.74000000", "0.00010000"], ["61619.60000000", "0.00009000"], ["61619.57000000", "0.00499000"], ["61619.54000000", "0.00009000"], ["61619.18000000", "0.00009000"], ["61618.96000000", "0.00009000"], ["61618.63000000", "0.01000000"], ["61618.59000000", "0.00400000"], ["61618.57000000", "0.01000000"], ["61618.50000000", "0.00048000"], ["61618.48000000", "0.00009000"], ["61618.44000000", "0.08771000"], ["61618.32000000", "0.00400000"], ["61618.29000000", "0.00009000"], ["61618.01000000", "0.01000000"], ["61618.00000000", "0.02400000"], ["61617.95000000", "0.01000000"], ["61617.90000000", "0.00009000"], ["61617.88000000", "0.01000000"], ["61617.82000000", "0.01000000"], ["61617.67000000", "0.00009000"], ["61617.65000000", "0.24750000"], ["61617.53000000", "0.86452000"], ["61617.52000000", "1.36818000"], ["61617.46000000", "0.00978000"], ["61617.26000000", "0.00189000"], ["61617.23000000", "0.02000000"], ["61617.03000000", "0.01000000"], ["61616.89000000", "0.00034000"], ["61616.66000000", "0.00010000"], ["61616.65000000", "0.00009000"], ["61616.52000000", "0.00009000"], ["61616.38000000", "0.00909000"], ["61616.29000000", "0.00009000"], ["61616.21000000", "0.00060000"], ["61616.00000000", "0.02400000"], ["61615.75000000", "0.00400000"], ["61615.55000000", "0.01000000"], ["61615.54000000", "0.97390000"], ["61615.43000000", "0.01000000"], ["61615.40000000", "0.00508000"], ["61615.05000000", "0.01000000"], ["61615.01000000", "1.11536000"], ["61615.00000000", "1.36330000"], ["61614.98000000", "0.00250000"], ["61614.97000000", "0.00009000"], ["61614.81000000", "0.01300000"], ["61614.74000000", "0.02000000"], ["61614.72000000", "0.00010000"], ["61614.57000000", "0.00022000"], ["61614.40000000", "0.38956000"], ["61614.33000000", "0.00649000"], ["61614.29000000", "0.00009000"], ["61614.06000000", "0.00400000"], ["61614.00000000", "0.02400000"], ["61613.70000000", "0.00009000"], ["61613.58000000", "0.00010000"], ["61613.50000000", "0.00009000"], ["61613.29000000", "0.04869000"], ["61613.18000000", "0.00978000"], ["61613.03000000", "0.00324000"], ["61612.51000000", "0.05922000"], ["61612.50000000", "1.36818000"], ["61612.43000000", "0.00400000"], ["61612.32000000", "0.00009000"], ["61612.29000000", "0.00009000"], ["61612.26000000", "0.02000000"], ["61612.12000000", "0.00400000"], ["61612.04000000", "0.00009000"], ["61612.00000000", "0.02400000"], ["61611.80000000", "0.00009000"], ["61611.78000000", "0.61117000"], ["61611.77000000", "0.97390000"], ["61611.50000000", "0.00016000"], ["61611.48000000", "0.00024000"], ["61611.35000000", "0.00013000"], ["61611.13000000", "0.46584000"], ["61611.12000000", "0.24750000"], ["61610.75000000", "0.00009000"], ["61610.72000000", "0.00034000"], ["61610.53000000", "0.12000000"], ["61610.50000000", "0.00010000"], ["61610.48000000", "0.00009000"], ["61610.35000000", "0.36367000"], ["61610.29000000", "0.00009000"], ["61610.11000000", "0.00024000"], ["61610.10000000", "0.00178000"], ["61610.01000000", "0.00488000"], ["61610.00000000", "0.02400000"], ["61609.86000000", "0.00899000"], ["61609.68000000", "0.00973000"], ["61609.24000000", "0.00009000"], ["61609.11000000", "0.00009000"], ["61608.64000000", "0.00010000"], ["61608.51000000", "0.00009000"], ["61608.38000000", "0.00013000"], ["61608.22000000", "0.86151000"], ["61608.21000000", "1.36330000"], ["61608.05000000", "0.56509000"], ["61608.00000000", "0.02400000"], ["61607.82000000", "0.03023000"], ["61607.80000000", "0.00009000"], ["61607.71000000", "0.97390000"], ["61607.60000000", "0.00400000"], ["61607.46000000", "0.00009000"], ["61607.42000000", "0.00010000"], ["61607.40000000", "0.00162000"], ["61607.39000000", "0.00059000"], ["61606.53000000", "0.00825000"], ["61606.18000000", "0.00009000"], ["61606.16000000", "0.91114000"], ["61606.13000000", "0.00009000"], ["61606.00000000", "0.02400000"], ["61605.90000000", "0.00400000"], ["61605.20000000", "0.00400000"], ["61604.85000000", "0.00009000"], ["61604.64000000", "0.00009000"], ["61604.44000000", "0.00009000"], ["61604.40000000", "0.00034000"], ["61604.34000000", "0.00010000"], ["61604.31000000", "0.00987000"], ["61604.29000000", "0.00009000"], ["61604.00000000", "0.02400000"], ["61603.98000000", "0.38956000"], ["61603.95000000", "1.36330000"], ["61603.93000000", "0.24750000"], ["61603.88000000", "0.97390000"], ["61603.68000000", "0.00144000"], ["61603.50000000", "0.64194000"], ["61603.33000000", "0.00012000"], ["61603.25000000", "0.00009000"], ["61603.08000000", "0.00409000"], ["61602.86000000", "0.04217000"], ["61602.56000000", "0.00010000"], ["61602.53000000", "0.89930000"], ["61602.34000000", "0.01624000"], ["61602.19000000", "0.00013000"], ["61602.00000000", "0.02400000"], ["61601.90000000", "0.58507000"], ["61601.65000000", "0.00488000"], ["61601.62000000", "0.00009000"], ["61601.42000000", "0.00009000"], ["61601.25000000", "0.00010000"], ["61600.91000000", "1.36330000"], ["61600.88000000", "0.01000000"], ["61600.83000000", "0.00191000"], ["61600.82000000", "0.01000000"], ["61600.77000000", "0.58499000"], ["61600.54000000", "0.00400000"], ["61600.32000000", "0.00009000"], ["61600.15000000", "0.97390000"], ["61600.00000000", "0.07720000"], ["61599.90000000", "0.00009000"], ["61599.15000000", "0.00360000"], ["61599.06000000", "0.01000000"], ["61599.02000000", "0.01000000"], ["61598.95000000", "0.00009000"], ["61598.42000000", "0.02000000"], ["61598.41000000", "0.00009000"], ["61598.38000000", "1.36330000"], ["61598.17000000", "0.00034000"], ["61598.13000000", "0.00009000"], ["61598.07000000", "0.01000000"], ["61598.00000000", "0.03400000"], ["61597.95000000", "0.00948000"], ["61597.83000000", "0.01200000"], ["61597.79000000", "0.01300000"], ["61597.74000000", "0.02000000"], ["61597.51000000", "0.24750000"], ["61597.48000000", "0.00009000"], ["61597.39000000", "0.00009000"], ["61597.20000000", "0.01000000"], ["61597.19000000", "0.00400000"], ["61596.92000000", "0.00009000"], ["61596.48000000", "0.00010000"], ["61596.32000000", "0.58503000"], ["61596.30000000", "0.00009000"], ["61596.04000000", "0.41628000"], ["61596.03000000", "0.13522000"], ["61596.00000000", "0.02413000"], ["61595.39000000", "0.00009000"], ["61595.34000000", "0.01000000"], ["61594.75000000", "0.04217000"], ["61594.73000000", "0.00009000"], ["61594.60000000", "0.00400000"], ["61594.58000000", "1.36330000"], ["61594.56000000", "0.97390000"], ["61594.46000000", "0.00009000"], ["61594.24000000", "0.38956000"], ["61594.00000000", "0.02400000"], ["61593.84000000", "0.00009000"], ["61593.71000000", "0.03227000"], ["61593.37000000", "0.00100000"], ["61593.21000000", "0.01823000"], ["61593.01000000", "0.00016000"], ["61592.93000000", "0.00009000"], ["61592.90000000", "0.00024000"], ["61592.74000000", "0.00499000"], ["61592.37000000", "0.00009000"], ["61592.20000000", "1.17014000"], ["61592.00000000", "0.02400000"], ["61591.53000000", "0.00009000"], ["61591.40000000", "0.00400000"], ["61590.98000000", "1.36330000"], ["61590.90000000", "0.00009000"], ["61590.76000000", "0.00009000"], ["61590.56000000", "1.14743000"], ["61590.40000000", "0.00010000"], ["61590.37000000", "0.97390000"], ["61590.32000000", "0.00009000"], ["61590.14000000", "0.24750000"], ["61590.00000000", "1.63797000"], ["61589.94000000", "0.77892000"], ["61589.85000000", "0.00009000"], ["61589.81000000", "0.00013000"], ["61589.35000000", "0.00009000"], ["61588.31000000", "0.00009000"], ["61588.12000000", "0.00034000"], ["61588.01000000", "0.38956000"], ["61588.00000000", "0.02400000"], ["61587.68000000", "0.00009000"], ["61586.83000000", "0.00024000"], ["61586.62000000", "0.00033000"], ["61586.57000000", "0.97390000"], ["61586.52000000", "0.00009000"], ["61586.33000000", "0.00009000"], ["61586.20000000", "0.00400000"], ["61586.00000000", "0.02728000"], ["61585.45000000", "0.01000000"], ["61584.72000000", "0.00250000"], ["61584.60000000", "0.00009000"], ["61584.45000000", "0.05363000"], ["61584.32000000", "0.00010000"], ["61584.31000000", "0.00009000"], ["61584.04000000", "0.01000000"], ["61584.01000000", "0.00051000"], ["61584.00000000", "0.02400000"], ["61583.94000000", "0.01000000"], ["61583.84000000", "1.33165000"], ["61583.83000000", "1.60917000"], ["61583.63000000", "0.01000000"], ["61583.62000000", "0.00013000"], ["61583.58000000", "1.36330000"], ["61583.32000000", "0.00434000"], ["61583.16000000", "0.00009000"], ["61583.13000000", "0.61712000"], ["61582.85000000", "0.97390000"], ["61582.52000000", "0.01000000"], ["61582.46000000", "0.00009000"], ["61582.37000000", "0.01300000"], ["61582.11000000", "0.00499000"], ["61582.00000000", "0.04023000"], ["61581.94000000", "0.00034000"], ["61581.91000000", "0.02200000"], ["61581.89000000", "0.01000000"], ["61581.78000000", "0.01000000"], ["61581.69000000", "0.38956000"], ["61581.64000000", "0.01000000"], ["61581.52000000", "0.00009000"], ["61581.45000000", "0.00400000"], ["61581.20000000", "0.11274000"], ["61580.93000000", "0.04217000"], ["61580.90000000", "0.02589000"], ["61580.57000000", "0.00013000"], ["61580.48000000", "0.00009000"], ["61580.31000000", "0.00009000"], ["61580.30000000", "0.00009000"], ["61580.23000000", "0.24750000"], ["61580.00000000", "0.02416000"], ["61579.89000000", "0.00825000"], ["61579.33000000", "0.00499000"], ["61578.82000000", "0.00400000"], ["61578.50000000", "0.01000000"], ["61578.44000000", "0.01009000"], ["61578.32000000", "0.00009000"], ["61578.24000000", "0.00010000"], ["61578.01000000", "1.08690000"], ["61578.00000000", "0.02400000"], ["61577.88000000", "0.01000000"], ["61577.43000000", "0.00013000"], ["61577.28000000", "0.00009000"], ["61576.56000000", "0.00499000"], ["61576.52000000", "0.00009000"], ["61576.21000000", "0.02477000"], ["61576.18000000", "1.36330000"], ["61576.10000000", "0.01826000"], ["61576.00000000", "0.02409000"], ["61575.74000000", "1.50196000"], ["61575.73000000", "0.00034000"], ["61575.45000000", "0.97390000"], ["61575.36000000", "0.00009000"], ["61575.10000000", "0.14947000"], ["61575.09000000", "0.38956000"], ["61574.96000000", "0.00009000"], ["61574.55000000", "0.00009000"], ["61574.52000000", "0.00016000"], ["61574.26000000", "0.00009000"], ["61574.00000000", "0.02400000"], ["61573.71000000", "0.00328000"], ["61573.54000000", "0.00009000"], ["61573.23000000", "0.00009000"], ["61573.13000000", "0.00436000"], ["61572.28000000", "0.00009000"], ["61572.16000000", "0.00010000"], ["61572.02000000", "0.00095000"], ["61572.01000000", "0.00401000"], ["61572.00000000", "0.02400000"], ["61571.89000000", "0.93294000"], ["61571.88000000", "1.36330000"], ["61571.84000000", "0.24750000"], ["61571.69000000", "0.03861000"], ["61571.68000000", "0.00282000"], ["61571.64000000", "1.60949000"], ["61571.51000000", "0.00010000"], ["61571.38000000", "0.00009000"], ["61571.24000000", "0.00013000"], ["61571.01000000", "0.00499000"], ["61570.36000000", "0.01133000"], ["61570.00000000", "0.02400000"], ["61569.91000000", "0.00250000"], ["61569.84000000", "0.00009000"], ["61569.20000000", "0.00009000"], ["61568.84000000", "0.00009000"], ["61568.79000000", "0.93013000"], ["61568.78000000", "1.36330000"], ["61568.61000000", "0.75064000"], ["61568.23000000", "0.00009000"], ["61568.21000000", "0.00034000"], ["61568.05000000", "0.97390000"], ["61568.00000000", "0.02400000"], ["61567.99000000", "0.00009000"], ["61566.57000000", "0.00826000"], ["61566.49000000", "0.00532000"], ["61566.12000000", "0.00009000"], ["61566.08000000", "0.00010000"], ["61566.03000000", "0.00009000"], ["61566.00000000", "0.02400000"], ["61565.92000000", "0.00500000"], ["61565.85000000", "0.01658000"], ["61565.35000000", "0.54538000"], ["61565.26000000", "1.60965000"], ["61565.05000000", "0.00013000"], ["61565.00000000", "0.07614000"], ["61564.93000000", "0.00009000"], ["61564.00000000", "0.02400000"], ["61563.68000000", "0.24750000"], ["61563.56000000", "0.97471000"], ["61563.49000000", "0.00112000"], ["61563.38000000", "0.00009000"], ["61563.20000000", "0.03255000"], ["61563.04000000", "0.00009000"], ["61562.55000000", "0.01692000"], ["61562.45000000", "0.04217000"], ["61562.20000000", "0.00009000"], ["61562.05000000", "0.38956000"], ["61562.04000000", "0.00034000"], ["61562.00000000", "0.02400000"], ["61561.68000000", "0.00039000"], ["61561.39000000", "0.00100000"], ["61561.38000000", "1.36330000"], ["61561.36000000", "0.00009000"], ["61561.32000000", "0.00009000"], ["61560.65000000", "0.97390000"], ["61560.00000000", "0.02428000"], ["61559.96000000", "0.00009000"], ["61559.91000000", "0.01000000"], ["61559.68000000", "0.08003000"], ["61559.61000000", "0.00009000"], ["61559.28000000", "0.00490000"], ["61559.18000000", "0.00009000"], ["61558.86000000", "0.00013000"], ["61558.52000000", "0.00009000"], ["61558.00000000", "0.02400000"], ["61557.60000000", "0.00009000"], ["61557.38000000", "0.24750000"], ["61556.88000000", "0.00009000"], ["61556.71000000", "0.00492000"], ["61556.50000000", "0.00030000"], ["61556.22000000", "0.01150000"], ["61556.03000000", "0.00016000"], ["61556.00000000", "0.02400000"], ["61555.85000000", "0.53157000"], ["61555.84000000", "1.36330000"], ["61555.75000000", "0.38956000"], ["61555.53000000", "0.00009000"], ["61555.40000000", "0.00034000"], ["61554.94000000", "0.00250000"], ["61554.52000000", "0.00009000"], ["61554.00000000", "0.02400000"], ["61553.92000000", "0.00010000"], ["61553.80000000", "0.31116000"], ["61553.68000000", "0.00009000"], ["61553.25000000", "0.98216000"], ["61553.21000000", "0.04217000"], ["61553.15000000", "0.00009000"], ["61552.67000000", "0.00013000"], ["61552.51000000", "0.00500000"], ["61552.00000000", "0.02409000"], ["61551.62000000", "0.00080000"], ["61551.10000000", "0.00009000"], ["61551.01000000", "0.00009000"], ["61550.72000000", "0.00009000"], ["61550.01000000", "0.00701000"], ["61550.00000000", "0.02454000"], ["61549.79000000", "0.00013000"], ["61549.39000000", "0.00009000"], ["61549.02000000", "0.00034000"], ["61548.81000000", "0.00500000"], ["61548.02000000", "0.25218000"], ["61548.01000000", "0.82053000"], ["61548.00000000", "0.02400000"], ["61547.84000000", "0.00010000"], ["61547.83000000", "0.00009000"], ["61547.64000000", "0.00009000"], ["61547.36000000", "0.00009000"], ["61547.12000000", "0.00009000"], ["61546.71000000", "1.14013000"], ["61546.70000000", "0.38956000"], ["61546.48000000", "0.00013000"], ["61546.00000000", "0.02400000"], ["61545.96000000", "0.00009000"], ["61545.47000000", "0.24750000"], ["61545.18000000", "0.00310000"], ["61544.71000000", "3.24002000"], ["61544.56000000", "0.00009000"], ["61544.33000000", "0.00009000"], ["61544.11000000", "0.00009000"], ["61544.10000000", "0.00009000"], ["61544.01000000", "0.02946000"], ["61544.00000000", "0.02400000"], ["61543.97000000", "0.04217000"], ["61543.50000000", "0.00009000"], ["61543.26000000", "0.00500000"], ["61542.81000000", "0.00034000"], ["61542.55000000", "0.00009000"], ["61542.00000000", "0.02400000"], ["61541.76000000", "0.00010000"], ["61541.18000000", "2.17512000"], ["61540.72000000", "0.69990000"], ["61540.43000000", "0.00100000"], ["61540.32000000", "0.00009000"], ["61540.29000000", "0.00013000"], ["61540.20000000", "0.00009000"], ["61540.00000000", "0.02400000"], ["61539.99000000", "4.87992000"], ["61539.93000000", "0.00826000"], ["61539.46000000", "0.38956000"], ["61539.10000000", "0.00500000"], ["61538.94000000", "0.24750000"], ["61538.40000000", "0.00009000"], ["61538.32000000", "0.00009000"], ["61538.07000000", "0.00009000"], ["61538.01000000", "0.01626000"], ["61538.00000000", "0.02400000"], ["61537.55000000", "0.00061000"], ["61536.64000000", "0.00024000"], ["61536.32000000", "0.00009000"], ["61536.00000000", "0.02400000"], ["61535.99000000", "0.00009000"], ["61535.68000000", "0.00010000"], ["61535.66000000", "0.00034000"], ["61535.62000000", "0.00155000"], ["61535.05000000", "0.00009000"], ["61534.74000000", "0.07358000"], ["61534.73000000", "0.04217000"], ["61534.32000000", "0.00009000"], ["61534.21000000", "0.12000000"], ["61534.00000000", "0.02400000"], ["61533.97000000", "0.00109000"], ["61533.85000000", "0.07511000"], ["61533.48000000", "0.00032000"], ["61533.38000000", "0.00026000"], ["61533.04000000", "0.00009000"], ["61532.56000000", "0.00060000"], ["61532.00000000", "0.02400000"], ["61531.99000000", "0.20014000"], ["61531.98000000", "0.38956000"], ["61531.82000000", "0.00009000"], ["61531.63000000", "0.00009000"], ["61531.28000000", "0.00064000"], ["61531.26000000", "0.00011000"], ["61531.25000000", "0.00015000"], ["61530.85000000", "0.00012000"], ["61530.56000000", "0.00009000"], ["61530.44000000", "0.24750000"], ["61530.00000000", "0.02459000"], ["61529.60000000", "0.00010000"], ["61529.56000000", "0.00010000"], ["61529.43000000", "0.00034000"], ["61529.41000000", "0.00755000"], ["61529.34000000", "0.00009000"], ["61529.32000000", "0.04553000"], ["61529.12000000", "0.00177000"], ["61528.90000000", "0.00018000"], ["61528.69000000", "0.00020000"], ["61528.62000000", "0.00022000"], ["61528.40000000", "0.00013000"], ["61528.21000000", "0.00161000"], ["61528.01000000", "0.03082000"], ["61528.00000000", "0.02414000"], ["61527.98000000", "0.00011000"], ["61527.79000000", "0.00009000"], ["61526.72000000", "0.00958000"], ["61526.61000000", "0.01326000"], ["61526.59000000", "0.00194000"], ["61526.31000000", "0.00009000"], ["61526.21000000", "0.05394000"], ["61526.17000000", "0.00009000"], ["61526.02000000", "0.17071000"], ["61526.01000000", "0.00009000"], ["61526.00000000", "0.02400000"], ["61525.99000000", "0.00045000"], ["61525.88000000", "0.00009000"], ["61525.81000000", "0.38956000"], ["61525.76000000", "0.00010000"], ["61525.69000000", "0.00500000"], ["61525.61000000", "0.00016000"], ["61525.52000000", "0.12000000"], ["61525.49000000", "0.04217000"], ["61525.04000000", "0.00237000"], ["61524.60000000", "0.00250000"], ["61524.59000000", "0.00010000"], ["61524.35000000", "0.01826000"], ["61524.29000000", "0.00009000"], ["61524.00000000", "0.02400000"], ["61523.91000000", "0.00009000"], ["61523.87000000", "0.00048000"], ["61523.80000000", "0.00010000"], ["61523.61000000", "0.00010000"], ["61523.55000000", "0.00009000"], ["61523.52000000", "0.00010000"], ["61523.03000000", "0.00665000"], ["61522.94000000", "0.82067000"], ["61522.93000000", "0.24750000"], ["61522.86000000", "0.06413000"], ["61522.85000000", "0.00011000"], ["61522.79000000", "0.00034000"], ["61522.71000000", "0.00015000"], ["61522.62000000", "0.00009000"], ["61522.00000000", "0.02400000"], ["61521.73000000", "0.00009000"], ["61521.72000000", "0.00009000"], ["61521.66000000", "0.00092000"], ["61521.32000000", "0.00032000"], ["61521.06000000", "0.00009000"], ["61520.15000000", "2.34266000"], ["61520.11000000", "0.00020000"], ["61520.00000000", "0.02862000"], ["61519.98000000", "0.00009000"], ["61519.92000000", "0.00009000"], ["61519.77000000", "0.00013000"], ["61519.41000000", "0.00480000"], ["61519.14000000", "0.16430000"], ["61519.01000000", "0.00013000"], ["61518.97000000", "0.38956000"], ["61518.78000000", "0.00009000"], ["61518.72000000", "0.00009000"], ["61518.50000000", "0.00025000"], ["61518.49000000", "0.00162000"], ["61518.33000000", "0.12000000"], ["61518.07000000", "0.00009000"], ["61518.00000000", "0.02400000"], ["61517.85000000", "0.00013000"], ["61517.83000000", "0.00045000"], ["61517.44000000", "0.00010000"], ["61517.22000000", "0.00009000"], ["61517.16000000", "0.00305000"], ["61516.74000000", "1.56861000"], ["61516.73000000", "0.24750000"], ["61516.35000000", "0.00013000"], ["61516.33000000", "0.00034000"], ["61516.26000000", "0.04217000"], ["61516.16000000", "0.00015000"], ["61516.12000000", "0.00009000"], ["61516.00000000", "0.10543000"], ["61515.95000000", "0.04607000"], ["61515.75000000", "4.88189000"], ["61515.51000000", "0.00160000"], ["61515.45000000", "0.00024000"], ["61515.17000000", "0.00038000"], ["61515.16000000", "0.00032000"], ["61515.15000000", "0.01159000"], ["61515.09000000", "0.00009000"], ["61514.93000000", "0.00027000"], ["61514.77000000", "0.00011000"], ["61514.38000000", "0.00262000"], ["61514.05000000", "0.00009000"], ["61514.00000000", "0.02428000"], ["61513.68000000", "0.00009000"], ["61513.50000000", "0.00009000"], ["61512.38000000", "0.00065000"], ["61512.28000000", "0.00500000"], ["61512.21000000", "1.47852000"], ["61512.20000000", "4.88196000"], ["61512.00000000", "0.02562000"], ["61511.91000000", "0.00009000"], ["61511.46000000", "0.00012000"], ["61511.36000000", "0.00010000"], ["61510.98000000", "0.00162000"], ["61510.86000000", "0.04367000"], ["61510.61000000", "0.22405000"], ["61510.60000000", "0.38956000"], ["61510.55000000", "0.24750000"], ["61510.44000000", "0.00009000"], ["61510.18000000", "0.00009000"], ["61510.13000000", "0.00128000"], ["61510.11000000", "0.00034000"], ["61510.00000000", "0.02450000"], ["61509.97000000", "0.00500000"], ["61509.87000000", "0.00010000"], ["61509.00000000", "0.00032000"], ["61508.86000000", "0.00012000"], ["61508.14000000", "0.00009000"], ["61508.02000000", "0.00110000"], ["61508.00000000", "0.15750000"], ["61507.99000000", "0.00043000"], ["61507.92000000", "0.00009000"], ["61507.50000000", "0.00054000"], ["61507.27000000", "0.00082000"], ["61507.10000000", "0.00009000"], ["61507.05000000", "0.00162000"], ["61507.03000000", "0.04217000"], ["61506.83000000", "0.00051000"], ["61506.81000000", "0.00020000"], ["61506.78000000", "0.00045000"], ["61506.00000000", "0.02400000"], ["61505.57000000", "0.00012000"], ["61505.28000000", "0.00010000"], ["61505.15000000", "0.00012000"], ["61504.91000000", "0.00009000"], ["61504.83000000", "0.00013000"], ["61504.38000000", "0.09222000"], ["61504.37000000", "0.24750000"], ["61504.13000000", "0.00065000"], ["61504.00000000", "0.02400000"], ["61503.97000000", "0.00009000"], ["61503.73000000", "0.00057000"], ["61503.61000000", "0.00100000"], ["61503.29000000", "0.00034000"], ["61502.83000000", "0.00032000"], ["61502.82000000", "0.00260000"], ["61502.28000000", "0.00009000"], ["61502.08000000", "0.00162000"], ["61502.07000000", "0.00845000"], ["61502.02000000", "0.00009000"], ["61502.00000000", "0.02400000"], ["61501.60000000", "0.00174000"], ["61501.44000000", "0.00009000"], ["61501.41000000", "0.00009000"], ["61501.06000000", "0.00015000"], ["61500.73000000", "0.00022000"], ["61500.63000000", "0.00037000"], ["61500.41000000", "0.17423000"], ["61500.22000000", "0.00162000"], ["61500.12000000", "0.00009000"], ["61500.01000000", "0.00018000"], ["61500.00000000", "0.51052000"], ["61499.66000000", "0.00067000"], ["61499.20000000", "0.00010000"], ["61499.00000000", "0.00058000"], ["61498.97000000", "0.00009000"], ["61498.94000000", "0.00009000"], ["61498.87000000", "0.00500000"], ["61498.30000000", "0.00109000"], ["61498.26000000", "0.00020000"], ["61498.19000000", "0.24750000"], ["61497.86000000", "0.00025000"], ["61497.80000000", "0.04217000"], ["61497.63000000", "0.00031000"], ["61497.24000000", "0.00009000"], ["61497.12000000", "0.00265000"], ["61497.07000000", "0.00034000"], ["61497.03000000", "0.00040000"], ["61496.67000000", "0.00032000"], ["61496.47000000", "0.00009000"], ["61495.85000000", "0.02542000"], ["61495.43000000", "0.00014000"], ["61494.99000000", "0.00379000"], ["61494.84000000", "0.00038000"], ["61494.42000000", "0.00064000"], ["61493.62000000", "0.00010000"], ["61493.46000000", "0.00013000"], ["61493.39000000", "0.00009000"], ["61493.32000000", "0.00500000"], ["61493.12000000", "0.00010000"], ["61493.08000000", "0.00019000"], ["61492.83000000", "0.00223000"], ["61492.34000000", "0.00009000"], ["61492.09000000", "0.00056000"], ["61492.02000000", "0.12528000"], ["61492.01000000", "0.24750000"], ["61491.99000000", "0.00047000"], ["61491.49000000", "0.00048000"], ["61490.99000000", "0.00162000"], ["61490.97000000", "0.00009000"], ["61490.92000000", "0.07396000"], ["61490.83000000", "0.00034000"], ["61490.55000000", "0.00108000"], ["61490.51000000", "0.00032000"], ["61490.31000000", "0.00009000"], ["61490.00000000", "0.00050000"], ["61489.18000000", "0.00016000"], ["61489.03000000", "0.00017000"], ["61489.01000000", "0.03115000"], ["61489.00000000", "0.07677000"], ["61488.57000000", "0.04217000"], ["61488.49000000", "0.00054000"], ["61488.48000000", "0.00271000"], ["61488.43000000", "1.20000000"], ["61488.23000000", "0.00013000"], ["61488.10000000", "0.00010000"], ["61488.00000000", "0.00048000"], ["61487.91000000", "0.00009000"], ["61487.62000000", "0.00104000"], ["61487.48000000", "0.00009000"], ["61487.04000000", "0.00010000"], ["61486.89000000", "0.00027000"], ["61486.88000000", "0.00015000"], ["61486.83000000", "0.00009000"], ["61486.76000000", "0.00016000"], ["61486.66000000", "0.00194000"], ["61485.99000000", "0.00020000"], ["61485.94000000", "0.00014000"], ["61485.83000000", "0.24750000"], ["61485.71000000", "0.00127000"], ["61485.59000000", "0.00024000"], ["61485.46000000", "0.00500000"], ["61485.30000000", "0.00056000"], ["61485.13000000", "0.21734000"], ["61485.10000000", "0.00016000"], ["61484.66000000", "0.00278000"], ["61484.56000000", "0.00011000"], ["61484.50000000", "0.00040000"], ["61484.44000000", "0.00044000"], ["61484.40000000", "0.00009000"], ["61484.34000000", "0.00032000"], ["61483.97000000", "0.00034000"], ["61483.77000000", "0.00009000"], ["61483.56000000", "0.00024000"], ["61483.37000000", "0.00019000"], ["61483.24000000", "0.00009000"], ["61482.96000000", "0.00009000"], ["61482.87000000", "0.00009000"], ["61482.78000000", "0.00009000"], ["61481.60000000", "0.00162000"], ["61481.33000000", "0.09255000"], ["61481.22000000", "0.00009000"], ["61481.18000000", "0.00024000"], ["61480.27000000", "0.00009000"], ["61480.19000000", "0.00009000"], ["61480.07000000", "0.00011000"], ["61480.00000000", "0.00649000"], ["61479.77000000", "0.00197000"], ["61479.70000000", "0.00316000"], ["61479.67000000", "0.00009000"], ["61479.65000000", "0.24750000"], ["61479.54000000", "0.00490000"], ["61479.42000000", "0.01486000"], ["61479.38000000", "0.00010000"], ["61479.35000000", "0.00012000"], ["61479.28000000", "0.01933000"], ["61478.26000000", "0.00026000"], ["61478.18000000", "0.00032000"], ["61477.79000000", "0.00009000"], ["61477.74000000", "0.00271000"], ["61477.73000000", "0.00048000"], ["61477.72000000", "0.00009000"], ["61477.57000000", "0.00059000"], ["61477.26000000", "0.00009000"], ["61477.19000000", "0.00052000"], ["61476.70000000", "0.00140000"], ["61476.67000000", "0.00500000"], ["61476.58000000", "0.00050000"], ["61476.47000000", "0.00031000"], ["61476.04000000", "0.00162000"], ["61475.84000000", "4.88484000"], ["61475.76000000", "0.00009000"], ["61475.25000000", "0.00035000"], ["61475.00000000", "0.00019000"], ["61474.64000000", "0.00009000"], ["61474.41000000", "0.00061000"], ["61474.26000000", "0.01504000"], ["61473.76000000", "4.88501000"], ["61473.47000000", "0.24750000"], ["61473.46000000", "0.00009000"], ["61472.77000000", "0.00046000"], ["61472.74000000", "0.00009000"], ["61472.65000000", "0.00009000"], ["61472.50000000", "0.00010000"], ["61472.40000000", "0.00211000"], ["61472.31000000", "0.01325000"], ["61472.28000000", "0.00676000"], ["61472.05000000", "0.00500000"], ["61472.02000000", "0.00032000"], ["61471.91000000", "0.00017000"], ["61471.89000000", "0.00933000"], ["61471.81000000", "0.00109000"], ["61471.79000000", "0.00032000"], ["61471.77000000", "0.00009000"], ["61471.53000000", "0.00034000"], ["61471.42000000", "0.00035000"], ["61471.25000000", "0.00009000"], ["61470.64000000", "0.00013000"], ["61470.59000000", "0.00013000"], ["61470.58000000", "0.00958000"], ["61470.06000000", "0.00812000"], ["61470.00000000", "0.00050000"], ["61469.77000000", "0.00009000"], ["61469.37000000", "0.00009000"], ["61468.94000000", "0.00012000"], ["61468.80000000", "0.00010000"], ["61468.41000000", "0.00011000"], ["61468.39000000", "0.00009000"], ["61468.33000000", "0.00009000"], ["61467.57000000", "0.00012000"], ["61467.55000000", "0.00028000"], ["61467.40000000", "0.00013000"], ["61467.29000000", "0.24750000"], ["61467.03000000", "0.00020000"], ["61466.87000000", "0.00014000"], ["61466.69000000", "0.00009000"], ["61466.66000000", "0.00211000"], ["61466.46000000", "0.00872000"], ["61466.39000000", "0.00009000"], ["61466.16000000", "0.00011000"], ["61466.00000000", "0.00058000"], ["61465.85000000", "0.00032000"], ["61465.74000000", "0.00009000"], ["61465.57000000", "0.00009000"], ["61465.00000000", "0.00034000"], ["61464.92000000", "0.00009000"], ["61464.75000000", "0.00009000"], ["61464.69000000", "0.00017000"], ["61464.48000000", "0.00009000"], ["61464.39000000", "0.00009000"], ["61464.31000000", "0.00010000"], ["61464.10000000", "0.00027000"], ["61464.09000000", "0.00162000"], ["61463.73000000", "0.00009000"], ["61462.96000000", "0.00009000"], ["61462.73000000", "0.00009000"], ["61462.61000000", "0.00014000"], ["61462.17000000", "0.00032000"], ["61461.65000000", "0.00205000"], ["61461.53000000", "0.00011000"], ["61461.33000000", "0.07669000"], ["61461.15000000", "0.00182000"], ["61461.11000000", "0.24750000"], ["61460.61000000", "0.00009000"], ["61460.27000000", "0.00027000"], ["61460.02000000", "0.00500000"], ["61460.00000000", "0.00481000"], ["61459.72000000", "0.00009000"], ["61459.69000000", "0.00032000"], ["61458.74000000", "0.00034000"], ["61458.71000000", "0.00162000"], ["61458.63000000", "0.00500000"], ["61458.33000000", "0.00132000"], ["61458.20000000", "0.00510000"], ["61457.92000000", "0.00010000"], ["61457.76000000", "0.00009000"], ["61457.45000000", "0.00013000"], ["61457.32000000", "0.00009000"], ["61457.25000000", "0.00051000"], ["61457.14000000", "0.00027000"], ["61457.10000000", "0.00087000"], ["61457.01000000", "0.00040000"], ["61456.57000000", "0.00053000"], ["61456.44000000", "0.00162000"], ["61456.15000000", "0.00162000"], ["61455.79000000", "0.00009000"], ["61455.47000000", "0.00009000"], ["61454.94000000", "0.01001000"], ["61454.93000000", "0.24750000"], ["61454.54000000", "0.00022000"], ["61454.49000000", "0.00244000"], ["61454.38000000", "0.01933000"], ["61454.28000000", "0.00009000"], ["61454.02000000", "0.00194000"], ["61453.96000000", "0.00341000"], ["61453.85000000", "0.00010000"], ["61453.79000000", "0.00100000"], ["61453.74000000", "0.00022000"], ["61452.94000000", "0.00010000"], ["61452.84000000", "0.00024000"], ["61452.80000000", "0.00009000"], ["61452.62000000", "0.86653000"], ["61452.56000000", "0.00034000"], ["61452.13000000", "0.00009000"], ["61451.61000000", "0.00267000"], ["61450.74000000", "0.00101000"], ["61450.69000000", "0.00009000"], ["61450.56000000", "0.00010000"], ["61450.17000000", "0.00232000"], ["61450.00000000", "0.03007000"], ["61449.63000000", "0.00028000"], ["61449.16000000", "0.00049000"], ["61448.75000000", "0.24750000"], ["61448.25000000", "0.00009000"], ["61448.24000000", "0.00010000"], ["61447.36000000", "0.00041000"], ["61446.38000000", "0.00034000"], ["61446.36000000", "0.00038000"], ["61446.00000000", "0.00009000"], ["61445.78000000", "0.00022000"], ["61445.56000000", "0.00097000"], ["61445.39000000", "0.00013000"], ["61445.20000000", "0.00011000"], ["61444.87000000", "0.00018000"], ["61444.67000000", "0.00009000"], ["61444.32000000", "0.00014000"], ["61444.00000000", "0.00091000"], ["61443.58000000", "0.00014000"], ["61443.37000000", "0.00500000"], ["61443.20000000", "0.00009000"], ["61443.15000000", "0.00011000"], ["61443.14000000", "0.00417000"], ["61442.86000000", "4.88768000"], ["61442.59000000", "0.24750000"], ["61442.56000000", "0.00109000"], ["61442.24000000", "0.00016000"], ["61441.80000000", "0.00025000"], ["61441.25000000", "0.00014000"], ["61440.92000000", "0.00019000"], ["61440.20000000", "0.00034000"], ["61440.00000000", "0.01698000"], ["61439.93000000", "0.00013000"], ["61439.71000000", "0.00020000"], ["61439.42000000", "0.00024000"], ["61439.28000000", "0.00806000"], ["61439.23000000", "0.00115000"], ["61438.92000000", "0.00009000"], ["61438.80000000", "0.00024000"], ["61438.18000000", "0.00010000"], ["61438.05000000", "0.00289000"], ["61437.91000000", "0.00010000"], ["61437.50000000", "0.00009000"], ["61437.20000000", "0.00086000"], ["61436.39000000", "0.24750000"], ["61435.93000000", "0.00009000"], ["61435.62000000", "0.00011000"]], "asks": [["61629.71000000", "4.87266000"], ["61629.72000000", "0.00311000"], ["61629.73000000", "0.00017000"], ["61629.98000000", "0.47325000"], ["61629.99000000", "1.41472000"], ["61630.00000000", "0.11592000"], ["61630.66000000", "0.01027000"], ["61630.87000000", "0.04235000"], ["61631.40000000", "0.00009000"], ["61631.42000000", "0.00400000"], ["61631.89000000", "0.00894000"], ["61632.00000000", "0.10366000"], ["61632.09000000", "0.00009000"], ["61632.55000000", "0.00009000"], ["61632.91000000", "0.00034000"], ["61633.33000000", "0.00009000"], ["61633.95000000", "0.14923000"], ["61633.99000000", "0.86180000"], ["61634.00000000", "0.04340000"], ["61634.05000000", "0.00400000"], ["61634.20000000", "0.00902000"], ["61634.34000000", "0.04046000"], ["61634.35000000", "0.00009000"], ["61634.63000000", "0.00009000"], ["61634.90000000", "0.00013000"], ["61635.14000000", "0.00009000"], ["61635.21000000", "0.04217000"], ["61635.24000000", "0.01300000"], ["61635.30000000", "1.37430000"], ["61635.48000000", "0.00009000"], ["61636.00000000", "0.02400000"], ["61636.05000000", "0.03000000"], ["61636.08000000", "0.00902000"], ["61636.16000000", "0.00010000"], ["61636.17000000", "0.25450000"], ["61636.64000000", "0.01007000"], ["61636.68000000", "0.00400000"], ["61636.96000000", "0.00009000"], ["61637.09000000", "0.01100000"], ["61637.28000000", "0.00009000"], ["61637.29000000", "0.00009000"], ["61637.30000000", "0.00033000"], ["61637.43000000", "0.58464000"], ["61637.59000000", "0.00499000"], ["61637.63000000", "0.00009000"], ["61637.65000000", "0.00009000"], ["61637.69000000", "0.00009000"], ["61637.72000000", "0.01100000"], ["61637.83000000", "0.97390000"], ["61637.84000000", "0.59415000"], ["61637.85000000", "1.36330000"], ["61637.88000000", "0.00898000"], ["61638.00000000", "0.02400000"], ["61638.07000000", "0.01000000"], ["61638.20000000", "0.00400000"], ["61638.24000000", "0.20000000"], ["61638.26000000", "0.00156000"], ["61638.33000000", "0.01000000"], ["61638.34000000", "0.01000000"], ["61638.38000000", "0.02200000"], ["61638.41000000", "0.00009000"], ["61638.85000000", "0.00009000"], ["61639.04000000", "0.00010000"], ["61639.08000000", "0.00034000"], ["61639.49000000", "0.04217000"], ["61639.55000000", "0.00191000"], ["61639.70000000", "0.00009000"], ["61640.00000000", "0.02400000"], ["61640.01000000", "0.01000000"], ["61640.04000000", "0.00009000"], ["61640.17000000", "0.00400000"], ["61640.24000000", "0.00905000"], ["61640.25000000", "0.00009000"], ["61640.44000000", "0.00009000"], ["61640.57000000", "0.38956000"], ["61640.59000000", "0.88399000"], ["61640.67000000", "0.00009000"], ["61640.85000000", "0.58461000"], ["61641.07000000", "0.01800000"], ["61641.11000000", "0.00013000"], ["61641.12000000", "0.01400000"], ["61641.34000000", "0.08761000"], ["61641.65000000", "1.36330000"], ["61641.66000000", "0.40100000"], ["61641.68000000", "0.01200000"], ["61641.70000000", "0.00009000"], ["61641.75000000", "0.01100000"], ["61642.00000000", "0.02400000"], ["61642.03000000", "0.60825000"], ["61642.21000000", "0.01000000"], ["61642.24000000", "0.00009000"], ["61642.33000000", "0.00300000"], ["61642.49000000", "0.00024000"], ["61642.50000000", "0.00162000"], ["61642.89000000", "0.08888000"], ["61642.98000000", "0.00400000"], ["61643.12000000", "0.00009000"], ["61643.14000000", "0.00499000"], ["61643.20000000", "0.00009000"], ["61643.23000000", "1.02426000"], ["61643.24000000", "0.97390000"], ["61643.36000000", "0.00009000"], ["61643.55000000", "0.12000000"], ["61643.69000000", "0.00009000"], ["61643.80000000", "0.09748000"], ["61643.99000000", "0.58458000"], ["61644.00000000", "0.02400000"], ["61644.15000000", "0.01000000"], ["61644.27000000", "0.00009000"], ["61644.38000000", "1.36330000"], ["61644.41000000", "0.24760000"], ["61645.12000000", "0.00010000"], ["61645.30000000", "0.00034000"], ["61645.83000000", "0.00084000"], ["61645.99000000", "0.00009000"], ["61646.00000000", "0.02400000"], ["61646.02000000", "0.00400000"], ["61646.12000000", "0.00188000"], ["61646.15000000", "0.00009000"], ["61646.20000000", "0.00009000"], ["61646.39000000", "0.00283000"], ["61646.47000000", "0.00825000"], ["61646.71000000", "0.00009000"], ["61646.72000000", "0.04217000"], ["61647.03000000", "0.00012000"], ["61647.15000000", "0.38956000"], ["61647.18000000", "0.98881000"], ["61647.19000000", "0.19793000"], ["61647.20000000", "0.01169000"], ["61647.32000000", "0.00013000"], ["61647.49000000", "0.00010000"], ["61647.58000000", "0.58454000"], ["61647.60000000", "0.00009000"], ["61647.70000000", "0.97390000"], ["61647.74000000", "1.36330000"], ["61648.00000000", "0.02400000"], ["61648.10000000", "0.00623000"], ["61648.28000000", "0.00400000"], ["61648.38000000", "0.00009000"], ["61648.49000000", "0.00016000"], ["61648.69000000", "0.00238000"], ["61649.10000000", "0.00009000"], ["61649.28000000", "0.00009000"], ["61649.73000000", "0.00009000"], ["61649.88000000", "0.28400000"], ["61650.00000000", "0.02433000"], ["61650.13000000", "0.00009000"], ["61650.20000000", "0.00009000"], ["61650.29000000", "0.85059000"], ["61650.30000000", "0.81209000"], ["61650.32000000", "1.36330000"], ["61650.54000000", "0.00400000"], ["61650.57000000", "0.00010000"], ["61650.58000000", "0.05024000"], ["61650.68000000", "0.58451000"], ["61651.20000000", "0.00010000"], ["61651.26000000", "0.00649000"], ["61651.40000000", "0.00059000"], ["61651.53000000", "0.00034000"], ["61652.00000000", "1.63138000"], ["61652.01000000", "0.00196000"], ["61652.05000000", "0.00009000"], ["61652.10000000", "0.00009000"], ["61652.36000000", "0.00009000"], ["61652.60000000", "0.02755000"], ["61652.75000000", "0.00009000"], ["61652.78000000", "1.09170000"], ["61652.79000000", "2.33720000"], ["61652.80000000", "0.00400000"], ["61653.06000000", "0.00009000"], ["61653.53000000", "0.00013000"], ["61653.65000000", "0.00010000"], ["61653.67000000", "0.05024000"], ["61653.80000000", "0.00009000"], ["61654.00000000", "0.03550000"], ["61654.27000000", "0.00012000"], ["61654.49000000", "0.24750000"], ["61654.76000000", "0.00009000"], ["61654.95000000", "0.00400000"], ["61655.00000000", "0.00009000"], ["61655.06000000", "0.00400000"], ["61655.08000000", "0.00230000"], ["61655.12000000", "0.38956000"], ["61655.35000000", "0.03117000"], ["61655.44000000", "0.00009000"], ["61655.65000000", "1.74702000"], ["61655.74000000", "0.00009000"], ["61655.77000000", "0.00009000"], ["61655.99000000", "0.00009000"], ["61656.00000000", "0.02400000"], ["61656.59000000", "0.04217000"], ["61656.73000000", "0.00010000"], ["61656.74000000", "0.00162000"], ["61656.75000000", "0.03349000"], ["61656.87000000", "0.00419000"], ["61657.13000000", "0.04576000"], ["61657.22000000", "0.00400000"], ["61657.28000000", "0.00010000"], ["61657.56000000", "1.49996000"], ["61657.66000000", "0.97390000"], ["61657.70000000", "0.00043000"], ["61657.73000000", "1.36330000"], ["61657.95000000", "0.00009000"], ["61658.00000000", "0.02400000"], ["61658.26000000", "0.64137000"], ["61658.29000000", "1.60723000"], ["61658.52000000", "0.00009000"], ["61658.79000000", "0.00009000"], ["61658.82000000", "0.00400000"], ["61658.92000000", "0.00009000"], ["61659.46000000", "0.00846000"], ["61659.74000000", "0.00013000"], ["61659.80000000", "0.01324000"], ["61659.81000000", "0.00010000"], ["61659.83000000", "0.03349000"], ["61660.00000000", "0.02650000"], ["61660.01000000", "0.00009000"], ["61660.21000000", "0.04709000"], ["61660.70000000", "0.10280000"], ["61661.00000000", "0.01000000"], ["61661.11000000", "0.05133000"], ["61661.25000000", "0.01700000"], ["61661.41000000", "0.81725000"], ["61661.42000000", "2.33720000"], ["61661.43000000", "0.38956000"], ["61661.53000000", "0.01100000"], ["61661.60000000", "0.00009000"], ["61661.62000000", "0.97417000"], ["61661.81000000", "0.00009000"], ["61661.92000000", "0.00009000"], ["61662.00000000", "0.02400000"], ["61662.18000000", "0.00009000"], ["61662.50000000", "0.01700000"], ["61662.56000000", "0.01400000"], ["61662.76000000", "0.01595000"], ["61662.90000000", "0.00010000"], ["61663.11000000", "0.00024000"], ["61663.12000000", "0.01200000"], ["61663.18000000", "0.01527000"], ["61663.34000000", "0.00433000"], ["61663.36000000", "0.00010000"], ["61664.00000000", "0.03434000"], ["61664.08000000", "0.01000000"], ["61664.18000000", "0.24750000"], ["61664.20000000", "0.00400000"], ["61664.48000000", "0.01000000"], ["61664.53000000", "1.36330000"], ["61664.55000000", "1.60705000"], ["61664.68000000", "0.00009000"], ["61664.81000000", "0.02507000"], ["61664.83000000", "0.00020000"], ["61665.00000000", "0.86503000"], ["61665.26000000", "0.00009000"], ["61665.59000000", "0.01000000"], ["61665.95000000", "0.00013000"], ["61666.00000000", "0.02400000"], ["61666.25000000", "0.00162000"], ["61666.26000000", "0.01200000"], ["61666.59000000", "0.01100000"], ["61666.98000000", "0.00016000"], ["61667.15000000", "0.00400000"], ["61667.60000000", "2.33720000"], ["61667.61000000", "0.00282000"], ["61667.70000000", "0.00009000"], ["61667.75000000", "0.38956000"], ["61667.76000000", "0.00009000"], ["61667.85000000", "0.00009000"], ["61668.00000000", "0.02400000"], ["61668.55000000", "0.04217000"], ["61668.62000000", "0.00009000"], ["61668.86000000", "0.01622000"], ["61669.08000000", "0.00009000"], ["61669.44000000", "0.00010000"], ["61669.72000000", "0.00400000"], ["61670.00000000", "0.02400000"], ["61670.01000000", "0.00328000"], ["61670.02000000", "0.00009000"], ["61670.19000000", "0.00034000"], ["61670.84000000", "0.73528000"], ["61670.88000000", "0.00009000"], ["61670.90000000", "0.00499000"], ["61671.13000000", "0.09284000"], ["61671.26000000", "0.00009000"], ["61671.45000000", "0.01622000"], ["61671.46000000", "0.01622000"], ["61671.68000000", "1.60686000"], ["61671.71000000", "0.00009000"], ["61671.82000000", "0.41678000"], ["61672.00000000", "0.02400000"], ["61672.10000000", "0.01622000"], ["61672.15000000", "0.01622000"], ["61672.16000000", "0.00013000"], ["61672.29000000", "0.01622000"], ["61673.10000000", "0.00379000"], ["61673.11000000", "0.00381000"], ["61673.12000000", "0.00824000"], ["61673.13000000", "0.00013000"], ["61673.32000000", "0.00202000"], ["61673.49000000", "0.56510000"], ["61673.62000000", "0.24750000"], ["61673.92000000", "0.00009000"], ["61673.94000000", "0.00009000"], ["61674.00000000", "0.02400000"], ["61674.89000000", "0.38956000"], ["61675.04000000", "0.00250000"], ["61675.40000000", "0.88992000"], ["61675.41000000", "1.36330000"], ["61675.44000000", "0.01721000"], ["61675.52000000", "0.00010000"], ["61675.53000000", "0.00162000"], ["61675.54000000", "0.97390000"], ["61676.00000000", "0.02400000"], ["61676.24000000", "0.00009000"], ["61676.44000000", "0.00034000"], ["61676.45000000", "0.00499000"], ["61676.51000000", "0.00009000"], ["61676.67000000", "0.00112000"], ["61676.92000000", "0.00009000"], ["61677.00000000", "0.00009000"], ["61677.09000000", "1.17182000"], ["61677.19000000", "0.00847000"], ["61677.34000000", "0.04576000"], ["61677.80000000", "1.60672000"], ["61677.92000000", "0.01800000"], ["61677.95000000", "1.36430000"], ["61677.98000000", "0.01400000"], ["61678.00000000", "0.06617000"], ["61678.07000000", "0.00009000"], ["61678.37000000", "0.00013000"], ["61678.54000000", "0.01200000"], ["61678.60000000", "0.01100000"], ["61678.77000000", "0.10000000"], ["61678.78000000", "0.00009000"], ["61678.89000000", "0.00410000"], ["61679.42000000", "0.01000000"], ["61679.50000000", "0.01000000"], ["61679.52000000", "0.00009000"], ["61679.56000000", "0.01100000"], ["61679.63000000", "0.04815000"], ["61679.65000000", "0.00064000"], ["61679.71000000", "0.00009000"], ["61679.89000000", "0.00137000"], ["61679.91000000", "0.00538000"], ["61680.00000000", "0.02409000"], ["61680.08000000", "0.00009000"], ["61680.16000000", "0.00194000"], ["61680.17000000", "0.01000000"], ["61680.79000000", "0.00405000"], ["61680.81000000", "0.00046000"], ["61680.97000000", "0.08318000"], ["61681.01000000", "0.01000000"], ["61681.08000000", "0.01255000"], ["61681.13000000", "0.95114000"], ["61681.14000000", "0.38956000"], ["61681.15000000", "0.24750000"], ["61681.29000000", "0.00009000"], ["61681.60000000", "0.00010000"], ["61681.68000000", "0.01200000"], ["61682.00000000", "0.02899000"], ["61682.61000000", "0.00034000"], ["61682.92000000", "0.01000000"], ["61682.95000000", "0.97390000"], ["61682.96000000", "0.00009000"], ["61682.97000000", "1.36330000"], ["61683.01000000", "0.32591000"], ["61683.16000000", "0.00009000"], ["61683.26000000", "0.97463000"], ["61683.40000000", "0.00009000"], ["61683.71000000", "0.00009000"], ["61684.00000000", "0.02400000"], ["61684.02000000", "0.04638000"], ["61684.19000000", "0.89670000"], ["61684.20000000", "1.60654000"], ["61684.58000000", "0.00013000"], ["61685.47000000", "0.00016000"], ["61685.56000000", "1.36330000"], ["61685.99000000", "0.00018000"], ["61686.00000000", "0.02400000"], ["61686.24000000", "0.00009000"], ["61686.30000000", "0.00009000"], ["61686.44000000", "0.00824000"], ["61687.68000000", "0.00010000"], ["61687.71000000", "0.00009000"], ["61687.73000000", "1.51399000"], ["61687.74000000", "0.38956000"], ["61688.00000000", "0.02400000"], ["61688.09000000", "2.33720000"], ["61688.17000000", "0.24750000"], ["61688.62000000", "0.00009000"], ["61688.80000000", "0.00034000"], ["61688.92000000", "1.89161000"], ["61689.08000000", "0.04217000"], ["61689.32000000", "0.00009000"], ["61689.65000000", "0.04646000"], ["61689.71000000", "0.00009000"], ["61689.91000000", "0.00105000"], ["61690.00000000", "0.02400000"], ["61690.05000000", "0.00250000"], ["61690.14000000", "0.00231000"], ["61690.56000000", "0.00009000"], ["61690.79000000", "0.00013000"], ["61691.14000000", "1.36330000"], ["61691.15000000", "1.25418000"], ["61691.16000000", "4.04175000"], ["61691.87000000", "0.00009000"], ["61692.00000000", "0.02400000"], ["61692.03000000", "0.00009000"], ["61692.20000000", "0.00046000"], ["61692.21000000", "0.01227000"], ["61692.40000000", "0.00009000"], ["61693.10000000", "0.00997000"], ["61693.31000000", "0.47106000"], ["61693.32000000", "0.97390000"], ["61693.71000000", "0.00009000"], ["61693.76000000", "0.00010000"], ["61693.99000000", "0.00162000"], ["61694.00000000", "0.02400000"], ["61694.42000000", "0.13368000"], ["61694.78000000", "0.00010000"], ["61694.88000000", "0.24750000"], ["61694.98000000", "0.01134000"], ["61695.06000000", "0.00009000"], ["61695.48000000", "0.00009000"], ["61695.49000000", "1.36330000"], ["61695.71000000", "0.00009000"], ["61696.00000000", "0.02400000"], ["61696.67000000", "0.98425000"], ["61696.74000000", "3.23204000"], ["61696.96000000", "0.04217000"], ["61697.00000000", "0.00013000"], ["61697.71000000", "0.00009000"], ["61697.72000000", "0.00009000"], ["61698.00000000", "0.02409000"], ["61698.01000000", "0.00811000"], ["61698.08000000", "0.00009000"], ["61698.56000000", "0.00009000"], ["61698.84000000", "0.04400000"], ["61698.85000000", "0.38956000"], ["61699.76000000", "0.00824000"], ["61699.84000000", "0.00010000"], ["61699.99000000", "0.69603000"], ["61700.00000000", "1.53375000"], ["61700.01000000", "0.03838000"], ["61700.06000000", "0.69990000"], ["61700.08000000", "0.00037000"], ["61700.17000000", "0.00675000"], ["61701.07000000", "0.04233000"], ["61701.10000000", "0.00009000"], ["61701.36000000", "0.00009000"], ["61701.64000000", "0.00009000"], ["61701.98000000", "1.17732000"], ["61702.00000000", "0.02400000"], ["61702.08000000", "0.00010000"], ["61702.19000000", "0.97390000"], ["61702.21000000", "0.00162000"], ["61702.22000000", "0.24750000"], ["61702.27000000", "0.00009000"], ["61702.30000000", "0.00034000"], ["61702.89000000", "1.36330000"], ["61703.04000000", "1.60611000"], ["61703.21000000", "0.00013000"], ["61703.91000000", "0.00013000"], ["61703.96000000", "0.00016000"], ["61704.00000000", "0.02400000"], ["61704.20000000", "0.00498000"], ["61704.72000000", "0.00009000"], ["61704.88000000", "0.00009000"], ["61705.03000000", "0.00250000"], ["61705.04000000", "0.04217000"], ["61705.34000000", "0.00009000"], ["61705.92000000", "0.00010000"], ["61706.00000000", "0.02400000"], ["61706.80000000", "0.11634000"], ["61706.81000000", "0.38956000"], ["61707.15000000", "0.00009000"], ["61707.80000000", "0.00009000"], ["61708.00000000", "0.02400000"], ["61708.09000000", "0.00009000"], ["61708.44000000", "0.37328000"], ["61708.45000000", "0.97390000"], ["61708.48000000", "0.00034000"], ["61708.72000000", "0.00100000"], ["61708.88000000", "0.00009000"], ["61709.06000000", "0.00009000"], ["61709.09000000", "0.00279000"], ["61709.42000000", "0.00013000"], ["61709.68000000", "0.00009000"], ["61710.00000000", "0.02419000"], ["61710.19000000", "0.24750000"], ["61710.58000000", "0.00030000"], ["61710.88000000", "0.00009000"], ["61711.02000000", "0.00194000"], ["61711.08000000", "0.05035000"], ["61711.74000000", "0.00009000"], ["61712.00000000", "0.02410000"], ["61712.03000000", "0.00162000"], ["61712.04000000", "0.00009000"], ["61713.07000000", "0.00824000"], ["61713.20000000", "0.00009000"], ["61713.29000000", "0.11634000"], ["61713.30000000", "0.38956000"], ["61713.79000000", "0.00009000"], ["61713.96000000", "0.00009000"], ["61713.99000000", "0.01171000"], ["61714.00000000", "0.02400000"], ["61714.28000000", "0.00037000"], ["61715.29000000", "0.00498000"], ["61715.40000000", "0.00009000"], ["61715.62000000", "0.12000000"], ["61715.63000000", "0.00013000"], ["61715.76000000", "1.76808000"], ["61715.77000000", "4.86591000"], ["61715.85000000", "0.97390000"], ["61716.00000000", "0.02413000"], ["61716.18000000", "0.00034000"], ["61716.22000000", "0.00009000"], ["61716.34000000", "0.16869000"], ["61716.35000000", "0.24750000"], ["61716.41000000", "0.00009000"], ["61716.86000000", "0.00009000"], ["61717.04000000", "0.00009000"], ["61717.30000000", "0.00013000"], ["61718.00000000", "0.02400000"], ["61718.08000000", "0.00010000"], ["61718.37000000", "0.00016000"], ["61718.76000000", "0.00480000"], ["61718.98000000", "0.10000000"], ["61719.05000000", "0.00009000"], ["61719.20000000", "0.00009000"], ["61719.69000000", "0.00009000"], ["61719.94000000", "0.00009000"], ["61720.00000000", "0.02410000"], ["61720.11000000", "0.00250000"], ["61720.23000000", "0.00929000"], ["61720.97000000", "0.00162000"], ["61720.98000000", "0.04217000"], ["61721.48000000", "0.00013000"], ["61721.60000000", "0.00024000"], ["61721.73000000", "0.00032000"], ["61721.84000000", "0.00013000"], ["61721.99000000", "0.08110000"], ["61722.00000000", "0.02400000"], ["61722.27000000", "0.00009000"], ["61722.43000000", "0.00114000"], ["61722.45000000", "0.00016000"], ["61722.52000000", "0.24750000"], ["61722.76000000", "0.00009000"], ["61723.20000000", "0.00009000"], ["61723.24000000", "0.16784000"], ["61723.25000000", "0.97390000"], ["61723.52000000", "0.00034000"], ["61723.63000000", "0.12000000"], ["61723.87000000", "0.06172000"], ["61724.00000000", "0.02400000"], ["61724.01000000", "0.00032000"], ["61724.16000000", "0.00010000"], ["61724.38000000", "0.00009000"], ["61724.39000000", "0.38956000"], ["61725.13000000", "0.00059000"], ["61725.16000000", "0.04217000"], ["61726.00000000", "0.02400000"], ["61726.27000000", "0.00124000"], ["61726.36000000", "0.00009000"], ["61726.39000000", "0.01321000"], ["61726.42000000", "0.07699000"], ["61726.68000000", "0.01826000"], ["61727.24000000", "0.00043000"], ["61727.27000000", "0.00012000"], ["61727.38000000", "0.00009000"], ["61727.45000000", "0.00009000"], ["61727.89000000", "0.00032000"], ["61728.00000000", "0.02565000"], ["61728.05000000", "0.00013000"], ["61728.23000000", "0.00123000"], ["61728.68000000", "0.24750000"], ["61729.49000000", "0.00009000"], ["61729.65000000", "0.00028000"], ["61729.72000000", "0.00569000"], ["61729.74000000", "0.00034000"], ["61730.00000000", "0.02450000"], ["61730.04000000", "0.00162000"], ["61730.24000000", "0.00010000"], ["61730.64000000", "0.10860000"], ["61730.65000000", "0.97390000"], ["61730.70000000", "0.00140000"], ["61730.74000000", "0.00041000"], ["61731.04000000", "0.12000000"], ["61731.47000000", "0.00009000"], ["61731.53000000", "0.00009000"], ["61732.00000000", "0.02400000"], ["61732.55000000", "4.86470000"], ["61732.59000000", "0.00329000"], ["61732.99000000", "0.09348000"], ["61733.00000000", "0.00033000"], ["61733.24000000", "0.00009000"], ["61733.33000000", "0.00009000"], ["61733.52000000", "0.00009000"], ["61734.00000000", "0.02400000"], ["61734.05000000", "0.00032000"], ["61734.64000000", "0.38956000"], ["61734.69000000", "0.00013000"], ["61734.84000000", "0.24750000"], ["61734.93000000", "0.00009000"], ["61734.97000000", "0.00009000"], ["61735.02000000", "0.00250000"], ["61735.03000000", "0.00100000"], ["61736.00000000", "0.02400000"], ["61736.06000000", "0.00034000"], ["61736.32000000", "0.00010000"], ["61736.45000000", "0.04217000"], ["61736.89000000", "0.00009000"], ["61737.04000000", "0.00009000"], ["61737.39000000", "0.00009000"], ["61737.49000000", "0.00498000"], ["61737.56000000", "4.86413000"], ["61737.94000000", "0.00232000"], ["61738.00000000", "0.02400000"], ["61738.05000000", "0.97390000"], ["61738.60000000", "0.00009000"], ["61738.61000000", "0.00023000"], ["61739.00000000", "0.00978000"], ["61739.13000000", "0.00026000"], ["61739.71000000", "0.00823000"], ["61739.92000000", "0.00009000"], ["61740.00000000", "0.05551000"], ["61740.21000000", "0.00032000"], ["61740.23000000", "0.00162000"], ["61740.42000000", "0.00009000"], ["61740.55000000", "0.00012000"], ["61740.68000000", "0.00009000"], ["61740.95000000", "0.00127000"], ["61741.00000000", "0.24750000"], ["61741.17000000", "0.00015000"], ["61741.31000000", "0.05758000"], ["61741.68000000", "0.00009000"], ["61741.99000000", "0.00194000"], ["61742.00000000", "0.02400000"], ["61742.07000000", "0.00009000"], ["61742.27000000", "0.00162000"], ["61742.28000000", "0.04217000"], ["61742.35000000", "0.00034000"], ["61742.40000000", "0.00010000"], ["61742.99000000", "0.00009000"], ["61744.00000000", "0.02400000"], ["61744.21000000", "0.97390000"], ["61744.22000000", "4.86361000"], ["61744.79000000", "0.00260000"], ["61744.92000000", "0.00009000"], ["61745.28000000", "0.38956000"], ["61745.96000000", "0.00013000"], ["61746.00000000", "0.02432000"], ["61746.06000000", "0.00009000"], ["61746.36000000", "0.00061000"], ["61746.38000000", "0.00032000"], ["61746.57000000", "0.00162000"], ["61746.81000000", "0.00017000"], ["61747.16000000", "0.24750000"], ["61748.00000000", "0.02400000"], ["61748.43000000", "0.00010000"], ["61748.48000000", "0.00010000"], ["61748.56000000", "0.00034000"], ["61748.59000000", "0.00498000"], ["61749.09000000", "0.00009000"], ["61749.49000000", "0.00009000"], ["61749.96000000", "0.00010000"], ["61750.00000000", "0.18070000"], ["61750.01000000", "0.00050000"], ["61750.67000000", "0.00022000"], ["61750.84000000", "0.00242000"], ["61751.08000000", "0.00085000"], ["61751.29000000", "0.00009000"], ["61752.00000000", "0.02400000"], ["61752.51000000", "0.00202000"], ["61752.52000000", "0.00009000"], ["61752.54000000", "0.00032000"], ["61753.03000000", "0.00823000"], ["61753.27000000", "0.04217000"], ["61753.28000000", "0.00009000"], ["61753.29000000", "0.00114000"], ["61753.32000000", "0.24750000"], ["61754.00000000", "0.02400000"], ["61754.32000000", "0.38956000"], ["61754.40000000", "0.00009000"], ["61754.56000000", "0.00010000"], ["61754.58000000", "0.07477000"], ["61754.77000000", "0.00034000"], ["61755.00000000", "0.00009000"], ["61755.23000000", "0.00009000"], ["61755.64000000", "0.01926000"], ["61756.00000000", "0.02400000"], ["61756.42000000", "0.00010000"], ["61756.76000000", "0.00009000"], ["61757.16000000", "0.00039000"], ["61757.83000000", "0.00162000"], ["61757.90000000", "0.00039000"], ["61758.00000000", "0.02400000"], ["61758.30000000", "0.00009000"], ["61758.57000000", "0.00009000"], ["61759.48000000", "0.24750000"], ["61759.69000000", "0.00498000"], ["61760.00000000", "0.02524000"], ["61760.09000000", "0.00009000"], ["61760.16000000", "0.00009000"], ["61760.33000000", "0.00079000"], ["61760.64000000", "0.00010000"], ["61761.06000000", "0.00034000"], ["61761.96000000", "0.00009000"], ["61762.00000000", "0.41356000"], ["61762.07000000", "0.00162000"], ["61763.18000000", "0.04217000"], ["61763.76000000", "0.00009000"], ["61764.00000000", "0.02400000"], ["61764.62000000", "0.00009000"], ["61764.70000000", "0.01571000"], ["61765.35000000", "0.00010000"], ["61765.47000000", "0.00013000"], ["61765.64000000", "0.24750000"], ["61766.00000000", "0.02400000"], ["61766.35000000", "0.00823000"], ["61766.72000000", "0.00010000"], ["61766.83000000", "0.00009000"], ["61766.91000000", "0.00011000"], ["61767.26000000", "0.00034000"], ["61767.50000000", "0.00009000"], ["61768.00000000", "0.02400000"], ["61768.14000000", "0.00009000"], ["61768.43000000", "0.00009000"], ["61768.46000000", "0.00009000"], ["61768.54000000", "0.00011000"], ["61768.59000000", "0.00056000"], ["61768.68000000", "0.01826000"], ["61770.00000000", "0.02450000"], ["61770.30000000", "6.35605000"], ["61770.33000000", "0.00009000"], ["61770.60000000", "4.86159000"], ["61770.79000000", "0.00498000"], ["61771.00000000", "0.00009000"], ["61771.02000000", "0.00032000"], ["61771.72000000", "0.00162000"], ["61771.81000000", "0.24750000"], ["61772.00000000", "0.02400000"], ["61772.08000000", "0.00021000"], ["61772.16000000", "0.00194000"], ["61773.10000000", "0.38956000"], ["61773.44000000", "0.00034000"], ["61773.70000000", "0.00009000"], ["61774.00000000", "0.02400000"], ["61774.07000000", "0.00009000"], ["61774.19000000", "0.00105000"], ["61774.94000000", "0.00074000"], ["61775.13000000", "0.00009000"], ["61775.69000000", "0.00176000"], ["61776.00000000", "0.02400000"], ["61776.30000000", "0.00011000"], ["61776.48000000", "0.00009000"], ["61776.50000000", "0.15182000"], ["61776.73000000", "0.00009000"], ["61777.14000000", "0.00009000"], ["61777.29000000", "0.00018000"], ["61777.80000000", "0.22391000"], ["61777.98000000", "0.24750000"], ["61778.00000000", "0.02400000"], ["61778.64000000", "0.00009000"], ["61778.88000000", "0.00010000"], ["61779.53000000", "0.04065000"], ["61779.67000000", "0.00823000"], ["61779.79000000", "0.00050000"], ["61779.92000000", "0.00009000"], ["61780.00000000", "0.02450000"], ["61780.21000000", "0.00009000"], ["61780.76000000", "0.00009000"], ["61781.25000000", "0.01238000"], ["61781.27000000", "0.00010000"], ["61781.68000000", "0.00100000"], ["61781.72000000", "0.00034000"], ["61781.75000000", "0.00019000"], ["61782.00000000", "0.02400000"], ["61782.15000000", "0.00009000"], ["61783.89000000", "0.00605000"], ["61784.00000000", "0.02400000"], ["61784.14000000", "0.00030000"], ["61784.15000000", "0.24750000"], ["61784.20000000", "0.38956000"], ["61784.24000000", "0.00009000"], ["61784.44000000", "0.00009000"], ["61784.64000000", "0.02973000"], ["61784.92000000", "0.00011000"], ["61785.59000000", "0.00162000"], ["61785.60000000", "0.06572000"], ["61785.71000000", "0.00020000"], ["61785.76000000", "0.00032000"], ["61785.77000000", "0.15182000"], ["61785.81000000", "0.00009000"], ["61786.00000000", "0.02400000"], ["61786.14000000", "0.00009000"], ["61786.64000000", "0.00009000"], ["61787.03000000", "0.00510000"], ["61787.47000000", "0.01925000"], ["61787.52000000", "0.00009000"], ["61788.00000000", "0.02806000"], ["61788.33000000", "0.00010000"], ["61788.43000000", "0.00009000"], ["61789.40000000", "0.00033000"], ["61789.47000000", "0.00041000"], ["61790.00000000", "0.02450000"], ["61790.01000000", "0.00009000"], ["61790.32000000", "0.24750000"], ["61790.71000000", "0.00034000"], ["61790.90000000", "0.00024000"], ["61791.87000000", "0.00009000"], ["61791.93000000", "0.00032000"], ["61792.00000000", "0.02400000"], ["61792.63000000", "0.00009000"], ["61792.99000000", "0.00823000"], ["61793.32000000", "0.00009000"], ["61793.95000000", "0.00009000"], ["61794.00000000", "0.02400000"], ["61794.26000000", "0.00009000"], ["61794.64000000", "0.00009000"], ["61794.87000000", "0.00010000"], ["61795.03000000", "0.00162000"], ["61795.04000000", "0.15182000"], ["61795.15000000", "0.00194000"], ["61795.30000000", "0.38956000"], ["61795.45000000", "0.00179000"], ["61795.71000000", "0.00009000"], ["61796.00000000", "0.02400000"], ["61796.11000000", "0.00223000"], ["61796.25000000", "0.00013000"], ["61796.90000000", "0.00034000"], ["61797.05000000", "0.00418000"], ["61797.12000000", "0.00019000"], ["61797.43000000", "0.00015000"], ["61797.68000000", "0.00009000"], ["61797.75000000", "0.00009000"], ["61797.96000000", "0.00009000"], ["61798.00000000", "0.02400000"], ["61798.05000000", "0.00202000"], ["61798.28000000", "0.02542000"], ["61798.97000000", "0.00013000"], ["61799.08000000", "0.00009000"], ["61799.52000000", "0.01140000"], ["61799.84000000", "0.00009000"], ["61799.99000000", "0.00162000"], ["61800.00000000", "0.62328000"], ["61801.41000000", "0.00009000"], ["61801.64000000", "0.00021000"], ["61802.35000000", "0.00009000"], ["61802.58000000", "0.00015000"], ["61803.06000000", "0.06885000"], ["61803.62000000", "0.00009000"], ["61803.98000000", "0.00009000"], ["61804.25000000", "0.00032000"], ["61804.31000000", "0.15182000"], ["61805.31000000", "0.00009000"], ["61805.54000000", "0.00016000"], ["61805.85000000", "0.00020000"], ["61806.23000000", "0.00012000"], ["61806.40000000", "0.38956000"], ["61806.85000000", "0.00009000"], ["61807.04000000", "0.00010000"], ["61807.22000000", "0.00013000"], ["61807.43000000", "0.02542000"], ["61807.48000000", "0.00009000"], ["61807.69000000", "0.00013000"], ["61807.82000000", "0.00034000"], ["61807.83000000", "0.00011000"], ["61808.12000000", "0.03595000"], ["61808.71000000", "0.00009000"], ["61809.27000000", "0.00809000"], ["61809.60000000", "0.00012000"], ["61809.89000000", "0.00009000"], ["61810.00000000", "0.87996000"], ["61810.04000000", "0.00009000"], ["61810.23000000", "0.00053000"], ["61810.32000000", "0.00025000"], ["61810.35000000", "0.00009000"], ["61810.42000000", "0.00032000"], ["61810.59000000", "0.00023000"], ["61811.29000000", "4.85846000"], ["61811.91000000", "0.08692000"], ["61812.00000000", "0.18106000"], ["61812.30000000", "0.00027000"], ["61813.33000000", "0.00101000"], ["61813.37000000", "0.00118000"], ["61813.45000000", "0.00015000"], ["61813.58000000", "0.00162000"], ["61813.59000000", "0.15182000"], ["61814.22000000", "0.00051000"], ["61814.76000000", "0.00034000"], ["61814.79000000", "0.00720000"], ["61815.00000000", "0.00324000"], ["61815.36000000", "0.00010000"], ["61815.52000000", "0.00009000"], ["61815.60000000", "0.00009000"], ["61816.00000000", "0.00014000"], ["61816.09000000", "0.00009000"], ["61816.62000000", "0.00025000"], ["61816.71000000", "0.00100000"], ["61816.89000000", "0.11561000"], ["61817.87000000", "0.00014000"], ["61818.05000000", "0.00010000"], ["61818.18000000", "0.00157000"], ["61818.61000000", "0.00045000"], ["61818.66000000", "0.00009000"], ["61818.80000000", "3.80030000"], ["61819.12000000", "0.00009000"], ["61819.44000000", "0.00009000"], ["61820.00000000", "0.00050000"], ["61820.41000000", "0.00013000"], ["61820.95000000", "0.00034000"], ["61821.53000000", "0.00046000"], ["61821.71000000", "0.00025000"], ["61821.73000000", "0.00050000"], ["61822.15000000", "0.00009000"], ["61822.20000000", "0.00122000"], ["61822.63000000", "0.00182000"], ["61822.72000000", "0.00026000"], ["61822.87000000", "0.15182000"], ["61822.90000000", "0.11453000"], ["61822.92000000", "0.00010000"], ["61823.33000000", "0.01883000"], ["61823.52000000", "0.00368000"], ["61823.53000000", "0.02793000"], ["61823.70000000", "0.00011000"], ["61824.06000000", "0.00013000"], ["61825.09000000", "0.00015000"], ["61825.58000000", "0.00016000"], ["61826.17000000", "0.00015000"], ["61826.45000000", "0.00491000"], ["61826.90000000", "0.01904000"], ["61826.94000000", "0.01916000"], ["61827.03000000", "0.00013000"], ["61827.22000000", "0.00009000"], ["61827.68000000", "0.00811000"], ["61827.72000000", "0.00034000"], ["61827.90000000", "0.00011000"], ["61828.00000000", "0.00406000"], ["61828.12000000", "0.00014000"], ["61828.57000000", "0.00010000"], ["61828.59000000", "0.00036000"], ["61828.70000000", "0.00009000"], ["61830.00000000", "0.00050000"], ["61830.50000000", "0.00109000"], ["61830.52000000", "0.00021000"], ["61830.98000000", "0.00240000"], ["61831.03000000", "0.00010000"], ["61831.06000000", "0.00170000"], ["61831.15000000", "0.00015000"], ["61832.53000000", "0.00013000"], ["61833.33000000", "0.00438000"], ["61833.60000000", "0.00010000"], ["61833.77000000", "0.00017000"], ["61833.97000000", "0.00034000"], ["61834.08000000", "0.00009000"], ["61834.17000000", "0.03243000"], ["61834.27000000", "0.00009000"], ["61834.56000000", "0.00038000"], ["61834.58000000", "0.00068000"], ["61834.65000000", "0.00194000"], ["61835.29000000", "0.00018000"], ["61835.68000000", "0.00009000"], ["61837.21000000", "0.00092000"], ["61838.00000000", "0.50000000"], ["61839.13000000", "0.00020000"], ["61839.75000000", "0.00066000"], ["61839.78000000", "0.00014000"], ["61840.00000000", "0.00093000"], ["61840.02000000", "0.00009000"], ["61840.21000000", "0.00076000"], ["61840.67000000", "0.00034000"], ["61840.92000000", "0.00009000"], ["61841.17000000", "0.00010000"], ["61841.24000000", "0.00032000"], ["61841.66000000", "0.00132000"], ["61841.83000000", "0.00062000"], ["61842.07000000", "0.00011000"], ["61842.52000000", "0.00019000"], ["61842.85000000", "0.00062000"], ["61842.89000000", "0.00025000"], ["61843.26000000", "0.00048000"], ["61843.58000000", "0.00009000"], ["61843.75000000", "0.00013000"], ["61844.19000000", "2.09001000"], ["61844.43000000", "0.00009000"], ["61844.54000000", "0.00009000"], ["61844.64000000", "0.00010000"], ["61844.66000000", "0.00014000"], ["61844.67000000", "0.00009000"], ["61844.83000000", "0.00105000"], ["61844.90000000", "0.00009000"], ["61845.21000000", "0.00600000"], ["61845.31000000", "0.00206000"], ["61845.89000000", "0.00016000"], ["61846.15000000", "0.00009000"], ["61846.20000000", "0.02377000"], ["61846.90000000", "4.85575000"], ["61847.18000000", "0.00486000"], ["61847.22000000", "0.00034000"], ["61847.39000000", "0.07859000"]]}
{"type": "depth", "ts": 1783008087014, "U": 96863148717, "u": 96863148741, "bids": [["61629.99000000", "1.26468000"], ["61620.92000000", "0.08771000"], ["61614.33000000", "0.00649000"], ["61591.53000000", "0.00000000"], ["61581.22000000", "0.13813000"], ["61529.61000000", "0.00000000"], ["61519.45000000", "0.00000000"], ["61490.89000000", "0.00000000"], ["55470.59000000", "0.00000000"], ["55467.00000000", "0.09407000"], ["49304.00000000", "0.00126000"]], "asks": [["61630.00000000", "3.41329000"], ["61665.76000000", "0.00829000"], ["61668.84000000", "0.01658000"], ["61722.38000000", "0.00000000"], ["61725.61000000", "0.00000000"], ["61729.91000000", "0.00000000"], ["61849.20000000", "3.00000000"], ["61908.90000000", "3.00000000"], ["61968.60000000", "3.00000000"]]}
{"type": "depth", "ts": 1783008087114, "U": 96863148742, "u": 96863148747, "bids": [["61591.53000000", "0.00000000"], ["55467.00000000", "0.09447000"], ["55466.00000000", "0.30200000"]], "asks": []}
{"type": "depth", "ts": 1783008087214, "U": 96863148748, "u": 96863148886, "bids": [["61629.99000000", "0.28956000"], ["61629.63000000", "0.00009000"], ["61629.03000000", "0.00000000"], ["61629.02000000", "0.00000000"], ["61628.00000000", "0.00518000"], ["61627.99000000", "0.00027000"], ["61626.28000000", "0.00000000"], ["61626.27000000", "0.00018000"], ["61626.26000000", "0.00027000"], ["61626.01000000", "0.00009000"], ["61625.90000000", "0.00009000"], ["61625.89000000", "0.03371000"], ["61624.72000000", "0.00000000"], ["61624.71000000", "0.00018000"], ["61624.01000000", "0.00009000"], ["61624.00000000", "0.10522000"], ["61623.84000000", "0.00000000"], ["61623.83000000", "0.00019000"], ["61623.82000000", "0.00300000"], ["61623.27000000", "0.00000000"], ["61623.26000000", "0.00000000"], ["61623.09000000", "0.00000000"], ["61623.07000000", "0.00034000"], ["61622.13000000", "0.09080000"], ["61621.40000000", "0.02190000"], ["61620.93000000", "0.00000000"], ["61620.92000000", "0.00000000"], ["61620.83000000", "0.09080000"], ["61620.82000000", "0.01209000"], ["61620.03000000", "1.36818000"], ["61620.02000000", "0.00000000"], ["61619.39000000", "0.00000000"], ["61618.63000000", "0.01000000"], ["61618.57000000", "0.01000000"], ["61618.01000000", "0.01000000"], ["61617.95000000", "0.01000000"], ["61617.75000000", "0.08771000"], ["61617.74000000", "0.00000000"], ["61617.65000000", "0.24750000"], ["61617.45000000", "0.00000000"], ["61617.23000000", "0.02000000"], ["61617.03000000", "0.01000000"], ["61616.01000000", "0.00000000"], ["61615.66000000", "0.00000000"], ["61615.55000000", "0.01000000"], ["61614.74000000", "0.01000000"], ["61612.51000000", "0.05922000"], ["61611.78000000", "0.61117000"], ["61610.53000000", "0.12000000"], ["61605.23000000", "0.00000000"], ["61592.20000000", "1.17014000"], ["61591.53000000", "0.00009000"], ["61588.03000000", "0.00000000"], ["61581.22000000", "0.00000000"], ["61575.12000000", "0.13806000"], ["61568.52000000", "0.01000000"], ["61566.48000000", "0.01000000"], ["61566.22000000", "0.01000000"], ["61563.08000000", "0.01000000"], ["61563.02000000", "0.01000000"], ["61562.46000000", "0.01000000"], ["61526.36000000", "0.00000000"], ["61525.62000000", "0.00016000"], ["61515.45000000", "0.00024000"], ["61488.57000000", "0.04217000"], ["61487.90000000", "0.00037000"], ["60705.54000000", "0.00030000"], ["55467.00000000", "0.09487000"], ["49304.00000000", "0.00086000"]], "asks": [["61630.00000000", "3.42363000"], ["61630.86000000", "0.07482000"], ["61630.87000000", "0.04217000"], ["61631.31000000", "0.00000000"], ["61632.00000000", "0.10357000"], ["61632.62000000", "0.09089000"], ["61633.32000000", "0.00018000"], ["61633.33000000", "0.00027000"], ["61633.93000000", "0.09089000"], ["61633.94000000", "0.09080000"], ["61637.30000000", "0.00033000"], ["61637.43000000", "0.58464000"], ["61638.18000000", "0.00000000"], ["61638.38000000", "0.01200000"], ["61652.00000000", "1.63138000"], ["61655.13000000", "0.00000000"], ["61664.47000000", "0.00000000"], ["61665.76000000", "0.00000000"], ["61668.84000000", "0.00000000"], ["61677.80000000", "1.60672000"], ["61815.44000000", "0.00000000"]]}
{"type": "depth", "ts": 1783008087314, "U": 96863148887, "u": 96863148986, "bids": [["61629.99000000", "0.28929000"], ["61629.98000000", "0.00071000"], ["61628.00000000", "0.00518000"], ["61627.99000000", "0.00009000"], ["61627.18000000", "0.00000000"], ["61626.49000000", "0.00000000"], ["61626.27000000", "0.00000000"], ["61626.26000000", "0.00000000"], ["61626.00000000", "0.01118000"], ["61625.89000000", "0.03389000"], ["61624.73000000", "0.04727000"], ["61624.71000000", "0.00000000"], ["61624.00000000", "0.01136000"], ["61623.99000000", "0.27388000"], ["61622.14000000", "0.00009000"], ["61620.84000000", "0.00009000"], ["61620.80000000", "0.00019000"], ["61620.12000000", "0.00243000"], ["61617.88000000", "0.01000000"], ["61617.82000000", "0.01000000"], ["61615.05000000", "0.01000000"], ["61606.48000000", "0.00000000"], ["61570.03000000", "0.00000000"], ["61566.36000000", "0.01000000"], ["61563.02000000", "0.00000000"], ["61562.46000000", "0.00000000"], ["58000.00000000", "341.77455000"], ["55467.00000000", "0.09527000"]], "asks": [["61630.66000000", "0.01027000"], ["61630.86000000", "0.07491000"], ["61630.87000000", "0.04235000"], ["61631.89000000", "0.00894000"], ["61632.00000000", "0.10375000"], ["61632.09000000", "0.00009000"], ["61632.62000000", "0.09107000"], ["61633.32000000", "0.00000000"], ["61633.33000000", "0.00009000"], ["61633.93000000", "0.09107000"], ["61633.94000000", "0.09098000"], ["61633.95000000", "0.14923000"], ["61633.99000000", "0.86180000"], ["61634.00000000", "0.04349000"], ["61634.20000000", "0.00902000"], ["61635.24000000", "0.01300000"], ["61635.30000000", "1.37430000"], ["61638.07000000", "0.01000000"], ["61642.21000000", "0.01000000"], ["61644.83000000", "0.00000000"], ["61647.11000000", "0.00000000"], ["61676.67000000", "0.00112000"], ["62554.45000000", "0.00030000"]]}
{"type": "depth", "ts": 1783008087414, "U": 96863148987, "u": 96863149006, "bids": [["61628.00000000", "0.00530000"], ["61627.06000000", "0.09640000"], ["61626.00000000", "0.01918000"], ["61624.00000000", "0.01636000"], ["61622.01000000", "0.00009000"], ["61622.00000000", "0.02400000"], ["61614.74000000", "0.02000000"], ["61568.52000000", "0.00000000"], ["61566.47000000", "0.01000000"], ["61566.36000000", "0.00000000"], ["61467.30000000", "0.00000000"], ["61461.34000000", "0.01001000"], ["55467.00000000", "0.09547000"]], "asks": [["61630.00000000", "3.42376000"], ["61637.09000000", "0.01100000"], ["61638.33000000", "0.01000000"], ["61638.38000000", "0.02200000"], ["61644.34000000", "0.00000000"], ["61676.95000000", "0.00000000"], ["61718.37000000", "0.00016000"], ["61721.61000000", "0.00024000"]]}
{"type": "depth", "ts": 1783008087514, "U": 96863149007, "u": 96863149042, "bids": [["61629.99000000", "0.28071000"], ["61628.00000000", "0.00530000"], ["61627.07000000", "0.00009000"], ["61624.00000000", "0.02427000"], ["61623.99000000", "0.02500000"], ["61623.83000000", "0.00028000"], ["61623.82000000", "0.25050000"], ["61622.01000000", "0.00000000"], ["61620.83000000", "0.09089000"], ["61620.80000000", "0.00010000"], ["61617.75000000", "0.00000000"], ["61596.04000000", "0.88554000"], ["61578.01000000", "1.08690000"], ["61566.48000000", "0.00000000"], ["61535.99000000", "0.00009000"], ["55467.00000000", "0.09587000"], ["49303.99000000", "0.00000000"]], "asks": [["61634.00000000", "0.04340000"], ["61636.63000000", "0.00000000"], ["61644.28000000", "0.00000000"], ["61648.52000000", "0.00000000"], ["61649.75000000", "0.00000000"], ["61649.81000000", "0.00000000"], ["61651.26000000", "0.00649000"], ["61655.65000000", "1.74702000"], ["61682.01000000", "0.00000000"], ["61725.91000000", "0.00040000"]]}
{"type": "depth", "ts": 1783008087614, "U": 96863149043, "u": 96863149071, "bids": [["61629.99000000", "0.28062000"], ["61629.71000000", "0.00009000"], ["61629.70000000", "0.24888000"], ["61627.06000000", "0.09658000"], ["61623.99000000", "0.02500000"], ["61623.84000000", "0.00009000"], ["61623.83000000", "0.11353000"], ["61620.84000000", "0.00000000"], ["61620.82000000", "0.01200000"], ["61615.43000000", "0.01000000"], ["61614.81000000", "0.01300000"], ["61596.04000000", "0.41628000"], ["61567.10000000", "0.01000000"], ["61566.94000000", "0.01300000"], ["61566.22000000", "0.00000000"], ["55467.00000000", "0.09627000"], ["49303.99000000", "0.00000000"]], "asks": [["61630.00000000", "3.42341000"], ["61637.72000000", "0.01100000"], ["61638.34000000", "0.01000000"]]}
{"type": "depth", "ts": 1783008087714, "U": 96863149072, "u": 96863149109, "bids": [["61629.99000000", "0.27252000"], ["61629.70000000", "0.24906000"], ["61628.01000000", "0.00009000"], ["61628.00000000", "0.01730000"], ["61627.07000000", "0.00000000"], ["61627.06000000", "0.00018000"], ["61623.99000000", "0.02482000"], ["61623.84000000", "0.00000000"], ["61623.83000000", "0.00019000"], ["61623.82000000", "0.00300000"], ["61622.13000000", "0.00000000"], ["61622.01000000", "0.00009000"], ["61618.58000000", "0.00000000"], ["61614.26000000", "0.02000000"], ["61566.94000000", "0.00000000"], ["61566.47000000", "0.00000000"], ["61563.08000000", "0.00000000"], ["61540.01000000", "0.00000000"], ["61525.62000000", "0.00000000"], ["61525.61000000", "0.00016000"], ["61487.90000000", "0.00000000"], ["61461.34000000", "0.00000000"], ["61454.94000000", "0.01001000"], ["55467.00000000", "0.09627000"]], "asks": [["61649.13000000", "0.00000000"], ["61649.74000000", "0.00000000"], ["61695.60000000", "0.00000000"], ["61721.61000000", "0.00000000"], ["61725.91000000", "0.00000000"]]}
{"type": "depth", "ts": 1783008087814, "U": 96863149110, "u": 96863149342, "bids": [["61629.99000000", "0.00000000"], ["61629.98000000", "0.00000000"], ["61629.97000000", "0.00000000"], ["61629.71000000", "0.00000000"], ["61629.70000000", "0.25033000"], ["61629.69000000", "0.00063000"], ["61628.00000000", "0.01730000"], ["61627.06000000", "0.00000000"], ["61623.99000000", "0.02491000"], ["61622.14000000", "0.00000000"], ["61622.05000000", "0.01018000"], ["61622.00000000", "0.02418000"], ["61621.41000000", "0.00009000"], ["61620.86000000", "0.00009000"], ["61620.85000000", "0.08583000"], ["61620.84000000", "0.00000000"], ["61620.83000000", "0.00000000"], ["61618.44000000", "0.08771000"], ["61614.26000000", "0.00000000"], ["61613.04000000", "0.00000000"], ["61612.52000000", "0.60917000"], ["61612.26000000", "0.02000000"], ["61608.22000000", "0.86151000"], ["61599.00000000", "0.00000000"], ["61598.95000000", "0.00009000"], ["61598.00000000", "0.03400000"], ["61575.12000000", "0.00000000"], ["61574.33000000", "0.00000000"], ["61573.71000000", "0.00328000"], ["61567.10000000", "0.00000000"], ["61464.92000000", "0.00009000"], ["60705.54000000", "0.00000000"], ["55467.00000000", "0.09187000"], ["55466.73000000", "0.00020000"]], "asks": [["61629.71000000", "4.85761000"], ["61629.72000000", "0.00311000"], ["61629.73000000", "0.00017000"], ["61629.98000000", "0.47307000"], ["61629.99000000", "1.41454000"], ["61630.00000000", "0.37838000"], ["61630.01000000", "0.00000000"], ["61630.02000000", "0.00000000"], ["61630.86000000", "0.00018000"], ["61631.31000000", "0.00000000"], ["61632.62000000", "0.00027000"], ["61633.93000000", "0.00018000"], ["61633.94000000", "0.00000000"], ["61642.26000000", "0.00000000"], ["61642.32000000", "0.00000000"], ["61650.82000000", "0.00000000"], ["61667.03000000", "0.00000000"], ["61669.54000000", "0.00000000"], ["61670.01000000", "0.00328000"], ["61670.63000000", "0.00000000"], ["61679.65000000", "0.00064000"], ["61680.27000000", "0.00000000"], ["61680.80000000", "0.00000000"], ["61708.44000000", "0.37328000"], ["61710.29000000", "0.00000000"], ["61727.24000000", "0.00043000"], ["61727.86000000", "0.00000000"], ["61796.49000000", "0.00000000"], ["62554.45000000", "0.00000000"]]}
{"type": "depth", "ts": 1783008087914, "U": 96863149343, "u": 96863149391, "bids": [["61629.70000000", "0.25051000"], ["61629.69000000", "0.00072000"], ["61626.95000000", "0.00000000"], ["61624.34000000", "0.00009000"], ["61624.33000000", "0.08276000"], ["61620.87000000", "0.60917000"], ["61620.86000000", "0.00009000"], ["61620.85000000", "0.08574000"], ["61612.52000000", "0.00000000"], ["61609.64000000", "0.00000000"], ["61583.17000000", "0.00000000"], ["61573.13000000", "0.00436000"], ["61565.85000000", "0.01658000"], ["61484.50000000", "0.00040000"], ["61462.13000000", "0.00000000"], ["55466.73000000", "0.00060000"]], "asks": [["61629.71000000", "4.87266000"], ["61629.98000000", "0.47325000"], ["61629.99000000", "1.41472000"], ["61630.00000000", "0.11592000"], ["61630.66000000", "0.01027000"], ["61630.86000000", "0.00000000"], ["61632.00000000", "0.10366000"], ["61632.62000000", "0.00000000"], ["61633.93000000", "0.00000000"], ["61642.03000000", "0.60825000"], ["61646.63000000", "0.00000000"], ["61671.13000000", "0.09284000"], ["61721.60000000", "0.00024000"]]}
{"type": "depth", "ts": 1783008088014, "U": 96863149392, "u": 96863149460, "bids": [["61629.70000000", "0.40248000"], ["61629.69000000", "0.00296000"], ["61627.01000000", "0.09620000"], ["61625.74000000", "0.00009000"], ["61625.73000000", "0.00009000"], ["61624.73000000", "0.04727000"], ["61624.34000000", "0.00000000"], ["61624.33000000", "0.00018000"], ["61623.17000000", "0.00009000"], ["61623.16000000", "0.06575000"], ["61623.15000000", "0.09080000"], ["61622.00000000", "0.02400000"], ["61621.85000000", "0.00000000"], ["61621.84000000", "0.09080000"], ["61621.41000000", "0.00000000"], ["61620.88000000", "0.09080000"], ["61620.86000000", "0.84026000"], ["61620.85000000", "0.00000000"], ["61620.79000000", "0.00000000"], ["61620.04000000", "0.97390000"], ["61611.78000000", "0.61117000"], ["61609.35000000", "0.00009000"], ["61608.22000000", "0.39225000"], ["61583.32000000", "0.00009000"], ["61573.27000000", "0.00427000"], ["55466.73000000", "0.00080000"], ["49303.76000000", "0.00040000"]], "asks": [["61629.71000000", "4.77745000"], ["61629.98000000", "0.06624000"], ["61629.99000000", "0.05142000"], ["61632.91000000", "0.00000000"], ["61646.34000000", "0.00009000"], ["61659.71000000", "0.00829000"], ["61661.79000000", "0.01658000"], ["61725.90000000", "0.00040000"]]}
{"type": "depth", "ts": 1783008088114, "U": 96863149461, "u": 96863149515, "bids": [["61629.70000000", "1.17937000"], ["61629.69000000", "0.00305000"], ["61628.00000000", "0.01730000"], ["61627.02000000", "0.00018000"], ["61627.01000000", "0.09638000"], ["61625.90000000", "0.00000000"], ["61625.89000000", "0.00018000"], ["61625.74000000", "0.00000000"], ["61625.60000000", "0.00009000"], ["61625.59000000", "0.04775000"], ["61624.73000000", "0.04727000"], ["61624.33000000", "0.00000000"], ["61623.99000000", "0.02491000"], ["61622.05000000", "0.01000000"], ["61620.87000000", "0.00000000"], ["61615.55000000", "0.61916000"], ["61556.50000000", "0.00000000"], ["61552.21000000", "0.00030000"], ["61484.50000000", "0.00000000"], ["55466.73000000", "0.00120000"]], "asks": [["61629.98000000", "0.09241000"], ["61630.00000000", "0.11601000"], ["61632.00000000", "0.00018000"], ["61632.86000000", "0.00034000"], ["61632.98000000", "0.11367000"], ["61633.95000000", "0.14941000"], ["61645.20000000", "0.54925000"], ["61659.71000000", "0.00000000"], ["61661.79000000", "0.00000000"], ["61663.92000000", "1.05515000"], ["61706.29000000", "0.00030000"], ["61710.58000000", "0.00000000"]]}
{"type": "depth", "ts": 1783008088214, "U": 96863149516, "u": 96863149564, "bids": [["61629.70000000", "1.18003000"], ["61629.69000000", "0.00296000"], ["61626.00000000", "0.01918000"], ["61625.89000000", "0.00000000"], ["61625.59000000", "0.04793000"], ["61614.33000000", "0.00000000"], ["61614.04000000", "0.00649000"], ["61575.06000000", "0.13823000"], ["61525.61000000", "0.00000000"], ["61525.32000000", "0.00016000"], ["61515.45000000", "0.00000000"], ["61385.82000000", "0.00000000"], ["60705.25000000", "0.00030000"], ["55466.73000000", "0.00160000"], ["49303.76000000", "0.00000000"]], "asks": [["61630.00000000", "0.11592000"], ["61631.89000000", "0.00894000"], ["61632.00000000", "0.00000000"], ["61632.98000000", "0.11385000"], ["61634.66000000", "0.01800000"], ["61634.72000000", "0.01400000"], ["61635.27000000", "0.01200000"], ["61635.34000000", "0.01100000"], ["61637.75000000", "0.01000000"], ["61641.07000000", "0.00000000"], ["61644.15000000", "0.00000000"], ["61651.26000000", "0.00000000"], ["61718.37000000", "0.00000000"], ["61721.60000000", "0.00000000"], ["61725.90000000", "0.00000000"]]}
{"type": "depth", "ts": 1783008088314, "U": 96863149565, "u": 96863149582, "bids": [["61629.70000000", "1.18068000"], ["61629.63000000", "0.00000000"], ["61620.83000000", "0.00009000"], ["61454.94000000", "0.01016000"], ["61409.41000000", "0.02542000"], ["55466.73000000", "0.00200000"], ["55466.00000000", "0.30220000"]], "asks": [["61629.71000000", "4.77583000"], ["61631.40000000", "0.00164000"], ["61641.12000000", "0.00000000"], ["61641.68000000", "0.00000000"], ["61676.67000000", "0.01412000"], ["61676.95000000", "0.01100000"], ["62554.16000000", "0.00030000"]]}
{"type": "depth", "ts": 1783008088414, "U": 96863149583, "u": 96863149622, "bids": [["61629.70000000", "0.25087000"], ["61627.02000000", "0.00009000"], ["61627.01000000", "0.00018000"], ["61625.60000000", "0.00000000"], ["61625.59000000", "0.00018000"], ["61625.37000000", "0.00009000"], ["61625.36000000", "0.02814000"], ["61624.13000000", "0.00000000"], ["61623.16000000", "0.00000000"], ["61623.15000000", "0.00000000"], ["61621.85000000", "0.00009000"], ["61620.86000000", "0.60740000"], ["61620.04000000", "0.00000000"], ["61608.22000000", "0.83839000"], ["61586.63000000", "0.00024000"], ["61515.16000000", "0.00056000"], ["61484.21000000", "0.00040000"], ["55466.73000000", "0.00220000"], ["55466.00000000", "0.30200000"]], "asks": [["61630.00000000", "0.11601000"], ["61631.46000000", "0.12617000"], ["61632.98000000", "0.00018000"], ["61641.75000000", "0.00000000"], ["61649.07000000", "0.04709000"], ["61660.21000000", "0.00000000"], ["61682.01000000", "0.01100000"]]}
{"type": "depth", "ts": 1783008088514, "U": 96863149623, "u": 96863150171, "bids": [["61629.70000000", "0.00000000"], ["61629.69000000", "0.00000000"], ["61628.45000000", "0.00000000"], ["61628.44000000", "0.00000000"], ["61628.40000000", "0.00000000"], ["61628.01000000", "0.00000000"], ["61628.00000000", "0.00000000"], ["61627.99000000", "0.00000000"], ["61627.72000000", "0.00000000"], ["61627.47000000", "0.00000000"], ["61627.02000000", "0.00000000"], ["61627.01000000", "0.00000000"], ["61626.33000000", "0.00000000"], ["61626.01000000", "0.00000000"], ["61626.00000000", "0.00000000"], ["61625.73000000", "0.00000000"], ["61625.59000000", "0.00000000"], ["61625.50000000", "0.00000000"], ["61625.37000000", "0.00000000"], ["61625.36000000", "0.00000000"], ["61625.00000000", "0.00000000"], ["61624.74000000", "0.00000000"], ["61624.73000000", "0.00000000"], ["61624.64000000", "0.00000000"], ["61624.47000000", "0.00000000"], ["61624.01000000", "0.00000000"], ["61624.00000000", "0.00000000"], ["61623.99000000", "0.02263000"], ["61623.98000000", "0.00080000"], ["61623.97000000", "0.00017000"], ["61623.83000000", "0.00009000"], ["61623.17000000", "0.00000000"], ["61623.07000000", "0.00000000"], ["61622.56000000", "0.00000000"], ["61622.06000000", "0.00009000"], ["61622.05000000", "0.00018000"], ["61622.00000000", "0.02418000"], ["61621.84000000", "0.00027000"], ["61621.41000000", "0.00009000"], ["61621.40000000", "0.02208000"], ["61620.89000000", "0.00409000"], ["61620.88000000", "0.00027000"], ["61620.87000000", "0.00009000"], ["61620.86000000", "0.00027000"], ["61620.83000000", "0.00000000"], ["61620.82000000", "0.00009000"], ["61620.81000000", "0.00000000"], ["61620.29000000", "0.00000000"], ["61620.05000000", "0.00009000"], ["61620.04000000", "0.00000000"], ["61620.03000000", "0.00000000"], ["61619.74000000", "0.00000000"], ["61619.54000000", "0.00000000"], ["61618.59000000", "0.00000000"], ["61618.44000000", "0.00000000"], ["61617.90000000", "0.00000000"], ["61617.83000000", "0.00010000"], ["61617.65000000", "0.00000000"], ["61617.54000000", "0.38956000"], ["61617.52000000", "0.00488000"], ["61617.46000000", "0.00000000"], ["61617.37000000", "0.00000000"], ["61617.23000000", "0.00000000"], ["61617.03000000", "0.00000000"], ["61616.66000000", "0.00000000"], ["61616.38000000", "0.00000000"], ["61616.03000000", "0.00000000"], ["61615.56000000", "0.00000000"], ["61615.55000000", "0.01000000"], ["61615.54000000", "0.00000000"], ["61615.00000000", "0.00000000"], ["61614.97000000", "0.00000000"], ["61614.71000000", "0.00000000"], ["61614.40000000", "0.00000000"], ["61613.90000000", "0.00400000"], ["61613.58000000", "0.00000000"], ["61613.46000000", "1.36330000"], ["61613.43000000", "0.03000000"], ["61612.51000000", "0.00000000"], ["61612.50000000", "0.00488000"], ["61612.43000000", "0.00000000"], ["61612.04000000", "0.00000000"], ["61611.79000000", "0.97390000"], ["61611.77000000", "0.00000000"], ["61611.67000000", "0.00010000"], ["61611.62000000", "0.00878000"], ["61611.13000000", "0.00000000"], ["61610.91000000", "1.36330000"], ["61610.56000000", "0.38956000"], ["61610.50000000", "0.00000000"], ["61608.58000000", "0.00010000"], ["61608.53000000", "0.00889000"], ["61608.23000000", "0.73343000"], ["61608.05000000", "0.00000000"], ["61607.70000000", "0.00400000"], ["61607.42000000", "0.00000000"], ["61606.17000000", "0.37436000"], ["61605.90000000", "0.00000000"], ["61605.50000000", "0.00010000"], ["61605.44000000", "0.00904000"], ["61604.34000000", "0.00000000"], ["61602.42000000", "0.00010000"], ["61602.35000000", "0.00899000"], ["61602.34000000", "0.00000000"], ["61601.90000000", "0.00009000"], ["61601.55000000", "0.00400000"], ["61601.25000000", "0.00000000"], ["61600.77000000", "0.00000000"], ["61599.34000000", "0.00010000"], ["61598.00000000", "0.02400000"], ["61596.57000000", "0.00000000"], ["61596.26000000", "0.00010000"], ["61596.00000000", "0.02422000"], ["61593.18000000", "0.00010000"], ["61593.00000000", "0.01000000"], ["61592.21000000", "0.76467000"], ["61590.00000000", "0.02896000"], ["61589.36000000", "0.58509000"], ["61588.60000000", "0.00009000"], ["61582.81000000", "0.58516000"], ["61577.17000000", "0.10000000"], ["61572.02000000", "0.00000000"], ["61572.01000000", "0.00000000"], ["61571.51000000", "0.00000000"], ["61566.58000000", "0.00403000"], ["61565.32000000", "1.60964000"], ["61563.56000000", "0.00000000"], ["61562.52000000", "0.00000000"], ["61562.37000000", "0.00010000"], ["61561.87000000", "0.97477000"], ["61561.39000000", "0.70598000"], ["61535.05000000", "0.00000000"], ["61515.17000000", "0.00000000"], ["61509.87000000", "0.00000000"], ["61502.82000000", "0.00000000"], ["61500.74000000", "0.00010000"], ["61497.82000000", "0.00260000"], ["61448.24000000", "0.00000000"], ["61439.12000000", "0.00010000"], ["61386.61000000", "0.00000000"], ["61377.49000000", "0.00010000"], ["61324.97000000", "0.00000000"], ["61315.87000000", "0.00010000"], ["61263.34000000", "0.00000000"], ["61254.25000000", "0.00010000"], ["61201.71000000", "0.00000000"], ["61192.62000000", "0.00010000"], ["61140.07000000", "0.00000000"], ["61131.00000000", "0.00010000"], ["60705.25000000", "0.00000000"], ["55467.00000000", "0.09177000"], ["55466.73000000", "0.00010000"], ["55461.60000000", "0.00020000"], ["49303.76000000", "0.00000000"]], "asks": [["61624.00000000", "4.77536000"], ["61624.01000000", "0.00035000"], ["61624.02000000", "0.00017000"], ["61624.48000000", "0.15365000"], ["61624.74000000", "0.00000000"], ["61624.77000000", "0.00000000"], ["61625.17000000", "0.04217000"], ["61625.37000000", "0.00000000"], ["61625.50000000", "0.00009000"], ["61626.01000000", "0.00000000"], ["61626.34000000", "0.00000000"], ["61626.69000000", "0.00009000"], ["61627.02000000", "0.00000000"], ["61627.03000000", "0.00000000"], ["61627.48000000", "0.00000000"], ["61627.73000000", "0.00000000"], ["61627.93000000", "0.00000000"], ["61628.00000000", "0.00000000"], ["61628.01000000", "0.00000000"], ["61628.02000000", "0.00000000"], ["61628.41000000", "0.00000000"], ["61628.45000000", "0.00009000"], ["61628.46000000", "0.00000000"], ["61628.59000000", "0.00009000"], ["61629.32000000", "0.00000000"], ["61629.62000000", "0.00009000"], ["61629.64000000", "0.15000000"], ["61629.69000000", "0.00000000"], ["61629.70000000", "2.98194000"], ["61629.71000000", "0.58624000"], ["61629.72000000", "0.00000000"], ["61629.73000000", "0.00000000"], ["61629.97000000", "0.12697000"], ["61629.98000000", "0.00027000"], ["61630.00000000", "0.02821000"], ["61630.16000000", "0.00010000"], ["61630.17000000", "0.00400000"], ["61630.80000000", "0.00009000"], ["61630.82000000", "0.58470000"], ["61630.87000000", "0.04235000"], ["61631.45000000", "0.81223000"], ["61631.46000000", "0.12801000"], ["61631.61000000", "0.00009000"], ["61631.69000000", "0.00009000"], ["61631.89000000", "0.00876000"], ["61632.98000000", "0.00000000"], ["61633.94000000", "0.97390000"], ["61633.95000000", "0.00000000"], ["61633.99000000", "0.70815000"], ["61634.00000000", "0.02433000"], ["61634.34000000", "0.00000000"], ["61636.05000000", "0.00400000"], ["61636.16000000", "0.00000000"], ["61636.32000000", "0.00010000"], ["61639.41000000", "0.00010000"], ["61640.17000000", "0.00000000"], ["61641.67000000", "0.00000000"], ["61642.03000000", "0.60500000"], ["61642.45000000", "0.02582000"], ["61642.49000000", "0.00034000"], ["61643.55000000", "0.00000000"], ["61644.41000000", "0.24750000"], ["61645.57000000", "0.00010000"], ["61645.66000000", "1.60755000"], ["61647.19000000", "0.00000000"], ["61647.49000000", "0.00000000"], ["61647.58000000", "0.00000000"], ["61648.65000000", "0.00010000"], ["61650.29000000", "1.21924000"], ["61650.30000000", "0.00000000"], ["61650.57000000", "0.00000000"], ["61650.68000000", "0.00000000"], ["61651.73000000", "0.00010000"], ["61653.65000000", "0.00000000"], ["61654.81000000", "0.00010000"], ["61654.95000000", "0.00000000"], ["61655.00000000", "0.00000000"], ["61655.99000000", "0.00000000"], ["61656.73000000", "0.00000000"], ["61657.95000000", "0.00000000"], ["61658.92000000", "0.00000000"], ["61659.81000000", "0.00000000"], ["61662.90000000", "0.00000000"], ["61667.99000000", "0.03417000"], ["61670.83000000", "0.00405000"], ["61678.77000000", "0.00000000"], ["61680.79000000", "0.00000000"], ["61685.62000000", "0.00010000"], ["61694.78000000", "0.00000000"], ["61695.99000000", "0.80362000"], ["61716.41000000", "0.00000000"], ["61718.08000000", "0.00026000"], ["61739.90000000", "0.00260000"], ["61744.22000000", "0.00000000"], ["61744.79000000", "0.00000000"], ["61747.25000000", "0.00010000"], ["61756.42000000", "0.00000000"], ["61790.32000000", "0.00000000"], ["61808.87000000", "0.00010000"], ["61818.05000000", "0.00000000"], ["61870.50000000", "0.00010000"], ["61879.68000000", "0.00000000"], ["61932.12000000", "0.00010000"], ["61933.04000000", "0.00000000"], ["61941.32000000", "0.00000000"], ["61993.74000000", "0.00010000"], ["62002.95000000", "0.00000000"], ["62055.37000000", "0.00010000"], ["62064.58000000", "0.00000000"], ["62116.99000000", "0.00010000"], ["62126.22000000", "0.00000000"], ["62234.51000000", "0.14935000"]]}
{"type": "depth", "ts": 1783008088614, "U": 96863150172, "u": 96863150761, "bids": [["61623.99000000", "0.00000000"], ["61623.98000000", "0.00000000"], ["61623.97000000", "0.00000000"], ["61623.83000000", "0.00000000"], ["61623.82000000", "0.00000000"], ["61622.55000000", "0.00000000"], ["61622.54000000", "0.00000000"], ["61622.29000000", "0.00000000"], ["61622.06000000", "0.00000000"], ["61622.05000000", "0.00000000"], ["61622.01000000", "0.00000000"], ["61622.00000000", "0.01474000"], ["61621.99000000", "0.00072000"], ["61621.85000000", "0.00000000"], ["61621.84000000", "0.00000000"], ["61621.41000000", "0.00000000"], ["61621.40000000", "0.00018000"], ["61621.06000000", "0.00000000"], ["61620.89000000", "0.00000000"], ["61620.88000000", "0.00000000"], ["61620.87000000", "0.00000000"], ["61620.86000000", "0.00000000"], ["61620.82000000", "0.00000000"], ["61620.59000000", "0.00000000"], ["61620.05000000", "0.00000000"], ["61620.01000000", "0.00009000"], ["61620.00000000", "0.02418000"], ["61619.85000000", "0.00000000"], ["61619.84000000", "0.00954000"], ["61619.53000000", "0.00000000"], ["61619.52000000", "0.00000000"], ["61618.91000000", "0.04709000"], ["61618.64000000", "0.00000000"], ["61618.63000000", "0.01018000"], ["61618.58000000", "0.00000000"], ["61618.57000000", "0.01018000"], ["61618.32000000", "0.00000000"], ["61618.29000000", "0.00000000"], ["61618.18000000", "0.00009000"], ["61618.17000000", "0.00000000"], ["61618.02000000", "0.00000000"], ["61618.01000000", "0.01027000"], ["61618.00000000", "0.02418000"], ["61617.95000000", "0.01018000"], ["61617.84000000", "0.00009000"], ["61617.83000000", "0.27880000"], ["61617.82000000", "0.01009000"], ["61617.56000000", "0.03035000"], ["61617.55000000", "0.00488000"], ["61617.54000000", "0.00000000"], ["61617.53000000", "0.00000000"], ["61617.52000000", "0.00000000"], ["61617.51000000", "0.00000000"], ["61615.84000000", "0.00010000"], ["61615.02000000", "0.09090000"], ["61615.01000000", "0.45906000"], ["61614.97000000", "0.00000000"], ["61614.37000000", "0.02191000"], ["61613.90000000", "0.00000000"], ["61613.55000000", "0.00153000"], ["61613.51000000", "0.08340000"], ["61613.18000000", "0.00000000"], ["61613.03000000", "0.00000000"], ["61612.80000000", "0.00047000"], ["61612.39000000", "0.00000000"], ["61612.26000000", "0.00000000"], ["61612.04000000", "0.00009000"], ["61611.80000000", "0.96966000"], ["61611.78000000", "0.00000000"], ["61611.72000000", "0.00000000"], ["61611.66000000", "0.00300000"], ["61611.62000000", "0.00000000"], ["61611.15000000", "0.00400000"], ["61610.76000000", "0.00000000"], ["61610.53000000", "0.04000000"], ["61610.35000000", "0.00000000"], ["61610.24000000", "0.08756000"], ["61609.11000000", "0.00009000"], ["61608.76000000", "0.02000000"], ["61608.70000000", "0.08893000"], ["61608.63000000", "0.08000000"], ["61608.24000000", "1.16509000"], ["61608.23000000", "0.00000000"], ["61608.22000000", "0.00000000"], ["61607.70000000", "0.00000000"], ["61607.39000000", "0.00000000"], ["61604.98000000", "0.00400000"], ["61604.65000000", "0.60921000"], ["61604.32000000", "0.19910000"], ["61603.50000000", "0.00000000"], ["61603.33000000", "0.00000000"], ["61603.16000000", "0.56509000"], ["61601.55000000", "0.00000000"], ["61601.36000000", "0.00324000"], ["61600.83000000", "0.00000000"], ["61597.75000000", "0.00400000"], ["61595.09000000", "0.01624000"], ["61594.86000000", "0.00060000"], ["61594.59000000", "0.00488000"], ["61593.71000000", "0.00000000"], ["61593.05000000", "0.00009000"], ["61593.00000000", "0.00000000"], ["61591.24000000", "0.00012000"], ["61591.00000000", "0.01000000"], ["61590.90000000", "0.00000000"], ["61589.78000000", "0.00189000"], ["61585.67000000", "0.00009000"], ["61582.74000000", "0.00009000"], ["61580.48000000", "0.00000000"], ["61575.36000000", "0.00409000"], ["61572.72000000", "0.00400000"], ["61566.49000000", "0.00000000"], ["61564.01000000", "0.00095000"], ["61563.49000000", "0.00000000"], ["61562.55000000", "0.00000000"], ["61561.87000000", "0.00000000"], ["61560.47000000", "0.00000000"], ["61553.66000000", "0.97477000"], ["61552.83000000", "0.00530000"], ["61551.02000000", "0.00112000"], ["61549.81000000", "0.01702000"], ["61548.02000000", "0.00000000"], ["61548.01000000", "0.00000000"], ["61507.04000000", "0.02027000"], ["61502.84000000", "0.00038000"], ["61463.38000000", "0.00009000"], ["61460.30000000", "0.00009000"], ["61457.22000000", "0.00009000"], ["61454.14000000", "0.00009000"], ["61374.39000000", "0.00000000"], ["55461.60000000", "0.00000000"], ["55459.80000000", "0.00040000"], ["49299.19000000", "0.00000000"]], "asks": [["61622.01000000", "2.97919000"], ["61622.02000000", "0.00035000"], ["61622.03000000", "0.00017000"], ["61622.05000000", "0.00000000"], ["61622.06000000", "0.00018000"], ["61622.55000000", "0.00009000"], ["61622.56000000", "0.00000000"], ["61623.32000000", "0.00000000"], ["61623.76000000", "0.00009000"], ["61623.82000000", "0.00000000"], ["61623.83000000", "0.00009000"], ["61623.84000000", "0.00000000"], ["61623.91000000", "0.12372000"], ["61623.98000000", "0.06136000"], ["61623.99000000", "1.41454000"], ["61624.00000000", "0.37372000"], ["61624.01000000", "0.00000000"], ["61624.02000000", "0.00000000"], ["61624.47000000", "0.00000000"], ["61624.48000000", "0.15410000"], ["61624.79000000", "0.00870000"], ["61624.84000000", "0.00009000"], ["61625.16000000", "0.05737000"], ["61625.17000000", "0.04235000"], ["61625.52000000", "0.00400000"], ["61625.55000000", "0.00009000"], ["61625.81000000", "0.00034000"], ["61626.68000000", "0.14923000"], ["61627.88000000", "0.00879000"], ["61628.16000000", "0.00400000"], ["61628.17000000", "0.00010000"], ["61628.69000000", "0.00013000"], ["61629.63000000", "0.09081000"], ["61629.64000000", "0.15036000"], ["61629.69000000", "0.56209000"], ["61629.70000000", "1.66207000"], ["61629.71000000", "0.48850000"], ["61629.98000000", "0.00009000"], ["61629.99000000", "0.05142000"], ["61630.00000000", "0.00913000"], ["61630.16000000", "0.00000000"], ["61630.17000000", "0.00700000"], ["61630.66000000", "0.01009000"], ["61630.81000000", "0.47237000"], ["61630.82000000", "0.58479000"], ["61630.87000000", "0.04217000"], ["61631.32000000", "0.00152000"], ["61631.40000000", "0.00009000"], ["61631.46000000", "0.00000000"], ["61632.96000000", "0.00010000"], ["61633.27000000", "0.00190000"], ["61633.33000000", "0.00000000"], ["61633.86000000", "0.58467000"], ["61633.99000000", "0.65706000"], ["61634.00000000", "0.02397000"], ["61634.34000000", "0.08753000"], ["61634.95000000", "0.00012000"], ["61635.14000000", "0.00000000"], ["61635.86000000", "0.00009000"], ["61635.88000000", "0.08889000"], ["61636.29000000", "0.00000000"], ["61637.28000000", "0.00000000"], ["61637.29000000", "0.00000000"], ["61637.88000000", "0.00000000"], ["61638.26000000", "0.00000000"], ["61638.87000000", "0.00060000"], ["61639.58000000", "0.00230000"], ["61640.24000000", "0.00000000"], ["61641.34000000", "0.00009000"], ["61642.21000000", "0.00000000"], ["61642.33000000", "0.00000000"], ["61642.89000000", "0.00000000"], ["61646.12000000", "0.00000000"], ["61647.03000000", "0.00000000"], ["61647.18000000", "0.63083000"], ["61650.29000000", "0.85059000"], ["61651.11000000", "0.03180000"], ["61651.29000000", "0.64144000"], ["61651.40000000", "0.00000000"], ["61653.00000000", "0.01000000"], ["61653.06000000", "0.00000000"], ["61653.18000000", "0.01100000"], ["61653.79000000", "0.01000000"], ["61654.89000000", "0.00430000"], ["61655.08000000", "0.00000000"], ["61655.14000000", "0.00424000"], ["61655.35000000", "0.00000000"], ["61658.26000000", "0.00000000"], ["61660.99000000", "0.00379000"], ["61661.00000000", "0.00000000"], ["61662.79000000", "0.01706000"], ["61663.11000000", "0.00000000"], ["61663.18000000", "0.01100000"], ["61663.34000000", "0.00000000"], ["61664.18000000", "0.24862000"], ["61667.15000000", "0.00000000"], ["61667.38000000", "0.00544000"], ["61669.72000000", "0.00000000"], ["61673.10000000", "0.00000000"], ["61673.19000000", "0.97477000"], ["61675.44000000", "0.00000000"], ["61676.67000000", "0.01300000"], ["61679.91000000", "0.00000000"], ["61683.26000000", "0.00000000"], ["61694.42000000", "0.00000000"], ["61695.60000000", "0.01000000"], ["61702.89000000", "0.00000000"], ["61715.76000000", "0.83496000"], ["61784.15000000", "0.00000000"], ["61803.62000000", "0.00000000"], ["61805.31000000", "0.00000000"], ["61806.85000000", "0.00000000"], ["61808.71000000", "0.00000000"], ["62234.51000000", "0.00012000"]]}
{"type": "depth", "ts": 1783008088714, "U": 96863150762, "u": 96863150971, "bids": [["61622.00000000", "0.01498000"], ["61621.40000000", "0.00000000"], ["61620.80000000", "0.00000000"], ["61620.12000000", "0.00000000"], ["61619.85000000", "0.00009000"], ["61619.84000000", "0.00954000"], ["61618.92000000", "0.00009000"], ["61618.91000000", "0.04727000"], ["61618.63000000", "0.00018000"], ["61618.57000000", "0.00018000"], ["61618.50000000", "0.00000000"], ["61618.18000000", "0.00000000"], ["61618.01000000", "0.00027000"], ["61617.95000000", "0.00018000"], ["61617.88000000", "0.00000000"], ["61617.85000000", "0.00000000"], ["61617.84000000", "0.00009000"], ["61617.83000000", "0.00000000"], ["61617.82000000", "0.00000000"], ["61617.57000000", "0.00000000"], ["61617.56000000", "0.00000000"], ["61617.55000000", "0.00000000"], ["61617.50000000", "0.01122000"], ["61617.26000000", "0.00000000"], ["61616.89000000", "0.00000000"], ["61616.81000000", "0.00009000"], ["61616.80000000", "0.00000000"], ["61616.01000000", "0.00009000"], ["61615.55000000", "0.00000000"], ["61615.51000000", "0.00009000"], ["61615.50000000", "0.00000000"], ["61615.43000000", "0.00000000"], ["61615.05000000", "0.00000000"], ["61615.03000000", "0.00009000"], ["61615.02000000", "0.00009000"], ["61615.01000000", "0.45418000"], ["61614.81000000", "0.00000000"], ["61614.74000000", "0.00000000"], ["61613.47000000", "1.36330000"], ["61613.46000000", "0.00000000"], ["61613.43000000", "0.00000000"], ["61612.04000000", "0.00000000"], ["61611.81000000", "2.19474000"], ["61611.80000000", "0.00009000"], ["61611.79000000", "0.00000000"], ["61611.61000000", "0.00243000"], ["61611.15000000", "0.00000000"], ["61610.92000000", "1.36330000"], ["61610.91000000", "0.00000000"], ["61610.66000000", "0.00048000"], ["61610.56000000", "0.00000000"], ["61610.53000000", "0.00000000"], ["61610.23000000", "0.00000000"], ["61609.75000000", "0.00000000"], ["61609.68000000", "0.00000000"], ["61609.49000000", "0.00000000"], ["61609.47000000", "0.00998000"], ["61609.11000000", "0.00000000"], ["61608.76000000", "0.00000000"], ["61608.63000000", "0.00192000"], ["61608.59000000", "0.00400000"], ["61608.53000000", "0.00000000"], ["61608.29000000", "0.00000000"], ["61608.27000000", "0.00875000"], ["61608.24000000", "0.83140000"], ["61606.93000000", "0.00000000"], ["61606.17000000", "0.00000000"], ["61605.95000000", "0.02000000"], ["61605.73000000", "0.15000000"], ["61604.98000000", "0.00000000"], ["61603.32000000", "0.00995000"], ["61602.42000000", "0.00410000"], ["61601.05000000", "0.36306000"], ["61600.92000000", "0.53935000"], ["61597.15000000", "0.00982000"], ["61596.32000000", "0.00000000"], ["61595.09000000", "0.00000000"], ["61590.98000000", "1.37339000"], ["61585.96000000", "0.00488000"], ["61584.81000000", "0.01008000"], ["61583.45000000", "0.58515000"], ["61575.74000000", "0.00000000"], ["61575.06000000", "0.00000000"], ["61573.39000000", "0.13445000"], ["61561.68000000", "0.00009000"], ["61544.71000000", "0.00000000"], ["61497.82000000", "0.00000000"], ["61491.26000000", "0.00130000"], ["61491.25000000", "0.00130000"], ["55459.80000000", "0.00060000"]], "asks": [["61622.01000000", "3.01480000"], ["61622.06000000", "0.00000000"], ["61623.31000000", "0.09030000"], ["61623.61000000", "0.16227000"], ["61623.91000000", "0.00018000"], ["61623.97000000", "0.09030000"], ["61623.98000000", "0.46068000"], ["61623.99000000", "1.41472000"], ["61624.00000000", "0.10972000"], ["61624.48000000", "0.15410000"], ["61624.79000000", "0.00888000"], ["61624.90000000", "0.04046000"], ["61625.17000000", "0.04217000"], ["61626.68000000", "0.14941000"], ["61628.18000000", "0.24750000"], ["61628.51000000", "0.00000000"], ["61629.61000000", "0.91985000"], ["61629.62000000", "0.97399000"], ["61629.63000000", "0.00000000"], ["61629.64000000", "0.15009000"], ["61629.69000000", "0.00000000"], ["61629.70000000", "1.41439000"], ["61629.71000000", "0.24082000"], ["61634.33000000", "0.00326000"], ["61636.08000000", "0.00000000"], ["61657.56000000", "0.00000000"], ["61671.67000000", "0.97390000"], ["61684.02000000", "0.18136000"], ["61695.60000000", "0.00000000"], ["61701.98000000", "0.70659000"], ["61721.31000000", "0.00024000"], ["61725.61000000", "0.00040000"], ["61733.93000000", "0.00260000"], ["61739.90000000", "0.00000000"], ["61744.21000000", "0.00000000"], ["61784.15000000", "0.24750000"]]}
{"type": "depth", "ts": 1783008088814, "U": 96863150972, "u": 96863151114, "bids": [["61622.00000000", "0.90905000"], ["61620.76000000", "0.00000000"], ["61618.91000000", "0.04727000"], ["61618.63000000", "0.00000000"], ["61618.57000000", "0.00000000"], ["61618.32000000", "0.04577000"], ["61618.01000000", "0.00009000"], ["61618.00000000", "0.02418000"], ["61617.95000000", "0.00000000"], ["61617.84000000", "0.00000000"], ["61617.56000000", "0.00009000"], ["61617.55000000", "0.00000000"], ["61617.51000000", "0.00000000"], ["61617.50000000", "0.00018000"], ["61616.97000000", "0.00034000"], ["61616.82000000", "0.00009000"], ["61616.81000000", "0.06316000"], ["61616.80000000", "0.09030000"], ["61616.00000000", "0.02418000"], ["61615.75000000", "0.00000000"], ["61615.51000000", "0.00009000"], ["61615.50000000", "0.09039000"], ["61615.40000000", "0.00526000"], ["61615.03000000", "0.00009000"], ["61615.02000000", "0.09518000"], ["61615.01000000", "0.45436000"], ["61613.52000000", "0.00000000"], ["61613.48000000", "0.00000000"], ["61611.82000000", "1.20433000"], ["61611.81000000", "0.97390000"], ["61609.47000000", "0.00000000"], ["61609.11000000", "0.00009000"], ["61608.34000000", "0.00981000"], ["61608.27000000", "0.00000000"], ["61607.89000000", "0.08771000"], ["61607.31000000", "0.00909000"], ["61606.16000000", "1.26411000"], ["61597.95000000", "0.00000000"], ["61597.86000000", "0.00000000"], ["61597.78000000", "0.00000000"], ["61597.77000000", "0.01498000"], ["61583.83000000", "0.00000000"], ["61579.81000000", "0.00009000"], ["61579.66000000", "1.60927000"], ["61578.01000000", "0.71162000"], ["61573.39000000", "0.00000000"], ["61567.44000000", "0.00400000"], ["61567.04000000", "1.50217000"], ["61565.26000000", "0.00000000"], ["61559.19000000", "1.60980000"], ["61546.71000000", "0.19839000"], ["61526.02000000", "1.13564000"], ["61525.01000000", "3.24106000"], ["61409.41000000", "0.00000000"], ["61383.52000000", "0.02542000"], ["60697.67000000", "0.00030000"], ["55459.80000000", "0.00100000"]], "asks": [["61622.01000000", "3.01489000"], ["61622.88000000", "0.00400000"], ["61623.31000000", "0.00018000"], ["61623.61000000", "0.00018000"], ["61623.90000000", "0.00000000"], ["61623.91000000", "0.00000000"], ["61623.97000000", "0.00000000"], ["61624.79000000", "0.00870000"], ["61624.91000000", "0.08712000"], ["61626.68000000", "0.14959000"], ["61627.88000000", "0.59352000"], ["61630.82000000", "0.58470000"], ["61642.03000000", "0.00000000"], ["61643.99000000", "0.00000000"], ["61647.38000000", "0.03133000"], ["61647.73000000", "0.00162000"], ["61648.95000000", "1.50017000"], ["61650.96000000", "0.00649000"], ["61651.11000000", "0.00000000"], ["61655.65000000", "0.96522000"], ["61664.20000000", "0.00000000"], ["61694.98000000", "0.00034000"], ["62554.16000000", "0.00000000"]]}
{"type": "depth", "ts": 1783008088914, "U": 96863151115, "u": 96863151204, "bids": [["61622.00000000", "0.90915000"], ["61621.99000000", "0.00054000"], ["61619.96000000", "0.00009000"], ["61619.95000000", "0.08878000"], ["61619.85000000", "0.00000000"], ["61618.91000000", "0.04727000"], ["61618.33000000", "0.00009000"], ["61618.32000000", "0.04595000"], ["61618.00000000", "0.02418000"], ["61617.56000000", "0.00000000"], ["61617.50000000", "0.00000000"], ["61616.81000000", "0.34588000"], ["61616.80000000", "0.09048000"], ["61616.01000000", "0.00000000"], ["61616.00000000", "0.02400000"], ["61615.53000000", "0.00009000"], ["61615.52000000", "0.08556000"], ["61615.51000000", "0.97390000"], ["61615.50000000", "0.00009000"], ["61615.40000000", "0.00508000"], ["61615.03000000", "0.00000000"], ["61615.02000000", "0.00488000"], ["61615.01000000", "0.45418000"], ["61614.04000000", "0.00000000"], ["61613.51000000", "0.00000000"], ["61612.04000000", "0.00009000"], ["61607.89000000", "0.00000000"], ["61597.77000000", "0.00000000"], ["61597.12000000", "0.09750000"], ["61579.81000000", "0.00000000"], ["61570.08000000", "0.00400000"], ["61567.44000000", "0.00000000"], ["55459.80000000", "0.00140000"]], "asks": [["61622.01000000", "3.01462000"], ["61623.31000000", "0.00000000"], ["61623.47000000", "0.00009000"], ["61623.61000000", "0.00000000"], ["61623.98000000", "0.48662000"], ["61624.48000000", "0.15419000"], ["61624.79000000", "0.00888000"], ["61624.90000000", "0.04064000"], ["61624.91000000", "0.08730000"], ["61625.16000000", "0.05755000"], ["61626.68000000", "0.14959000"], ["61627.87000000", "1.04733000"], ["61629.61000000", "0.00000000"], ["61632.09000000", "0.00000000"], ["61633.88000000", "0.00009000"], ["61650.96000000", "0.00000000"], ["61659.11000000", "0.32591000"], ["61683.01000000", "0.00000000"]]}
{"type": "depth", "ts": 1783008089014, "U": 96863151205, "u": 96863151505, "bids": [["61622.00000000", "0.00000000"], ["61621.99000000", "0.00000000"], ["61621.66000000", "0.00000000"], ["61621.56000000", "0.00000000"], ["61620.01000000", "0.00000000"], ["61620.00000000", "0.97192000"], ["61619.99000000", "0.00045000"], ["61619.96000000", "0.00000000"], ["61619.95000000", "0.00027000"], ["61619.85000000", "0.00009000"], ["61619.18000000", "0.00000000"], ["61618.33000000", "0.00000000"], ["61618.32000000", "0.00018000"], ["61617.67000000", "0.00000000"], ["61617.55000000", "0.00000000"], ["61616.82000000", "0.00000000"], ["61616.81000000", "0.00027000"], ["61616.80000000", "0.00036000"], ["61616.29000000", "0.00000000"], ["61616.01000000", "0.00009000"], ["61616.00000000", "0.02418000"], ["61615.84000000", "0.00000000"], ["61615.72000000", "0.03060000"], ["61615.53000000", "0.00000000"], ["61615.52000000", "0.00000000"], ["61615.51000000", "0.00009000"], ["61615.02000000", "0.00497000"], ["61613.84000000", "0.00010000"], ["61613.50000000", "0.09040000"], ["61613.48000000", "0.00009000"], ["61611.67000000", "0.00000000"], ["61611.50000000", "0.00000000"], ["61610.23000000", "0.08771000"], ["61609.96000000", "0.00009000"], ["61609.35000000", "0.00000000"], ["61608.58000000", "0.00000000"], ["61608.34000000", "0.00000000"], ["61608.28000000", "0.01012000"], ["61607.68000000", "0.00019000"], ["61607.31000000", "0.00000000"], ["61607.23000000", "0.00871000"], ["61606.35000000", "0.00649000"], ["61605.50000000", "0.00000000"], ["61604.60000000", "0.00010000"], ["61602.42000000", "0.00400000"], ["61601.65000000", "0.00497000"], ["61601.51000000", "0.00026000"], ["61599.34000000", "0.00000000"], ["61598.43000000", "0.00010000"], ["61597.12000000", "0.00000000"], ["61597.07000000", "0.00000000"], ["61597.06000000", "0.09750000"], ["61596.26000000", "0.00000000"], ["61595.67000000", "0.58503000"], ["61595.35000000", "0.00010000"], ["61593.18000000", "0.00000000"], ["61593.01000000", "0.00000000"], ["61592.27000000", "0.00010000"], ["61592.20000000", "0.58507000"], ["61591.00000000", "0.00000000"], ["61590.10000000", "0.00009000"], ["61589.19000000", "0.00010000"], ["61589.00000000", "0.01000000"], ["61583.03000000", "0.00016000"], ["61574.52000000", "0.00000000"], ["61572.27000000", "0.13559000"], ["61564.54000000", "0.00016000"], ["61556.03000000", "0.00000000"], ["61546.06000000", "0.00016000"], ["61537.55000000", "0.00045000"], ["61527.57000000", "0.00016000"], ["61454.94000000", "0.00000000"], ["61452.14000000", "0.00009000"], ["61449.06000000", "0.00009000"], ["60697.67000000", "0.00000000"], ["55459.80000000", "0.00000000"], ["55458.00000000", "0.00020000"], ["49298.00000000", "0.00321000"], ["49296.00000000", "0.00547000"]], "asks": [["61620.01000000", "2.94640000"], ["61620.02000000", "0.00035000"], ["61620.03000000", "0.00017000"], ["61620.83000000", "0.00009000"], ["61621.41000000", "0.00000000"], ["61621.57000000", "0.00000000"], ["61621.67000000", "0.00000000"], ["61621.99000000", "1.14717000"], ["61622.00000000", "0.20465000"], ["61622.01000000", "0.30263000"], ["61622.02000000", "0.00000000"], ["61622.03000000", "0.00000000"], ["61622.98000000", "0.09117000"], ["61623.90000000", "0.00000000"], ["61623.98000000", "0.00027000"], ["61624.91000000", "0.00018000"], ["61625.16000000", "0.05737000"], ["61626.17000000", "0.00010000"], ["61627.70000000", "0.00009000"], ["61628.17000000", "0.00000000"], ["61629.99000000", "0.00042000"], ["61631.69000000", "0.00000000"], ["61632.33000000", "0.00010000"], ["61634.25000000", "0.00000000"], ["61634.33000000", "0.00000000"], ["61635.42000000", "0.00010000"], ["61636.32000000", "0.00000000"], ["61638.50000000", "0.00026000"], ["61638.64000000", "0.00009000"], ["61639.41000000", "0.00000000"], ["61641.58000000", "0.00010000"], ["61642.24000000", "0.00000000"], ["61642.49000000", "0.00024000"], ["61644.66000000", "0.00010000"], ["61645.57000000", "0.00000000"], ["61646.34000000", "0.00000000"], ["61647.74000000", "1.36340000"], ["61648.49000000", "0.00000000"], ["61648.65000000", "0.00000000"], ["61650.82000000", "0.00010000"], ["61651.73000000", "0.00000000"], ["61652.05000000", "0.00000000"], ["61654.81000000", "0.00000000"], ["61656.98000000", "0.00016000"], ["61666.98000000", "0.00000000"], ["61675.47000000", "0.00016000"], ["61685.47000000", "0.00000000"], ["61693.95000000", "0.00016000"], ["61703.96000000", "0.00000000"], ["61712.44000000", "0.00016000"], ["61716.22000000", "0.00000000"], ["61722.45000000", "0.00000000"], ["61803.26000000", "0.00009000"]]}
{"type": "depth", "ts": 1783008089114, "U": 96863151506, "u": 96863151606, "bids": [["61620.00000000", "0.97304000"], ["61619.99000000", "0.00072000"], ["61619.95000000", "0.00009000"], ["61618.91000000", "0.04727000"], ["61618.32000000", "0.00000000"], ["61618.00000000", "0.02418000"], ["61616.81000000", "0.00009000"], ["61616.80000000", "0.00009000"], ["61616.25000000", "0.00009000"], ["61616.24000000", "0.04592000"], ["61616.00000000", "0.02418000"], ["61615.73000000", "0.00000000"], ["61615.72000000", "0.00018000"], ["61615.40000000", "0.00526000"], ["61615.01000000", "0.45445000"], ["61614.37000000", "0.02209000"], ["61613.51000000", "0.00009000"], ["61597.06000000", "0.00000000"], ["61596.60000000", "0.09750000"], ["61515.16000000", "0.00032000"], ["61449.06000000", "0.00000000"], ["55458.00000000", "0.00060000"], ["49298.00000000", "0.00121000"]], "asks": [["61620.01000000", "2.99546000"], ["61621.99000000", "0.59085000"], ["61622.00000000", "0.20483000"], ["61622.01000000", "0.27613000"], ["61623.98000000", "0.00009000"], ["61624.48000000", "0.15410000"], ["61624.90000000", "0.04046000"], ["61624.91000000", "0.00000000"], ["61629.99000000", "0.00033000"], ["61632.33000000", "0.00338000"], ["61634.20000000", "0.00000000"], ["61651.00000000", "0.01000000"], ["61653.00000000", "0.00000000"], ["61663.92000000", "0.00000000"], ["61803.26000000", "0.00000000"]]}
{"type": "depth", "ts": 1783008089214, "U": 96863151607, "u": 96863151888, "bids": [["61620.00000000", "0.00000000"], ["61619.99000000", "0.00000000"], ["61619.95000000", "0.00000000"], ["61619.85000000", "0.00000000"], ["61619.84000000", "0.00000000"], ["61619.60000000", "0.00000000"], ["61619.57000000", "0.21839000"], ["61619.56000000", "0.00089000"], ["61619.55000000", "0.00017000"], ["61618.00000000", "0.02418000"], ["61617.24000000", "0.00009000"], ["61617.23000000", "0.08064000"], ["61616.25000000", "0.00000000"], ["61616.24000000", "0.00018000"], ["61616.00000000", "0.02418000"], ["61615.72000000", "0.00000000"], ["61615.26000000", "0.00009000"], ["61615.25000000", "0.03009000"], ["61615.04000000", "0.00009000"], ["61615.03000000", "0.08683000"], ["61615.02000000", "0.00497000"], ["61614.00000000", "0.02418000"], ["61612.04000000", "0.00000000"], ["61611.83000000", "0.00009000"], ["61611.82000000", "1.20433000"], ["61610.57000000", "0.01000000"], ["61610.51000000", "0.01000000"], ["61610.24000000", "0.00000000"], ["61610.23000000", "0.00000000"], ["61609.95000000", "0.01000000"], ["61609.90000000", "0.01000000"], ["61609.11000000", "0.00000000"], ["61608.70000000", "0.00000000"], ["61607.50000000", "0.01000000"], ["61607.23000000", "0.00000000"], ["61606.82000000", "0.01000000"], ["61606.35000000", "0.00000000"], ["61598.42000000", "0.00000000"], ["61592.14000000", "0.64206000"], ["61590.56000000", "0.49703000"], ["61589.94000000", "0.00000000"], ["61589.00000000", "0.00000000"], ["61588.00000000", "0.03400000"], ["61572.27000000", "0.00000000"], ["61568.52000000", "0.01000000"], ["61566.64000000", "0.13465000"], ["61566.48000000", "0.01000000"], ["61566.22000000", "0.01000000"], ["61563.08000000", "0.01000000"], ["61563.02000000", "0.01000000"], ["61562.46000000", "0.01000000"], ["61560.00000000", "0.02419000"], ["61525.32000000", "0.00000000"], ["61517.64000000", "0.00016000"], ["61507.48000000", "0.00024000"], ["61491.26000000", "0.00000000"], ["61491.25000000", "0.00000000"], ["61490.58000000", "0.00260000"], ["61484.21000000", "0.00000000"], ["61200.00000000", "1.96394000"], ["60695.70000000", "0.00000000"], ["55458.00000000", "0.00000000"], ["55457.62000000", "0.00020000"], ["49296.00000000", "0.00507000"]], "asks": [["61619.58000000", "3.51688000"], ["61619.59000000", "0.00017000"], ["61619.60000000", "0.00017000"], ["61619.61000000", "0.00018000"], ["61619.85000000", "0.00000000"], ["61619.86000000", "0.00000000"], ["61619.96000000", "0.00000000"], ["61619.99000000", "0.35135000"], ["61620.00000000", "0.05100000"], ["61620.01000000", "0.12594000"], ["61620.02000000", "0.00000000"], ["61620.03000000", "0.00000000"], ["61621.45000000", "0.11605000"], ["61621.67000000", "0.00000000"], ["61621.70000000", "0.00000000"], ["61622.01000000", "0.02854000"], ["61622.98000000", "0.00000000"], ["61624.79000000", "0.00870000"], ["61627.72000000", "0.00009000"], ["61629.62000000", "1.06152000"], ["61629.70000000", "1.36339000"], ["61629.99000000", "0.00024000"], ["61631.16000000", "0.08889000"], ["61631.90000000", "0.00000000"], ["61631.91000000", "0.00000000"], ["61632.33000000", "0.00010000"], ["61633.15000000", "0.00133000"], ["61634.34000000", "0.00000000"], ["61635.88000000", "0.00000000"], ["61638.24000000", "0.00000000"], ["61643.27000000", "0.00000000"], ["61660.13000000", "0.41686000"], ["61671.82000000", "0.00000000"], ["61680.00000000", "0.02418000"], ["61718.08000000", "0.00010000"], ["61721.31000000", "0.00000000"], ["61725.61000000", "0.00000000"], ["61732.73000000", "0.00260000"], ["61733.93000000", "0.00000000"], ["62040.00000000", "0.02343000"]]}
{"type": "depth", "ts": 1783008089314, "U": 96863151889, "u": 96863151965, "bids": [["61619.57000000", "0.17722000"], ["61618.00000000", "0.02418000"], ["61617.23000000", "0.08082000"], ["61616.24000000", "0.00000000"], ["61615.40000000", "0.00526000"], ["61615.25000000", "0.03027000"], ["61615.03000000", "0.08701000"], ["61614.37000000", "0.02191000"], ["61614.00000000", "0.02400000"], ["61609.96000000", "0.01009000"], ["61609.90000000", "0.02000000"], ["61608.28000000", "0.00000000"], ["61607.69000000", "0.00986000"], ["61607.13000000", "0.01000000"], ["61599.02000000", "0.00000000"], ["61597.74000000", "0.01000000"], ["61596.60000000", "0.00000000"], ["61596.53000000", "0.09750000"], ["61570.03000000", "0.00000000"], ["61566.36000000", "0.01000000"], ["61562.46000000", "0.00000000"], ["61553.19000000", "0.01000000"], ["61450.02000000", "0.00162000"], ["61450.01000000", "0.00974000"], ["55457.62000000", "0.00060000"]], "asks": [["61619.58000000", "3.61886000"], ["61619.59000000", "0.00035000"], ["61619.61000000", "0.00000000"], ["61619.99000000", "0.07716000"], ["61620.00000000", "0.05118000"], ["61620.01000000", "0.11944000"], ["61621.45000000", "0.11623000"], ["61622.01000000", "0.02836000"], ["61624.00000000", "0.10954000"], ["61624.48000000", "0.15392000"], ["61631.90000000", "0.00324000"], ["62543.88000000", "0.00067000"]]}
{"type": "depth", "ts": 1783008089414, "U": 96863151966, "u": 96863152246, "bids": [["61619.57000000", "0.00000000"], ["61619.56000000", "0.00000000"], ["61619.55000000", "0.00000000"], ["61618.96000000", "0.00000000"], ["61618.92000000", "0.00000000"], ["61618.91000000", "0.24631000"], ["61618.90000000", "0.00063000"], ["61617.24000000", "0.00000000"], ["61617.23000000", "0.00027000"], ["61616.97000000", "0.00000000"], ["61616.11000000", "0.00009000"], ["61615.50000000", "0.00000000"], ["61615.26000000", "0.00000000"], ["61615.25000000", "0.00018000"], ["61615.19000000", "0.00000000"], ["61615.04000000", "0.00000000"], ["61615.03000000", "0.00018000"], ["61615.02000000", "0.00000000"], ["61615.01000000", "0.00027000"], ["61614.99000000", "0.00000000"], ["61614.39000000", "0.00009000"], ["61614.38000000", "0.46315000"], ["61614.37000000", "0.02209000"], ["61614.13000000", "0.00009000"], ["61614.12000000", "0.02083000"], ["61614.06000000", "0.00000000"], ["61614.01000000", "0.00009000"], ["61613.51000000", "0.00488000"], ["61613.50000000", "0.00009000"], ["61613.49000000", "0.08429000"], ["61613.48000000", "1.36330000"], ["61613.47000000", "0.00000000"], ["61613.30000000", "0.00000000"], ["61612.50000000", "0.00000000"], ["61612.42000000", "0.00009000"], ["61612.41000000", "0.00000000"], ["61612.04000000", "0.00000000"], ["61612.01000000", "0.00000000"], ["61611.84000000", "0.00009000"], ["61611.83000000", "0.62915000"], ["61611.82000000", "0.38956000"], ["61611.81000000", "0.00000000"], ["61611.13000000", "0.00000000"], ["61610.93000000", "1.36330000"], ["61610.92000000", "0.00000000"], ["61609.43000000", "0.00000000"], ["61609.11000000", "0.00009000"], ["61608.59000000", "0.00000000"], ["61608.25000000", "0.00000000"], ["61608.24000000", "0.66627000"], ["61607.69000000", "0.00000000"], ["61606.95000000", "0.00400000"], ["61606.82000000", "0.02000000"], ["61606.71000000", "0.01000000"], ["61606.63000000", "0.00000000"], ["61605.44000000", "0.00000000"], ["61605.28000000", "0.00000000"], ["61600.82000000", "0.00000000"], ["61596.53000000", "0.00000000"], ["61595.79000000", "0.09750000"], ["61595.67000000", "0.00000000"], ["61579.81000000", "0.00009000"], ["61577.87000000", "0.58520000"], ["61577.33000000", "0.00488000"], ["61568.21000000", "0.01034000"], ["61567.44000000", "0.00400000"], ["61566.64000000", "0.00000000"], ["61566.47000000", "0.01000000"], ["61566.36000000", "0.00000000"], ["61565.52000000", "0.00000000"], ["61565.38000000", "0.13734000"], ["61553.66000000", "0.00000000"], ["61477.89000000", "0.00039000"], ["61383.52000000", "0.00000000"], ["55457.62000000", "0.00000000"], ["55457.02000000", "0.00020000"]], "asks": [["61618.92000000", "4.96724000"], ["61618.93000000", "0.00035000"], ["61618.94000000", "0.00017000"], ["61618.97000000", "0.00000000"], ["61619.56000000", "0.10131000"], ["61619.57000000", "0.05100000"], ["61619.58000000", "0.31500000"], ["61619.59000000", "0.00000000"], ["61619.60000000", "0.00009000"], ["61619.99000000", "0.00018000"], ["61620.01000000", "0.09953000"], ["61620.24000000", "0.00400000"], ["61620.72000000", "0.16228000"], ["61621.22000000", "0.00000000"], ["61621.45000000", "0.00018000"], ["61622.44000000", "0.03000000"], ["61623.99000000", "1.36354000"], ["61624.00000000", "0.10945000"], ["61629.64000000", "0.12000000"], ["61629.71000000", "0.24055000"], ["61629.98000000", "0.00000000"], ["61631.77000000", "0.00000000"], ["61631.90000000", "0.00000000"], ["61633.28000000", "0.00009000"], ["61650.00000000", "0.03433000"], ["61650.13000000", "0.00000000"], ["61651.00000000", "0.00000000"], ["61661.25000000", "0.01300000"], ["61710.38000000", "0.00016000"], ["61740.68000000", "0.00000000"]]}
{"type": "depth", "ts": 1783008089514, "U": 96863152247, "u": 96863152380, "bids": [["61618.91000000", "0.98354000"], ["61618.90000000", "0.00054000"], ["61618.00000000", "0.02418000"], ["61617.94000000", "0.00009000"], ["61617.23000000", "0.00000000"], ["61615.40000000", "0.00526000"], ["61615.25000000", "0.00000000"], ["61615.03000000", "0.00000000"], ["61615.01000000", "0.00009000"], ["61614.91000000", "0.00009000"], ["61614.90000000", "0.04186000"], ["61614.38000000", "0.46333000"], ["61614.37000000", "0.02209000"], ["61614.13000000", "0.00000000"], ["61614.12000000", "0.00018000"], ["61614.01000000", "0.00000000"], ["61614.00000000", "0.02418000"], ["61613.50000000", "0.00009000"], ["61613.49000000", "0.00027000"], ["61612.42000000", "0.00000000"], ["61611.86000000", "0.00009000"], ["61611.85000000", "0.99095000"], ["61611.84000000", "0.97390000"], ["61611.83000000", "0.00009000"], ["61609.43000000", "0.08771000"], ["61605.48000000", "0.01200000"], ["61604.34000000", "0.00649000"], ["61600.88000000", "0.00000000"], ["61599.06000000", "0.00000000"], ["61598.39000000", "0.50993000"], ["61597.83000000", "0.00000000"], ["61597.74000000", "0.00000000"], ["61595.79000000", "0.00000000"], ["61595.65000000", "0.00000000"], ["61595.36000000", "0.00000000"], ["61595.33000000", "0.09750000"], ["61581.20000000", "0.57862000"], ["61579.81000000", "0.00000000"], ["61568.21000000", "0.00034000"], ["61566.49000000", "0.01200000"], ["61565.38000000", "0.00000000"], ["61563.63000000", "0.00000000"], ["61563.51000000", "0.13738000"], ["61559.68000000", "0.55297000"], ["61553.19000000", "0.00000000"], ["61529.02000000", "0.00009000"], ["61528.01000000", "0.00000000"], ["61526.21000000", "0.00000000"], ["61379.33000000", "0.02542000"], ["55457.02000000", "0.00060000"], ["49295.13000000", "0.00000000"]], "asks": [["61618.92000000", "4.97392000"], ["61619.56000000", "0.06133000"], ["61619.57000000", "0.05118000"], ["61619.58000000", "0.30807000"], ["61619.99000000", "0.00000000"], ["61620.01000000", "0.09926000"], ["61620.72000000", "0.00000000"], ["61621.45000000", "0.00000000"], ["61621.55000000", "0.09800000"], ["61623.47000000", "0.00000000"], ["61625.57000000", "0.00009000"], ["61631.24000000", "0.00326000"], ["61645.20000000", "0.00000000"], ["61647.18000000", "1.10329000"], ["61670.84000000", "1.27494000"], ["61711.08000000", "0.00000000"], ["63303.68000000", "0.00013000"]]}
{"type": "depth", "ts": 1783008089614, "U": 96863152381, "u": 96863152434, "bids": [["61618.91000000", "0.98417000"], ["61615.40000000", "0.00526000"], ["61614.90000000", "0.04204000"], ["61614.57000000", "0.00013000"], ["61614.37000000", "0.02209000"], ["61614.12000000", "0.00000000"], ["61614.00000000", "0.02418000"], ["61613.49000000", "0.00009000"], ["61613.48000000", "1.36348000"], ["61606.58000000", "0.00300000"], ["61606.57000000", "0.01021000"], ["61606.11000000", "0.01000000"], ["61606.09000000", "0.08757000"], ["61605.49000000", "0.01300000"], ["61605.35000000", "0.00009000"], ["61605.21000000", "0.00889000"], ["61604.55000000", "0.08893000"], ["61595.33000000", "0.00000000"], ["61595.32000000", "0.00000000"], ["61595.31000000", "0.09750000"], ["61593.34000000", "0.01624000"], ["61567.10000000", "0.01000000"], ["61566.95000000", "0.01300000"], ["61566.58000000", "0.00000000"], ["61562.01000000", "0.00405000"], ["61517.42000000", "0.05395000"], ["55457.02000000", "0.00100000"], ["49295.13000000", "0.00000000"]], "asks": [["61618.92000000", "4.64558000"], ["61619.58000000", "0.28807000"], ["61623.75000000", "0.01100000"], ["61625.09000000", "0.00300000"], ["61636.17000000", "0.25150000"], ["61702.26000000", "0.05036000"]]}
{"type": "depth", "ts": 1783008089714, "U": 96863152435, "u": 96863152469, "bids": [["61618.91000000", "0.24639000"], ["61616.86000000", "0.00009000"], ["61616.85000000", "0.10231000"], ["61614.90000000", "0.00018000"], ["61614.58000000", "0.02737000"], ["61606.57000000", "0.00000000"], ["61606.55000000", "0.00991000"], ["61605.21000000", "0.00000000"], ["61605.20000000", "0.01292000"], ["61598.07000000", "0.00000000"], ["61597.79000000", "0.00000000"], ["61566.95000000", "0.00000000"], ["61518.51000000", "0.05395000"], ["61517.42000000", "0.00000000"], ["61452.62000000", "0.00000000"], ["61450.01000000", "0.00000000"], ["61448.76000000", "0.01001000"], ["55457.02000000", "0.00140000"]], "asks": [["61619.56000000", "0.15386000"], ["61620.65000000", "0.12300000"], ["61621.55000000", "0.00000000"], ["61629.71000000", "0.20009000"], ["61713.61000000", "0.00024000"], ["61717.91000000", "0.00040000"]]}
{"type": "depth", "ts": 1783008089814, "U": 96863152470, "u": 96863152736, "bids": [["61618.91000000", "0.00000000"], ["61618.90000000", "0.00000000"], ["61618.48000000", "0.00000000"], ["61618.01000000", "0.00000000"], ["61618.00000000", "0.02378000"], ["61617.99000000", "0.00063000"], ["61616.86000000", "0.00000000"], ["61616.85000000", "0.00027000"], ["61616.52000000", "0.00000000"], ["61615.40000000", "0.00526000"], ["61615.01000000", "0.00000000"], ["61614.91000000", "0.00000000"], ["61614.90000000", "0.00000000"], ["61614.59000000", "0.00000000"], ["61614.58000000", "0.00018000"], ["61614.39000000", "0.00000000"], ["61614.38000000", "0.00045000"], ["61614.29000000", "0.00000000"], ["61614.14000000", "0.00009000"], ["61614.13000000", "0.00000000"], ["61614.01000000", "0.00009000"], ["61613.84000000", "0.00000000"], ["61613.57000000", "0.01085000"], ["61613.51000000", "0.00000000"], ["61613.50000000", "0.00000000"], ["61613.49000000", "0.00000000"], ["61613.48000000", "0.00018000"], ["61613.30000000", "0.00009000"], ["61612.01000000", "0.00009000"], ["61611.86000000", "0.38965000"], ["61611.85000000", "0.51220000"], ["61611.84000000", "0.00010000"], ["61611.83000000", "0.00000000"], ["61611.82000000", "0.00000000"], ["61611.13000000", "0.00009000"], ["61610.94000000", "0.00009000"], ["61606.55000000", "0.00000000"], ["61605.20000000", "0.00400000"], ["61604.46000000", "0.00000000"], ["61603.16000000", "0.00000000"], ["61595.31000000", "0.00000000"], ["61595.04000000", "0.00000000"], ["61593.34000000", "0.00000000"], ["61588.00000000", "0.02400000"], ["61587.00000000", "0.01000000"], ["61579.81000000", "0.00009000"], ["61555.96000000", "0.01658000"], ["61541.48000000", "0.00009000"], ["61452.85000000", "0.77844000"], ["60694.62000000", "0.00000000"], ["55466.73000000", "0.00000000"], ["55457.02000000", "0.00000000"], ["55457.01000000", "0.00010000"], ["55457.00000000", "0.00000000"], ["55456.20000000", "0.00020000"]], "asks": [["61618.01000000", "4.14345000"], ["61618.02000000", "0.00035000"], ["61618.03000000", "0.00017000"], ["61618.49000000", "0.00009000"], ["61618.90000000", "0.66830000"], ["61618.91000000", "0.20465000"], ["61618.92000000", "0.35436000"], ["61618.93000000", "0.00000000"], ["61618.94000000", "0.00000000"], ["61619.56000000", "0.00027000"], ["61619.60000000", "0.16238000"], ["61620.01000000", "0.10122000"], ["61620.58000000", "0.00000000"], ["61620.65000000", "0.00018000"], ["61622.00000000", "0.15365000"], ["61624.17000000", "0.00010000"], ["61624.18000000", "0.00400000"], ["61624.48000000", "0.15383000"], ["61624.64000000", "0.00009000"], ["61626.17000000", "0.00000000"], ["61626.68000000", "0.14941000"], ["61626.88000000", "0.00010000"], ["61629.71000000", "0.20000000"], ["61631.05000000", "0.00000000"], ["61631.24000000", "0.00000000"], ["61636.17000000", "0.24750000"], ["61637.47000000", "0.54373000"], ["61648.62000000", "0.00829000"], ["61649.10000000", "0.00000000"], ["61649.98000000", "0.00009000"], ["61651.71000000", "0.00829000"], ["61653.79000000", "0.02658000"], ["61656.18000000", "1.02174000"], ["61665.57000000", "0.00829000"], ["61715.76000000", "0.00000000"], ["61717.04000000", "0.00000000"], ["61723.24000000", "0.00000000"], ["61730.64000000", "0.00152000"], ["61761.96000000", "0.19370000"], ["61777.80000000", "0.00000000"], ["62533.00000000", "1.94941000"], ["62543.88000000", "0.00037000"], ["62547.97000000", "0.00000000"]]}
{"type": "depth", "ts": 1783008089914, "U": 96863152737, "u": 96863152903, "bids": [["61618.00000000", "0.02414000"], ["61616.85000000", "0.00009000"], ["61616.81000000", "0.00000000"], ["61616.80000000", "0.00000000"], ["61615.51000000", "0.00000000"], ["61615.40000000", "0.00526000"], ["61614.72000000", "0.00000000"], ["61614.58000000", "0.00000000"], ["61614.38000000", "0.00018000"], ["61614.14000000", "0.00000000"], ["61614.08000000", "0.00009000"], ["61614.07000000", "0.00000000"], ["61614.00000000", "0.02418000"], ["61613.58000000", "0.00000000"], ["61613.57000000", "0.00018000"], ["61613.53000000", "0.00009000"], ["61613.52000000", "0.02661000"], ["61613.48000000", "0.00000000"], ["61613.29000000", "0.04887000"], ["61612.77000000", "0.00009000"], ["61612.76000000", "0.00009000"], ["61612.12000000", "0.00000000"], ["61612.00000000", "0.02418000"], ["61611.92000000", "0.00009000"], ["61611.91000000", "0.04709000"], ["61611.88000000", "0.00009000"], ["61611.87000000", "1.03844000"], ["61611.86000000", "0.00018000"], ["61611.85000000", "0.00009000"], ["61611.14000000", "0.00000000"], ["61611.13000000", "0.38956000"], ["61610.94000000", "1.36330000"], ["61610.93000000", "0.00000000"], ["61609.43000000", "0.00000000"], ["61605.95000000", "0.00000000"], ["61604.65000000", "0.00000000"], ["61604.45000000", "0.02000000"], ["61604.32000000", "0.00000000"], ["61602.42000000", "0.00000000"], ["61601.06000000", "0.60927000"], ["61600.16000000", "0.12323000"], ["61599.93000000", "0.00400000"], ["61597.75000000", "0.00000000"], ["61596.49000000", "0.56508000"], ["61595.09000000", "0.00000000"], ["61594.74000000", "0.00000000"], ["61594.70000000", "0.00000000"], ["61593.98000000", "0.00400000"], ["61583.13000000", "0.00000000"], ["61579.81000000", "0.00009000"], ["61564.80000000", "0.00400000"], ["61517.64000000", "0.00000000"], ["61507.48000000", "0.00000000"], ["61477.89000000", "0.00000000"], ["61450.14000000", "0.00009000"], ["61447.94000000", "0.00009000"], ["61444.86000000", "0.00000000"], ["55456.20000000", "0.00060000"]], "asks": [["61618.01000000", "4.17306000"], ["61618.90000000", "0.25786000"], ["61618.91000000", "0.20483000"], ["61618.92000000", "0.32786000"], ["61619.54000000", "0.00034000"], ["61619.56000000", "0.00009000"], ["61619.58000000", "0.28825000"], ["61619.60000000", "0.00027000"], ["61619.63000000", "0.00000000"], ["61619.66000000", "0.04217000"], ["61619.76000000", "0.13574000"], ["61620.01000000", "0.10086000"], ["61620.65000000", "0.00000000"], ["61621.99000000", "0.59067000"], ["61624.93000000", "0.58476000"], ["61625.70000000", "0.00009000"], ["61626.68000000", "0.14932000"], ["61630.33000000", "0.00326000"], ["61631.86000000", "0.00009000"], ["61640.85000000", "0.00000000"], ["61644.27000000", "0.03252000"], ["61647.38000000", "0.00000000"], ["61649.00000000", "0.01000000"], ["61650.00000000", "0.02433000"], ["61710.38000000", "0.00000000"], ["61713.61000000", "0.00000000"], ["61717.91000000", "0.00000000"], ["61801.41000000", "0.00000000"]]}
{"type": "depth", "ts": 1783008090014, "U": 96863152904, "u": 96863153015, "bids": [["61618.00000000", "0.02396000"], ["61616.85000000", "0.00000000"], ["61614.38000000", "0.00000000"], ["61614.37000000", "0.00018000"], ["61614.08000000", "0.00000000"], ["61614.00000000", "0.02418000"], ["61613.58000000", "0.00009000"], ["61613.57000000", "0.01085000"], ["61613.55000000", "0.00000000"], ["61613.53000000", "0.00000000"], ["61613.52000000", "0.00018000"], ["61612.77000000", "0.00000000"], ["61612.29000000", "0.00000000"], ["61612.00000000", "0.02418000"], ["61611.91000000", "0.04727000"], ["61611.87000000", "0.09146000"], ["61611.86000000", "0.00000000"], ["61611.85000000", "0.00000000"], ["61611.19000000", "0.00009000"], ["61611.18000000", "0.07756000"], ["61611.15000000", "0.00009000"], ["61611.14000000", "0.38956000"], ["61611.13000000", "0.00000000"], ["61611.12000000", "0.00000000"], ["61610.94000000", "0.00000000"], ["61610.01000000", "0.00000000"], ["61609.55000000", "0.00030000"], ["61609.11000000", "0.00000000"], ["61608.83000000", "0.09128000"], ["61608.25000000", "0.09128000"], ["61608.20000000", "0.02191000"], ["61606.41000000", "0.00153000"], ["61606.18000000", "0.00000000"], ["61604.45000000", "0.00000000"], ["61602.86000000", "0.00000000"], ["61602.35000000", "0.02899000"], ["61601.65000000", "0.00488000"], ["61597.65000000", "0.00009000"], ["61596.04000000", "0.84241000"], ["61594.28000000", "0.00000000"], ["61594.15000000", "0.02414000"], ["61528.21000000", "0.00000000"], ["61515.21000000", "0.00016000"], ["61490.58000000", "0.00000000"], ["61487.81000000", "0.00260000"], ["61479.34000000", "0.04217000"], ["61448.76000000", "0.01016000"], ["61368.50000000", "0.25070000"], ["61358.44000000", "0.00043000"], ["55456.20000000", "0.00100000"], ["49294.40000000", "0.00109000"]], "asks": [["61618.01000000", "4.18249000"], ["61618.92000000", "0.08036000"], ["61619.54000000", "0.00000000"], ["61619.58000000", "0.28816000"], ["61619.60000000", "0.16238000"], ["61619.66000000", "0.04235000"], ["61619.76000000", "0.00000000"], ["61620.26000000", "0.04046000"], ["61623.75000000", "0.00000000"], ["61623.95000000", "0.00156000"], ["61624.48000000", "0.15392000"], ["61624.84000000", "0.00000000"], ["61624.90000000", "0.00000000"], ["61624.92000000", "0.23412000"], ["61625.16000000", "0.00000000"], ["61626.68000000", "0.14923000"], ["61631.32000000", "0.00000000"], ["61631.89000000", "0.00000000"], ["61634.64000000", "0.00009000"], ["61638.64000000", "0.00000000"], ["61639.48000000", "1.60771000"], ["61640.59000000", "0.60828000"], ["61661.61000000", "0.09326000"], ["61671.13000000", "0.00000000"], ["61671.68000000", "0.00000000"], ["61730.29000000", "0.00260000"], ["61732.73000000", "0.00000000"]]}
{"type": "depth", "ts": 1783008090114, "U": 96863153016, "u": 96863153092, "bids": [["61618.00000000", "0.02387000"], ["61617.99000000", "0.00054000"], ["61615.40000000", "0.00526000"], ["61614.57000000", "0.00000000"], ["61614.37000000", "0.00000000"], ["61614.00000000", "0.02418000"], ["61613.57000000", "0.01103000"], ["61613.52000000", "0.00000000"], ["61612.81000000", "0.09137000"], ["61612.80000000", "0.08507000"], ["61611.87000000", "0.09146000"], ["61611.83000000", "0.24750000"], ["61611.20000000", "0.00009000"], ["61611.19000000", "0.25957000"], ["61611.18000000", "0.00000000"], ["61608.26000000", "0.00488000"], ["61607.28000000", "0.00069000"], ["61606.83000000", "0.00047000"], ["61606.18000000", "0.00009000"], ["61604.82000000", "0.00047000"], ["61594.15000000", "0.00000000"], ["61594.11000000", "0.00000000"], ["61593.83000000", "0.02396000"], ["61573.27000000", "0.00000000"], ["61573.13000000", "0.00000000"], ["61565.69000000", "0.00618000"], ["61565.32000000", "1.61388000"], ["61562.63000000", "0.00423000"], ["61562.60000000", "0.00429000"], ["61552.48000000", "0.97493000"], ["61552.21000000", "0.00000000"], ["61540.53000000", "0.00030000"], ["55456.20000000", "0.00120000"]], "asks": [["61618.01000000", "3.39245000"], ["61619.58000000", "0.28816000"], ["61619.60000000", "0.16256000"], ["61619.66000000", "0.04235000"], ["61619.78000000", "0.00009000"], ["61620.01000000", "0.09917000"], ["61633.75000000", "0.00419000"], ["61635.52000000", "0.04752000"], ["61641.26000000", "0.00649000"], ["61643.37000000", "0.00424000"], ["61643.75000000", "0.00618000"], ["61648.62000000", "0.00000000"], ["61670.84000000", "0.00009000"], ["61677.34000000", "0.00000000"], ["61694.57000000", "0.00030000"], ["61695.48000000", "1.64122000"], ["61696.67000000", "0.00000000"], ["61698.84000000", "0.00000000"], ["61706.29000000", "0.00000000"]]}
{"type": "depth", "ts": 1783008090214, "U": 96863153093, "u": 96863153154, "bids": [["61618.00000000", "0.02396000"], ["61617.99000000", "0.00063000"], ["61613.29000000", "0.04887000"], ["61612.82000000", "0.00009000"], ["61612.81000000", "0.09146000"], ["61612.80000000", "0.00000000"], ["61611.91000000", "0.04709000"], ["61611.87000000", "0.09146000"], ["61611.85000000", "0.00009000"], ["61611.84000000", "0.14700000"], ["61611.83000000", "0.00000000"], ["61611.20000000", "0.00000000"], ["61611.19000000", "0.00000000"], ["61611.15000000", "0.00000000"], ["61609.96000000", "0.01000000"], ["61604.34000000", "0.00000000"], ["61593.83000000", "0.00000000"], ["61593.68000000", "0.02387000"], ["61584.35000000", "0.00419000"], ["61505.04000000", "0.00024000"], ["61474.09000000", "0.00040000"], ["60693.73000000", "0.00030000"], ["59400.00000000", "2.52675000"], ["55456.20000000", "0.00160000"], ["49294.40000000", "0.00069000"], ["49294.00000000", "0.00800000"]], "asks": [["61625.89000000", "0.01800000"], ["61625.95000000", "0.01400000"], ["61626.50000000", "0.01200000"], ["61626.56000000", "0.01100000"], ["61628.97000000", "0.01000000"], ["61629.65000000", "0.01200000"], ["61633.01000000", "0.00009000"], ["61634.66000000", "0.00000000"], ["61637.75000000", "0.00000000"], ["61641.26000000", "0.00000000"], ["61656.87000000", "0.00000000"], ["61707.94000000", "0.00016000"]]}
{"type": "depth", "ts": 1783008090314, "U": 96863153155, "u": 96863153182, "bids": [["61612.81000000", "0.09146000"], ["61570.03000000", "0.01000000"], ["61561.68000000", "0.00067000"], ["61448.76000000", "0.00000000"], ["60000.00000000", "23.26936000"], ["55456.20000000", "0.00200000"], ["43132.60000000", "0.00000000"]], "asks": [["61618.89000000", "0.01300000"], ["61624.48000000", "0.15401000"], ["61624.90000000", "0.54450000"], ["61624.91000000", "0.97390000"], ["61624.92000000", "0.00000000"], ["61625.55000000", "0.00000000"], ["61626.50000000", "0.02500000"], ["61626.57000000", "0.01100000"], ["61629.34000000", "0.01000000"], ["61634.72000000", "0.00000000"], ["61635.27000000", "0.00000000"], ["61638.07000000", "0.00000000"], ["61638.38000000", "0.01000000"], ["61676.67000000", "0.00000000"], ["61738.05000000", "0.00000000"], ["62542.29000000", "0.00030000"]]}
{"type": "depth", "ts": 1783008090414, "U": 96863153183, "u": 96863153215, "bids": [["61618.00000000", "0.02405000"], ["61613.24000000", "0.00009000"], ["61613.23000000", "0.08407000"], ["61611.84000000", "0.14709000"], ["61611.83000000", "0.24750000"], ["61611.14000000", "0.00000000"], ["61609.11000000", "0.00009000"], ["61602.34000000", "0.00649000"], ["61568.21000000", "0.01034000"], ["55456.20000000", "0.00240000"], ["49294.00000000", "0.00800000"]], "asks": [["61618.01000000", "3.39263000"], ["61619.56000000", "0.00173000"], ["61620.00000000", "0.05100000"], ["61624.48000000", "0.15392000"], ["61627.84000000", "0.14245000"], ["61628.35000000", "0.01100000"], ["61629.65000000", "0.02200000"], ["61635.34000000", "0.00000000"], ["61639.26000000", "0.00649000"], ["61676.95000000", "0.00000000"], ["61711.17000000", "0.00024000"], ["61715.47000000", "0.00040000"]]}
{"type": "depth", "ts": 1783008090514, "U": 96863153216, "u": 96863153262, "bids": [["61618.00000000", "0.02396000"], ["61613.29000000", "0.04869000"], ["61613.24000000", "0.00000000"], ["61613.23000000", "0.00000000"], ["61612.81000000", "0.09155000"], ["61611.93000000", "0.00009000"], ["61611.92000000", "0.07206000"], ["61611.87000000", "0.09137000"], ["61611.85000000", "0.00000000"], ["61611.84000000", "0.00010000"], ["61611.83000000", "0.00000000"], ["61610.14000000", "0.09128000"], ["61586.58000000", "0.30835000"], ["61568.79000000", "1.28370000"], ["61564.86000000", "0.00400000"], ["61564.80000000", "0.00000000"], ["61550.01000000", "0.02832000"], ["61515.21000000", "0.00000000"], ["61505.04000000", "0.00000000"], ["61474.09000000", "0.00000000"], ["61379.34000000", "0.01003000"], ["55456.20000000", "0.00280000"], ["49294.40000000", "0.00069000"], ["49294.00000000", "0.00800000"]], "asks": [["61618.89000000", "0.01318000"], ["61629.59000000", "0.01000000"], ["61635.24000000", "0.00000000"], ["61635.30000000", "1.36330000"], ["61637.46000000", "1.38845000"], ["61637.84000000", "0.00000000"], ["61638.33000000", "0.00000000"], ["61638.38000000", "0.00000000"], ["61646.85000000", "0.00847000"], ["61655.65000000", "1.41154000"], ["61682.01000000", "0.00000000"], ["61707.94000000", "0.00000000"], ["61711.17000000", "0.00000000"], ["61715.47000000", "0.00000000"]]}
{"type": "depth", "ts": 1783008090614, "U": 96863153263, "u": 96863153292, "bids": [["61618.00000000", "0.02387000"], ["61617.99000000", "0.00054000"], ["61613.29000000", "0.04887000"], ["61612.82000000", "0.00000000"], ["61612.81000000", "0.00027000"], ["61612.00000000", "0.02400000"], ["61611.92000000", "0.20634000"], ["61610.16000000", "0.00009000"], ["61610.15000000", "0.38956000"], ["61606.95000000", "0.00000000"], ["61605.73000000", "0.07000000"], ["61605.56000000", "0.00400000"], ["61602.73000000", "0.08000000"], ["61588.13000000", "0.01624000"], ["61568.79000000", "0.99096000"], ["61567.78000000", "0.61712000"], ["61566.95000000", "0.01300000"], ["61520.98000000", "0.00009000"], ["55456.20000000", "0.00320000"], ["49294.40000000", "0.00089000"], ["33000.00000000", "37.44300000"]], "asks": [["61622.55000000", "0.00018000"], ["61628.98000000", "0.01100000"], ["61629.59000000", "0.02000000"], ["61637.09000000", "0.00000000"], ["61653.20000000", "0.60659000"]]}
{"type": "depth", "ts": 1783008090714, "U": 96863153293, "u": 96863153355, "bids": [["61618.00000000", "0.02403000"], ["61613.29000000", "0.04887000"], ["61612.81000000", "0.00009000"], ["61612.00000000", "0.02418000"], ["61611.93000000", "0.00000000"], ["61611.92000000", "0.00027000"], ["61611.88000000", "0.00000000"], ["61611.87000000", "0.00009000"], ["61611.45000000", "0.08772000"], ["61611.10000000", "0.00009000"], ["61611.09000000", "0.07958000"], ["61610.16000000", "0.00000000"], ["61610.15000000", "0.00009000"], ["61610.01000000", "0.00009000"], ["61609.91000000", "0.00009000"], ["61609.11000000", "0.00000000"], ["61606.18000000", "0.00009000"], ["61605.14000000", "0.08775000"], ["61600.92000000", "0.00000000"], ["61596.50000000", "0.44656000"], ["61576.88000000", "0.00000000"], ["61570.36000000", "0.00000000"], ["61553.21000000", "0.05351000"], ["61552.48000000", "0.00000000"], ["61513.64000000", "0.00016000"], ["61503.48000000", "0.00024000"], ["61473.90000000", "0.00039000"], ["61452.85000000", "0.00000000"], ["61420.74000000", "0.77844000"], ["55456.20000000", "0.00340000"], ["49294.40000000", "0.00069000"]], "asks": [["61618.01000000", "3.42225000"], ["61618.02000000", "0.00922000"], ["61618.26000000", "0.00400000"], ["61619.55000000", "0.00000000"], ["61637.72000000", "0.00000000"], ["61638.34000000", "0.00000000"], ["61646.61000000", "0.00427000"], ["61646.85000000", "0.01282000"], ["61654.89000000", "0.00000000"], ["61655.14000000", "0.00000000"], ["61658.82000000", "0.00000000"], ["61680.17000000", "0.00000000"], ["61790.37000000", "3.80211000"], ["61818.80000000", "0.00000000"]]}
{"type": "depth", "ts": 1783008090814, "U": 96863153356, "u": 96863153385, "bids": [["61618.00000000", "0.02412000"], ["61612.00000000", "0.02418000"], ["61611.92000000", "0.00009000"], ["61611.46000000", "0.00009000"], ["61610.15000000", "0.38965000"], ["61609.91000000", "0.00000000"], ["61379.34000000", "0.01018000"], ["55457.01000000", "0.00000000"], ["55456.20000000", "0.00390000"]], "asks": [["61618.01000000", "3.42214000"], ["61618.02000000", "0.00940000"], ["61618.92000000", "0.08194000"], ["61619.56000000", "0.00009000"], ["61619.66000000", "0.04217000"], ["61626.00000000", "0.00140000"], ["61627.84000000", "0.00000000"], ["61628.00000000", "0.00500000"], ["61630.00000000", "0.01413000"], ["61632.00000000", "0.00500000"], ["61664.81000000", "0.00000000"]]}
{"type": "depth", "ts": 1783008090914, "U": 96863153386, "u": 96863153398, "bids": [["61610.16000000", "0.00009000"], ["61610.01000000", "0.00000000"], ["61602.73000000", "0.00000000"], ["61601.73000000", "0.08000000"], ["61000.00000000", "17.34668000"], ["60000.00000000", "23.26945000"], ["59000.00000000", "44.69583000"], ["58000.00000000", "341.77464000"], ["55456.20000000", "0.00410000"]], "asks": [["61706.36000000", "0.00016000"], ["61709.60000000", "0.00024000"], ["63000.00000000", "42.95151000"], ["64000.00000000", "33.03480000"]]}
{"type": "depth", "ts": 1783008091014, "U": 96863153399, "u": 96863154091, "bids": [["61618.00000000", "0.00000000"], ["61617.99000000", "0.00000000"], ["61617.94000000", "0.00000000"], ["61616.65000000", "0.00000000"], ["61616.21000000", "0.00000000"], ["61616.11000000", "0.00000000"], ["61616.01000000", "0.00000000"], ["61616.00000000", "0.00000000"], ["61615.40000000", "0.00000000"], ["61614.98000000", "0.00000000"], ["61614.01000000", "0.00000000"], ["61614.00000000", "0.00000000"], ["61613.99000000", "0.00000000"], ["61613.70000000", "0.00000000"], ["61613.58000000", "0.00000000"], ["61613.57000000", "0.06031000"], ["61613.56000000", "0.00045000"], ["61611.91000000", "0.04727000"], ["61611.84000000", "0.00000000"], ["61611.48000000", "0.00000000"], ["61611.45000000", "0.00027000"], ["61611.09000000", "0.00027000"], ["61610.57000000", "0.01018000"], ["61610.51000000", "0.01018000"], ["61610.15000000", "0.00036000"], ["61610.14000000", "0.00000000"], ["61609.86000000", "0.00499000"], ["61608.84000000", "0.00009000"], ["61608.83000000", "0.00000000"], ["61608.82000000", "0.00010000"], ["61608.26000000", "0.00009000"], ["61608.25000000", "0.00000000"], ["61608.21000000", "0.00000000"], ["61607.71000000", "0.00000000"], ["61607.68000000", "0.00009000"], ["61606.18000000", "0.00000000"], ["61605.73000000", "0.00000000"], ["61605.56000000", "0.00000000"], ["61605.14000000", "0.00000000"], ["61604.60000000", "0.00000000"], ["61604.33000000", "0.00010000"], ["61603.99000000", "1.36330000"], ["61603.95000000", "0.00000000"], ["61603.88000000", "0.00000000"], ["61603.44000000", "0.00000000"], ["61603.32000000", "0.00000000"], ["61603.25000000", "0.00000000"], ["61602.35000000", "0.00000000"], ["61602.03000000", "0.07000000"], ["61601.51000000", "0.00016000"], ["61601.25000000", "0.00010000"], ["61601.06000000", "0.00000000"], ["61601.05000000", "0.38306000"], ["61599.93000000", "0.00000000"], ["61599.15000000", "0.00000000"], ["61598.43000000", "0.00000000"], ["61598.17000000", "0.00044000"], ["61597.65000000", "0.00000000"], ["61597.29000000", "0.00400000"], ["61597.16000000", "0.60926000"], ["61595.35000000", "0.00000000"], ["61595.08000000", "0.00010000"], ["61593.98000000", "0.00000000"], ["61593.23000000", "0.00009000"], ["61592.27000000", "0.00000000"], ["61592.20000000", "0.00000000"], ["61592.00000000", "0.02410000"], ["61589.36000000", "0.00000000"], ["61589.19000000", "0.00000000"], ["61588.92000000", "0.00010000"], ["61588.13000000", "0.00000000"], ["61587.15000000", "0.00009000"], ["61587.00000000", "0.00000000"], ["61586.41000000", "0.58512000"], ["61585.84000000", "0.00010000"], ["61585.00000000", "0.00000000"], ["61584.20000000", "0.00009000"], ["61583.00000000", "0.00000000"], ["61582.00000000", "0.05023000"], ["61579.66000000", "0.00000000"], ["61577.17000000", "0.00000000"], ["61576.88000000", "0.00009000"], ["61574.46000000", "0.00024000"], ["61573.68000000", "0.58524000"], ["61568.61000000", "0.39956000"], ["61564.01000000", "0.00000000"], ["61563.51000000", "0.00000000"], ["61562.75000000", "0.00000000"], ["61562.37000000", "0.00000000"], ["61562.17000000", "0.00000000"], ["61562.06000000", "0.00000000"], ["61562.01000000", "0.00000000"], ["61557.39000000", "0.00499000"], ["61555.03000000", "0.00010000"], ["61554.73000000", "1.60992000"], ["61552.41000000", "0.00000000"], ["61551.46000000", "0.35117000"], ["61550.01000000", "0.02832000"], ["61548.44000000", "1.36330000"], ["61545.85000000", "0.97390000"], ["61543.13000000", "0.97495000"], ["61541.19000000", "0.97390000"], ["61526.59000000", "0.00000000"], ["61515.75000000", "0.00000000"], ["61500.74000000", "0.00000000"], ["61493.42000000", "0.00010000"], ["61487.81000000", "0.00000000"], ["61486.56000000", "0.00260000"], ["61442.88000000", "0.00162000"], ["61442.87000000", "0.00972000"], ["61439.12000000", "0.00000000"], ["61431.80000000", "0.00010000"], ["61379.34000000", "0.00015000"], ["61377.49000000", "0.00000000"], ["61370.18000000", "0.00010000"], ["61359.95000000", "4.89405000"], ["61315.87000000", "0.00000000"], ["61308.57000000", "0.00010000"], ["61254.25000000", "0.00000000"], ["61246.95000000", "0.00010000"], ["61192.62000000", "0.00000000"], ["61185.33000000", "0.00010000"], ["61131.00000000", "0.00000000"], ["61123.72000000", "0.00010000"], ["60693.73000000", "0.00000000"], ["55456.20000000", "0.00010000"], ["49294.00000000", "0.00800000"], ["49291.20000000", "0.00040000"]], "asks": [["61613.58000000", "3.94972000"], ["61613.59000000", "0.00035000"], ["61613.60000000", "0.00017000"], ["61613.70000000", "0.57464000"], ["61613.71000000", "0.57464000"], ["61614.00000000", "1.87254000"], ["61614.01000000", "0.12027000"], ["61614.02000000", "0.00000000"], ["61614.03000000", "0.00000000"], ["61614.97000000", "0.00009000"], ["61614.99000000", "0.26574000"], ["61615.20000000", "0.06646000"], ["61615.21000000", "0.09027000"], ["61615.22000000", "0.00000000"], ["61615.23000000", "0.00000000"], ["61615.41000000", "0.00000000"], ["61616.00000000", "0.05100000"], ["61616.01000000", "0.00000000"], ["61616.12000000", "0.00000000"], ["61616.22000000", "0.00000000"], ["61616.65000000", "0.00009000"], ["61616.66000000", "0.31675000"], ["61617.90000000", "0.00009000"], ["61617.94000000", "1.36330000"], ["61617.95000000", "0.00009000"], ["61617.97000000", "0.00000000"], ["61618.00000000", "0.20465000"], ["61618.01000000", "0.14889000"], ["61618.02000000", "0.00905000"], ["61618.03000000", "0.00000000"], ["61618.05000000", "0.05000000"], ["61618.10000000", "0.05000000"], ["61618.91000000", "0.00000000"], ["61618.92000000", "0.08176000"], ["61619.57000000", "0.00000000"], ["61619.58000000", "0.20027000"], ["61619.60000000", "0.00043000"], ["61619.74000000", "0.00010000"], ["61620.00000000", "0.00000000"], ["61620.18000000", "0.00400000"], ["61621.37000000", "0.00000000"], ["61621.56000000", "0.00009000"], ["61621.70000000", "0.00009000"], ["61621.72000000", "0.58479000"], ["61622.01000000", "0.00911000"], ["61622.48000000", "0.00013000"], ["61624.00000000", "0.01038000"], ["61624.17000000", "0.00000000"], ["61624.48000000", "0.00027000"], ["61626.00000000", "0.00940000"], ["61626.49000000", "0.00499000"], ["61627.56000000", "0.00325000"], ["61628.00000000", "0.01300000"], ["61628.98000000", "0.01110000"], ["61630.00000000", "0.02213000"], ["61630.17000000", "0.00300000"], ["61630.20000000", "0.00009000"], ["61630.33000000", "0.00000000"], ["61632.00000000", "0.01300000"], ["61632.06000000", "0.00010000"], ["61632.33000000", "0.00000000"], ["61633.86000000", "0.00000000"], ["61634.64000000", "0.00000000"], ["61635.14000000", "0.00010000"], ["61635.42000000", "0.00000000"], ["61636.72000000", "0.04709000"], ["61636.87000000", "0.28400000"], ["61637.43000000", "0.00000000"], ["61638.23000000", "0.00010000"], ["61638.50000000", "0.00016000"], ["61641.31000000", "0.00010000"], ["61641.58000000", "0.00000000"], ["61642.49000000", "0.00000000"], ["61644.39000000", "0.00010000"], ["61644.66000000", "0.00000000"], ["61646.15000000", "0.00000000"], ["61647.20000000", "0.01160000"], ["61647.47000000", "0.00010000"], ["61647.74000000", "1.36330000"], ["61649.07000000", "0.00000000"], ["61649.88000000", "0.00000000"], ["61650.00000000", "0.02409000"], ["61650.82000000", "0.00000000"], ["61651.71000000", "0.00000000"], ["61658.85000000", "0.03246000"], ["61658.88000000", "0.01623000"], ["61658.93000000", "0.01623000"], ["61660.70000000", "0.00000000"], ["61671.45000000", "0.00000000"], ["61671.46000000", "0.00000000"], ["61672.10000000", "0.00000000"], ["61672.15000000", "0.00000000"], ["61673.19000000", "0.00000000"], ["61678.28000000", "0.00010000"], ["61684.02000000", "0.04638000"], ["61685.62000000", "0.00000000"], ["61695.49000000", "0.00000000"], ["61708.88000000", "0.00000000"], ["61713.90000000", "0.00040000"], ["61713.96000000", "0.00000000"], ["61721.24000000", "4.86540000"], ["61729.12000000", "0.00260000"], ["61730.29000000", "0.00000000"], ["61739.89000000", "0.00010000"], ["61747.25000000", "0.00000000"], ["61801.51000000", "0.00010000"], ["61808.87000000", "0.00000000"], ["61863.13000000", "0.00023000"], ["61870.50000000", "0.00000000"], ["61888.14000000", "0.00000000"], ["61924.74000000", "0.00010000"], ["61932.12000000", "0.00000000"], ["61986.36000000", "0.00010000"], ["61993.74000000", "0.00000000"], ["62047.98000000", "0.00010000"], ["62055.37000000", "0.00000000"], ["62109.59000000", "0.00010000"], ["62116.99000000", "0.00000000"], ["62542.29000000", "0.00000000"]]}
{"type": "depth", "ts": 1783008091114, "U": 96863154092, "u": 96863154804, "bids": [["61613.57000000", "0.00000000"], ["61613.56000000", "0.00000000"], ["61613.55000000", "0.00000000"], ["61613.54000000", "0.00000000"], ["61613.30000000", "0.00000000"], ["61613.29000000", "0.00000000"], ["61613.28000000", "0.00000000"], ["61612.81000000", "0.00000000"], ["61612.76000000", "0.00000000"], ["61612.32000000", "0.00000000"], ["61612.01000000", "0.00000000"], ["61612.00000000", "0.00499000"], ["61611.99000000", "0.00018000"], ["61611.91000000", "0.04727000"], ["61611.87000000", "0.00000000"], ["61611.61000000", "0.00000000"], ["61611.46000000", "0.00000000"], ["61611.45000000", "0.00000000"], ["61611.19000000", "0.00009000"], ["61611.10000000", "0.00000000"], ["61611.09000000", "0.00000000"], ["61610.72000000", "0.00000000"], ["61610.66000000", "0.00000000"], ["61610.57000000", "0.00018000"], ["61610.51000000", "0.00018000"], ["61610.48000000", "0.00000000"], ["61610.16000000", "0.00000000"], ["61610.15000000", "0.00000000"], ["61610.14000000", "0.00009000"], ["61610.01000000", "0.00009000"], ["61610.00000000", "0.02418000"], ["61609.96000000", "0.00018000"], ["61609.95000000", "0.00018000"], ["61609.91000000", "0.00000000"], ["61609.90000000", "0.00018000"], ["61609.26000000", "0.00000000"], ["61608.84000000", "0.00000000"], ["61608.82000000", "0.00000000"], ["61608.63000000", "0.00000000"], ["61608.51000000", "0.00000000"], ["61608.30000000", "0.01928000"], ["61608.26000000", "0.00000000"], ["61608.25000000", "0.00000000"], ["61608.24000000", "0.00027000"], ["61608.21000000", "0.00009000"], ["61608.20000000", "0.02200000"], ["61608.02000000", "0.00000000"], ["61608.01000000", "0.00009000"], ["61607.83000000", "0.00009000"], ["61607.60000000", "0.00000000"], ["61607.50000000", "0.00000000"], ["61607.46000000", "0.00000000"], ["61607.40000000", "0.00000000"], ["61607.13000000", "0.00010000"], ["61607.08000000", "0.00009000"], ["61607.07000000", "0.00000000"], ["61606.82000000", "0.00000000"], ["61606.18000000", "0.00009000"], ["61606.17000000", "0.00009000"], ["61606.16000000", "0.00532000"], ["61606.09000000", "0.00000000"], ["61604.90000000", "0.00243000"], ["61604.55000000", "0.00000000"], ["61604.47000000", "0.00000000"], ["61604.33000000", "0.00000000"], ["61604.31000000", "0.00499000"], ["61604.01000000", "0.00000000"], ["61603.99000000", "0.00000000"], ["61603.98000000", "0.00000000"], ["61603.93000000", "0.00000000"], ["61603.25000000", "0.00000000"], ["61602.14000000", "0.00000000"], ["61601.93000000", "0.00047000"], ["61601.36000000", "0.00000000"], ["61601.26000000", "0.00400000"], ["61601.25000000", "0.00000000"], ["61601.05000000", "0.36306000"], ["61600.97000000", "0.00010000"], ["61600.94000000", "0.00000000"], ["61600.62000000", "0.00000000"], ["61600.32000000", "0.00000000"], ["61600.16000000", "0.00000000"], ["61599.75000000", "0.00192000"], ["61599.04000000", "0.00000000"], ["61598.17000000", "0.00034000"], ["61597.97000000", "0.00893000"], ["61597.89000000", "0.00010000"], ["61597.44000000", "0.02000000"], ["61597.29000000", "0.00000000"], ["61596.50000000", "0.10853000"], ["61595.10000000", "0.00400000"], ["61595.08000000", "0.00000000"], ["61594.89000000", "0.00889000"], ["61594.86000000", "0.00000000"], ["61594.81000000", "0.00172000"], ["61593.68000000", "0.00000000"], ["61592.22000000", "0.74262000"], ["61592.21000000", "0.43914000"], ["61592.14000000", "0.00000000"], ["61592.00000000", "0.02400000"], ["61591.87000000", "0.00000000"], ["61591.81000000", "0.00905000"], ["61591.73000000", "0.00010000"], ["61591.66000000", "0.00000000"], ["61591.24000000", "0.00000000"], ["61590.90000000", "0.00000000"], ["61590.00000000", "0.02896000"], ["61589.94000000", "0.06031000"], ["61589.82000000", "0.00400000"], ["61589.78000000", "0.00000000"], ["61588.92000000", "0.00000000"], ["61588.73000000", "0.00908000"], ["61588.64000000", "0.00010000"], ["61586.58000000", "0.44926000"], ["61586.41000000", "0.00000000"], ["61585.84000000", "0.00000000"], ["61585.65000000", "0.00882000"], ["61585.56000000", "0.00010000"], ["61584.35000000", "0.00000000"], ["61583.91000000", "0.00059000"], ["61582.48000000", "0.00010000"], ["61582.00000000", "0.04023000"], ["61581.25000000", "0.00009000"], ["61581.20000000", "0.11274000"], ["61580.37000000", "0.00012000"], ["61578.90000000", "0.00194000"], ["61575.10000000", "0.28147000"], ["61574.54000000", "0.58523000"], ["61573.95000000", "0.00009000"], ["61571.90000000", "0.00488000"], ["61571.14000000", "0.77916000"], ["61567.04000000", "0.00000000"], ["61563.27000000", "0.00488000"], ["61562.19000000", "0.00400000"], ["61560.84000000", "0.00000000"], ["61560.39000000", "0.00000000"], ["61559.52000000", "0.00400000"], ["61559.25000000", "0.13613000"], ["61557.39000000", "0.00404000"], ["61555.85000000", "0.88513000"], ["61550.01000000", "0.43254000"], ["61546.71000000", "0.46374000"], ["61544.01000000", "0.31588000"], ["61535.32000000", "0.00009000"], ["61529.32000000", "0.00000000"], ["61519.98000000", "0.00000000"], ["61516.74000000", "0.12764000"], ["61510.65000000", "0.04522000"], ["61502.84000000", "0.00000000"], ["61502.07000000", "0.00000000"], ["61498.20000000", "0.09542000"], ["61493.78000000", "0.00845000"], ["61493.33000000", "0.00000000"], ["61486.56000000", "0.00000000"], ["61362.33000000", "0.24750000"], ["55452.22000000", "0.00000000"], ["55451.97000000", "0.00000000"]], "asks": [["61612.01000000", "4.15139000"], ["61612.02000000", "0.00009000"], ["61612.33000000", "0.05297000"], ["61612.77000000", "0.00000000"], ["61612.81000000", "1.59064000"], ["61612.82000000", "0.36611000"], ["61613.29000000", "0.05109000"], ["61613.30000000", "0.37759000"], ["61613.31000000", "0.00009000"], ["61613.32000000", "0.00000000"], ["61613.35000000", "0.05000000"], ["61613.56000000", "0.00000000"], ["61613.57000000", "1.41430000"], ["61613.58000000", "0.27616000"], ["61613.59000000", "0.00000000"], ["61613.60000000", "0.00000000"], ["61613.69000000", "0.00000000"], ["61613.70000000", "0.00027000"], ["61613.71000000", "0.00027000"], ["61614.00000000", "0.00018000"], ["61614.01000000", "0.12036000"], ["61614.97000000", "0.16239000"], ["61614.99000000", "0.17984000"], ["61615.20000000", "0.06646000"], ["61615.21000000", "0.04018000"], ["61615.22000000", "0.00000000"], ["61615.50000000", "0.04046000"], ["61615.59000000", "0.00400000"], ["61616.00000000", "0.05109000"], ["61616.43000000", "0.12000000"], ["61616.65000000", "0.14932000"], ["61616.66000000", "0.32666000"], ["61617.93000000", "0.50181000"], ["61618.00000000", "0.15365000"], ["61618.01000000", "0.11963000"], ["61618.02000000", "0.00887000"], ["61618.05000000", "0.00000000"], ["61618.10000000", "0.00000000"], ["61618.17000000", "0.00010000"], ["61618.51000000", "0.58482000"], ["61618.89000000", "0.01300000"], ["61618.90000000", "0.14111000"], ["61618.92000000", "0.08009000"], ["61619.56000000", "0.00000000"], ["61619.58000000", "0.20018000"], ["61619.62000000", "0.00000000"], ["61619.70000000", "0.00009000"], ["61620.01000000", "0.01917000"], ["61620.26000000", "0.00000000"], ["61622.01000000", "0.00902000"], ["61623.83000000", "0.00000000"], ["61623.98000000", "0.00000000"], ["61624.00000000", "0.01013000"], ["61624.36000000", "0.08754000"], ["61624.48000000", "0.00000000"], ["61625.62000000", "0.00010000"], ["61625.90000000", "0.08890000"], ["61626.68000000", "0.00000000"], ["61628.05000000", "0.00059000"], ["61628.70000000", "0.00010000"], ["61628.98000000", "0.01100000"], ["61629.62000000", "0.97399000"], ["61629.64000000", "0.00000000"], ["61630.00000000", "0.01300000"], ["61631.16000000", "0.00000000"], ["61631.78000000", "0.00010000"], ["61632.06000000", "0.00000000"], ["61632.74000000", "1.60788000"], ["61633.27000000", "0.00000000"], ["61634.00000000", "0.02409000"], ["61634.86000000", "0.00010000"], ["61634.95000000", "0.00000000"], ["61635.14000000", "0.00000000"], ["61637.95000000", "0.00010000"], ["61638.23000000", "0.00000000"], ["61638.87000000", "0.00000000"], ["61641.03000000", "0.00010000"], ["61641.31000000", "0.64155000"], ["61643.20000000", "0.00000000"], ["61644.11000000", "0.00010000"], ["61644.27000000", "0.03243000"], ["61644.39000000", "0.00000000"], ["61645.00000000", "0.01000000"], ["61647.18000000", "0.63083000"], ["61647.47000000", "0.00000000"], ["61648.00000000", "0.02400000"], ["61648.95000000", "0.00000000"], ["61649.00000000", "0.00000000"], ["61649.82000000", "0.56510000"], ["61651.29000000", "0.00000000"], ["61652.59000000", "0.00379000"], ["61657.22000000", "0.00000000"], ["61660.99000000", "0.00000000"], ["61661.62000000", "1.74172000"], ["61662.64000000", "0.97495000"], ["61664.04000000", "1.89243000"], ["61671.66000000", "0.54961000"], ["61673.49000000", "0.00000000"], ["61677.67000000", "0.13534000"], ["61687.73000000", "0.90772000"], ["61688.92000000", "0.00000000"], ["61691.14000000", "0.00000000"], ["61699.99000000", "0.00000000"], ["61701.98000000", "0.00000000"], ["61708.44000000", "0.00000000"], ["61709.41000000", "0.12000000"], ["61713.89000000", "0.00152000"], ["61729.12000000", "0.00000000"], ["61730.64000000", "0.00000000"], ["61732.55000000", "0.00000000"], ["61771.81000000", "0.00000000"], ["61777.98000000", "0.00000000"], ["61784.15000000", "0.00000000"], ["61799.84000000", "0.00000000"], ["62223.22000000", "0.00000000"]]}
{"type": "depth", "ts": 1783008091214, "U": 96863154805, "u": 96863155984, "bids": [["61612.00000000", "0.00000000"], ["61611.99000000", "0.00000000"], ["61611.92000000", "0.00000000"], ["61611.91000000", "0.00000000"], ["61611.90000000", "0.00000000"], ["61611.80000000", "0.00000000"], ["61611.66000000", "0.00000000"], ["61611.35000000", "0.00000000"], ["61611.19000000", "0.00000000"], ["61610.75000000", "0.00000000"], ["61610.57000000", "0.00000000"], ["61610.51000000", "0.00000000"], ["61610.29000000", "0.00000000"], ["61610.14000000", "0.00000000"], ["61610.11000000", "0.00000000"], ["61610.10000000", "0.00000000"], ["61610.01000000", "0.00000000"], ["61610.00000000", "0.00000000"], ["61609.99000000", "0.00000000"], ["61609.96000000", "0.00000000"], ["61609.95000000", "0.00000000"], ["61609.90000000", "0.00000000"], ["61609.86000000", "0.00000000"], ["61609.55000000", "0.00000000"], ["61609.24000000", "0.00000000"], ["61608.64000000", "0.00000000"], ["61608.38000000", "0.00000000"], ["61608.31000000", "0.00000000"], ["61608.30000000", "0.00000000"], ["61608.29000000", "0.00000000"], ["61608.24000000", "0.00000000"], ["61608.21000000", "0.00000000"], ["61608.20000000", "0.15629000"], ["61608.19000000", "0.00054000"], ["61608.11000000", "0.00009000"], ["61608.00000000", "0.02418000"], ["61607.82000000", "0.03041000"], ["61607.68000000", "0.00000000"], ["61607.46000000", "0.00000000"], ["61607.28000000", "0.00000000"], ["61607.13000000", "0.00000000"], ["61607.08000000", "0.00000000"], ["61606.83000000", "0.00000000"], ["61606.71000000", "0.00018000"], ["61606.53000000", "0.00843000"], ["61606.41000000", "0.00000000"], ["61606.18000000", "0.00000000"], ["61606.17000000", "0.00000000"], ["61606.16000000", "0.00526000"], ["61606.13000000", "0.00000000"], ["61606.11000000", "0.00018000"], ["61606.01000000", "0.00009000"], ["61606.00000000", "0.02418000"], ["61605.50000000", "0.00000000"], ["61605.49000000", "0.00000000"], ["61605.48000000", "0.00000000"], ["61605.20000000", "0.00000000"], ["61604.90000000", "0.00000000"], ["61604.82000000", "0.00000000"], ["61604.74000000", "0.00009000"], ["61604.73000000", "0.04709000"], ["61604.40000000", "0.00000000"], ["61604.29000000", "0.00000000"], ["61604.20000000", "0.00000000"], ["61604.04000000", "0.00000000"], ["61604.01000000", "0.00009000"], ["61603.84000000", "0.00000000"], ["61603.57000000", "0.00009000"], ["61603.56000000", "0.02049000"], ["61603.50000000", "0.00000000"], ["61603.08000000", "0.00009000"], ["61602.91000000", "0.00000000"], ["61602.90000000", "0.00000000"], ["61602.54000000", "0.00000000"], ["61602.53000000", "0.00000000"], ["61602.49000000", "0.10471000"], ["61602.26000000", "0.00034000"], ["61602.14000000", "0.00010000"], ["61602.04000000", "0.00000000"], ["61602.03000000", "0.00000000"], ["61602.01000000", "0.03838000"], ["61601.87000000", "0.00009000"], ["61601.86000000", "0.02191000"], ["61601.74000000", "0.00000000"], ["61601.73000000", "0.00000000"], ["61601.70000000", "0.08359000"], ["61601.65000000", "0.00000000"], ["61601.26000000", "0.00000000"], ["61601.07000000", "0.00000000"], ["61601.06000000", "0.00000000"], ["61601.05000000", "0.00000000"], ["61600.97000000", "0.00000000"], ["61600.92000000", "0.00000000"], ["61600.91000000", "0.00000000"], ["61600.40000000", "0.09060000"], ["61600.34000000", "0.00000000"], ["61600.16000000", "0.00000000"], ["61600.15000000", "0.00000000"], ["61600.01000000", "0.00009000"], ["61599.57000000", "0.00070000"], ["61599.28000000", "0.00153000"], ["61599.10000000", "0.08304000"], ["61599.04000000", "0.01000000"], ["61599.02000000", "0.00047000"], ["61598.98000000", "0.01000000"], ["61598.63000000", "0.00243000"], ["61598.40000000", "1.06450000"], ["61598.39000000", "0.08832000"], ["61598.38000000", "0.00000000"], ["61598.37000000", "0.01000000"], ["61598.17000000", "0.00000000"], ["61597.97000000", "0.00000000"], ["61597.89000000", "0.00000000"], ["61597.68000000", "0.00010000"], ["61597.44000000", "0.00000000"], ["61597.39000000", "0.00000000"], ["61597.17000000", "1.36330000"], ["61597.16000000", "0.00000000"], ["61597.15000000", "0.00000000"], ["61596.87000000", "0.00000000"], ["61596.79000000", "0.00000000"], ["61596.50000000", "0.09060000"], ["61596.05000000", "0.09060000"], ["61596.04000000", "0.84275000"], ["61595.96000000", "0.01000000"], ["61595.92000000", "0.00000000"], ["61595.87000000", "0.00009000"], ["61595.75000000", "0.01009000"], ["61595.44000000", "0.00000000"], ["61595.23000000", "0.00000000"], ["61595.10000000", "0.00000000"], ["61594.89000000", "0.00000000"], ["61594.81000000", "0.00162000"], ["61594.75000000", "0.00000000"], ["61594.60000000", "0.00410000"], ["61594.59000000", "0.38956000"], ["61594.47000000", "0.08758000"], ["61594.46000000", "0.00009000"], ["61594.40000000", "0.00873000"], ["61594.24000000", "0.00000000"], ["61593.83000000", "0.07000000"], ["61593.74000000", "0.00000000"], ["61593.51000000", "0.08775000"], ["61592.93000000", "0.16904000"], ["61592.61000000", "0.01000000"], ["61592.23000000", "0.65003000"], ["61592.22000000", "0.00000000"], ["61592.21000000", "0.00000000"], ["61591.73000000", "0.00000000"], ["61591.52000000", "0.00010000"], ["61591.41000000", "0.60932000"], ["61591.03000000", "0.02000000"], ["61590.72000000", "0.00000000"], ["61590.56000000", "0.78885000"], ["61589.94000000", "0.00000000"], ["61589.82000000", "0.00000000"], ["61589.80000000", "0.00000000"], ["61589.71000000", "0.00000000"], ["61589.40000000", "0.00000000"], ["61589.18000000", "0.36231000"], ["61588.89000000", "0.00400000"], ["61588.79000000", "0.00400000"], ["61588.65000000", "0.00650000"], ["61588.64000000", "0.00000000"], ["61588.44000000", "0.00010000"], ["61588.02000000", "1.01809000"], ["61586.58000000", "0.31101000"], ["61585.56000000", "0.00000000"], ["61585.36000000", "0.00010000"], ["61584.55000000", "0.00400000"], ["61583.84000000", "0.85316000"], ["61583.45000000", "0.00000000"], ["61582.81000000", "0.00000000"], ["61582.48000000", "0.00000000"], ["61582.28000000", "0.00010000"], ["61581.20000000", "0.29059000"], ["61581.00000000", "0.00000000"], ["61580.51000000", "0.64218000"], ["61579.20000000", "0.00010000"], ["61579.00000000", "0.00000000"], ["61578.30000000", "0.00009000"], ["61577.00000000", "0.01000000"], ["61575.10000000", "0.43928000"], ["61571.68000000", "0.00000000"], ["61571.64000000", "0.00000000"], ["61571.02000000", "0.00009000"], ["61568.70000000", "0.00024000"], ["61568.09000000", "0.00009000"], ["61567.78000000", "0.00000000"], ["61565.69000000", "0.00000000"], ["61565.32000000", "1.60964000"], ["61565.25000000", "0.58532000"], ["61565.16000000", "0.00000000"], ["61562.46000000", "0.01000000"], ["61561.68000000", "0.00009000"], ["61559.25000000", "0.00000000"], ["61557.39000000", "0.00000000"], ["61557.11000000", "0.00000000"], ["61556.85000000", "0.00400000"], ["61556.45000000", "0.00000000"], ["61555.86000000", "0.00488000"], ["61555.85000000", "1.34723000"], ["61555.79000000", "0.00000000"], ["61555.44000000", "1.50245000"], ["61555.07000000", "0.00000000"], ["61555.03000000", "0.00000000"], ["61554.53000000", "0.00000000"], ["61553.10000000", "0.01000000"], ["61552.84000000", "0.00404000"], ["61552.83000000", "0.00000000"], ["61551.07000000", "0.01000000"], ["61551.02000000", "0.00000000"], ["61550.81000000", "0.00095000"], ["61550.80000000", "0.01000000"], ["61549.81000000", "0.00000000"], ["61548.39000000", "0.00010000"], ["61547.66000000", "0.01000000"], ["61547.60000000", "0.01000000"], ["61546.89000000", "1.61013000"], ["61544.01000000", "0.02946000"], ["61543.13000000", "0.00000000"], ["61542.93000000", "0.00000000"], ["61541.97000000", "0.00000000"], ["61541.26000000", "0.00000000"], ["61541.20000000", "1.36330000"], ["61540.04000000", "0.00000000"], ["61538.09000000", "0.00538000"], ["61535.75000000", "0.00111000"], ["61534.74000000", "0.41802000"], ["61534.21000000", "0.00000000"], ["61534.03000000", "0.01729000"], ["61533.85000000", "0.00000000"], ["61533.80000000", "1.36330000"], ["61533.19000000", "0.97503000"], ["61515.11000000", "0.07431000"], ["61513.64000000", "0.00000000"], ["61511.56000000", "0.00009000"], ["61503.48000000", "0.00000000"], ["61502.08000000", "0.00000000"], ["61493.78000000", "0.00000000"], ["61493.42000000", "0.00000000"], ["61491.50000000", "0.00162000"], ["61489.04000000", "0.00038000"], ["61488.43000000", "0.00000000"], ["61486.78000000", "0.00010000"], ["61485.13000000", "0.00000000"], ["61474.46000000", "1.20000000"], ["61473.90000000", "0.00000000"], ["61470.11000000", "0.04217000"], ["61453.72000000", "0.20605000"], ["61445.94000000", "0.00009000"], ["61442.87000000", "0.00000000"], ["61442.86000000", "4.88777000"], ["61439.69000000", "0.00009000"], ["61436.61000000", "0.00009000"], ["61431.80000000", "0.00000000"], ["61425.17000000", "0.00010000"], ["61420.20000000", "0.00000000"], ["61414.37000000", "0.00000000"], ["61379.34000000", "0.00000000"], ["61370.18000000", "0.00000000"], ["61363.56000000", "0.00010000"], ["61358.44000000", "0.00000000"], ["61327.49000000", "0.01936000"], ["61308.57000000", "0.00000000"], ["61301.95000000", "0.00010000"], ["61246.95000000", "0.00000000"], ["61240.34000000", "0.00010000"], ["61185.33000000", "0.00000000"], ["61178.73000000", "0.00010000"], ["61123.72000000", "0.00000000"], ["61117.12000000", "0.00010000"], ["60684.17000000", "0.00000000"], ["55452.00000000", "0.13668000"], ["55447.47000000", "0.00000000"], ["55447.38000000", "0.00020000"], ["49291.20000000", "0.00000000"]], "asks": [["61608.21000000", "4.56392000"], ["61608.22000000", "0.00017000"], ["61608.23000000", "0.00017000"], ["61608.25000000", "0.00000000"], ["61608.30000000", "2.19658000"], ["61608.31000000", "0.43573000"], ["61608.32000000", "0.00000000"], ["61608.33000000", "0.00000000"], ["61609.11000000", "0.00009000"], ["61609.56000000", "0.00000000"], ["61609.61000000", "0.00000000"], ["61609.87000000", "0.00000000"], ["61609.89000000", "0.16240000"], ["61609.91000000", "0.00000000"], ["61609.96000000", "0.00000000"], ["61609.97000000", "0.00000000"], ["61609.99000000", "0.00000000"], ["61610.00000000", "1.41430000"], ["61610.01000000", "0.08036000"], ["61610.02000000", "0.00000000"], ["61610.03000000", "0.00000000"], ["61610.25000000", "0.00400000"], ["61610.50000000", "0.04217000"], ["61610.52000000", "0.00000000"], ["61610.75000000", "0.00009000"], ["61610.76000000", "0.04046000"], ["61611.20000000", "0.00000000"], ["61611.31000000", "0.00000000"], ["61611.36000000", "0.00000000"], ["61611.67000000", "0.00000000"], ["61611.81000000", "0.15374000"], ["61611.91000000", "0.05100000"], ["61611.92000000", "0.36376000"], ["61611.93000000", "0.00009000"], ["61611.94000000", "0.00000000"], ["61612.00000000", "0.00000000"], ["61612.01000000", "0.44786000"], ["61612.02000000", "0.00000000"], ["61612.03000000", "0.00000000"], ["61612.04000000", "0.00009000"], ["61612.32000000", "0.17274000"], ["61612.33000000", "0.00018000"], ["61612.72000000", "0.00034000"], ["61612.80000000", "0.75578000"], ["61612.81000000", "0.00042000"], ["61612.82000000", "0.25763000"], ["61612.92000000", "0.00400000"], ["61613.29000000", "0.00018000"], ["61613.30000000", "0.32768000"], ["61613.35000000", "0.00000000"], ["61613.43000000", "0.03000000"], ["61613.57000000", "1.36330000"], ["61613.58000000", "0.24786000"], ["61613.70000000", "0.00009000"], ["61613.71000000", "0.00904000"], ["61614.00000000", "0.00000000"], ["61614.01000000", "0.12027000"], ["61614.47000000", "0.00010000"], ["61614.72000000", "0.00010000"], ["61614.97000000", "0.00009000"], ["61614.99000000", "0.17966000"], ["61615.21000000", "0.04009000"], ["61615.33000000", "0.58485000"], ["61616.00000000", "0.00018000"], ["61616.17000000", "0.00000000"], ["61616.27000000", "0.00013000"], ["61616.66000000", "0.00991000"], ["61616.80000000", "0.00911000"], ["61617.29000000", "0.00152000"], ["61617.95000000", "0.00000000"], ["61618.01000000", "0.03945000"], ["61618.17000000", "0.00000000"], ["61618.49000000", "0.00000000"], ["61618.50000000", "0.61473000"], ["61618.90000000", "0.00000000"], ["61618.92000000", "0.00000000"], ["61619.06000000", "0.00400000"], ["61619.58000000", "0.20000000"], ["61619.74000000", "0.00000000"], ["61619.75000000", "0.24750000"], ["61619.78000000", "0.00000000"], ["61620.01000000", "0.01881000"], ["61620.53000000", "0.08755000"], ["61620.80000000", "0.00010000"], ["61621.19000000", "0.97390000"], ["61622.00000000", "0.00600000"], ["61622.07000000", "0.08891000"], ["61622.29000000", "0.28400000"], ["61622.33000000", "0.00010000"], ["61622.44000000", "0.00000000"], ["61622.50000000", "0.00193000"], ["61623.14000000", "0.00230000"], ["61623.95000000", "0.00000000"], ["61624.14000000", "0.00012000"], ["61624.36000000", "0.00000000"], ["61624.79000000", "0.00000000"], ["61625.41000000", "0.00010000"], ["61625.62000000", "0.00000000"], ["61625.90000000", "0.00000000"], ["61626.12000000", "0.00009000"], ["61627.23000000", "0.00419000"], ["61627.78000000", "0.01131000"], ["61627.88000000", "0.58473000"], ["61628.26000000", "0.02812000"], ["61628.49000000", "0.00172000"], ["61628.70000000", "0.00000000"], ["61629.97000000", "0.00000000"], ["61630.81000000", "0.85620000"], ["61630.82000000", "0.00000000"], ["61631.57000000", "0.00010000"], ["61631.78000000", "0.00000000"], ["61633.75000000", "0.00851000"], ["61634.32000000", "0.00628000"], ["61634.65000000", "0.00010000"], ["61634.86000000", "0.00000000"], ["61636.05000000", "0.00000000"], ["61636.87000000", "0.00000000"], ["61637.22000000", "1.50046000"], ["61637.73000000", "0.00010000"], ["61637.95000000", "0.00000000"], ["61638.19000000", "0.00162000"], ["61638.31000000", "0.03227000"], ["61639.02000000", "0.00420000"], ["61639.58000000", "0.00000000"], ["61640.00000000", "0.03400000"], ["61640.01000000", "0.00000000"], ["61640.25000000", "0.00000000"], ["61640.82000000", "0.00010000"], ["61641.03000000", "0.00000000"], ["61641.34000000", "0.00000000"], ["61642.35000000", "0.00013000"], ["61642.50000000", "0.00000000"], ["61643.37000000", "0.00000000"], ["61643.75000000", "0.00000000"], ["61644.11000000", "0.00000000"], ["61644.27000000", "0.00000000"], ["61645.00000000", "0.00000000"], ["61646.61000000", "0.00000000"], ["61646.85000000", "0.00847000"], ["61647.20000000", "0.00000000"], ["61647.71000000", "0.01714000"], ["61649.01000000", "0.00111000"], ["61650.30000000", "0.00400000"], ["61650.54000000", "0.00000000"], ["61651.03000000", "0.41692000"], ["61652.68000000", "0.97503000"], ["61652.80000000", "0.00000000"], ["61653.20000000", "0.00000000"], ["61653.31000000", "0.00539000"], ["61654.83000000", "0.01623000"], ["61655.06000000", "0.00000000"], ["61658.26000000", "0.01623000"], ["61658.84000000", "0.00405000"], ["61660.13000000", "0.00000000"], ["61661.61000000", "0.00000000"], ["61662.64000000", "0.00000000"], ["61662.79000000", "0.00000000"], ["61664.18000000", "0.24750000"], ["61667.38000000", "0.00000000"], ["61668.86000000", "0.00000000"], ["61670.83000000", "0.00000000"], ["61671.62000000", "0.00010000"], ["61671.66000000", "0.38092000"], ["61672.29000000", "0.00000000"], ["61677.67000000", "0.00000000"], ["61678.28000000", "0.00000000"], ["61679.28000000", "3.23295000"], ["61687.73000000", "0.00000000"], ["61688.08000000", "0.16151000"], ["61688.09000000", "0.97390000"], ["61691.15000000", "1.16784000"], ["61695.48000000", "0.00009000"], ["61696.74000000", "0.00000000"], ["61699.00000000", "0.07505000"], ["61701.36000000", "0.00000000"], ["61706.36000000", "0.00000000"], ["61709.60000000", "0.00000000"], ["61713.90000000", "0.00000000"], ["61730.65000000", "0.00000000"], ["61731.04000000", "0.00000000"], ["61733.23000000", "0.00010000"], ["61739.89000000", "0.00000000"], ["61753.32000000", "0.00000000"], ["61754.58000000", "0.00000000"], ["61759.48000000", "0.00000000"], ["61765.64000000", "0.00000000"], ["61776.64000000", "0.11532000"], ["61782.24000000", "0.11530000"], ["61783.66000000", "0.02766000"], ["61786.27000000", "0.01898000"], ["61786.93000000", "0.01910000"], ["61787.25000000", "0.01913000"], ["61794.84000000", "0.00010000"], ["61795.71000000", "0.00000000"], ["61797.75000000", "0.00000000"], ["61801.51000000", "0.00000000"], ["61803.67000000", "0.02406000"], ["61813.58000000", "0.00000000"], ["61816.89000000", "0.00000000"], ["61822.90000000", "0.00000000"], ["61823.33000000", "0.00000000"], ["61823.53000000", "0.00000000"], ["61826.90000000", "0.00000000"], ["61826.94000000", "0.00000000"], ["61846.20000000", "0.00000000"], ["61847.18000000", "0.00000000"], ["61847.56000000", "0.00000000"], ["61856.45000000", "0.00010000"], ["61863.13000000", "0.00013000"], ["61918.06000000", "0.00010000"], ["61924.74000000", "0.00000000"], ["61979.67000000", "0.00010000"], ["61986.36000000", "0.00000000"], ["62041.28000000", "0.00010000"], ["62047.98000000", "0.00000000"], ["62102.89000000", "0.00010000"], ["62109.59000000", "0.00000000"]]}
{"type": "depth", "ts": 1783008091314, "U": 96863155985, "u": 96863156189, "bids": [["61608.20000000", "0.30213000"], ["61608.19000000", "0.00045000"], ["61607.82000000", "0.03041000"], ["61606.71000000", "0.00000000"], ["61606.16000000", "0.00526000"], ["61606.11000000", "0.00000000"], ["61606.00000000", "0.02418000"], ["61605.35000000", "0.00000000"], ["61604.73000000", "0.04727000"], ["61604.00000000", "0.02427000"], ["61603.99000000", "0.02866000"], ["61603.57000000", "0.00000000"], ["61603.56000000", "0.00018000"], ["61603.01000000", "0.00009000"], ["61603.00000000", "0.09007000"], ["61602.51000000", "0.00009000"], ["61602.50000000", "0.13517000"], ["61602.02000000", "0.00000000"], ["61602.01000000", "0.00009000"], ["61601.87000000", "0.00000000"], ["61600.32000000", "0.00009000"], ["61600.01000000", "0.00000000"], ["61598.41000000", "0.81311000"], ["61598.39000000", "0.00000000"], ["61597.52000000", "0.00000000"], ["61597.42000000", "0.08775000"], ["61597.39000000", "0.00009000"], ["61597.18000000", "0.00488000"], ["61596.50000000", "0.00000000"], ["61596.12000000", "0.00009000"], ["61596.05000000", "0.00000000"], ["61595.75000000", "0.01000000"], ["61595.11000000", "0.00047000"], ["61594.40000000", "0.00000000"], ["61593.51000000", "0.00000000"], ["61592.92000000", "0.01000000"], ["61588.65000000", "0.00000000"], ["61584.04000000", "0.00000000"], ["61576.21000000", "0.00000000"], ["61568.09000000", "0.00000000"], ["61564.86000000", "0.01400000"], ["61562.60000000", "0.00000000"], ["61557.91000000", "0.02478000"], ["61556.22000000", "0.00000000"], ["61555.33000000", "0.00631000"], ["61555.27000000", "0.00433000"], ["61554.61000000", "0.00000000"], ["61553.33000000", "0.00430000"], ["61553.20000000", "0.01000000"], ["61547.60000000", "0.00000000"], ["61546.90000000", "0.96973000"], ["61546.71000000", "0.00000000"], ["61537.42000000", "0.01153000"], ["61534.74000000", "0.67019000"], ["61518.51000000", "0.00000000"], ["61515.95000000", "0.00000000"], ["61496.96000000", "0.04613000"], ["61486.19000000", "0.00845000"], ["61414.22000000", "0.00000000"], ["61377.05000000", "0.11334000"], ["61372.14000000", "0.11544000"], ["56701.45000000", "0.00018000"], ["55452.00000000", "0.13648000"], ["55447.38000000", "0.00060000"]], "asks": [["61608.21000000", "4.54724000"], ["61608.29000000", "0.48401000"], ["61608.30000000", "0.00027000"], ["61608.31000000", "0.43477000"], ["61609.89000000", "0.00018000"], ["61609.97000000", "0.11193000"], ["61610.00000000", "0.05118000"], ["61610.01000000", "0.08036000"], ["61610.50000000", "0.04235000"], ["61610.76000000", "0.04064000"], ["61611.92000000", "0.11599000"], ["61612.01000000", "0.08018000"], ["61612.33000000", "0.00000000"], ["61612.81000000", "0.00024000"], ["61612.82000000", "0.00986000"], ["61613.29000000", "0.00000000"], ["61613.30000000", "0.08018000"], ["61613.58000000", "0.00036000"], ["61618.89000000", "0.00000000"], ["61624.00000000", "0.01613000"], ["61626.00000000", "0.01540000"], ["61628.00000000", "0.01900000"], ["61629.16000000", "0.00324000"], ["61630.00000000", "0.01900000"], ["61632.00000000", "0.01900000"], ["61633.01000000", "0.00000000"], ["61633.75000000", "0.00432000"], ["61637.13000000", "0.00436000"], ["61637.35000000", "0.00424000"], ["61637.63000000", "0.00000000"], ["61649.72000000", "0.08246000"], ["61650.56000000", "0.09284000"], ["61652.68000000", "0.00000000"], ["61653.11000000", "0.00000000"], ["61654.24000000", "0.00000000"], ["61655.71000000", "0.97503000"], ["61664.12000000", "0.04623000"], ["61676.66000000", "0.01300000"], ["61676.95000000", "0.01100000"], ["61677.09000000", "1.77361000"], ["61680.97000000", "0.00000000"], ["61684.02000000", "0.00000000"], ["61688.08000000", "0.35134000"], ["61702.26000000", "0.00000000"], ["61753.33000000", "0.24750000"], ["61759.50000000", "0.24750000"], ["61765.67000000", "0.24750000"], ["61771.84000000", "0.24750000"], ["61803.92000000", "0.00497000"], ["61804.59000000", "0.07719000"], ["62532.34000000", "0.00030000"]]}
{"type": "depth", "ts": 1783008091414, "U": 96863156190, "u": 96863156281, "bids": [["61608.20000000", "0.27132000"], ["61606.03000000", "0.00009000"], ["61606.02000000", "0.09093000"], ["61604.00000000", "0.02427000"], ["61603.99000000", "0.02884000"], ["61603.56000000", "0.00000000"], ["61602.50000000", "0.09246000"], ["61602.49000000", "0.00000000"], ["61602.34000000", "0.00000000"], ["61599.38000000", "0.08775000"], ["61598.56000000", "0.03142000"], ["61597.42000000", "0.00000000"], ["61596.03000000", "0.00000000"], ["61595.74000000", "0.01015000"], ["61595.47000000", "0.03142000"], ["61594.39000000", "0.00897000"], ["61593.91000000", "0.01000000"], ["61592.61000000", "0.02000000"], ["61592.39000000", "0.02094000"], ["61589.31000000", "0.02095000"], ["61581.91000000", "0.01200000"], ["61581.35000000", "0.47970000"], ["61581.34000000", "0.58517000"], ["61581.20000000", "0.00000000"], ["61553.10000000", "0.00000000"], ["61552.80000000", "0.01000000"], ["61551.06000000", "0.01000000"], ["61532.02000000", "0.45243000"], ["61532.01000000", "0.82057000"], ["61531.99000000", "0.00000000"], ["61509.22000000", "0.00016000"], ["61506.38000000", "0.00000000"], ["55447.38000000", "0.00080000"]], "asks": [["61608.21000000", "4.55509000"], ["61608.22000000", "0.00035000"], ["61608.29000000", "0.29144000"], ["61608.30000000", "0.00000000"], ["61608.31000000", "0.18727000"], ["61609.89000000", "0.00000000"], ["61609.97000000", "0.11211000"], ["61612.80000000", "0.33954000"], ["61614.99000000", "0.17808000"], ["61615.20000000", "0.06655000"], ["61615.40000000", "0.00009000"], ["61621.74000000", "0.01100000"], ["61622.01000000", "0.00000000"], ["61623.03000000", "0.01000000"], ["61639.26000000", "0.00000000"], ["61650.58000000", "0.00000000"], ["61653.67000000", "0.00000000"], ["61655.71000000", "0.00000000"], ["61656.39000000", "0.97503000"], ["61656.75000000", "0.00000000"], ["61659.83000000", "0.00000000"], ["61682.01000000", "0.01100000"], ["61691.18000000", "0.05037000"], ["61710.88000000", "0.00000000"], ["61778.01000000", "0.24750000"]]}
{"type": "depth", "ts": 1783008091514, "U": 96863156282, "u": 96863156510, "bids": [["61608.20000000", "0.00000000"], ["61608.19000000", "0.00000000"], ["61608.11000000", "0.00000000"], ["61608.01000000", "0.00000000"], ["61608.00000000", "0.02554000"], ["61607.99000000", "0.00045000"], ["61606.16000000", "0.00526000"], ["61606.03000000", "0.00000000"], ["61606.02000000", "0.00018000"], ["61604.00000000", "0.02418000"], ["61603.99000000", "0.00018000"], ["61603.65000000", "0.00009000"], ["61603.64000000", "0.00000000"], ["61603.58000000", "0.01049000"], ["61603.54000000", "0.00000000"], ["61603.00000000", "0.00009000"], ["61601.87000000", "0.00009000"], ["61601.70000000", "0.00009000"], ["61600.32000000", "0.00000000"], ["61598.40000000", "0.00000000"], ["61597.91000000", "0.00649000"], ["61595.74000000", "0.00000000"], ["61595.11000000", "0.01028000"], ["61594.39000000", "0.00000000"], ["61593.83000000", "0.00000000"], ["61593.76000000", "0.00905000"], ["61593.03000000", "0.07000000"], ["61592.68000000", "0.01200000"], ["61585.45000000", "0.00000000"], ["61581.91000000", "0.00000000"], ["61581.89000000", "0.00000000"], ["61561.68000000", "0.00019000"], ["61554.45000000", "0.00000000"], ["61552.80000000", "0.00000000"], ["61551.07000000", "0.02200000"], ["61532.24000000", "0.00009000"], ["61504.77000000", "0.05746000"], ["61499.05000000", "0.00024000"], ["61420.75000000", "0.01002000"], ["61379.33000000", "0.00000000"], ["61369.36000000", "0.02543000"], ["55447.38000000", "0.00000000"], ["49286.56000000", "0.00000000"]], "asks": [["61608.01000000", "4.55083000"], ["61608.02000000", "0.00311000"], ["61608.03000000", "0.00017000"], ["61608.12000000", "0.00000000"], ["61608.19000000", "1.46684000"], ["61608.20000000", "0.87305000"], ["61608.21000000", "0.27598000"], ["61608.22000000", "0.00000000"], ["61608.23000000", "0.00000000"], ["61608.29000000", "0.00018000"], ["61608.31000000", "0.20603000"], ["61609.26000000", "0.16231000"], ["61609.90000000", "0.00000000"], ["61609.97000000", "0.00018000"], ["61610.01000000", "0.08941000"], ["61611.10000000", "0.06597000"], ["61611.81000000", "0.15374000"], ["61612.80000000", "0.69907000"], ["61614.18000000", "0.04398000"], ["61615.21000000", "0.00009000"], ["61617.26000000", "0.04398000"], ["61617.99000000", "0.60500000"], ["61620.01000000", "0.00999000"], ["61621.18000000", "1.36330000"], ["61622.97000000", "0.01000000"], ["61625.72000000", "0.00323000"], ["61627.56000000", "0.00000000"], ["61629.59000000", "0.01000000"], ["61629.65000000", "0.01200000"], ["61632.73000000", "1.36330000"], ["61636.64000000", "0.00000000"], ["61667.99000000", "0.06413000"], ["61670.77000000", "0.13522000"], ["61682.01000000", "0.00000000"], ["61682.97000000", "0.00000000"], ["61685.56000000", "0.00000000"], ["61903.72000000", "0.55052000"], ["61933.47000000", "0.00000000"]]}
{"type": "depth", "ts": 1783008091614, "U": 96863156511, "u": 96863156637, "bids": [["61608.00000000", "0.02505000"], ["61606.58000000", "0.00000000"], ["61606.16000000", "0.00526000"], ["61606.02000000", "0.00000000"], ["61605.04000000", "0.00009000"], ["61604.00000000", "0.02418000"], ["61603.99000000", "0.00000000"], ["61603.65000000", "0.00000000"], ["61603.58000000", "0.01067000"], ["61603.01000000", "0.00000000"], ["61602.51000000", "0.00000000"], ["61602.50000000", "0.00027000"], ["61601.88000000", "0.00009000"], ["61601.87000000", "0.00009000"], ["61601.83000000", "0.00300000"], ["61600.41000000", "0.00497000"], ["61600.01000000", "0.00009000"], ["61599.39000000", "0.00000000"], ["61599.38000000", "0.00000000"], ["61598.42000000", "0.09065000"], ["61598.41000000", "0.49877000"], ["61597.21000000", "0.08611000"], ["61595.66000000", "0.00300000"], ["61595.11000000", "0.00047000"], ["61593.76000000", "0.00000000"], ["61593.31000000", "0.01000000"], ["61592.69000000", "0.01300000"], ["61591.81000000", "0.00000000"], ["61591.64000000", "0.00908000"], ["61583.63000000", "0.00000000"], ["61579.29000000", "0.01624000"], ["61562.63000000", "0.00000000"], ["61551.68000000", "0.01000000"], ["61551.53000000", "0.01300000"], ["61550.80000000", "0.00000000"], ["61518.49000000", "0.00000000"], ["61420.76000000", "0.00162000"], ["55447.20000000", "0.00040000"], ["45000.00000000", "269.97530000"]], "asks": [["61608.01000000", "5.09792000"], ["61608.05000000", "0.05000000"], ["61608.10000000", "0.05000000"], ["61608.19000000", "0.45823000"], ["61608.20000000", "0.29868000"], ["61608.21000000", "0.24777000"], ["61608.29000000", "0.00000000"], ["61608.31000000", "0.20594000"], ["61609.97000000", "0.00000000"], ["61610.01000000", "0.08950000"], ["61610.76000000", "0.04046000"], ["61613.49000000", "0.00009000"], ["61614.18000000", "0.04698000"], ["61616.00000000", "0.00009000"], ["61616.51000000", "0.00009000"], ["61617.07000000", "0.01100000"], ["61617.69000000", "0.01000000"], ["61618.50000000", "0.97273000"], ["61620.35000000", "0.00300000"], ["61625.09000000", "0.00000000"], ["61628.35000000", "0.00000000"], ["61630.17000000", "0.00000000"], ["61639.00000000", "0.01000000"], ["61640.00000000", "0.02400000"], ["61641.00000000", "0.00400000"], ["61650.30000000", "0.00000000"], ["61656.18000000", "0.00000000"], ["61669.21000000", "0.01000000"], ["61681.13000000", "0.49630000"], ["61684.19000000", "0.48846000"]]}
{"type": "depth", "ts": 1783008091714, "U": 96863156638, "u": 96863156689, "bids": [["61608.00000000", "0.02514000"], ["61603.58000000", "0.01067000"], ["61602.74000000", "0.00009000"], ["61602.73000000", "0.09247000"], ["61602.50000000", "0.00009000"], ["61602.00000000", "0.02418000"], ["61601.88000000", "0.00000000"], ["61599.11000000", "0.00009000"], ["61582.52000000", "0.00000000"], ["61582.37000000", "0.00000000"], ["61552.31000000", "0.00434000"], ["61551.53000000", "0.00000000"], ["61547.66000000", "0.00000000"], ["61468.09000000", "0.00040000"], ["55447.20000000", "0.00080000"], ["49286.40000000", "0.00000000"]], "asks": [["61608.01000000", "5.12776000"], ["61608.05000000", "0.05027000"], ["61608.10000000", "0.05018000"], ["61608.20000000", "0.05118000"], ["61608.21000000", "0.00027000"], ["61610.01000000", "0.08932000"], ["61610.50000000", "0.04217000"], ["61614.01000000", "0.12018000"], ["61615.21000000", "0.00000000"], ["61618.01000000", "0.00969000"], ["61618.48000000", "0.00009000"], ["61628.98000000", "0.00000000"], ["61629.59000000", "0.00000000"], ["61634.83000000", "0.00649000"], ["61669.21000000", "0.00000000"], ["61701.93000000", "0.00016000"], ["61705.16000000", "0.00024000"], ["61707.80000000", "0.00000000"]]}
