{"type": "depth", "ts": 1783008091814, "U": 96863156690, "u": 96863156718, "bids": [["61607.49000000", "0.00009000"], ["61603.58000000", "0.01067000"], ["61602.00000000", "0.02400000"], ["61591.64000000", "0.00000000"], ["61591.63000000", "0.00908000"], ["61591.51000000", "0.00009000"], ["61575.44000000", "0.00419000"], ["61420.75000000", "0.01017000"], ["55447.20000000", "0.00120000"], ["49286.00000000", "0.00442000"]], "asks": [["61608.01000000", "5.12777000"], ["61608.20000000", "0.05118000"], ["61608.21000000", "0.00009000"], ["61609.26000000", "0.16249000"], ["61610.01000000", "0.08950000"], ["61611.80000000", "0.01200000"], ["67768.81000000", "0.00009000"]]}
{"type": "depth", "ts": 1783008091914, "U": 96863156719, "u": 96863156743, "bids": [["61608.00000000", "0.02496000"], ["61602.74000000", "0.00000000"], ["61602.73000000", "0.00000000"], ["61601.87000000", "0.06045000"], ["61597.91000000", "0.00000000"], ["61575.44000000", "0.00000000"], ["61554.37000000", "0.13651000"], ["61509.22000000", "0.00000000"], ["61499.05000000", "0.00000000"], ["61468.09000000", "0.00000000"], ["56701.45000000", "0.00000000"], ["55447.20000000", "0.00160000"], ["49286.00000000", "0.00242000"]], "asks": [["61608.01000000", "5.09802000"], ["61617.45000000", "0.97390000"], ["61634.83000000", "0.00000000"], ["61639.55000000", "0.00000000"], ["61653.79000000", "0.01000000"], ["61701.93000000", "0.00000000"], ["61705.16000000", "0.00000000"], ["61709.46000000", "0.00040000"], ["61723.25000000", "0.00000000"], ["67768.81000000", "0.00000000"]]}
{"type": "depth", "ts": 1783008092014, "U": 96863156744, "u": 96863156925, "bids": [["61608.00000000", "0.00000000"], ["61607.99000000", "0.00000000"], ["61607.83000000", "0.00000000"], ["61607.82000000", "0.03148000"], ["61607.81000000", "0.00053000"], ["61607.80000000", "0.00017000"], ["61603.58000000", "0.01067000"], ["61602.00000000", "0.02418000"], ["61601.88000000", "0.00009000"], ["61601.87000000", "0.00027000"], ["61600.41000000", "0.00009000"], ["61598.18000000", "0.08775000"], ["61593.23000000", "0.00000000"], ["61591.63000000", "0.00000000"], ["61591.21000000", "0.00883000"], ["61579.29000000", "0.00000000"], ["61565.85000000", "0.00000000"], ["61554.37000000", "0.00000000"], ["61491.10000000", "0.09757000"], ["60683.88000000", "0.00000000"], ["55456.20000000", "0.00000000"], ["55447.20000000", "0.00010000"], ["55447.04000000", "0.00020000"], ["49286.40000000", "0.00040000"]], "asks": [["61607.83000000", "5.49216000"], ["61607.84000000", "0.00035000"], ["61607.85000000", "0.00017000"], ["61608.00000000", "2.99816000"], ["61608.01000000", "0.34533000"], ["61608.02000000", "0.00000000"], ["61608.03000000", "0.00000000"], ["61608.05000000", "0.00027000"], ["61608.10000000", "0.00018000"], ["61608.19000000", "0.00018000"], ["61610.01000000", "0.08932000"], ["61611.91000000", "0.00000000"], ["61613.56000000", "0.97581000"], ["61617.44000000", "0.93388000"], ["61617.93000000", "0.00000000"], ["61617.99000000", "0.00000000"], ["61620.33000000", "0.00009000"], ["61625.74000000", "0.00000000"], ["61626.30000000", "0.04709000"], ["61629.16000000", "0.00000000"], ["61629.99000000", "0.00000000"], ["61630.20000000", "0.00000000"], ["61630.49000000", "0.00024000"], ["61636.72000000", "0.00000000"], ["61637.30000000", "0.00009000"], ["61638.85000000", "0.00000000"], ["61709.46000000", "0.00000000"], ["61715.85000000", "0.00000000"], ["62532.34000000", "0.00000000"]]}
{"type": "depth", "ts": 1783008092114, "U": 96863156926, "u": 96863157497, "bids": [["61607.82000000", "0.00000000"], ["61607.81000000", "0.00000000"], ["61607.80000000", "0.00000000"], ["61607.49000000", "0.00000000"], ["61606.53000000", "0.00000000"], ["61606.52000000", "0.00000000"], ["61606.16000000", "0.00000000"], ["61606.01000000", "0.00000000"], ["61606.00000000", "0.02500000"], ["61605.99000000", "0.00054000"], ["61605.04000000", "0.00000000"], ["61604.44000000", "0.00000000"], ["61603.81000000", "0.00009000"], ["61603.59000000", "0.00000000"], ["61603.58000000", "0.00018000"], ["61603.07000000", "0.00000000"], ["61602.56000000", "0.00000000"], ["61602.26000000", "0.00000000"], ["61602.14000000", "0.00000000"], ["61602.00000000", "0.02418000"], ["61601.93000000", "0.00000000"], ["61601.88000000", "0.00000000"], ["61601.87000000", "0.00000000"], ["61601.86000000", "0.00018000"], ["61601.58000000", "0.01071000"], ["61601.42000000", "0.00000000"], ["61600.54000000", "0.00000000"], ["61600.41000000", "0.00000000"], ["61600.40000000", "0.00027000"], ["61600.37000000", "0.00010000"], ["61600.00000000", "0.07756000"], ["61599.75000000", "0.00000000"], ["61599.45000000", "0.09066000"], ["61599.11000000", "0.00000000"], ["61599.10000000", "0.00018000"], ["61598.66000000", "0.00009000"], ["61598.65000000", "0.07697000"], ["61598.57000000", "0.00009000"], ["61598.56000000", "0.00000000"], ["61598.43000000", "0.00009000"], ["61598.42000000", "0.09075000"], ["61598.19000000", "0.00009000"], ["61597.68000000", "0.00000000"], ["61597.51000000", "0.00000000"], ["61597.39000000", "0.00000000"], ["61597.31000000", "0.00032000"], ["61597.21000000", "0.09066000"], ["61597.18000000", "1.36330000"], ["61597.17000000", "0.00000000"], ["61595.47000000", "0.00000000"], ["61595.30000000", "0.02191000"], ["61594.60000000", "0.97790000"], ["61594.56000000", "0.00000000"], ["61594.47000000", "0.00000000"], ["61594.21000000", "0.00010000"], ["61593.46000000", "0.00047000"], ["61592.93000000", "0.08009000"], ["61592.39000000", "0.00000000"], ["61592.23000000", "0.43248000"], ["61591.52000000", "0.00000000"], ["61591.41000000", "0.00000000"], ["61591.13000000", "0.00010000"], ["61591.07000000", "0.00191000"], ["61589.31000000", "0.00000000"], ["61588.44000000", "0.00000000"], ["61588.05000000", "0.00010000"], ["61587.48000000", "0.00009000"], ["61587.17000000", "0.49020000"], ["61587.16000000", "0.60938000"], ["61586.58000000", "0.00000000"], ["61585.36000000", "0.00000000"], ["61584.97000000", "0.00010000"], ["61584.55000000", "0.00000000"], ["61582.28000000", "0.00000000"], ["61581.89000000", "0.00010000"], ["61581.35000000", "0.00000000"], ["61581.34000000", "0.00000000"], ["61580.76000000", "0.00400000"], ["61579.20000000", "0.00000000"], ["61578.82000000", "0.12900000"], ["61578.81000000", "0.00010000"], ["61578.80000000", "0.12500000"], ["61577.00000000", "0.00000000"], ["61575.73000000", "0.00044000"], ["61575.35000000", "0.00009000"], ["61575.00000000", "0.01000000"], ["61571.89000000", "0.47248000"], ["61571.14000000", "0.00000000"], ["61568.09000000", "0.00009000"], ["61565.35000000", "0.63724000"], ["61563.49000000", "0.58534000"], ["61553.80000000", "0.00009000"], ["61553.27000000", "0.58676000"], ["61553.26000000", "0.00000000"], ["61552.10000000", "0.00000000"], ["61551.90000000", "0.00400000"], ["61551.73000000", "0.00000000"], ["61541.22000000", "1.43910000"], ["61541.21000000", "0.00000000"], ["61541.18000000", "0.00000000"], ["61540.53000000", "0.00000000"], ["61539.99000000", "0.00000000"], ["61534.74000000", "0.92869000"], ["61533.81000000", "0.97390000"], ["61532.01000000", "0.00000000"], ["61530.36000000", "0.00030000"], ["61529.16000000", "0.00009000"], ["61526.02000000", "0.17071000"], ["61525.01000000", "0.00000000"], ["61451.61000000", "0.00105000"], ["61356.16000000", "0.24750000"], ["61353.79000000", "4.89454000"], ["61345.79000000", "0.00048000"], ["55447.04000000", "0.00000000"], ["55445.40000000", "0.00020000"], ["49294.00000000", "0.00800000"]], "asks": [["61606.01000000", "4.27186000"], ["61606.02000000", "0.00035000"], ["61606.03000000", "0.00017000"], ["61606.16000000", "0.05109000"], ["61606.17000000", "0.01479000"], ["61606.18000000", "0.00009000"], ["61606.52000000", "0.52138000"], ["61606.53000000", "0.05100000"], ["61606.54000000", "0.23392000"], ["61606.55000000", "0.00000000"], ["61606.56000000", "0.00000000"], ["61607.48000000", "0.00000000"], ["61607.50000000", "0.00000000"], ["61607.60000000", "0.16232000"], ["61607.80000000", "0.00009000"], ["61607.81000000", "0.00000000"], ["61607.82000000", "0.05124000"], ["61607.83000000", "0.02870000"], ["61607.84000000", "0.00000000"], ["61607.85000000", "0.00000000"], ["61607.99000000", "0.00000000"], ["61608.00000000", "1.36348000"], ["61608.01000000", "0.24811000"], ["61608.05000000", "0.00000000"], ["61608.10000000", "0.00000000"], ["61608.19000000", "0.00000000"], ["61608.20000000", "0.00018000"], ["61608.31000000", "0.11828000"], ["61608.79000000", "0.00000000"], ["61609.26000000", "0.00018000"], ["61609.99000000", "0.24719000"], ["61610.00000000", "0.00018000"], ["61610.01000000", "0.08932000"], ["61611.10000000", "0.00000000"], ["61611.81000000", "0.15365000"], ["61611.92000000", "0.11590000"], ["61611.93000000", "0.00000000"], ["61612.32000000", "0.17292000"], ["61612.39000000", "0.58488000"], ["61612.70000000", "0.00010000"], ["61612.81000000", "0.00000000"], ["61613.30000000", "0.00027000"], ["61613.70000000", "0.00018000"], ["61613.71000000", "0.00895000"], ["61614.01000000", "0.00000000"], ["61614.18000000", "0.00300000"], ["61614.47000000", "0.00000000"], ["61614.99000000", "0.17799000"], ["61615.20000000", "0.06646000"], ["61615.50000000", "0.00000000"], ["61615.87000000", "0.08755000"], ["61617.26000000", "0.00000000"], ["61617.41000000", "0.08891000"], ["61617.66000000", "0.60500000"], ["61618.01000000", "0.00941000"], ["61618.86000000", "0.00010000"], ["61619.84000000", "0.00825000"], ["61620.53000000", "0.00000000"], ["61621.94000000", "0.00010000"], ["61622.07000000", "0.00000000"], ["61622.33000000", "0.00000000"], ["61624.45000000", "0.00009000"], ["61624.90000000", "0.93579000"], ["61625.02000000", "0.00010000"], ["61625.41000000", "0.00000000"], ["61626.26000000", "1.60805000"], ["61626.88000000", "0.00034000"], ["61627.88000000", "0.00000000"], ["61628.10000000", "0.00010000"], ["61628.49000000", "0.00162000"], ["61628.81000000", "0.00324000"], ["61630.81000000", "1.23632000"], ["61631.18000000", "0.00010000"], ["61631.57000000", "0.00000000"], ["61632.82000000", "0.64163000"], ["61633.33000000", "0.01156000"], ["61634.26000000", "0.00010000"], ["61634.65000000", "0.00000000"], ["61634.91000000", "0.03244000"], ["61637.30000000", "0.00000000"], ["61637.34000000", "0.00010000"], ["61637.73000000", "0.00000000"], ["61638.31000000", "0.00000000"], ["61638.41000000", "0.00000000"], ["61639.00000000", "0.00000000"], ["61639.24000000", "0.00009000"], ["61640.82000000", "0.00000000"], ["61641.31000000", "0.00000000"], ["61649.71000000", "0.00194000"], ["61654.00000000", "0.02400000"], ["61655.65000000", "0.96522000"], ["61658.29000000", "0.00000000"], ["61662.76000000", "0.00000000"], ["61684.38000000", "0.00030000"], ["61689.65000000", "0.00000000"], ["61691.15000000", "0.31744000"], ["61693.31000000", "0.00000000"], ["61694.57000000", "0.00000000"], ["61701.10000000", "0.00000000"], ["61706.80000000", "0.00000000"], ["61713.29000000", "0.00000000"], ["61721.99000000", "0.00000000"], ["61915.84000000", "0.00000000"]]}
{"type": "depth", "ts": 1783008092214, "U": 96863157498, "u": 96863157650, "bids": [["61606.00000000", "0.01905000"], ["61605.99000000", "0.00045000"], ["61604.74000000", "0.00000000"], ["61604.73000000", "0.00018000"], ["61604.00000000", "0.02418000"], ["61603.58000000", "0.00000000"], ["61602.53000000", "0.00034000"], ["61602.00000000", "0.02418000"], ["61601.86000000", "0.00000000"], ["61601.59000000", "0.00009000"], ["61601.58000000", "0.01089000"], ["61600.40000000", "0.00009000"], ["61600.00000000", "0.07747000"], ["61599.46000000", "0.00009000"], ["61599.45000000", "0.09093000"], ["61599.28000000", "0.00000000"], ["61599.10000000", "0.00000000"], ["61599.04000000", "0.01018000"], ["61598.98000000", "0.01018000"], ["61598.66000000", "0.00000000"], ["61598.65000000", "0.00000000"], ["61598.57000000", "0.00000000"], ["61598.41000000", "0.00009000"], ["61598.19000000", "0.00000000"], ["61598.18000000", "0.00000000"], ["61597.22000000", "0.00009000"], ["61597.19000000", "0.00009000"], ["61597.18000000", "0.00000000"], ["61596.36000000", "0.03142000"], ["61594.60000000", "0.00400000"], ["61594.46000000", "0.00000000"], ["61594.04000000", "0.04709000"], ["61593.27000000", "0.03142000"], ["61592.34000000", "0.00649000"], ["61591.58000000", "0.00153000"], ["61591.53000000", "0.00000000"], ["61591.21000000", "0.00000000"], ["61591.03000000", "0.00000000"], ["61590.19000000", "0.02095000"], ["61587.43000000", "0.02000000"], ["61587.11000000", "0.02095000"], ["61580.52000000", "0.35927000"], ["61565.16000000", "0.00009000"], ["61549.20000000", "0.00400000"], ["61532.02000000", "0.20761000"], ["61510.61000000", "1.18623000"], ["61508.91000000", "3.24191000"], ["61503.66000000", "0.00016000"], ["61493.49000000", "0.00024000"], ["60681.91000000", "0.00030000"], ["55445.40000000", "0.00060000"], ["49286.40000000", "0.00000000"]], "asks": [["61606.01000000", "4.88622000"], ["61606.16000000", "0.05136000"], ["61606.17000000", "0.01497000"], ["61606.38000000", "0.04217000"], ["61606.52000000", "0.52156000"], ["61606.53000000", "0.05118000"], ["61606.54000000", "0.23410000"], ["61607.60000000", "0.16250000"], ["61607.83000000", "0.00870000"], ["61608.00000000", "1.36330000"], ["61608.01000000", "0.00034000"], ["61608.20000000", "0.00000000"], ["61608.31000000", "0.11792000"], ["61609.10000000", "0.06597000"], ["61609.26000000", "0.00000000"], ["61609.38000000", "0.00156000"], ["61610.00000000", "0.00000000"], ["61610.01000000", "0.08923000"], ["61612.18000000", "0.04398000"], ["61612.95000000", "0.01800000"], ["61613.00000000", "0.01400000"], ["61613.56000000", "0.98781000"], ["61613.58000000", "0.00018000"], ["61613.62000000", "0.01100000"], ["61614.00000000", "0.00500000"], ["61615.26000000", "0.04398000"], ["61616.03000000", "0.01000000"], ["61616.70000000", "0.01200000"], ["61617.29000000", "0.00000000"], ["61618.01000000", "0.00026000"], ["61637.00000000", "0.01000000"], ["61638.00000000", "0.02400000"], ["61643.83000000", "0.01400000"], ["61644.40000000", "0.01200000"], ["61644.45000000", "0.01100000"], ["61646.86000000", "0.01000000"], ["61647.54000000", "0.01200000"], ["61668.96000000", "0.04591000"], ["61785.08000000", "0.09711000"], ["61792.63000000", "0.00000000"]]}
{"type": "depth", "ts": 1783008092314, "U": 96863157651, "u": 96863157728, "bids": [["61606.00000000", "0.01923000"], ["61605.65000000", "0.00009000"], ["61604.73000000", "0.00000000"], ["61602.19000000", "0.00000000"], ["61598.98000000", "0.01018000"], ["61598.42000000", "0.09084000"], ["61598.01000000", "0.00009000"], ["61597.19000000", "0.00000000"], ["61596.51000000", "0.00009000"], ["61596.50000000", "0.84191000"], ["61596.04000000", "0.00034000"], ["61594.60000000", "0.97790000"], ["61594.46000000", "0.00009000"], ["61593.37000000", "0.00000000"], ["61591.53000000", "0.00009000"], ["61590.98000000", "1.36330000"], ["61590.37000000", "0.98399000"], ["61580.37000000", "0.00000000"], ["61578.90000000", "0.00000000"], ["61568.36000000", "0.00192000"], ["61565.16000000", "0.00000000"], ["61554.61000000", "0.01000000"], ["61525.52000000", "0.00000000"], ["61472.99000000", "0.00100000"], ["55445.40000000", "0.00100000"]], "asks": [["61606.01000000", "4.89451000"], ["61606.17000000", "0.01497000"], ["61607.83000000", "0.00040000"], ["61608.31000000", "0.11801000"], ["61612.01000000", "0.08027000"], ["61612.18000000", "0.29148000"], ["61613.30000000", "0.00018000"], ["61613.31000000", "0.00000000"], ["61613.56000000", "1.00081000"], ["61613.58000000", "0.00000000"], ["61613.62000000", "0.02200000"], ["61616.00000000", "0.00509000"], ["61616.40000000", "0.01000000"], ["61618.00000000", "0.15865000"], ["61619.17000000", "0.00009000"], ["61620.00000000", "0.00500000"], ["61622.00000000", "0.01100000"], ["61624.00000000", "0.02113000"], ["61624.92000000", "0.53770000"], ["61626.00000000", "0.02040000"], ["61628.00000000", "0.02400000"], ["61630.00000000", "0.02400000"], ["61632.00000000", "0.02400000"], ["61644.39000000", "0.01300000"], ["61644.46000000", "0.01100000"], ["61646.63000000", "0.00100000"], ["61647.23000000", "0.01000000"], ["61661.25000000", "0.00000000"], ["61662.56000000", "0.00000000"], ["61663.12000000", "0.00000000"], ["61676.66000000", "0.00000000"], ["61677.98000000", "0.00000000"], ["61678.54000000", "0.00000000"], ["61816.71000000", "0.00000000"], ["61911.55000000", "0.00100000"], ["62032.14000000", "0.00000000"], ["62530.11000000", "0.00030000"]]}
{"type": "depth", "ts": 1783008092414, "U": 96863157729, "u": 96863157752, "bids": [["61597.53000000", "0.10328000"], ["61569.80000000", "0.00012000"], ["61561.68000000", "0.00063000"], ["61554.60000000", "0.00400000"], ["61552.80000000", "0.01000000"], ["61549.20000000", "0.00000000"], ["61462.53000000", "0.00040000"], ["55445.40000000", "0.00140000"]], "asks": [["61606.52000000", "0.52466000"], ["61606.53000000", "0.05290000"], ["61615.41000000", "0.01100000"], ["61616.70000000", "0.02200000"], ["61647.53000000", "0.01000000"], ["61661.53000000", "0.00000000"], ["61663.18000000", "0.00000000"], ["61676.95000000", "0.00000000"], ["61678.60000000", "0.00000000"], ["61682.00000000", "0.03999000"], ["61696.35000000", "0.00016000"], ["61722.80000000", "0.02543000"], ["61807.43000000", "0.00000000"]]}
{"type": "depth", "ts": 1783008092514, "U": 96863157753, "u": 96863157775, "bids": [["61597.54000000", "0.00009000"], ["61596.51000000", "0.00000000"], ["61594.60000000", "0.00400000"], ["61571.84000000", "0.25169000"], ["55445.40000000", "0.00180000"], ["49284.80000000", "0.00000000"]], "asks": [["61606.01000000", "4.89460000"], ["61616.65000000", "0.15932000"], ["61617.66000000", "0.00000000"], ["61622.97000000", "0.00000000"], ["61623.03000000", "0.00000000"], ["61623.84000000", "0.00327000"], ["61625.72000000", "0.00000000"], ["61647.48000000", "0.01000000"], ["61664.08000000", "0.00000000"], ["61666.26000000", "0.00000000"], ["61679.42000000", "0.00000000"], ["61679.50000000", "0.00000000"], ["61681.68000000", "0.00000000"], ["61682.00000000", "0.02899000"]]}
{"type": "depth", "ts": 1783008092614, "U": 96863157776, "u": 96863157799, "bids": [["61602.53000000", "0.00000000"], ["61602.26000000", "0.00034000"], ["61601.83000000", "0.00000000"], ["61593.67000000", "0.00300000"], ["61590.37000000", "0.97390000"], ["61590.36000000", "0.01011000"], ["61572.12000000", "0.01625000"], ["61571.84000000", "0.24750000"], ["61553.24000000", "0.61731000"], ["61551.53000000", "0.01300000"], ["61551.09000000", "0.13879000"], ["55445.40000000", "0.00220000"], ["55445.00000000", "0.00000000"]], "asks": [["61610.47000000", "0.00009000"], ["61619.53000000", "0.00009000"], ["61621.74000000", "0.00000000"], ["61638.64000000", "0.60678000"], ["61665.59000000", "0.00000000"], ["61669.21000000", "0.01000000"], ["61673.99000000", "0.01171000"], ["61681.01000000", "0.00000000"], ["61713.99000000", "0.00000000"]]}
{"type": "depth", "ts": 1783008092714, "U": 96863157800, "u": 96863157852, "bids": [["61606.00000000", "0.01905000"], ["61605.99000000", "0.00036000"], ["61601.51000000", "0.00000000"], ["61599.45000000", "0.09102000"], ["61599.23000000", "0.00009000"], ["61599.22000000", "0.08331000"], ["61597.54000000", "0.00000000"], ["61597.53000000", "0.00000000"], ["61596.51000000", "0.00488000"], ["61587.52000000", "0.00016000"], ["61583.03000000", "0.00000000"], ["61569.04000000", "0.00016000"], ["61564.54000000", "0.00000000"], ["61550.55000000", "0.00016000"], ["61546.06000000", "0.00000000"], ["61532.07000000", "0.00016000"], ["61527.57000000", "0.00000000"], ["61513.59000000", "0.00016000"], ["61503.66000000", "0.00000000"], ["61493.49000000", "0.00000000"], ["61462.53000000", "0.00000000"], ["55445.40000000", "0.00240000"], ["49284.80000000", "0.00000000"]], "asks": [["61606.01000000", "4.89267000"], ["61606.38000000", "0.04235000"], ["61624.49000000", "0.00016000"], ["61638.50000000", "0.00000000"], ["61642.97000000", "0.00016000"], ["61656.98000000", "0.00000000"], ["61661.46000000", "0.00016000"], ["61662.50000000", "0.00000000"], ["61675.47000000", "0.00000000"], ["61677.92000000", "0.00000000"], ["61679.94000000", "0.00016000"], ["61682.92000000", "0.00000000"], ["61687.53000000", "0.05295000"], ["61691.18000000", "0.00000000"], ["61693.95000000", "0.00000000"], ["61696.35000000", "0.00000000"], ["61698.42000000", "0.00016000"], ["61699.58000000", "0.00000000"], ["61703.88000000", "0.00000000"], ["61712.44000000", "0.00000000"]]}
{"type": "depth", "ts": 1783008092814, "U": 96863157853, "u": 96863158128, "bids": [["61606.00000000", "0.00000000"], ["61605.99000000", "0.00000000"], ["61605.65000000", "0.00000000"], ["61604.85000000", "0.00000000"], ["61604.64000000", "0.00000000"], ["61604.31000000", "0.00000000"], ["61604.01000000", "0.00000000"], ["61604.00000000", "0.02553000"], ["61603.99000000", "0.00080000"], ["61603.98000000", "0.00017000"], ["61603.19000000", "0.00009000"], ["61602.26000000", "0.00000000"], ["61601.58000000", "0.00018000"], ["61601.25000000", "0.00000000"], ["61600.37000000", "0.00000000"], ["61599.90000000", "0.00000000"], ["61599.63000000", "0.01134000"], ["61599.46000000", "0.00000000"], ["61599.45000000", "0.00027000"], ["61599.23000000", "0.00000000"], ["61599.22000000", "0.00018000"], ["61598.42000000", "0.09093000"], ["61597.84000000", "0.00010000"], ["61597.21000000", "0.09075000"], ["61596.51000000", "0.00009000"], ["61596.50000000", "0.75134000"], ["61596.36000000", "0.00000000"], ["61594.59000000", "0.47731000"], ["61593.27000000", "0.00000000"], ["61590.19000000", "0.00000000"], ["61590.00000000", "0.02887000"], ["61588.79000000", "0.00000000"], ["61587.11000000", "0.00000000"], ["61586.17000000", "0.00400000"], ["61577.87000000", "0.00000000"], ["61575.00000000", "0.00000000"], ["61574.55000000", "0.00000000"], ["61573.00000000", "0.01000000"], ["61572.12000000", "0.00000000"], ["61565.37000000", "1.35909000"], ["61565.36000000", "1.36330000"], ["61565.35000000", "0.00000000"], ["61559.17000000", "0.58538000"], ["61555.96000000", "0.00000000"], ["61552.84000000", "0.00000000"], ["61551.09000000", "0.00000000"], ["61546.91000000", "0.00405000"], ["61504.40000000", "0.00009000"], ["61434.14000000", "0.00009000"], ["61431.06000000", "0.00009000"], ["61422.37000000", "0.00009000"], ["60681.91000000", "0.00000000"], ["59520.00000000", "0.14295000"], ["55445.40000000", "0.00020000"]], "asks": [["61604.01000000", "3.62591000"], ["61604.02000000", "0.00035000"], ["61604.03000000", "0.00017000"], ["61604.32000000", "0.00000000"], ["61604.65000000", "0.00000000"], ["61604.85000000", "0.00009000"], ["61604.86000000", "0.00000000"], ["61605.32000000", "0.00000000"], ["61605.64000000", "0.16232000"], ["61605.66000000", "0.00000000"], ["61605.81000000", "0.04046000"], ["61605.99000000", "0.88238000"], ["61606.00000000", "0.05124000"], ["61606.01000000", "0.11804000"], ["61606.02000000", "0.00000000"], ["61606.03000000", "0.00000000"], ["61606.52000000", "0.00018000"], ["61606.53000000", "0.05118000"], ["61606.74000000", "0.00000000"], ["61607.59000000", "0.51074000"], ["61607.60000000", "0.00018000"], ["61607.82000000", "0.00024000"], ["61609.10000000", "0.00000000"], ["61610.17000000", "0.00010000"], ["61610.18000000", "0.00400000"], ["61610.76000000", "0.00000000"], ["61611.70000000", "0.00009000"], ["61612.01000000", "0.00027000"], ["61612.18000000", "0.24750000"], ["61612.70000000", "0.00000000"], ["61612.80000000", "0.98025000"], ["61614.95000000", "0.23041000"], ["61615.26000000", "0.00000000"], ["61615.40000000", "0.00508000"], ["61617.86000000", "0.00009000"], ["61618.96000000", "0.00009000"], ["61620.00000000", "0.00509000"], ["61624.18000000", "0.00000000"], ["61626.97000000", "0.00000000"], ["61628.96000000", "0.00162000"], ["61629.26000000", "0.00649000"], ["61630.49000000", "0.00000000"], ["61635.48000000", "0.00000000"], ["61677.95000000", "0.00100000"], ["61710.00000000", "0.02410000"], ["61722.80000000", "0.00000000"], ["61726.36000000", "0.00000000"], ["61799.99000000", "0.00000000"], ["61969.80000000", "0.00000000"]]}
{"type": "depth", "ts": 1783008092914, "U": 96863158129, "u": 96863158228, "bids": [["61604.00000000", "0.02488000"], ["61602.00000000", "0.02418000"], ["61601.59000000", "0.00000000"], ["61601.58000000", "0.00000000"], ["61600.00000000", "0.07747000"], ["61599.64000000", "0.00009000"], ["61599.63000000", "0.01152000"], ["61599.45000000", "0.00009000"], ["61599.22000000", "0.00000000"], ["61598.76000000", "0.09066000"], ["61598.37000000", "0.01018000"], ["61598.00000000", "0.02418000"], ["61596.51000000", "0.00497000"], ["61594.36000000", "0.00000000"], ["61593.21000000", "0.00998000"], ["61592.34000000", "0.00000000"], ["61591.27000000", "0.00000000"], ["61588.19000000", "0.00000000"], ["61583.91000000", "0.00000000"], ["61579.89000000", "0.00000000"], ["61573.14000000", "0.00060000"], ["61566.57000000", "0.00000000"], ["61553.25000000", "0.97390000"], ["61550.54000000", "0.00000000"], ["61550.19000000", "0.00000000"], ["61547.70000000", "0.13946000"], ["61539.93000000", "0.00000000"], ["61526.61000000", "0.00500000"], ["61501.66000000", "0.00016000"], ["61491.50000000", "0.00186000"], ["61431.06000000", "0.00000000"], ["55443.60000000", "0.00040000"]], "asks": [["61604.01000000", "4.06491000"], ["61605.63000000", "0.09116000"], ["61605.64000000", "0.16259000"], ["61605.81000000", "0.04064000"], ["61605.99000000", "0.00027000"], ["61606.00000000", "0.05142000"], ["61606.01000000", "0.08944000"], ["61606.16000000", "0.05127000"], ["61606.38000000", "0.04217000"], ["61606.52000000", "0.00000000"], ["61606.53000000", "0.05100000"], ["61606.54000000", "0.23392000"], ["61607.60000000", "0.00000000"], ["61608.31000000", "0.11792000"], ["61612.82000000", "0.00977000"], ["61613.30000000", "0.00000000"], ["61619.84000000", "0.00000000"], ["61624.02000000", "0.00009000"], ["61625.30000000", "0.00324000"], ["61628.81000000", "0.00000000"], ["61629.26000000", "0.00000000"], ["61633.15000000", "0.00000000"], ["61635.00000000", "0.01000000"], ["61637.00000000", "0.00000000"], ["61646.47000000", "0.00000000"], ["61659.80000000", "0.00499000"], ["61673.12000000", "0.00000000"], ["61686.44000000", "0.00000000"], ["61699.76000000", "0.00000000"], ["61713.07000000", "0.00000000"], ["61726.39000000", "0.00498000"], ["61739.71000000", "0.00000000"], ["61753.03000000", "0.00000000"], ["61766.35000000", "0.00000000"], ["61770.30000000", "0.00000000"], ["61779.67000000", "0.00000000"], ["61784.44000000", "0.00000000"], ["61787.52000000", "0.00000000"], ["61790.01000000", "0.00000000"], ["61792.99000000", "0.00000000"]]}
{"type": "depth", "ts": 1783008093014, "U": 96863158229, "u": 96863158288, "bids": [["61600.00000000", "0.07756000"], ["61598.98000000", "0.01018000"], ["61598.77000000", "0.00009000"], ["61598.76000000", "0.09084000"], ["61598.00000000", "0.02400000"], ["61590.34000000", "0.00649000"], ["61553.75000000", "0.00000000"], ["61547.70000000", "0.00000000"], ["61545.88000000", "0.00000000"], ["61532.02000000", "0.42606000"], ["61530.01000000", "0.82073000"], ["61460.53000000", "0.00040000"], ["61006.44000000", "0.01227000"], ["60803.15000000", "0.00820000"], ["60679.94000000", "0.00822000"], ["60371.92000000", "0.00413000"], ["60063.90000000", "0.00415000"], ["55445.40000000", "0.00000000"], ["55443.60000000", "0.00080000"], ["49283.20000000", "0.00132000"]], "asks": [["61604.01000000", "4.07546000"], ["61604.05000000", "0.05000000"], ["61604.10000000", "0.05000000"], ["61605.63000000", "0.09134000"], ["61605.81000000", "0.04064000"], ["61605.99000000", "0.00009000"], ["61609.99000000", "0.46241000"], ["61610.00000000", "0.81257000"], ["61614.99000000", "0.15365000"], ["61631.45000000", "0.00000000"], ["61667.99000000", "0.03417000"], ["61670.77000000", "0.00000000"], ["61676.00000000", "0.02400000"], ["61677.66000000", "0.00000000"], ["61678.09000000", "0.13743000"]]}
{"type": "depth", "ts": 1783008093114, "U": 96863158289, "u": 96863159079, "bids": [["61604.00000000", "0.00000000"], ["61603.99000000", "0.00000000"], ["61603.98000000", "0.00000000"], ["61603.81000000", "0.00000000"], ["61603.68000000", "0.00000000"], ["61603.19000000", "0.00000000"], ["61603.08000000", "0.00000000"], ["61603.00000000", "0.00000000"], ["61602.50000000", "0.00000000"], ["61602.01000000", "0.00000000"], ["61602.00000000", "0.00000000"], ["61601.99000000", "0.00000000"], ["61601.90000000", "0.00000000"], ["61601.70000000", "0.00000000"], ["61601.62000000", "0.00000000"], ["61600.40000000", "0.00000000"], ["61600.01000000", "0.00000000"], ["61600.00000000", "0.23035000"], ["61599.99000000", "0.00045000"], ["61599.64000000", "0.00000000"], ["61599.63000000", "0.00018000"], ["61599.57000000", "0.00000000"], ["61599.05000000", "0.00000000"], ["61599.04000000", "0.00018000"], ["61599.02000000", "0.00000000"], ["61598.99000000", "0.00000000"], ["61598.98000000", "0.00018000"], ["61598.77000000", "0.00000000"], ["61598.76000000", "0.00018000"], ["61598.43000000", "0.00000000"], ["61598.42000000", "0.00027000"], ["61598.41000000", "0.00000000"], ["61598.37000000", "0.00018000"], ["61598.13000000", "0.00000000"], ["61598.00000000", "0.02418000"], ["61597.84000000", "0.00000000"], ["61597.22000000", "0.00000000"], ["61597.21000000", "0.00036000"], ["61597.20000000", "0.00000000"], ["61596.51000000", "0.00009000"], ["61596.50000000", "0.33166000"], ["61596.49000000", "0.56517000"], ["61596.30000000", "0.00000000"], ["61595.96000000", "0.00000000"], ["61595.84000000", "0.00000000"], ["61595.82000000", "0.00000000"], ["61595.81000000", "0.00000000"], ["61595.39000000", "0.00000000"], ["61595.18000000", "0.02246000"], ["61594.81000000", "0.00000000"], ["61594.61000000", "0.00009000"], ["61594.60000000", "0.00400000"], ["61594.59000000", "0.00000000"], ["61594.58000000", "0.00000000"], ["61594.46000000", "0.00000000"], ["61594.21000000", "0.00000000"], ["61593.84000000", "0.00019000"], ["61593.03000000", "0.00000000"], ["61592.93000000", "0.00009000"], ["61592.39000000", "0.00000000"], ["61592.23000000", "0.42129000"], ["61591.13000000", "0.00000000"], ["61590.87000000", "0.00000000"], ["61590.56000000", "0.29182000"], ["61590.38000000", "0.97390000"], ["61590.37000000", "0.00000000"], ["61590.36000000", "0.00000000"], ["61589.44000000", "0.00000000"], ["61589.18000000", "0.00000000"], ["61588.73000000", "0.00000000"], ["61588.05000000", "0.00000000"], ["61588.02000000", "0.00000000"], ["61587.79000000", "0.00000000"], ["61587.68000000", "0.00019000"], ["61587.48000000", "0.00000000"], ["61587.17000000", "0.50368000"], ["61587.16000000", "0.00000000"], ["61586.17000000", "0.00000000"], ["61585.65000000", "0.00000000"], ["61585.52000000", "0.15000000"], ["61585.36000000", "0.08760000"], ["61584.97000000", "0.00000000"], ["61584.92000000", "0.00878000"], ["61584.71000000", "0.00000000"], ["61584.60000000", "0.00019000"], ["61584.01000000", "0.08332000"], ["61583.82000000", "0.08896000"], ["61583.66000000", "0.00009000"], ["61582.64000000", "0.00400000"], ["61582.01000000", "0.60943000"], ["61581.89000000", "0.00000000"], ["61581.84000000", "0.00889000"], ["61581.63000000", "0.00000000"], ["61581.52000000", "0.00181000"], ["61580.76000000", "0.00000000"], ["61580.54000000", "0.59875000"], ["61580.53000000", "0.81257000"], ["61580.52000000", "0.00000000"], ["61580.51000000", "0.00000000"], ["61578.81000000", "0.00000000"], ["61578.76000000", "0.00889000"], ["61578.55000000", "0.00000000"], ["61578.44000000", "0.01019000"], ["61575.73000000", "0.00034000"], ["61575.68000000", "0.00878000"], ["61575.47000000", "0.00000000"], ["61575.37000000", "0.00400000"], ["61575.36000000", "0.00419000"], ["61575.10000000", "0.28147000"], ["61574.54000000", "0.00000000"], ["61573.00000000", "0.00000000"], ["61572.60000000", "0.00899000"], ["61572.40000000", "0.00009000"], ["61572.39000000", "0.00000000"], ["61572.28000000", "0.00019000"], ["61572.00000000", "0.02400000"], ["61571.00000000", "0.00000000"], ["61570.56000000", "0.58527000"], ["61569.45000000", "0.00009000"], ["61569.20000000", "0.00019000"], ["61569.00000000", "0.01000000"], ["61565.37000000", "0.87864000"], ["61565.32000000", "0.00000000"], ["61565.16000000", "0.00009000"], ["61562.23000000", "0.00009000"], ["61557.82000000", "0.77933000"], ["61555.44000000", "0.00000000"], ["61550.81000000", "0.00000000"], ["61550.66000000", "0.00000000"], ["61548.39000000", "0.00000000"], ["61547.90000000", "0.00000000"], ["61542.21000000", "0.00010000"], ["61540.69000000", "1.61029000"], ["61532.02000000", "0.20761000"], ["61530.01000000", "0.00000000"], ["61526.42000000", "0.29079000"], ["61526.41000000", "0.97390000"], ["61526.08000000", "0.00009000"], ["61510.98000000", "0.00000000"], ["61489.04000000", "0.00000000"], ["61486.78000000", "0.00000000"], ["61480.60000000", "0.00010000"], ["61425.17000000", "0.00000000"], ["61419.00000000", "0.00010000"], ["61363.56000000", "0.00000000"], ["61356.78000000", "0.00010000"], ["61301.95000000", "0.00000000"], ["61295.50000000", "0.00009000"], ["61295.17000000", "0.00010000"], ["61286.68000000", "0.00009000"], ["61240.34000000", "0.00000000"], ["61233.57000000", "0.00010000"], ["61178.73000000", "0.00000000"], ["61171.97000000", "0.00010000"], ["61117.12000000", "0.00000000"], ["61110.36000000", "0.00010000"], ["61006.44000000", "0.02045000"], ["61006.12000000", "0.00409000"], ["60803.15000000", "0.01230000"], ["60801.17000000", "0.00410000"], ["60799.21000000", "0.00820000"], ["60679.94000000", "0.01233000"], ["60676.01000000", "0.00822000"], ["55447.20000000", "0.00000000"], ["55443.60000000", "0.00010000"], ["55440.00000000", "0.01018000"]], "asks": [["61600.01000000", "3.72359000"], ["61600.02000000", "0.00035000"], ["61600.03000000", "0.00017000"], ["61600.32000000", "0.00009000"], ["61600.41000000", "0.15365000"], ["61601.61000000", "0.00000000"], ["61601.63000000", "0.00000000"], ["61601.71000000", "0.00000000"], ["61601.74000000", "0.16233000"], ["61601.90000000", "0.00009000"], ["61601.91000000", "0.00000000"], ["61601.99000000", "0.93217000"], ["61602.00000000", "0.05100000"], ["61602.01000000", "0.48693000"], ["61602.02000000", "0.00000000"], ["61602.03000000", "0.00000000"], ["61602.51000000", "0.00000000"], ["61603.01000000", "0.00000000"], ["61603.09000000", "0.00000000"], ["61603.19000000", "1.06582000"], ["61603.20000000", "0.20392000"], ["61603.21000000", "0.00000000"], ["61603.22000000", "0.00000000"], ["61603.25000000", "0.00009000"], ["61603.63000000", "0.00400000"], ["61603.67000000", "0.00000000"], ["61603.69000000", "0.00000000"], ["61603.81000000", "0.40109000"], ["61603.82000000", "0.00027000"], ["61603.83000000", "1.36330000"], ["61603.86000000", "0.00000000"], ["61603.87000000", "0.00027000"], ["61603.99000000", "0.00000000"], ["61604.00000000", "0.05100000"], ["61604.01000000", "0.37773000"], ["61604.02000000", "0.00000000"], ["61604.03000000", "0.00000000"], ["61604.05000000", "0.00018000"], ["61604.10000000", "0.00018000"], ["61604.77000000", "0.00000000"], ["61605.23000000", "0.01000000"], ["61605.63000000", "0.00018000"], ["61605.64000000", "0.00009000"], ["61605.81000000", "0.04046000"], ["61606.00000000", "0.05100000"], ["61606.01000000", "0.08926000"], ["61606.02000000", "0.00034000"], ["61606.16000000", "0.00000000"], ["61606.17000000", "0.01489000"], ["61606.43000000", "0.02000000"], ["61606.44000000", "0.00400000"], ["61606.53000000", "0.00000000"], ["61607.59000000", "0.81299000"], ["61607.70000000", "0.00009000"], ["61607.99000000", "0.97390000"], ["61608.01000000", "0.00009000"], ["61608.17000000", "0.00000000"], ["61608.31000000", "0.01885000"], ["61609.03000000", "0.58491000"], ["61609.24000000", "0.00009000"], ["61610.01000000", "0.00905000"], ["61610.06000000", "0.00013000"], ["61610.17000000", "0.00000000"], ["61610.54000000", "0.08756000"], ["61611.92000000", "0.11572000"], ["61612.01000000", "0.00000000"], ["61612.08000000", "0.08892000"], ["61612.32000000", "0.17274000"], ["61612.33000000", "0.00010000"], ["61613.43000000", "0.00000000"], ["61614.99000000", "0.00000000"], ["61615.41000000", "0.01110000"], ["61615.52000000", "0.00000000"], ["61615.87000000", "0.00000000"], ["61616.43000000", "0.00000000"], ["61616.65000000", "0.01009000"], ["61616.80000000", "0.00000000"], ["61617.41000000", "0.00000000"], ["61618.00000000", "0.00500000"], ["61618.49000000", "0.00010000"], ["61618.60000000", "0.00000000"], ["61618.86000000", "0.00000000"], ["61619.58000000", "0.10602000"], ["61620.18000000", "0.00000000"], ["61620.63000000", "0.00009000"], ["61621.57000000", "0.00010000"], ["61621.68000000", "0.00000000"], ["61621.94000000", "0.00000000"], ["61622.50000000", "0.00000000"], ["61624.14000000", "0.00000000"], ["61624.45000000", "0.00000000"], ["61624.65000000", "0.00010000"], ["61624.75000000", "0.00024000"], ["61624.76000000", "0.00000000"], ["61624.93000000", "0.00000000"], ["61625.02000000", "0.00000000"], ["61625.30000000", "0.00000000"], ["61627.45000000", "0.64169000"], ["61627.73000000", "0.00010000"], ["61627.84000000", "0.00000000"], ["61628.05000000", "0.00000000"], ["61628.10000000", "0.00000000"], ["61630.66000000", "0.00000000"], ["61630.81000000", "1.23642000"], ["61630.82000000", "0.00011000"], ["61630.92000000", "0.00000000"], ["61631.18000000", "0.00000000"], ["61631.40000000", "0.00000000"], ["61632.55000000", "0.00000000"], ["61632.82000000", "0.00000000"], ["61634.00000000", "0.02409000"], ["61634.26000000", "0.00000000"], ["61634.35000000", "0.00000000"], ["61637.22000000", "0.00000000"], ["61637.34000000", "0.00000000"], ["61639.01000000", "0.00379000"], ["61640.59000000", "0.42441000"], ["61641.00000000", "0.42099000"], ["61641.66000000", "0.00000000"], ["61644.83000000", "0.01623000"], ["61644.84000000", "0.01623000"], ["61644.87000000", "0.01623000"], ["61644.92000000", "0.01623000"], ["61646.02000000", "0.00000000"], ["61648.28000000", "0.00000000"], ["61651.03000000", "0.00000000"], ["61652.59000000", "0.00000000"], ["61658.85000000", "0.00000000"], ["61658.88000000", "0.00000000"], ["61658.93000000", "0.00000000"], ["61665.42000000", "0.00010000"], ["61671.62000000", "0.00000000"], ["61678.09000000", "0.00000000"], ["61696.24000000", "0.12000000"], ["61698.08000000", "0.00000000"], ["61701.64000000", "0.00000000"], ["61708.44000000", "0.00162000"], ["61708.45000000", "0.00000000"], ["61727.03000000", "0.00010000"], ["61733.23000000", "0.00000000"], ["61742.27000000", "0.00000000"], ["61746.11000000", "0.21547000"], ["61748.87000000", "6.68529000"], ["61761.96000000", "0.00009000"], ["61771.84000000", "0.00000000"], ["61778.01000000", "0.00000000"], ["61788.63000000", "0.00010000"], ["61794.84000000", "0.00000000"], ["61850.24000000", "0.00010000"], ["61856.45000000", "0.00000000"], ["61911.89000000", "0.00010000"], ["61918.06000000", "0.00000000"], ["61973.49000000", "0.00010000"], ["61979.67000000", "0.00000000"], ["62035.10000000", "0.00010000"], ["62041.28000000", "0.00000000"], ["62096.70000000", "0.00010000"], ["62102.89000000", "0.00000000"], ["62208.72000000", "0.00000000"], ["62514.72000000", "1.95395000"], ["62530.11000000", "0.00000000"], ["62533.00000000", "0.00000000"]]}
{"type": "depth", "ts": 1783008093214, "U": 96863159080, "u": 96863160059, "bids": [["61600.00000000", "0.00000000"], ["61599.99000000", "0.00000000"], ["61599.98000000", "0.00000000"], ["61599.63000000", "0.00000000"], ["61599.45000000", "0.00000000"], ["61599.04000000", "0.00000000"], ["61598.98000000", "0.00000000"], ["61598.95000000", "0.00000000"], ["61598.76000000", "0.00000000"], ["61598.63000000", "0.00000000"], ["61598.42000000", "0.00000000"], ["61598.37000000", "0.00000000"], ["61598.01000000", "0.00000000"], ["61598.00000000", "0.00000000"], ["61597.99000000", "0.00000000"], ["61597.48000000", "0.00000000"], ["61597.31000000", "0.00000000"], ["61597.21000000", "0.00000000"], ["61596.92000000", "0.00000000"], ["61596.51000000", "0.00000000"], ["61596.50000000", "0.00000000"], ["61596.49000000", "0.71832000"], ["61596.48000000", "0.00036000"], ["61596.04000000", "0.00000000"], ["61596.01000000", "0.00009000"], ["61596.00000000", "0.02440000"], ["61595.87000000", "0.00000000"], ["61595.75000000", "0.00018000"], ["61595.34000000", "0.00018000"], ["61595.30000000", "0.00018000"], ["61595.18000000", "0.00018000"], ["61595.11000000", "0.00000000"], ["61594.73000000", "0.00000000"], ["61594.71000000", "0.00000000"], ["61594.61000000", "0.00000000"], ["61594.60000000", "0.00000000"], ["61594.05000000", "0.00009000"], ["61594.04000000", "0.04727000"], ["61594.01000000", "0.00009000"], ["61594.00000000", "0.02418000"], ["61593.97000000", "0.00009000"], ["61593.91000000", "0.00018000"], ["61593.84000000", "0.00009000"], ["61593.46000000", "0.00000000"], ["61593.31000000", "0.00000000"], ["61593.21000000", "0.00499000"], ["61592.92000000", "0.00000000"], ["61592.90000000", "0.00000000"], ["61592.69000000", "0.00000000"], ["61592.68000000", "0.00000000"], ["61592.61000000", "0.00000000"], ["61592.40000000", "0.00000000"], ["61592.24000000", "0.00009000"], ["61592.23000000", "0.42138000"], ["61592.10000000", "0.00243000"], ["61592.01000000", "0.00009000"], ["61591.95000000", "0.02492000"], ["61591.84000000", "0.00010000"], ["61591.53000000", "0.00000000"], ["61591.07000000", "0.00000000"], ["61590.99000000", "0.00009000"], ["61590.57000000", "0.00009000"], ["61590.56000000", "0.17104000"], ["61590.53000000", "0.00047000"], ["61590.38000000", "0.00000000"], ["61590.33000000", "0.00000000"], ["61590.28000000", "0.00070000"], ["61590.15000000", "0.00000000"], ["61590.14000000", "0.00000000"], ["61589.10000000", "0.02191000"], ["61588.60000000", "0.00000000"], ["61588.02000000", "0.00009000"], ["61587.76000000", "0.01000000"], ["61587.71000000", "0.01000000"], ["61587.68000000", "0.00009000"], ["61587.47000000", "0.00000000"], ["61587.43000000", "0.00000000"], ["61587.17000000", "0.33752000"], ["61587.15000000", "0.01009000"], ["61587.09000000", "0.00000000"], ["61585.96000000", "0.00535000"], ["61585.67000000", "0.00000000"], ["61585.52000000", "0.00000000"], ["61584.92000000", "0.00000000"], ["61584.91000000", "0.00911000"], ["61584.62000000", "0.00000000"], ["61584.60000000", "0.00009000"], ["61584.43000000", "0.02000000"], ["61584.18000000", "0.00010000"], ["61584.01000000", "0.01051000"], ["61582.64000000", "0.00000000"], ["61582.11000000", "0.00000000"], ["61582.01000000", "0.00000000"], ["61581.52000000", "0.00171000"], ["61581.32000000", "0.15000000"], ["61581.10000000", "0.00010000"], ["61580.54000000", "0.40971000"], ["61580.53000000", "0.00000000"], ["61580.24000000", "0.11897000"], ["61579.96000000", "0.00000000"], ["61579.08000000", "0.36232000"], ["61578.50000000", "0.00000000"], ["61578.44000000", "0.01009000"], ["61578.02000000", "0.00010000"], ["61578.01000000", "1.05672000"], ["61577.44000000", "0.60947000"], ["61577.02000000", "0.00400000"], ["61576.10000000", "0.00000000"], ["61575.46000000", "0.81266000"], ["61575.37000000", "0.00000000"], ["61575.36000000", "0.00409000"], ["61575.10000000", "0.12877000"], ["61574.94000000", "0.00010000"], ["61573.68000000", "0.00000000"], ["61572.28000000", "0.00009000"], ["61571.86000000", "0.00010000"], ["61571.01000000", "0.00000000"], ["61570.83000000", "0.00400000"], ["61569.20000000", "0.00009000"], ["61569.00000000", "0.00000000"], ["61568.78000000", "1.36340000"], ["61567.00000000", "0.00000000"], ["61566.50000000", "0.00009000"], ["61565.70000000", "0.00010000"], ["61565.00000000", "0.08614000"], ["61561.68000000", "0.00053000"], ["61559.91000000", "0.00500000"], ["61559.68000000", "0.49866000"], ["61559.30000000", "0.00009000"], ["61559.19000000", "0.00000000"], ["61555.27000000", "0.00000000"], ["61555.15000000", "0.00024000"], ["61554.68000000", "0.58542000"], ["61553.33000000", "0.00000000"], ["61553.21000000", "0.04217000"], ["61553.11000000", "0.01000000"], ["61551.46000000", "0.00000000"], ["61550.81000000", "0.01000000"], ["61548.81000000", "0.00000000"], ["61547.67000000", "0.01000000"], ["61547.61000000", "0.01000000"], ["61547.05000000", "0.01000000"], ["61546.91000000", "0.00000000"], ["61545.98000000", "0.00000000"], ["61545.14000000", "0.00000000"], ["61545.12000000", "0.01826000"], ["61544.62000000", "0.00400000"], ["61542.21000000", "0.00000000"], ["61542.01000000", "0.00095000"], ["61540.73000000", "0.00404000"], ["61535.88000000", "0.00010000"], ["61535.65000000", "0.01000000"], ["61534.99000000", "0.01157000"], ["61534.29000000", "1.61046000"], ["61533.19000000", "0.00000000"], ["61530.54000000", "0.35128000"], ["61526.02000000", "0.41946000"], ["61525.64000000", "0.97513000"], ["61518.33000000", "0.00000000"], ["61491.50000000", "0.00024000"], ["61486.19000000", "0.00000000"], ["61485.84000000", "0.07746000"], ["61481.34000000", "0.02989000"], ["61480.60000000", "0.00000000"], ["61480.01000000", "0.00038000"], ["61479.55000000", "0.00162000"], ["61479.30000000", "0.00845000"], ["61474.29000000", "0.00010000"], ["61430.77000000", "0.00009000"], ["61427.69000000", "0.00009000"], ["61423.82000000", "0.00009000"], ["61420.75000000", "0.01026000"], ["61419.00000000", "0.00000000"], ["61412.69000000", "0.00010000"], ["61369.36000000", "0.00000000"], ["61356.78000000", "0.00000000"], ["61350.53000000", "0.00010000"], ["61350.00000000", "1.30468000"], ["61295.17000000", "0.00000000"], ["61288.94000000", "0.00010000"], ["61233.57000000", "0.00000000"], ["61227.34000000", "0.00010000"], ["61171.97000000", "0.00000000"], ["61165.74000000", "0.00010000"], ["61110.36000000", "0.00000000"], ["61104.14000000", "0.00010000"], ["61002.48000000", "0.00409000"], ["61002.47000000", "0.00409000"], ["60799.20000000", "0.00410000"], ["60796.45000000", "0.00410000"], ["60676.01000000", "0.01233000"], ["60676.00000000", "0.00559000"], ["60674.03000000", "0.00000000"], ["60672.55000000", "0.00411000"], ["60368.01000000", "0.00909000"], ["60368.00000000", "0.00763000"], ["60366.04000000", "0.00413000"], ["60060.00000000", "0.01670000"], ["60057.28000000", "0.00415000"], ["59752.00000000", "0.01337000"], ["59748.60000000", "0.00417000"], ["55440.00000000", "0.00998000"], ["55436.85000000", "0.00020000"], ["49283.20000000", "0.00092000"]], "asks": [["61596.50000000", "4.47777000"], ["61596.51000000", "2.18088000"], ["61596.52000000", "0.00017000"], ["61596.53000000", "0.00000000"], ["61596.93000000", "0.00000000"], ["61597.20000000", "0.00000000"], ["61597.22000000", "0.00000000"], ["61597.32000000", "0.00009000"], ["61597.39000000", "0.00009000"], ["61597.49000000", "0.00009000"], ["61597.55000000", "0.16234000"], ["61597.82000000", "0.00000000"], ["61597.99000000", "0.14923000"], ["61598.00000000", "0.05100000"], ["61598.01000000", "0.37777000"], ["61598.02000000", "0.00000000"], ["61598.03000000", "0.00000000"], ["61598.43000000", "0.00009000"], ["61598.63000000", "0.05100000"], ["61598.95000000", "0.00009000"], ["61598.96000000", "0.00000000"], ["61598.99000000", "0.00000000"], ["61599.05000000", "0.00000000"], ["61599.32000000", "0.00000000"], ["61599.46000000", "0.00000000"], ["61599.59000000", "0.00034000"], ["61599.64000000", "0.00000000"], ["61599.99000000", "0.00000000"], ["61600.00000000", "2.02586000"], ["61600.01000000", "0.34850000"], ["61600.02000000", "0.00000000"], ["61600.03000000", "0.00000000"], ["61600.41000000", "0.00027000"], ["61600.82000000", "0.00400000"], ["61601.46000000", "0.04217000"], ["61601.74000000", "0.00027000"], ["61601.98000000", "0.00000000"], ["61601.99000000", "0.00027000"], ["61602.00000000", "0.00018000"], ["61602.01000000", "0.48684000"], ["61603.10000000", "0.00894000"], ["61603.19000000", "0.66139000"], ["61603.20000000", "0.20383000"], ["61603.33000000", "0.12000000"], ["61603.81000000", "0.40100000"], ["61603.82000000", "0.00009000"], ["61603.85000000", "0.00013000"], ["61603.87000000", "0.00018000"], ["61604.00000000", "0.00000000"], ["61604.01000000", "0.28934000"], ["61604.05000000", "0.00000000"], ["61604.10000000", "0.00000000"], ["61604.17000000", "0.00010000"], ["61605.62000000", "0.58494000"], ["61605.63000000", "0.00000000"], ["61605.64000000", "0.00000000"], ["61605.69000000", "0.00009000"], ["61605.99000000", "0.00000000"], ["61606.00000000", "0.00000000"], ["61606.01000000", "0.00908000"], ["61606.17000000", "0.01479000"], ["61606.54000000", "0.00000000"], ["61607.59000000", "0.81290000"], ["61607.83000000", "0.00000000"], ["61608.01000000", "0.00000000"], ["61608.21000000", "0.00000000"], ["61608.31000000", "0.01867000"], ["61608.64000000", "0.00010000"], ["61608.83000000", "0.00010000"], ["61609.74000000", "0.00190000"], ["61609.99000000", "0.46232000"], ["61611.29000000", "0.00012000"], ["61611.80000000", "0.00009000"], ["61611.81000000", "0.00000000"], ["61611.91000000", "0.00010000"], ["61611.92000000", "0.10667000"], ["61612.16000000", "0.02644000"], ["61612.33000000", "0.00000000"], ["61613.71000000", "0.00000000"], ["61614.99000000", "0.00010000"], ["61615.40000000", "0.00009000"], ["61615.41000000", "0.01100000"], ["61615.51000000", "0.00059000"], ["61615.95000000", "0.00162000"], ["61618.07000000", "0.00010000"], ["61618.49000000", "0.00000000"], ["61619.58000000", "0.00000000"], ["61620.07000000", "1.60821000"], ["61621.15000000", "0.00010000"], ["61621.27000000", "0.00324000"], ["61621.57000000", "0.00000000"], ["61621.72000000", "0.00000000"], ["61624.00000000", "0.01100000"], ["61624.23000000", "0.00010000"], ["61624.65000000", "0.00000000"], ["61624.75000000", "0.00000000"], ["61624.89000000", "0.00619000"], ["61625.76000000", "0.00434000"], ["61626.49000000", "0.00000000"], ["61626.88000000", "0.00010000"], ["61627.31000000", "0.00010000"], ["61627.73000000", "0.00000000"], ["61628.02000000", "0.00427000"], ["61628.18000000", "0.25174000"], ["61628.45000000", "0.00000000"], ["61628.49000000", "0.00000000"], ["61629.62000000", "0.97390000"], ["61629.98000000", "0.03172000"], ["61630.81000000", "0.91285000"], ["61631.00000000", "0.01000000"], ["61633.75000000", "0.00000000"], ["61634.32000000", "0.00000000"], ["61634.91000000", "0.00000000"], ["61635.00000000", "0.00000000"], ["61635.89000000", "0.01695000"], ["61637.12000000", "0.00111000"], ["61637.13000000", "0.00000000"], ["61637.35000000", "0.00000000"], ["61637.59000000", "0.00000000"], ["61641.32000000", "0.01623000"], ["61642.98000000", "0.00000000"], ["61643.23000000", "1.49302000"], ["61644.75000000", "0.01623000"], ["61645.12000000", "0.97523000"], ["61647.71000000", "0.00000000"], ["61648.69000000", "0.00000000"], ["61649.01000000", "0.00000000"], ["61653.31000000", "0.00000000"], ["61654.83000000", "0.00000000"], ["61656.39000000", "0.00000000"], ["61658.11000000", "0.00010000"], ["61658.18000000", "0.00009000"], ["61658.26000000", "0.00000000"], ["61659.80000000", "0.00000000"], ["61661.62000000", "0.97417000"], ["61664.55000000", "0.00000000"], ["61665.28000000", "0.13887000"], ["61665.42000000", "0.00000000"], ["61670.90000000", "0.00000000"], ["61675.01000000", "0.01826000"], ["61675.40000000", "0.30009000"], ["61675.41000000", "0.00000000"], ["61677.09000000", "1.17182000"], ["61681.13000000", "0.25377000"], ["61682.00000000", "0.02400000"], ["61688.08000000", "0.00000000"], ["61691.15000000", "0.00000000"], ["61691.16000000", "0.00000000"], ["61693.10000000", "0.00498000"], ["61694.35000000", "0.00016000"], ["61697.58000000", "0.00024000"], ["61704.20000000", "0.00000000"], ["61715.29000000", "0.00000000"], ["61719.20000000", "0.00000000"], ["61719.70000000", "0.00010000"], ["61723.63000000", "0.00000000"], ["61726.39000000", "0.00000000"], ["61726.68000000", "0.00000000"], ["61727.03000000", "0.00000000"], ["61728.05000000", "0.00000000"], ["61737.49000000", "0.00000000"], ["61748.59000000", "0.00000000"], ["61759.50000000", "0.00000000"], ["61759.69000000", "0.00000000"], ["61765.67000000", "0.00000000"], ["61770.79000000", "0.00000000"], ["61779.53000000", "0.00000000"], ["61781.30000000", "0.00010000"], ["61782.15000000", "0.00000000"], ["61788.63000000", "0.00000000"], ["61810.35000000", "0.00000000"], ["61830.57000000", "1.19998000"], ["61842.90000000", "0.00010000"], ["61850.24000000", "0.00000000"], ["61854.16000000", "0.00000000"], ["61904.49000000", "0.00010000"], ["61911.89000000", "0.00000000"], ["61966.09000000", "0.00010000"], ["61973.49000000", "0.00000000"], ["62027.69000000", "0.00010000"], ["62035.10000000", "0.00000000"], ["62089.28000000", "0.00010000"], ["62096.70000000", "0.00000000"], ["62126.27000000", "0.55300000"], ["62180.97000000", "0.00035000"], ["62204.01000000", "0.00000000"], ["62513.27000000", "1.69949000"], ["62514.72000000", "0.00000000"]]}
{"type": "depth", "ts": 1783008093314, "U": 96863160060, "u": 96863160419, "bids": [["61596.49000000", "0.00000000"], ["61596.48000000", "0.00000000"], ["61596.12000000", "0.00000000"], ["61596.01000000", "0.00000000"], ["61596.00000000", "0.02548000"], ["61595.99000000", "0.00045000"], ["61595.75000000", "0.00000000"], ["61595.34000000", "0.00000000"], ["61595.30000000", "0.00000000"], ["61595.18000000", "0.00000000"], ["61594.05000000", "0.00000000"], ["61594.04000000", "0.00018000"], ["61594.00000000", "0.02418000"], ["61593.91000000", "0.00000000"], ["61592.93000000", "0.00000000"], ["61592.61000000", "0.00000000"], ["61592.60000000", "0.00000000"], ["61592.23000000", "0.41677000"], ["61592.01000000", "0.00009000"], ["61592.00000000", "0.02418000"], ["61591.96000000", "0.00000000"], ["61591.95000000", "0.00018000"], ["61591.93000000", "0.00009000"], ["61591.92000000", "0.00000000"], ["61591.84000000", "0.08798000"], ["61591.65000000", "0.01133000"], ["61591.40000000", "0.00000000"], ["61591.00000000", "0.00009000"], ["61590.99000000", "0.00506000"], ["61590.98000000", "0.00018000"], ["61590.58000000", "0.00009000"], ["61590.57000000", "0.10612000"], ["61590.56000000", "0.00027000"], ["61590.34000000", "0.00676000"], ["61590.33000000", "0.24750000"], ["61589.84000000", "0.00010000"], ["61588.60000000", "0.00000000"], ["61588.02000000", "0.00000000"], ["61588.01000000", "0.00000000"], ["61587.18000000", "0.00009000"], ["61587.17000000", "0.32597000"], ["61587.15000000", "0.02009000"], ["61586.58000000", "1.36330000"], ["61585.82000000", "0.00000000"], ["61585.67000000", "0.00009000"], ["61585.36000000", "0.00000000"], ["61585.24000000", "0.00047000"], ["61584.91000000", "0.00000000"], ["61584.70000000", "0.08775000"], ["61584.32000000", "0.01010000"], ["61583.82000000", "0.00000000"], ["61582.94000000", "0.00192000"], ["61580.54000000", "0.30483000"], ["61578.44000000", "0.00009000"], ["61577.88000000", "0.00000000"], ["61567.84000000", "0.64231000"], ["61561.68000000", "0.00009000"], ["61556.37000000", "0.00009000"], ["61555.33000000", "0.00000000"], ["61552.31000000", "0.00000000"], ["61549.45000000", "0.01000000"], ["61545.71000000", "0.00430000"], ["61545.38000000", "0.00630000"], ["61544.22000000", "0.13685000"], ["61543.18000000", "0.00426000"], ["61541.81000000", "0.00400000"], ["61539.20000000", "0.00000000"], ["61537.78000000", "0.01000000"], ["61535.75000000", "0.00000000"], ["61534.03000000", "0.00000000"], ["61522.79000000", "0.00145000"], ["61520.16000000", "0.97390000"], ["61510.65000000", "0.00000000"], ["61492.95000000", "0.04603000"], ["61479.30000000", "0.00000000"], ["61474.46000000", "0.00000000"], ["61472.21000000", "0.00845000"], ["61460.49000000", "1.20000000"], ["61426.10000000", "0.00009000"], ["61420.75000000", "0.01017000"], ["60999.01000000", "0.01650000"], ["60999.00000000", "0.27992000"], ["60795.75000000", "0.00410000"], ["60795.74000000", "0.00410000"], ["60795.73000000", "0.00820000"], ["60672.54000000", "0.01644000"], ["60364.57000000", "0.00413000"], ["60364.56000000", "0.01239000"], ["60056.59000000", "0.00415000"], ["60056.58000000", "0.00415000"], ["59748.60000000", "0.00834000"], ["55436.85000000", "0.00000000"], ["55436.40000000", "0.00050000"]], "asks": [["61596.01000000", "3.98348000"], ["61596.02000000", "0.00035000"], ["61596.03000000", "0.00017000"], ["61596.13000000", "0.00000000"], ["61596.49000000", "2.55075000"], ["61596.50000000", "0.07410000"], ["61596.51000000", "0.12811000"], ["61596.52000000", "0.00000000"], ["61597.55000000", "0.00027000"], ["61597.63000000", "0.16234000"], ["61597.99000000", "0.14950000"], ["61598.00000000", "0.05118000"], ["61598.01000000", "0.32786000"], ["61598.05000000", "0.00000000"], ["61598.10000000", "0.00000000"], ["61598.13000000", "0.00000000"], ["61598.63000000", "0.00018000"], ["61598.70000000", "0.00000000"], ["61600.01000000", "0.34020000"], ["61600.41000000", "0.00000000"], ["61601.74000000", "0.00000000"], ["61601.99000000", "0.00000000"], ["61602.00000000", "0.00000000"], ["61602.01000000", "0.23934000"], ["61602.17000000", "0.00010000"], ["61603.20000000", "0.15383000"], ["61603.80000000", "0.97390000"], ["61604.01000000", "0.02175000"], ["61604.17000000", "0.00000000"], ["61606.01000000", "0.00891000"], ["61606.76000000", "0.08757000"], ["61608.30000000", "0.08893000"], ["61610.54000000", "0.00000000"], ["61612.08000000", "0.00000000"], ["61616.31000000", "0.05104000"], ["61617.48000000", "0.00324000"], ["61621.27000000", "0.00000000"], ["61627.26000000", "0.00649000"], ["61628.00000000", "0.03400000"], ["61631.00000000", "0.00000000"], ["61640.38000000", "0.00543000"], ["61640.64000000", "0.09420000"], ["61650.56000000", "0.00000000"], ["61681.13000000", "0.45580000"], ["61687.73000000", "0.33526000"], ["61702.19000000", "0.00000000"], ["61759.49000000", "0.24750000"], ["61780.21000000", "0.00000000"], ["61789.50000000", "3.00000000"], ["62520.45000000", "0.00030000"]]}
{"type": "depth", "ts": 1783008093414, "U": 96863160420, "u": 96863160852, "bids": [["61596.00000000", "0.00000000"], ["61595.99000000", "0.00000000"], ["61595.66000000", "0.00000000"], ["61595.20000000", "0.00000000"], ["61594.04000000", "0.00000000"], ["61594.01000000", "0.00000000"], ["61594.00000000", "0.20146000"], ["61593.99000000", "0.00036000"], ["61593.53000000", "0.00009000"], ["61593.52000000", "0.00009000"], ["61592.37000000", "0.00000000"], ["61592.24000000", "0.00000000"], ["61592.23000000", "0.00045000"], ["61592.17000000", "0.00000000"], ["61592.11000000", "0.00009000"], ["61592.10000000", "0.00252000"], ["61592.02000000", "0.00009000"], ["61592.01000000", "0.00009000"], ["61592.00000000", "0.02418000"], ["61591.95000000", "0.00000000"], ["61591.93000000", "0.00000000"], ["61591.85000000", "0.00000000"], ["61591.84000000", "0.00027000"], ["61591.65000000", "0.00018000"], ["61591.55000000", "0.00000000"], ["61591.54000000", "0.00000000"], ["61591.51000000", "0.00000000"], ["61591.00000000", "0.00000000"], ["61590.99000000", "0.00027000"], ["61590.98000000", "0.00000000"], ["61590.81000000", "0.00009000"], ["61590.80000000", "0.00000000"], ["61590.57000000", "0.00018000"], ["61590.56000000", "0.00009000"], ["61590.34000000", "0.00027000"], ["61590.33000000", "0.00036000"], ["61590.01000000", "0.00000000"], ["61589.84000000", "0.00000000"], ["61589.51000000", "0.00009000"], ["61589.50000000", "0.04709000"], ["61589.35000000", "0.00000000"], ["61588.21000000", "0.00009000"], ["61588.20000000", "0.08990000"], ["61587.84000000", "0.24760000"], ["61587.18000000", "0.08990000"], ["61587.17000000", "0.70335000"], ["61586.89000000", "0.00009000"], ["61586.59000000", "0.00000000"], ["61586.57000000", "0.00000000"], ["61585.67000000", "0.00000000"], ["61585.30000000", "0.01000000"], ["61584.81000000", "0.00000000"], ["61584.70000000", "0.00000000"], ["61584.13000000", "0.00000000"], ["61584.01000000", "0.02051000"], ["61583.83000000", "0.00977000"], ["61582.74000000", "0.00000000"], ["61579.81000000", "0.00000000"], ["61577.67000000", "0.01016000"], ["61577.44000000", "0.00000000"], ["61576.88000000", "0.00000000"], ["61575.64000000", "0.56513000"], ["61573.95000000", "0.00000000"], ["61571.51000000", "0.01000000"], ["61571.02000000", "0.00000000"], ["61568.09000000", "0.00009000"], ["61565.35000000", "0.00978000"], ["61565.00000000", "0.07614000"], ["61563.55000000", "0.00009000"], ["61563.00000000", "0.01000000"], ["61561.68000000", "0.00045000"], ["61561.36000000", "0.00000000"], ["61559.19000000", "0.01012000"], ["61556.37000000", "0.00000000"], ["61544.83000000", "1.50271000"], ["61544.23000000", "0.07227000"], ["61544.22000000", "0.00000000"], ["61544.01000000", "0.00000000"], ["61541.99000000", "0.00426000"], ["61538.09000000", "0.00000000"], ["61537.55000000", "0.00000000"], ["61537.38000000", "0.01000000"], ["61535.64000000", "0.01000000"], ["61534.10000000", "0.00013000"], ["61525.07000000", "0.00532000"], ["61521.43000000", "0.01700000"], ["61512.76000000", "0.97390000"], ["61501.66000000", "0.00000000"], ["61491.50000000", "0.00000000"], ["61460.53000000", "0.00000000"], ["61419.47000000", "0.00009000"], ["61416.40000000", "0.00000000"], ["61377.89000000", "0.00000000"], ["61324.44000000", "0.02789000"], ["60998.53000000", "0.00409000"], ["60795.26000000", "0.01230000"], ["60672.07000000", "0.01233000"], ["60364.09000000", "0.00826000"], ["60056.58000000", "0.00830000"], ["60056.11000000", "0.01254000"], ["59748.13000000", "0.01668000"], ["55436.40000000", "0.00030000"]], "asks": [["61594.01000000", "2.96226000"], ["61594.02000000", "0.00035000"], ["61594.03000000", "0.00017000"], ["61594.05000000", "0.00000000"], ["61594.46000000", "0.00009000"], ["61595.21000000", "0.00000000"], ["61595.67000000", "0.00009000"], ["61596.00000000", "1.09247000"], ["61596.01000000", "0.06358000"], ["61596.02000000", "0.00000000"], ["61596.03000000", "0.00000000"], ["61596.47000000", "0.00000000"], ["61596.48000000", "0.00000000"], ["61596.49000000", "0.20483000"], ["61596.50000000", "0.05127000"], ["61596.51000000", "0.04036000"], ["61597.55000000", "0.00009000"], ["61597.60000000", "0.16234000"], ["61597.63000000", "0.00018000"], ["61597.75000000", "0.00000000"], ["61597.76000000", "0.00000000"], ["61597.98000000", "0.00000000"], ["61598.00000000", "0.00018000"], ["61598.01000000", "0.32750000"], ["61598.33000000", "0.00000000"], ["61598.63000000", "0.00000000"], ["61600.00000000", "1.61631000"], ["61600.01000000", "0.34011000"], ["61600.17000000", "0.00010000"], ["61602.01000000", "0.00027000"], ["61602.17000000", "0.00000000"], ["61603.19000000", "1.00836000"], ["61603.33000000", "0.12009000"], ["61603.69000000", "0.00009000"], ["61603.81000000", "0.40109000"], ["61604.01000000", "0.02166000"], ["61604.17000000", "0.24750000"], ["61609.83000000", "0.00009000"], ["61610.01000000", "0.00000000"], ["61619.17000000", "0.00000000"], ["61624.90000000", "1.51448000"], ["61625.50000000", "0.00000000"], ["61626.60000000", "1.50072000"], ["61626.69000000", "0.00000000"], ["61627.00000000", "0.01000000"], ["61627.26000000", "0.00000000"], ["61628.00000000", "0.02400000"], ["61640.63000000", "0.00406000"], ["61658.84000000", "0.00000000"], ["61682.00000000", "0.03500000"], ["61686.30000000", "0.00000000"], ["61694.35000000", "0.00000000"], ["61697.58000000", "0.00000000"], ["61701.88000000", "0.00000000"], ["61774.07000000", "0.00000000"], ["61777.14000000", "0.00000000"], ["61903.66000000", "0.00000000"], ["77803.32000000", "0.00072000"]]}
{"type": "depth", "ts": 1783008093514, "U": 96863160853, "u": 96863161052, "bids": [["61594.00000000", "0.73283000"], ["61593.99000000", "0.00036000"], ["61593.53000000", "0.00000000"], ["61592.23000000", "0.00009000"], ["61592.11000000", "0.00000000"], ["61592.02000000", "0.00000000"], ["61592.00000000", "0.02418000"], ["61591.84000000", "0.00000000"], ["61591.65000000", "0.00000000"], ["61591.63000000", "0.00000000"], ["61591.40000000", "0.08989000"], ["61590.99000000", "0.00000000"], ["61590.81000000", "0.00000000"], ["61590.58000000", "0.00000000"], ["61590.57000000", "0.00000000"], ["61590.34000000", "0.00000000"], ["61590.33000000", "0.00018000"], ["61590.11000000", "0.00009000"], ["61590.10000000", "0.09007000"], ["61590.01000000", "0.00009000"], ["61590.00000000", "0.02905000"], ["61589.79000000", "0.00009000"], ["61589.78000000", "0.03426000"], ["61589.50000000", "0.04727000"], ["61589.12000000", "0.00009000"], ["61589.11000000", "0.14909000"], ["61589.10000000", "0.02209000"], ["61588.81000000", "0.00009000"], ["61588.80000000", "0.08989000"], ["61588.21000000", "0.00000000"], ["61588.20000000", "0.09017000"], ["61588.01000000", "0.00000000"], ["61588.00000000", "0.02418000"], ["61587.85000000", "0.38956000"], ["61587.84000000", "0.24778000"], ["61587.76000000", "0.01018000"], ["61587.19000000", "0.00000000"], ["61587.18000000", "0.08990000"], ["61587.17000000", "0.66407000"], ["61586.59000000", "0.97390000"], ["61584.35000000", "0.00649000"], ["61584.07000000", "0.01200000"], ["61581.68000000", "0.00009000"], ["61580.24000000", "0.00000000"], ["61576.19000000", "0.43791000"], ["61568.09000000", "0.00000000"], ["61556.37000000", "0.00009000"], ["61544.23000000", "0.03269000"], ["61537.78000000", "0.00000000"], ["61537.38000000", "0.00000000"], ["61535.66000000", "0.00034000"], ["61535.65000000", "0.00000000"], ["61523.00000000", "0.00009000"], ["61481.34000000", "0.00000000"], ["61481.33000000", "0.00000000"], ["61479.66000000", "0.10022000"], ["61454.04000000", "0.09381000"], ["61420.75000000", "0.00000000"], ["61377.69000000", "0.00000000"], ["61374.45000000", "0.00000000"], ["61374.41000000", "0.00000000"], ["61324.08000000", "0.01919000"], ["61320.27000000", "0.01920000"], ["61320.18000000", "0.01904000"], ["55434.60000000", "0.00040000"]], "asks": [["61594.01000000", "2.98546000"], ["61595.98000000", "0.00009000"], ["61595.99000000", "0.11897000"], ["61596.00000000", "0.00045000"], ["61596.01000000", "0.04054000"], ["61596.03000000", "0.00009000"], ["61596.04000000", "0.10180000"], ["61596.48000000", "0.00009000"], ["61596.49000000", "0.20492000"], ["61596.50000000", "0.06138000"], ["61596.51000000", "0.04915000"], ["61597.60000000", "0.00018000"], ["61597.63000000", "0.00000000"], ["61597.97000000", "0.00009000"], ["61597.98000000", "0.41051000"], ["61597.99000000", "0.14923000"], ["61598.00000000", "0.00009000"], ["61600.00000000", "1.62899000"], ["61601.69000000", "0.00009000"], ["61603.08000000", "0.00009000"], ["61603.81000000", "0.40100000"], ["61604.01000000", "0.02148000"], ["61614.95000000", "0.00000000"], ["61620.01000000", "0.00000000"], ["61620.06000000", "0.00162000"], ["61625.00000000", "0.01000000"], ["61627.00000000", "0.00000000"], ["61698.56000000", "0.00000000"], ["61771.00000000", "0.00000000"], ["61795.03000000", "0.00000000"]]}
{"type": "depth", "ts": 1783008093614, "U": 96863161053, "u": 96863161290, "bids": [["61594.00000000", "1.52304000"], ["61593.99000000", "0.00036000"], ["61593.21000000", "0.00000000"], ["61592.02000000", "0.00009000"], ["61592.01000000", "0.03470000"], ["61592.00000000", "0.02418000"], ["61591.41000000", "0.00009000"], ["61591.40000000", "0.09007000"], ["61590.33000000", "0.00018000"], ["61590.28000000", "0.00000000"], ["61590.11000000", "0.00000000"], ["61590.10000000", "0.09034000"], ["61590.01000000", "0.00000000"], ["61590.00000000", "0.02905000"], ["61589.79000000", "0.00000000"], ["61589.78000000", "0.00018000"], ["61589.51000000", "0.00000000"], ["61589.50000000", "0.04727000"], ["61589.13000000", "0.79088000"], ["61589.12000000", "1.36818000"], ["61589.11000000", "0.00018000"], ["61589.10000000", "0.02209000"], ["61588.81000000", "0.00000000"], ["61588.80000000", "0.00000000"], ["61588.60000000", "0.00009000"], ["61588.20000000", "0.00018000"], ["61588.00000000", "0.02400000"], ["61587.84000000", "0.24769000"], ["61587.76000000", "0.01000000"], ["61587.24000000", "0.08775000"], ["61587.18000000", "0.00000000"], ["61586.90000000", "0.00812000"], ["61586.62000000", "0.00000000"], ["61585.67000000", "0.00009000"], ["61584.19000000", "0.01000000"], ["61583.57000000", "0.01300000"], ["61582.74000000", "0.00009000"], ["61579.81000000", "0.00009000"], ["61576.88000000", "0.00009000"], ["61576.56000000", "0.00000000"], ["61573.95000000", "0.00009000"], ["61571.02000000", "0.00009000"], ["61568.09000000", "0.00009000"], ["61567.38000000", "0.03163000"], ["61566.11000000", "0.00000000"], ["61561.68000000", "0.00009000"], ["61559.91000000", "0.00000000"], ["61559.30000000", "0.00000000"], ["61556.37000000", "0.00000000"], ["61543.26000000", "0.00000000"], ["61538.02000000", "0.00405000"], ["61536.27000000", "0.01000000"], ["61536.12000000", "0.01300000"], ["61526.61000000", "0.00000000"], ["61509.97000000", "0.00000000"], ["61507.05000000", "0.00000000"], ["61495.85000000", "0.00000000"], ["61493.32000000", "0.00000000"], ["61481.31000000", "0.02543000"], ["61476.67000000", "0.00000000"], ["61476.05000000", "0.00162000"], ["61460.02000000", "0.00000000"], ["61443.37000000", "0.00000000"], ["61426.73000000", "0.00000000"], ["61410.08000000", "0.00000000"], ["60996.55000000", "0.00409000"], ["60996.54000000", "0.00409000"], ["60793.29000000", "0.00410000"], ["60793.28000000", "0.00553000"], ["60670.10000000", "0.00411000"], ["60670.09000000", "0.00411000"], ["60362.12000000", "0.00413000"], ["60054.15000000", "0.00415000"], ["55434.60000000", "0.00080000"], ["49275.20000000", "0.00000000"]], "asks": [["61594.01000000", "1.79145000"], ["61595.98000000", "0.00812000"], ["61595.99000000", "0.00027000"], ["61596.00000000", "0.00018000"], ["61596.01000000", "0.00054000"], ["61596.03000000", "0.00000000"], ["61596.04000000", "0.00018000"], ["61596.47000000", "0.00009000"], ["61596.48000000", "0.00009000"], ["61596.49000000", "0.00027000"], ["61596.50000000", "0.01020000"], ["61596.51000000", "0.00897000"], ["61596.98000000", "0.00009000"], ["61596.99000000", "0.00000000"], ["61597.55000000", "0.00000000"], ["61597.60000000", "0.00000000"], ["61597.98000000", "0.07409000"], ["61597.99000000", "0.00000000"], ["61598.01000000", "0.24750000"], ["61599.58000000", "0.00812000"], ["61599.99000000", "0.00009000"], ["61600.00000000", "0.26578000"], ["61600.01000000", "0.26020000"], ["61601.41000000", "0.00009000"], ["61601.46000000", "0.00000000"], ["61601.89000000", "0.14923000"], ["61603.19000000", "0.66139000"], ["61603.20000000", "0.15374000"], ["61603.33000000", "0.12000000"], ["61603.80000000", "0.00000000"], ["61603.82000000", "0.00000000"], ["61603.83000000", "0.00000000"], ["61603.87000000", "0.00000000"], ["61604.43000000", "0.00009000"], ["61605.62000000", "0.00000000"], ["61607.99000000", "0.00000000"], ["61608.00000000", "0.00000000"], ["61608.31000000", "0.00976000"], ["61608.61000000", "0.01100000"], ["61609.03000000", "0.00000000"], ["61609.21000000", "0.01000000"], ["61612.39000000", "0.00000000"], ["61613.56000000", "0.02691000"], ["61614.18000000", "0.00000000"], ["61618.50000000", "1.49557000"], ["61620.78000000", "0.58480000"], ["61621.00000000", "0.00324000"], ["61623.84000000", "0.00000000"], ["61641.99000000", "0.00381000"], ["61643.14000000", "0.00000000"], ["61643.26000000", "0.10000000"], ["61645.12000000", "0.00010000"], ["61673.11000000", "0.00000000"], ["61676.45000000", "0.00000000"], ["61689.99000000", "0.01971000"], ["61693.10000000", "0.00000000"], ["61693.31000000", "0.34884000"], ["61703.99000000", "0.00153000"], ["61765.65000000", "0.24750000"]]}
{"type": "depth", "ts": 1783008093714, "U": 96863161291, "u": 96863161511, "bids": [["61594.00000000", "1.54435000"], ["61593.99000000", "0.00018000"], ["61593.67000000", "0.00000000"], ["61592.71000000", "0.06043000"], ["61592.70000000", "0.08368000"], ["61592.39000000", "0.00400000"], ["61592.02000000", "0.00000000"], ["61592.01000000", "0.00018000"], ["61591.55000000", "0.00000000"], ["61591.53000000", "0.00009000"], ["61591.41000000", "0.00000000"], ["61591.40000000", "0.09016000"], ["61590.53000000", "0.00000000"], ["61590.22000000", "0.06098000"], ["61590.10000000", "0.09025000"], ["61590.00000000", "0.02887000"], ["61589.78000000", "0.00000000"], ["61589.50000000", "0.04709000"], ["61589.11000000", "0.00000000"], ["61589.10000000", "0.02191000"], ["61588.15000000", "0.04217000"], ["61587.84000000", "0.25069000"], ["61587.24000000", "0.00000000"], ["61585.96000000", "0.00488000"], ["61585.24000000", "0.00000000"], ["61583.96000000", "0.00400000"], ["61583.47000000", "0.00876000"], ["61581.68000000", "0.00309000"], ["61562.23000000", "0.00000000"], ["61561.39000000", "1.09631000"], ["61560.97000000", "1.60976000"], ["61547.43000000", "0.00000000"], ["61544.62000000", "0.00000000"], ["61541.81000000", "0.00000000"], ["61538.02000000", "0.00405000"], ["61536.12000000", "0.00000000"], ["61535.64000000", "0.00000000"], ["61532.08000000", "0.60364000"], ["61532.07000000", "0.97544000"], ["61532.02000000", "0.00000000"], ["61526.02000000", "0.00000000"], ["61525.82000000", "0.14841000"], ["61525.64000000", "0.00000000"], ["61506.78000000", "0.00000000"], ["61495.67000000", "0.00016000"], ["61491.10000000", "0.00000000"], ["61485.50000000", "0.00024000"], ["61481.31000000", "0.00000000"], ["61476.05000000", "0.00000000"], ["61470.11000000", "0.00000000"], ["61454.53000000", "0.00040000"], ["61359.95000000", "0.00000000"], ["60362.12000000", "0.00826000"], ["60054.15000000", "0.00830000"], ["59746.18000000", "0.00834000"], ["55434.60000000", "0.00120000"], ["49294.00000000", "0.00800000"], ["49275.20000000", "0.00000000"]], "asks": [["61594.01000000", "1.62219000"], ["61594.22000000", "0.00009000"], ["61594.23000000", "0.02000000"], ["61594.46000000", "0.00000000"], ["61595.98000000", "0.00018000"], ["61595.99000000", "0.00009000"], ["61596.00000000", "0.00009000"], ["61596.01000000", "0.00036000"], ["61596.04000000", "0.00000000"], ["61596.47000000", "0.00000000"], ["61596.48000000", "0.00000000"], ["61596.49000000", "0.00009000"], ["61596.50000000", "0.01020000"], ["61596.51000000", "0.00906000"], ["61596.97000000", "0.00000000"], ["61596.98000000", "0.00000000"], ["61597.39000000", "0.00000000"], ["61597.49000000", "0.00000000"], ["61597.68000000", "0.00009000"], ["61597.69000000", "0.08281000"], ["61597.96000000", "0.00812000"], ["61597.98000000", "0.07427000"], ["61598.01000000", "0.24768000"], ["61599.58000000", "0.00018000"], ["61599.59000000", "0.00000000"], ["61599.85000000", "0.00034000"], ["61600.00000000", "0.11231000"], ["61600.01000000", "0.26038000"], ["61600.17000000", "0.00310000"], ["61601.44000000", "0.00000000"], ["61601.88000000", "0.00000000"], ["61601.89000000", "0.14932000"], ["61602.99000000", "0.00047000"], ["61603.11000000", "0.08998000"], ["61603.18000000", "0.08225000"], ["61603.19000000", "0.30089000"], ["61603.23000000", "0.00048000"], ["61604.54000000", "0.00189000"], ["61606.34000000", "0.00300000"], ["61606.42000000", "0.06927000"], ["61607.58000000", "0.08989000"], ["61607.59000000", "0.00000000"], ["61609.61000000", "0.08232000"], ["61609.96000000", "0.08989000"], ["61609.97000000", "1.14743000"], ["61609.98000000", "1.36330000"], ["61609.99000000", "0.00000000"], ["61612.15000000", "0.97390000"], ["61612.80000000", "0.63131000"], ["61617.07000000", "0.00000000"], ["61617.69000000", "0.00000000"], ["61620.07000000", "0.00000000"], ["61620.35000000", "0.00000000"], ["61623.14000000", "0.00000000"], ["61626.59000000", "1.36330000"], ["61626.69000000", "0.00009000"], ["61631.90000000", "0.00230000"], ["61641.99000000", "0.00381000"], ["61645.20000000", "0.00000000"], ["61646.14000000", "0.00000000"], ["61647.18000000", "0.93029000"], ["61648.27000000", "0.00000000"], ["61651.56000000", "0.97528000"], ["61669.21000000", "0.00000000"], ["61695.98000000", "0.30520000"], ["61699.99000000", "0.69296000"], ["61703.03000000", "0.48715000"], ["61703.99000000", "0.00000000"], ["61712.65000000", "4.86608000"], ["61785.08000000", "0.00000000"], ["61903.66000000", "0.00009000"]]}
{"type": "depth", "ts": 1783008093814, "U": 96863161512, "u": 96863161644, "bids": [["61594.00000000", "2.51825000"], ["61593.97000000", "0.00000000"], ["61592.87000000", "0.04217000"], ["61592.71000000", "0.06061000"], ["61592.70000000", "0.08386000"], ["61592.40000000", "0.00812000"], ["61592.10000000", "0.00243000"], ["61592.08000000", "0.10211000"], ["61592.01000000", "0.00000000"], ["61591.51000000", "0.00009000"], ["61591.40000000", "0.08989000"], ["61590.22000000", "0.00000000"], ["61586.90000000", "0.00000000"], ["61586.63000000", "0.00043000"], ["61582.94000000", "0.00000000"], ["61536.27000000", "0.00000000"], ["61479.34000000", "0.00000000"], ["61377.06000000", "0.01003000"], ["55434.60000000", "0.00160000"]], "asks": [["61594.01000000", "0.23874000"], ["61594.14000000", "0.00000000"], ["61594.22000000", "0.00000000"], ["61594.23000000", "0.00018000"], ["61595.98000000", "0.00000000"], ["61596.49000000", "0.00000000"], ["61596.50000000", "0.00036000"], ["61596.51000000", "0.00018000"], ["61597.33000000", "0.00009000"], ["61597.34000000", "0.02000000"], ["61597.68000000", "0.00000000"], ["61597.69000000", "0.00018000"], ["61597.96000000", "0.00018000"], ["61597.97000000", "0.00000000"], ["61597.98000000", "0.00018000"], ["61598.00000000", "0.00000000"], ["61598.01000000", "0.00018000"], ["61598.36000000", "0.03329000"], ["61599.58000000", "0.00000000"], ["61599.99000000", "0.00000000"], ["61600.00000000", "0.00036000"], ["61600.01000000", "0.26020000"], ["61600.32000000", "0.00000000"], ["61601.81000000", "0.08989000"], ["61601.88000000", "0.00000000"], ["61601.89000000", "0.00009000"], ["61602.01000000", "0.00018000"], ["61603.10000000", "0.00903000"], ["61603.17000000", "0.00009000"], ["61603.19000000", "0.00000000"], ["61603.20000000", "0.00009000"], ["61603.25000000", "0.00000000"], ["61603.32000000", "0.00009000"], ["61605.71000000", "0.08989000"], ["61606.16000000", "0.00009000"], ["61606.18000000", "0.00000000"], ["61606.38000000", "0.00000000"], ["61606.42000000", "0.11525000"], ["61607.01000000", "0.08989000"], ["61607.87000000", "0.00000000"], ["61608.14000000", "0.00000000"], ["61608.15000000", "0.00000000"], ["61608.16000000", "0.00000000"], ["61608.20000000", "0.00400000"], ["61609.11000000", "0.00000000"], ["61610.18000000", "0.00000000"], ["61612.04000000", "0.00000000"], ["61614.07000000", "0.00000000"], ["61614.30000000", "0.00000000"], ["61614.31000000", "0.00000000"], ["61614.32000000", "0.00000000"], ["61614.35000000", "0.00400000"], ["61614.97000000", "0.00000000"], ["61617.90000000", "0.00000000"], ["61619.06000000", "0.00000000"], ["61620.83000000", "0.00000000"], ["61621.26000000", "0.00649000"], ["61623.76000000", "0.00000000"], ["61624.90000000", "2.44381000"], ["61624.96000000", "1.99800000"], ["61626.69000000", "0.00000000"], ["61637.47000000", "0.00000000"], ["61651.56000000", "0.00000000"], ["61651.97000000", "0.97515000"], ["61695.48000000", "0.00000000"], ["61771.81000000", "0.24750000"], ["63480.00000000", "0.08786000"], ["63480.68000000", "0.00008000"]]}
{"type": "depth", "ts": 1783008093914, "U": 96863161645, "u": 96863161739, "bids": [["61594.00000000", "2.60789000"], ["61592.74000000", "0.00508000"], ["61592.71000000", "0.08692000"], ["61592.70000000", "0.08377000"], ["61584.35000000", "0.00000000"], ["61582.28000000", "0.00009000"], ["61543.82000000", "0.13460000"], ["61422.67000000", "0.00828000"], ["55434.60000000", "0.00200000"]], "asks": [["61594.01000000", "0.23746000"], ["61594.23000000", "0.00000000"], ["61596.01000000", "0.00018000"], ["61596.50000000", "0.00000000"], ["61596.51000000", "0.00000000"], ["61597.32000000", "0.00000000"], ["61597.34000000", "0.02018000"], ["61597.39000000", "0.00009000"], ["61597.69000000", "0.00000000"], ["61597.96000000", "0.00000000"], ["61597.98000000", "0.00000000"], ["61598.01000000", "0.00000000"], ["61598.35000000", "0.00009000"], ["61598.36000000", "0.03347000"], ["61599.99000000", "0.00009000"], ["61600.00000000", "0.08374000"], ["61600.01000000", "0.26047000"], ["61600.32000000", "0.00009000"], ["61600.82000000", "0.00000000"], ["61601.80000000", "0.00009000"], ["61601.81000000", "0.09007000"], ["61602.98000000", "0.00000000"], ["61603.10000000", "0.00921000"], ["61603.11000000", "0.09016000"], ["61603.18000000", "0.08252000"], ["61603.25000000", "0.00009000"], ["61603.31000000", "0.00009000"], ["61603.32000000", "0.00009000"], ["61603.33000000", "0.12018000"], ["61603.80000000", "0.00000000"], ["61604.16000000", "0.00000000"], ["61606.18000000", "0.00009000"], ["61609.11000000", "0.00009000"], ["61610.50000000", "0.00000000"], ["61612.04000000", "0.00009000"], ["61614.97000000", "0.00009000"], ["61617.90000000", "0.00009000"], ["61620.83000000", "0.00009000"], ["61621.26000000", "0.00000000"], ["61623.76000000", "0.00009000"], ["61626.69000000", "0.00009000"], ["61648.59000000", "0.00400000"], ["61651.97000000", "0.00000000"], ["61652.69000000", "0.97515000"], ["61688.34000000", "0.00016000"], ["61691.57000000", "0.00024000"]]}
{"type": "depth", "ts": 1783008094014, "U": 96863161740, "u": 96863161787, "bids": [["61594.00000000", "2.60919000"], ["61592.87000000", "0.04235000"], ["61592.74000000", "0.00009000"], ["61590.10000000", "0.09007000"], ["61579.33000000", "0.00000000"], ["61565.92000000", "0.00000000"], ["61552.51000000", "0.00000000"], ["61544.23000000", "0.06601000"], ["61539.10000000", "0.00000000"], ["61525.69000000", "0.00000000"], ["61512.28000000", "0.00000000"], ["61498.87000000", "0.00000000"], ["61485.46000000", "0.00000000"], ["61472.05000000", "0.00000000"], ["61458.63000000", "0.00000000"], ["61440.63000000", "0.00828000"], ["55434.60000000", "0.00240000"], ["55434.00000000", "0.00000000"], ["49275.20000000", "0.00040000"]], "asks": [["61594.01000000", "0.38916000"], ["61595.16000000", "0.00009000"], ["61595.17000000", "0.00982000"], ["61596.52000000", "0.00009000"], ["61596.53000000", "0.00886000"], ["61598.36000000", "0.03347000"], ["61600.00000000", "0.08392000"], ["61601.68000000", "0.00812000"], ["61602.98000000", "0.00000000"], ["61603.10000000", "0.00912000"], ["61603.17000000", "0.00000000"], ["61603.31000000", "0.00000000"], ["61603.32000000", "0.28240000"], ["61603.33000000", "0.12000000"], ["61603.80000000", "0.00000000"], ["61604.42000000", "0.00812000"], ["61604.53000000", "0.00000000"], ["61617.58000000", "0.55700000"], ["61646.39000000", "0.00000000"], ["61722.43000000", "0.00000000"]]}
{"type": "depth", "ts": 1783008094114, "U": 96863161788, "u": 96863161837, "bids": [["61592.87000000", "0.04217000"], ["61583.66000000", "0.00000000"], ["61573.66000000", "0.00009000"], ["61542.01000000", "0.00000000"], ["61536.01000000", "0.00095000"], ["61530.36000000", "0.00000000"], ["61516.56000000", "0.00030000"], ["61458.59000000", "0.00827000"], ["61420.75000000", "0.01002000"], ["61377.06000000", "0.00000000"], ["60670.09000000", "0.00441000"], ["55434.60000000", "0.00260000"]], "asks": [["61594.01000000", "0.18141000"], ["61594.04000000", "0.00009000"], ["61594.05000000", "0.05000000"], ["61594.09000000", "0.00009000"], ["61594.10000000", "0.05000000"], ["61595.16000000", "0.00000000"], ["61595.17000000", "0.01000000"], ["61596.52000000", "0.00000000"], ["61596.53000000", "0.00904000"], ["61600.01000000", "0.26047000"], ["61601.68000000", "0.00830000"], ["61603.10000000", "0.00903000"], ["61603.11000000", "0.08998000"], ["61603.17000000", "0.00009000"], ["61603.18000000", "0.08234000"], ["61604.42000000", "0.00000000"], ["61610.63000000", "0.00009000"], ["61620.63000000", "0.00000000"], ["61670.54000000", "0.00030000"], ["61684.38000000", "0.00000000"], ["62520.45000000", "0.00000000"]]}
{"type": "depth", "ts": 1783008094214, "U": 96863161838, "u": 96863161867, "bids": [["61578.35000000", "0.00649000"], ["61495.67000000", "0.00000000"], ["61485.50000000", "0.00000000"], ["61476.56000000", "0.00827000"], ["61454.53000000", "0.00000000"], ["61439.61000000", "0.00501000"], ["61378.43000000", "0.00196000"], ["55434.60000000", "0.00300000"], ["49275.20000000", "0.00000000"]], "asks": [["61594.01000000", "0.18168000"], ["61594.05000000", "0.05018000"], ["61601.68000000", "0.00812000"], ["61601.81000000", "0.08989000"], ["61604.00000000", "0.00500000"], ["61606.00000000", "0.00500000"], ["61608.00000000", "0.00500000"], ["61610.00000000", "0.81757000"], ["61612.00000000", "0.00500000"], ["61614.00000000", "0.01000000"], ["61616.00000000", "0.01009000"], ["61688.34000000", "0.00000000"], ["61691.57000000", "0.00000000"], ["61695.87000000", "0.00000000"]]}
{"type": "depth", "ts": 1783008094314, "U": 96863161868, "u": 96863161907, "bids": [["61594.00000000", "2.52144000"], ["61593.53000000", "0.00812000"], ["61592.70000000", "0.08377000"], ["61592.40000000", "0.00000000"], ["61592.38000000", "0.00000000"], ["61592.14000000", "0.11979000"], ["61592.08000000", "0.00000000"], ["61587.45000000", "0.01019000"], ["61586.26000000", "0.00892000"], ["61494.52000000", "0.00827000"], ["61455.88000000", "0.00501000"], ["55434.60000000", "0.00340000"]], "asks": [["61594.01000000", "0.18370000"], ["61595.17000000", "0.00018000"], ["61595.24000000", "0.01007000"], ["61596.42000000", "0.00009000"], ["61596.53000000", "0.00018000"], ["61596.59000000", "0.00894000"], ["61598.35000000", "0.00000000"], ["61598.36000000", "0.00018000"], ["61598.55000000", "0.02992000"], ["61599.08000000", "0.00009000"], ["61599.09000000", "0.00000000"], ["61600.00000000", "0.19223000"], ["61601.68000000", "0.00000000"], ["61602.01000000", "0.00009000"], ["61602.98000000", "0.00812000"], ["61618.00000000", "0.01000000"], ["61620.00000000", "0.01009000"], ["61622.00000000", "0.01600000"], ["61624.00000000", "0.01600000"], ["61626.00000000", "0.02400000"], ["61753.29000000", "0.00000000"], ["62517.93000000", "0.00030000"]]}
{"type": "depth", "ts": 1783008094414, "U": 96863161908, "u": 96863161960, "bids": [["61594.00000000", "2.52126000"], ["61593.53000000", "0.00000000"], ["61593.26000000", "0.08775000"], ["61592.75000000", "0.00812000"], ["61592.70000000", "0.08377000"], ["61540.73000000", "0.00000000"], ["61536.02000000", "0.00401000"], ["61512.48000000", "0.00827000"], ["61494.53000000", "0.01727000"], ["61489.69000000", "0.00016000"], ["61479.55000000", "0.00000000"], ["61479.52000000", "0.00024000"], ["61475.26000000", "0.00162000"], ["61472.15000000", "0.00501000"], ["61420.75000000", "0.01017000"], ["55434.60000000", "0.00380000"]], "asks": [["61594.01000000", "0.18151000"], ["61594.05000000", "0.05027000"], ["61594.10000000", "0.05027000"], ["61595.17000000", "0.00000000"], ["61595.24000000", "0.01025000"], ["61596.15000000", "0.08775000"], ["61596.53000000", "0.00000000"], ["61596.59000000", "0.00912000"], ["61597.34000000", "0.02018000"], ["61598.36000000", "0.00000000"], ["61598.54000000", "0.00009000"], ["61598.55000000", "0.03010000"], ["61599.08000000", "0.00000000"], ["61599.20000000", "0.00009000"], ["61599.21000000", "0.08989000"], ["61600.01000000", "0.26047000"], ["61601.40000000", "0.00812000"], ["61602.98000000", "0.00000000"], ["61603.10000000", "0.00903000"], ["61603.17000000", "0.00000000"], ["61604.00000000", "0.00823000"], ["61641.20000000", "0.01100000"], ["61702.29000000", "0.00162000"], ["61708.44000000", "0.00000000"]]}
{"type": "depth", "ts": 1783008094514, "U": 96863161961, "u": 96863162109, "bids": [["61594.00000000", "1.54736000"], ["61593.99000000", "0.00018000"], ["61593.27000000", "0.00009000"], ["61592.87000000", "0.00000000"], ["61592.75000000", "0.00000000"], ["61592.72000000", "0.08998000"], ["61592.71000000", "0.06070000"], ["61592.70000000", "0.00000000"], ["61592.15000000", "0.00000000"], ["61592.14000000", "0.00000000"], ["61592.01000000", "0.00009000"], ["61591.59000000", "0.00812000"], ["61591.58000000", "0.07264000"], ["61591.41000000", "0.00000000"], ["61587.52000000", "0.00000000"], ["61587.45000000", "0.00000000"], ["61586.26000000", "0.00000000"], ["61577.67000000", "0.01025000"], ["61569.04000000", "0.00000000"], ["61550.55000000", "0.00000000"], ["61538.02000000", "0.00405000"], ["61530.45000000", "0.00826000"], ["61488.42000000", "0.00500000"], ["61479.34000000", "0.04217000"], ["61476.57000000", "0.00162000"], ["55434.60000000", "0.00420000"]], "asks": [["61594.01000000", "0.59856000"], ["61594.10000000", "0.05036000"], ["61595.24000000", "0.01025000"], ["61595.80000000", "0.00009000"], ["61596.14000000", "0.00009000"], ["61596.15000000", "0.08802000"], ["61597.82000000", "0.00009000"], ["61597.83000000", "0.04770000"], ["61597.90000000", "0.00009000"], ["61597.91000000", "0.08989000"], ["61598.54000000", "0.00000000"], ["61598.55000000", "0.00018000"], ["61599.21000000", "0.09007000"], ["61600.00000000", "0.19205000"], ["61600.01000000", "0.26029000"], ["61601.80000000", "0.00000000"], ["61602.01000000", "0.00000000"], ["61603.10000000", "0.00894000"], ["61603.15000000", "0.08989000"], ["61603.16000000", "0.70599000"], ["61603.17000000", "1.36330000"], ["61603.18000000", "0.00000000"], ["61603.20000000", "0.00000000"], ["61603.32000000", "0.00000000"], ["61605.71000000", "0.00000000"], ["61605.81000000", "0.00000000"], ["61606.42000000", "0.40160000"], ["61607.01000000", "0.00000000"], ["61607.58000000", "0.00000000"], ["61608.29000000", "0.97390000"], ["61609.61000000", "0.00000000"], ["61609.96000000", "0.00000000"], ["61618.43000000", "0.00324000"], ["61621.00000000", "0.00000000"], ["61626.69000000", "0.00000000"], ["61641.99000000", "0.00381000"], ["61682.00000000", "0.02400000"], ["61703.03000000", "0.00000000"], ["61703.99000000", "0.00153000"], ["61903.66000000", "0.00000000"]]}
{"type": "depth", "ts": 1783008094614, "U": 96863162110, "u": 96863162188, "bids": [["61594.00000000", "1.54754000"], ["61593.27000000", "0.50731000"], ["61593.26000000", "0.08802000"], ["61592.72000000", "0.08998000"], ["61592.71000000", "0.00009000"], ["61592.01000000", "0.00000000"], ["61592.00000000", "0.02400000"], ["61591.61000000", "0.08989000"], ["61591.60000000", "1.36818000"], ["61591.40000000", "0.00000000"], ["61590.10000000", "0.00018000"], ["61589.13000000", "0.70099000"], ["61576.68000000", "0.01625000"], ["61575.52000000", "0.00016000"], ["61557.04000000", "0.00016000"], ["61548.41000000", "0.00826000"], ["61545.18000000", "0.00000000"], ["61538.57000000", "0.00016000"], ["61532.07000000", "0.97528000"], ["61526.72000000", "0.00000000"], ["61520.09000000", "0.00016000"], ["61513.59000000", "0.00000000"], ["61504.69000000", "0.00500000"], ["61501.61000000", "0.00016000"], ["61236.25000000", "0.00502000"], ["55434.60000000", "0.00460000"], ["49275.20000000", "0.00000000"]], "asks": [["61594.01000000", "0.50746000"], ["61597.34000000", "0.02018000"], ["61597.83000000", "0.04788000"], ["61597.91000000", "0.09007000"], ["61598.40000000", "0.00009000"], ["61598.55000000", "0.00000000"], ["61599.21000000", "0.08989000"], ["61600.01000000", "0.26020000"], ["61602.00000000", "0.00800000"], ["61603.11000000", "0.08989000"], ["61604.00000000", "0.01623000"], ["61606.00000000", "0.01300000"], ["61607.45000000", "0.00009000"], ["61608.00000000", "0.01300000"], ["61612.49000000", "0.00016000"], ["61624.49000000", "0.00000000"], ["61625.41000000", "0.58475000"], ["61626.41000000", "0.01100000"], ["61627.01000000", "0.01000000"], ["61630.97000000", "0.00016000"], ["61642.97000000", "0.00000000"], ["61649.44000000", "0.00016000"], ["61661.46000000", "0.00000000"], ["61667.92000000", "0.00016000"], ["61669.21000000", "0.01000000"], ["61679.94000000", "0.00000000"], ["61686.40000000", "0.00016000"], ["61698.42000000", "0.00000000"]]}
{"type": "depth", "ts": 1783008094714, "U": 96863162189, "u": 96863162231, "bids": [["61594.00000000", "1.54754000"], ["61593.27000000", "0.50731000"], ["61593.26000000", "0.00018000"], ["61592.72000000", "0.00000000"], ["61591.62000000", "0.97390000"], ["61591.61000000", "0.00000000"], ["61566.37000000", "0.00826000"], ["61525.82000000", "0.37297000"], ["61524.01000000", "0.82089000"], ["61520.95000000", "0.00500000"], ["61448.55000000", "0.00040000"], ["61260.65000000", "0.00502000"], ["55434.60000000", "0.00440000"], ["49275.20000000", "0.00000000"]], "asks": [["61594.01000000", "0.75496000"], ["61594.46000000", "0.00009000"], ["61596.14000000", "0.00000000"], ["61596.15000000", "0.00027000"], ["61610.00000000", "0.82557000"], ["61612.00000000", "0.01300000"], ["61614.00000000", "0.01800000"], ["61616.00000000", "0.01809000"], ["61618.00000000", "0.01800000"], ["61620.00000000", "0.01809000"], ["61622.00000000", "0.02400000"], ["61624.00000000", "0.02400000"], ["61667.99000000", "1.24440000"], ["61669.21000000", "0.00000000"], ["61670.12000000", "4.04301000"], ["61682.34000000", "0.00016000"], ["61685.57000000", "0.00024000"]]}
{"type": "depth", "ts": 1783008094814, "U": 96863162232, "u": 96863162258, "bids": [["61594.00000000", "1.54745000"], ["61593.27000000", "0.50749000"], ["61593.26000000", "0.00000000"], ["61584.34000000", "0.00826000"], ["61539.41000000", "0.00309000"], ["61537.22000000", "0.00500000"], ["61520.95000000", "0.01472000"], ["61494.53000000", "0.01727000"], ["61429.42000000", "0.00000000"], ["61285.05000000", "0.01400000"], ["61260.66000000", "0.00194000"], ["55434.60000000", "0.00440000"]], "asks": [["61595.24000000", "0.01025000"], ["61596.15000000", "0.00009000"], ["61599.21000000", "0.09007000"], ["61679.56000000", "0.00000000"]]}
{"type": "depth", "ts": 1783008094914, "U": 96863162259, "u": 96863162282, "bids": [["61553.49000000", "0.00500000"], ["61309.46000000", "0.00502000"], ["60940.56000000", "0.00388000"], ["60874.58000000", "0.00000000"], ["55434.60000000", "0.00461000"]], "asks": [["61596.42000000", "0.00000000"], ["61598.00000000", "0.00600000"], ["61600.00000000", "0.19805000"], ["61602.00000000", "0.01400000"], ["61604.00000000", "0.02223000"], ["61606.00000000", "0.01900000"], ["61608.00000000", "0.01900000"], ["61610.00000000", "0.83157000"], ["61612.00000000", "0.01900000"], ["61614.00000000", "0.02400000"], ["61615.26000000", "0.00649000"], ["61616.00000000", "0.02409000"], ["61618.00000000", "0.02400000"], ["61620.00000000", "0.02409000"], ["61620.26000000", "0.00825000"], ["61689.87000000", "0.00040000"]]}
{"type": "depth", "ts": 1783008095014, "U": 96863162283, "u": 96863162333, "bids": [["61593.27000000", "0.50758000"], ["61591.63000000", "0.08989000"], ["61591.59000000", "0.00000000"], ["61590.77000000", "0.00812000"], ["61587.84000000", "0.25078000"], ["61585.38000000", "0.00009000"], ["61582.92000000", "0.00009000"], ["61569.76000000", "0.00500000"], ["61489.69000000", "0.00000000"], ["61448.55000000", "0.00000000"], ["61388.72000000", "0.04065000"], ["61333.86000000", "0.00502000"], ["61313.90000000", "0.00502000"], ["60860.34000000", "0.00776000"], ["60794.52000000", "0.00223000"], ["55434.60000000", "0.00440000"], ["49275.20000000", "0.00040000"], ["49275.00000000", "0.00200000"]], "asks": [["61594.01000000", "0.50833000"], ["61596.86000000", "0.02434000"], ["61597.91000000", "0.09007000"], ["61598.00000000", "0.00618000"], ["61599.21000000", "0.08989000"], ["61600.17000000", "0.00319000"], ["61600.72000000", "0.00009000"], ["61601.79000000", "0.00812000"], ["61601.80000000", "0.00009000"], ["61601.88000000", "0.00000000"], ["61602.63000000", "0.00009000"], ["61604.01000000", "0.01905000"], ["61605.09000000", "0.00009000"], ["61638.23000000", "0.00825000"], ["61682.34000000", "0.00000000"], ["62602.81000000", "0.00000000"], ["62670.50000000", "0.00401000"]]}
{"type": "depth", "ts": 1783008095115, "U": 96863162334, "u": 96863162369, "bids": [["61586.03000000", "0.00500000"], ["61585.61000000", "0.00909000"], ["61573.66000000", "0.00009000"], ["61497.07000000", "0.12034000"], ["61358.26000000", "0.00501000"], ["61333.13000000", "0.00502000"], ["60670.09000000", "0.00441000"], ["55434.60000000", "0.00440000"], ["55434.00000000", "0.00020000"], ["49275.00000000", "0.00000000"]], "asks": [["61596.59000000", "0.00912000"], ["61596.85000000", "0.00009000"], ["61596.86000000", "0.02452000"], ["61598.00000000", "0.00600000"], ["61600.01000000", "0.26011000"], ["61601.79000000", "0.00000000"], ["61601.80000000", "0.00000000"], ["61601.89000000", "0.00000000"], ["61610.63000000", "0.00009000"], ["61656.19000000", "0.00825000"], ["61693.31000000", "0.00000000"], ["61694.28000000", "0.12000000"], ["62604.76000000", "0.00000000"], ["62672.53000000", "0.00775000"]]}
{"type": "depth", "ts": 1783008095214, "U": 96863162370, "u": 96863162404, "bids": [["61594.00000000", "2.52161000"], ["61593.99000000", "0.00035000"], ["61593.98000000", "0.00017000"], ["61593.28000000", "0.08989000"], ["61592.03000000", "0.09558000"], ["61591.58000000", "0.00153000"], ["61489.68000000", "0.00016000"], ["61448.54000000", "0.00040000"], ["61382.67000000", "0.00501000"], ["61352.35000000", "0.00501000"], ["55434.60000000", "0.00460000"], ["55434.00000000", "0.00000000"], ["49275.20000000", "0.00000000"]], "asks": [["61594.01000000", "0.33878000"], ["61597.83000000", "0.00018000"], ["61597.90000000", "0.00000000"], ["61597.91000000", "0.00018000"], ["61598.27000000", "0.03527000"], ["61601.80000000", "0.00009000"], ["61606.33000000", "0.00009000"], ["61618.57000000", "0.00499000"], ["61620.33000000", "0.00000000"], ["61674.15000000", "0.00824000"], ["61682.33000000", "0.00016000"], ["61699.99000000", "0.00000000"], ["61715.62000000", "0.00000000"]]}
{"type": "depth", "ts": 1783008095314, "U": 96863162405, "u": 96863162450, "bids": [["61594.00000000", "2.52161000"], ["61593.28000000", "0.00018000"], ["61593.27000000", "0.70196000"], ["61591.63000000", "0.00000000"], ["61587.97000000", "0.01000000"], ["61581.78000000", "0.00000000"], ["61407.07000000", "0.00501000"], ["61371.58000000", "0.00501000"], ["55434.60000000", "0.00460000"]], "asks": [["61594.10000000", "0.05027000"], ["61596.15000000", "0.00000000"], ["61597.34000000", "0.02018000"], ["61597.82000000", "0.00000000"], ["61597.83000000", "0.00000000"], ["61597.91000000", "0.00000000"], ["61598.00000000", "0.00618000"], ["61598.26000000", "0.00009000"], ["61598.27000000", "0.03545000"], ["61629.71000000", "0.00000000"], ["61634.84000000", "0.00499000"], ["61692.12000000", "0.00824000"], ["62517.93000000", "0.00030000"]]}
{"type": "depth", "ts": 1783008095414, "U": 96863162451, "u": 96863162477, "bids": [["61594.00000000", "2.52152000"], ["61593.28000000", "0.00000000"], ["61593.27000000", "0.70214000"], ["61525.82000000", "0.36547000"], ["61449.96000000", "0.00039000"], ["61448.54000000", "0.00000000"], ["61431.48000000", "0.00501000"], ["61390.81000000", "0.00501000"], ["55434.60000000", "0.00440000"]], "asks": [["61594.01000000", "0.75741000"], ["61651.11000000", "0.00499000"], ["61710.08000000", "0.00824000"]]}
{"type": "depth", "ts": 1783008095514, "U": 96863162478, "u": 96863162538, "bids": [["61594.00000000", "1.54452000"], ["61593.99000000", "0.00035000"], ["61593.28000000", "0.00009000"], ["61593.27000000", "0.70205000"], ["61592.04000000", "0.00000000"], ["61592.03000000", "0.00000000"], ["61591.63000000", "0.00009000"], ["61591.62000000", "0.97399000"], ["61591.61000000", "0.00009000"], ["61591.39000000", "0.06916000"], ["61586.96000000", "0.01009000"], ["61586.63000000", "0.00102000"], ["61501.61000000", "0.00061000"], ["61455.88000000", "0.01002000"], ["61431.49000000", "0.00162000"], ["61410.03000000", "0.00501000"], ["55434.60000000", "0.00440000"]], "asks": [["61594.01000000", "0.60991000"], ["61594.10000000", "0.05045000"], ["61597.71000000", "0.00009000"], ["61597.72000000", "0.10032000"], ["61597.73000000", "0.05099000"], ["61597.90000000", "0.00009000"], ["61597.91000000", "0.08989000"], ["61598.25000000", "0.00000000"], ["61598.26000000", "0.00000000"], ["61598.27000000", "0.00018000"], ["61599.19000000", "0.00812000"], ["61599.99000000", "0.00009000"], ["61600.00000000", "0.19796000"], ["61601.40000000", "0.00000000"], ["61601.80000000", "0.00000000"], ["61616.10000000", "0.00325000"], ["61618.43000000", "0.00000000"], ["61634.00000000", "0.20409000"], ["61645.78000000", "0.00400000"], ["61648.59000000", "0.00000000"], ["61667.38000000", "0.00499000"], ["61695.98000000", "0.00000000"], ["61728.04000000", "0.00824000"]]}
{"type": "depth", "ts": 1783008095614, "U": 96863162539, "u": 96863162642, "bids": [["61594.00000000", "2.51842000"], ["61593.99000000", "0.00035000"], ["61593.27000000", "0.67342000"], ["61592.01000000", "0.00009000"], ["61592.00000000", "0.02418000"], ["61591.64000000", "0.00000000"], ["61591.63000000", "0.97390000"], ["61591.62000000", "0.00009000"], ["61591.61000000", "0.00000000"], ["61591.53000000", "0.00000000"], ["61591.39000000", "0.06916000"], ["61590.77000000", "0.00000000"], ["61589.86000000", "0.00812000"], ["61589.14000000", "0.00000000"], ["61588.60000000", "0.00000000"], ["61586.96000000", "0.00000000"], ["61586.63000000", "0.00083000"], ["61585.69000000", "0.00187000"], ["61585.67000000", "0.00000000"], ["61585.61000000", "0.00000000"], ["61582.74000000", "0.00000000"], ["61579.81000000", "0.00000000"], ["61576.88000000", "0.00000000"], ["61573.95000000", "0.00000000"], ["61562.23000000", "0.00009000"], ["61516.97000000", "0.00009000"], ["61513.95000000", "0.00009000"], ["61480.28000000", "0.00500000"], ["61429.26000000", "0.00501000"], ["55443.60000000", "0.00000000"], ["55434.60000000", "0.00450000"], ["49275.20000000", "0.00000000"], ["33000.00000000", "37.44300000"]], "asks": [["61594.01000000", "0.79723000"], ["61597.34000000", "0.02018000"], ["61597.72000000", "0.10050000"], ["61597.73000000", "0.05117000"], ["61597.91000000", "0.00000000"], ["61598.00000000", "0.00600000"], ["61598.27000000", "0.00000000"], ["61599.99000000", "0.00009000"], ["61605.34000000", "0.00009000"], ["61614.48000000", "0.78000000"], ["61626.83000000", "0.58474000"], ["61683.65000000", "0.00499000"], ["61746.01000000", "0.00823000"]]}
{"type": "depth", "ts": 1783008095714, "U": 96863162643, "u": 96863162712, "bids": [["61594.00000000", "2.51793000"], ["61592.01000000", "0.00000000"], ["61592.00000000", "0.02418000"], ["61591.64000000", "0.00009000"], ["61591.63000000", "0.97408000"], ["61591.61000000", "0.00009000"], ["61591.60000000", "1.36836000"], ["61591.39000000", "0.06934000"], ["61590.00000000", "0.02905000"], ["61589.86000000", "0.00830000"], ["61589.50000000", "0.04727000"], ["61588.60000000", "0.00009000"], ["61587.31000000", "0.08775000"], ["61585.67000000", "0.00009000"], ["61582.74000000", "0.00009000"], ["61579.81000000", "0.00009000"], ["61576.88000000", "0.00009000"], ["61573.95000000", "0.00009000"], ["61504.77000000", "0.00000000"], ["61504.69000000", "0.01000000"], ["61498.41000000", "0.05233000"], ["61470.85000000", "0.00045000"], ["61450.99000000", "0.00038000"], ["61449.96000000", "0.00000000"], ["61448.49000000", "0.00501000"], ["55434.60000000", "0.00430000"], ["49275.20000000", "0.00000000"]], "asks": [["61594.01000000", "1.04333000"], ["61597.71000000", "0.00009000"], ["61597.72000000", "0.07359000"], ["61597.73000000", "0.05108000"], ["61597.90000000", "0.00000000"], ["61600.00000000", "0.19805000"], ["61699.91000000", "0.00499000"]]}
{"type": "depth", "ts": 1783008095814, "U": 96863162713, "u": 96863162797, "bids": [["61594.00000000", "1.29752000"], ["61593.99000000", "0.00089000"], ["61591.63000000", "0.97417000"], ["61591.39000000", "0.00018000"], ["61590.61000000", "0.05923000"], ["61589.86000000", "0.00018000"], ["61589.14000000", "0.00009000"], ["61589.13000000", "0.70108000"], ["61588.61000000", "0.00000000"], ["61586.64000000", "0.00812000"], ["61538.02000000", "0.00000000"], ["61534.29000000", "0.00000000"], ["61529.09000000", "0.00500000"], ["61467.71000000", "0.00500000"], ["61350.38000000", "4.89480000"], ["55434.60000000", "0.00450000"]], "asks": [["61594.01000000", "1.07345000"], ["61594.10000000", "0.05063000"], ["61596.60000000", "0.00009000"], ["61596.61000000", "0.08997000"], ["61597.39000000", "0.00018000"], ["61597.40000000", "0.07083000"], ["61597.70000000", "0.00009000"], ["61597.71000000", "0.08838000"], ["61597.72000000", "0.07350000"], ["61597.73000000", "0.00018000"], ["61599.20000000", "0.00000000"], ["61599.99000000", "0.00000000"], ["61600.00000000", "0.19796000"], ["61614.48000000", "0.00000000"], ["61616.20000000", "0.00230000"], ["61631.90000000", "0.00000000"], ["61647.18000000", "2.05491000"], ["61648.77000000", "4.87111000"], ["61681.13000000", "0.25377000"], ["61684.19000000", "0.00162000"], ["61687.73000000", "0.00000000"], ["61703.99000000", "0.00000000"], ["61716.18000000", "0.00533000"], ["61721.24000000", "0.00000000"], ["61763.97000000", "0.00823000"], ["61789.50000000", "0.00000000"], ["61798.28000000", "0.00000000"], ["61849.20000000", "0.00000000"], ["61908.90000000", "0.00000000"], ["61968.60000000", "0.00000000"]]}
{"type": "depth", "ts": 1783008095914, "U": 96863162798, "u": 96863162881, "bids": [["61594.00000000", "1.54421000"], ["61593.99000000", "0.00044000"], ["61593.27000000", "0.67333000"], ["61591.62000000", "0.00000000"], ["61591.60000000", "1.36836000"], ["61591.53000000", "0.00009000"], ["61591.39000000", "0.00000000"], ["61590.61000000", "0.05941000"], ["61590.00000000", "0.02905000"], ["61589.86000000", "0.00000000"], ["61589.14000000", "0.00000000"], ["61589.13000000", "0.70117000"], ["61586.63000000", "0.00024000"], ["61553.49000000", "0.01000000"], ["61486.94000000", "0.00500000"], ["55434.60000000", "0.00450000"]], "asks": [["61594.01000000", "0.79600000"], ["61594.10000000", "0.05054000"], ["61596.59000000", "0.00912000"], ["61596.60000000", "0.00000000"], ["61596.61000000", "0.00027000"], ["61597.34000000", "0.02018000"], ["61597.40000000", "0.07101000"], ["61597.70000000", "0.00000000"], ["61597.71000000", "0.00009000"], ["61597.72000000", "0.07332000"], ["61597.73000000", "0.00000000"], ["61599.20000000", "0.00009000"], ["61599.99000000", "0.00009000"], ["61600.00000000", "0.20305000"], ["61602.00000000", "0.01900000"], ["61604.00000000", "0.02723000"], ["61606.00000000", "0.02400000"], ["61608.00000000", "0.02400000"], ["61610.00000000", "0.83657000"], ["61612.00000000", "0.02400000"], ["61732.45000000", "0.00498000"], ["61781.93000000", "0.00823000"], ["61789.50000000", "3.00000000"], ["61849.20000000", "3.00000000"], ["61908.90000000", "3.00000000"]]}
{"type": "depth", "ts": 1783008096014, "U": 96863162882, "u": 96863162918, "bids": [["61591.54000000", "0.07097000"], ["61590.61000000", "0.00018000"], ["61590.11000000", "0.00812000"], ["61586.64000000", "0.00000000"], ["61506.17000000", "0.00500000"], ["55434.60000000", "0.00450000"], ["49275.20000000", "0.00040000"]], "asks": [["61594.01000000", "0.62645000"], ["61596.59000000", "0.00912000"], ["61596.61000000", "0.00009000"], ["61597.40000000", "0.00018000"], ["61597.72000000", "0.07350000"], ["61597.81000000", "0.04848000"], ["61600.71000000", "0.00000000"], ["61601.40000000", "0.00812000"], ["61686.39000000", "0.00114000"], ["61748.72000000", "0.00498000"]]}
{"type": "depth", "ts": 1783008096114, "U": 96863162919, "u": 96863162987, "bids": [["61591.63000000", "0.97417000"], ["61591.60000000", "1.36836000"], ["61591.54000000", "0.07115000"], ["61591.53000000", "0.00000000"], ["61590.61000000", "0.00000000"], ["61590.11000000", "0.00830000"], ["61589.13000000", "0.70099000"], ["61544.75000000", "0.10000000"], ["61525.39000000", "0.00500000"], ["61476.57000000", "0.00000000"], ["61473.48000000", "0.00162000"], ["61472.22000000", "0.00000000"], ["60670.09000000", "0.00441000"], ["55434.60000000", "0.00430000"]], "asks": [["61594.01000000", "0.62717000"], ["61594.02000000", "0.00071000"], ["61594.10000000", "0.05045000"], ["61596.61000000", "0.00000000"], ["61597.34000000", "0.02018000"], ["61597.39000000", "0.00009000"], ["61597.40000000", "0.00000000"], ["61597.72000000", "0.07350000"], ["61597.80000000", "0.00009000"], ["61597.81000000", "0.04866000"], ["61601.40000000", "0.00000000"], ["61626.70000000", "0.00499000"], ["61630.79000000", "0.00250000"], ["61641.99000000", "0.00000000"], ["61644.74000000", "0.00381000"], ["61645.65000000", "0.00000000"], ["61764.99000000", "0.00498000"]]}
{"type": "depth", "ts": 1783008096214, "U": 96863162988, "u": 96863163006, "bids": [["61573.66000000", "0.00009000"], ["61544.62000000", "0.00500000"], ["61450.99000000", "0.00000000"], ["55434.60000000", "0.00430000"], ["49275.20000000", "0.00000000"]], "asks": [["61594.01000000", "0.79655000"], ["61605.74000000", "0.01800000"], ["61605.80000000", "0.01400000"], ["61606.36000000", "0.01200000"], ["61606.41000000", "0.01100000"], ["61608.82000000", "0.01000000"], ["61609.49000000", "0.01200000"], ["61610.63000000", "0.00009000"], ["61612.95000000", "0.00000000"]]}
{"type": "depth", "ts": 1783008096314, "U": 96863163007, "u": 96863163037, "bids": [["61587.84000000", "0.25478000"], ["61563.85000000", "0.00500000"], ["55434.60000000", "0.00430000"], ["55434.00000000", "0.00000000"]], "asks": [["61594.01000000", "0.79681000"], ["61594.02000000", "0.00080000"], ["61597.70000000", "0.00009000"], ["61597.71000000", "0.08131000"], ["61599.99000000", "0.00000000"], ["61600.00000000", "0.20296000"], ["61600.17000000", "0.00719000"], ["61606.36000000", "0.02500000"], ["61606.42000000", "0.41260000"], ["61609.19000000", "0.01000000"], ["61613.00000000", "0.00000000"], ["61613.56000000", "0.01491000"], ["61613.62000000", "0.01100000"], ["61616.03000000", "0.00000000"], ["61616.40000000", "0.00000000"], ["61644.39000000", "0.00000000"], ["61651.11000000", "0.00998000"], ["61717.23000000", "0.00114000"], ["62517.93000000", "0.00030000"]]}
{"type": "depth", "ts": 1783008096414, "U": 96863163038, "u": 96863163087, "bids": [["61593.27000000", "0.43551000"], ["61591.64000000", "0.97390000"], ["61591.63000000", "0.00027000"], ["61590.11000000", "0.00018000"], ["61589.11000000", "0.00812000"], ["61586.94000000", "0.01004000"], ["61585.68000000", "0.00894000"], ["61543.82000000", "0.00000000"], ["61542.81000000", "0.00034000"], ["61542.55000000", "0.13417000"], ["61452.00000000", "0.00037000"], ["55434.60000000", "0.00430000"]], "asks": [["61594.01000000", "1.04397000"], ["61597.34000000", "0.02018000"], ["61597.71000000", "0.08149000"], ["61597.81000000", "0.04848000"], ["61604.84000000", "0.04217000"], ["61608.21000000", "0.01100000"], ["61609.49000000", "0.02200000"], ["61613.62000000", "0.00000000"], ["61616.70000000", "0.01000000"], ["61658.79000000", "0.00009000"], ["61662.39000000", "0.13488000"], ["61665.28000000", "0.00000000"], ["61675.51000000", "0.00499000"], ["61789.50000000", "3.00000000"], ["61849.20000000", "3.00000000"], ["61908.90000000", "3.00000000"]]}
{"type": "depth", "ts": 1783008096514, "U": 96863163088, "u": 96863163155, "bids": [["61594.00000000", "2.51793000"], ["61593.99000000", "0.00035000"], ["61593.27000000", "0.67342000"], ["61592.01000000", "0.00000000"], ["61592.00000000", "0.02418000"], ["61591.65000000", "0.00000000"], ["61591.64000000", "0.97408000"], ["61591.63000000", "0.00009000"], ["61591.61000000", "0.00000000"], ["61591.54000000", "0.07115000"], ["61590.11000000", "0.00000000"], ["61589.13000000", "0.70117000"], ["61574.03000000", "0.58524000"], ["61572.60000000", "0.00000000"], ["61554.68000000", "0.00000000"], ["55434.60000000", "0.00450000"]], "asks": [["61594.01000000", "0.62700000"], ["61594.02000000", "0.00071000"], ["61596.59000000", "0.00018000"], ["61596.60000000", "0.00896000"], ["61597.71000000", "0.00018000"], ["61597.72000000", "0.00018000"], ["61599.19000000", "0.00000000"], ["61599.99000000", "0.00009000"], ["61600.00000000", "0.09474000"], ["61600.71000000", "0.00812000"], ["61603.17000000", "0.00000000"], ["61608.29000000", "0.00000000"], ["61609.44000000", "0.01000000"], ["61612.15000000", "0.00000000"], ["61613.55000000", "0.00000000"], ["61613.56000000", "0.00191000"], ["61614.00000000", "0.02726000"], ["61616.10000000", "0.00000000"], ["61616.65000000", "0.00009000"], ["61616.70000000", "0.00000000"], ["61621.53000000", "0.00499000"], ["61666.59000000", "0.00000000"], ["61669.99000000", "0.80368000"], ["61695.99000000", "0.00000000"], ["61699.91000000", "0.00998000"]]}
{"type": "depth", "ts": 1783008096614, "U": 96863163156, "u": 96863163228, "bids": [["61594.00000000", "2.51981000"], ["61592.01000000", "0.00812000"], ["61591.54000000", "0.07124000"], ["61591.53000000", "0.00009000"], ["61591.45000000", "0.08775000"], ["61589.11000000", "0.00000000"], ["61587.31000000", "0.00000000"], ["61585.69000000", "0.00000000"], ["61575.10000000", "0.28435000"], ["61573.58000000", "0.09753000"], ["61562.23000000", "0.00000000"], ["61523.00000000", "0.00018000"], ["61510.94000000", "0.00009000"], ["55434.60000000", "0.00450000"], ["49275.20000000", "0.00000000"]], "asks": [["61594.01000000", "0.62674000"], ["61594.02000000", "0.00071000"], ["61594.10000000", "0.05027000"], ["61594.46000000", "0.00000000"], ["61595.24000000", "0.01025000"], ["61596.59000000", "0.00000000"], ["61596.60000000", "0.00914000"], ["61597.34000000", "0.02018000"], ["61597.70000000", "0.00000000"], ["61597.71000000", "0.00000000"], ["61597.72000000", "0.00000000"], ["61597.81000000", "0.04866000"], ["61598.00000000", "0.00618000"], ["61600.00000000", "0.20981000"], ["61600.17000000", "0.00319000"], ["61601.65000000", "0.00400000"], ["61601.80000000", "0.00009000"], ["61603.16000000", "0.28042000"], ["61605.71000000", "0.08878000"], ["61606.42000000", "0.14046000"], ["61607.01000000", "0.08988000"], ["61608.29000000", "0.08988000"], ["61609.61000000", "0.08988000"], ["61609.96000000", "0.08988000"], ["61609.97000000", "0.83046000"], ["61613.56000000", "0.97581000"], ["61615.41000000", "0.00000000"], ["61616.20000000", "0.00000000"], ["61624.93000000", "0.00230000"], ["61640.75000000", "0.00499000"]]}
{"type": "depth", "ts": 1783008096714, "U": 96863163229, "u": 96863163272, "bids": [["61593.27000000", "0.67351000"], ["61592.03000000", "0.09794000"], ["61592.01000000", "0.00830000"], ["61591.54000000", "0.00027000"], ["61591.45000000", "0.08793000"], ["61589.50000000", "0.04709000"], ["61589.13000000", "0.70099000"], ["61586.63000000", "0.00024000"], ["61453.00000000", "0.00036000"], ["61452.00000000", "0.00000000"], ["55434.60000000", "0.00430000"], ["49275.20000000", "0.00000000"]], "asks": [["61594.01000000", "0.47012000"], ["61594.02000000", "0.00071000"], ["61597.80000000", "0.00000000"], ["61597.81000000", "0.00018000"], ["61598.29000000", "0.00009000"], ["61598.30000000", "0.03492000"], ["61601.58000000", "0.00070000"], ["61659.98000000", "0.00499000"]]}
{"type": "depth", "ts": 1783008096814, "U": 96863163273, "u": 96863163305, "bids": [["61593.27000000", "0.67351000"], ["61592.03000000", "0.09812000"], ["61591.60000000", "1.36836000"], ["61591.54000000", "0.00009000"], ["55434.60000000", "0.00440000"]], "asks": [["61594.01000000", "0.47099000"], ["61594.46000000", "0.00009000"], ["61597.34000000", "0.02018000"], ["61597.81000000", "0.00000000"], ["61598.00000000", "0.00618000"], ["61598.30000000", "0.03510000"], ["61601.58000000", "0.00000000"]]}
{"type": "depth", "ts": 1783008097014, "U": 96863163312, "u": 96863163324, "bids": [["61506.64000000", "0.05039000"], ["61498.41000000", "0.00000000"], ["55434.60000000", "0.00450000"], ["49275.20000000", "0.00040000"]], "asks": [["61606.01000000", "0.01269000"], ["61669.99000000", "0.00000000"], ["61687.53000000", "0.00000000"], ["61691.44000000", "0.05036000"], ["61800.00000000", "0.15153000"], ["62474.19000000", "0.05101000"]]}
{"type": "depth", "ts": 1783008097114, "U": 96863163325, "u": 96863163364, "bids": [["61594.00000000", "2.51999000"], ["61593.99000000", "0.00044000"], ["61592.03000000", "0.00018000"], ["61592.01000000", "0.00018000"], ["61591.65000000", "0.00009000"], ["61591.61000000", "0.00009000"], ["61591.45000000", "0.08802000"], ["61591.32000000", "0.08294000"], ["61590.77000000", "0.00812000"], ["61586.94000000", "0.00000000"], ["61585.68000000", "0.00000000"], ["61578.82000000", "0.00400000"], ["61578.80000000", "0.00000000"], ["61532.40000000", "0.00209000"], ["61507.04000000", "0.03706000"], ["61461.33000000", "0.00000000"], ["61367.99000000", "0.00000000"], ["60670.09000000", "0.00441000"], ["55434.60000000", "0.00450000"]], "asks": [["61594.01000000", "0.81854000"], ["61594.02000000", "0.00080000"], ["61597.93000000", "0.00009000"], ["61597.94000000", "0.04609000"], ["61598.29000000", "0.00000000"], ["61598.30000000", "0.00018000"], ["61599.56000000", "0.00191000"], ["61601.80000000", "0.00000000"], ["61613.56000000", "0.97390000"], ["61692.58000000", "0.12000000"], ["61720.11000000", "0.00000000"], ["61735.02000000", "0.00000000"]]}
{"type": "depth", "ts": 1783008097214, "U": 96863163365, "u": 96863163424, "bids": [["61594.00000000", "2.51999000"], ["61593.99000000", "0.00044000"], ["61593.27000000", "0.67342000"], ["61592.03000000", "0.00000000"], ["61592.01000000", "0.00000000"], ["61591.45000000", "0.08802000"], ["61591.32000000", "0.08321000"], ["61590.77000000", "0.00830000"], ["61590.20000000", "0.25000000"], ["61580.54000000", "0.19320000"], ["61573.66000000", "0.00009000"], ["61573.58000000", "0.00000000"], ["61453.98000000", "0.00035000"], ["61453.00000000", "0.00000000"], ["61409.38000000", "0.03559000"], ["61405.93000000", "0.00264000"], ["55434.60000000", "0.00470000"], ["49275.20000000", "0.00000000"]], "asks": [["61594.01000000", "0.81314000"], ["61597.34000000", "0.02018000"], ["61597.94000000", "0.04627000"], ["61598.00000000", "0.00618000"], ["61598.30000000", "0.00000000"], ["61610.63000000", "0.00009000"], ["61709.41000000", "0.00000000"]]}
{"type": "depth", "ts": 1783008097414, "U": 96863163442, "u": 96863163450, "bids": [["60980.77000000", "0.03464000"], ["55434.60000000", "0.00450000"], ["55434.00000000", "0.00000000"]], "asks": [["61623.66000000", "0.01100000"], ["61624.95000000", "0.01000000"], ["61656.62000000", "0.01100000"]]}
{"type": "depth", "ts": 1783008097514, "U": 96863163451, "u": 96863163459, "bids": [["60919.78000000", "0.01927000"], ["60858.86000000", "0.02163000"], ["55434.60000000", "0.00450000"]], "asks": [["61624.89000000", "0.01619000"], ["61656.62000000", "0.00000000"], ["61664.00000000", "0.02434000"]]}
{"type": "depth", "ts": 1783008097614, "U": 96863163460, "u": 96863163475, "bids": [["61532.04000000", "0.00009000"], ["61501.90000000", "0.00009000"], ["60798.00000000", "0.02426000"], ["55434.60000000", "0.00450000"], ["49275.20000000", "0.00000000"]], "asks": [["61597.93000000", "0.07166000"], ["61603.08000000", "0.77141000"], ["61603.09000000", "1.36330000"], ["61603.16000000", "0.00000000"], ["61605.71000000", "0.00000000"], ["61607.01000000", "0.00000000"], ["61612.09000000", "0.00326000"], ["61614.00000000", "0.02400000"]]}
{"type": "depth", "ts": 1783008097714, "U": 96863163476, "u": 96863163522, "bids": [["61594.00000000", "1.54421000"], ["61590.77000000", "0.00018000"], ["61590.21000000", "0.00009000"], ["61589.14000000", "0.00812000"], ["61589.13000000", "0.70099000"], ["61587.39000000", "0.00000000"], ["61585.66000000", "0.00187000"], ["61539.41000000", "0.00000000"], ["61521.92000000", "0.01658000"], ["61520.95000000", "0.00500000"], ["61489.01000000", "0.06599000"], ["61486.49000000", "0.09758000"], ["61454.68000000", "0.00034000"], ["61453.98000000", "0.00000000"], ["55434.60000000", "0.00450000"]], "asks": [["61594.01000000", "1.06090000"], ["61594.02000000", "0.00089000"], ["61594.10000000", "0.05045000"], ["61597.34000000", "0.02018000"], ["61597.90000000", "0.00009000"], ["61597.91000000", "0.08988000"], ["61597.92000000", "0.00009000"], ["61597.93000000", "0.07184000"], ["61598.00000000", "0.00600000"], ["61599.20000000", "0.00009000"], ["61599.99000000", "0.00000000"], ["61600.00000000", "0.20972000"], ["61603.07000000", "0.08988000"], ["61603.11000000", "0.00000000"], ["61603.15000000", "0.00000000"], ["61664.48000000", "0.00000000"]]}
{"type": "depth", "ts": 1783008097814, "U": 96863163523, "u": 96863163549, "bids": [["61591.32000000", "0.08321000"], ["61590.77000000", "0.00000000"], ["61590.00000000", "0.02905000"], ["61573.47000000", "0.09753000"], ["61562.23000000", "0.00000000"], ["61533.54000000", "0.00315000"], ["61515.08000000", "0.00977000"], ["55434.60000000", "0.00470000"], ["49275.20000000", "0.00000000"]], "asks": [["61597.34000000", "0.02018000"], ["61597.91000000", "0.09006000"], ["61597.94000000", "0.04609000"], ["61604.00000000", "0.02400000"]]}
{"type": "depth", "ts": 1783008098014, "U": 96863163558, "u": 96863163567, "bids": [["61587.15000000", "0.02009000"], ["61587.14000000", "0.01001000"], ["61562.23000000", "0.00009000"], ["55434.60000000", "0.00470000"], ["49275.20000000", "0.00040000"]], "asks": [["61719.83000000", "0.01827000"], ["61768.68000000", "0.00000000"]]}
{"type": "depth", "ts": 1783008098114, "U": 96863163568, "u": 96863163572, "bids": [["60670.09000000", "0.00441000"], ["55434.60000000", "0.00450000"]], "asks": []}
{"type": "depth", "ts": 1783008098214, "U": 96863163573, "u": 96863163649, "bids": [["61594.00000000", "1.29743000"], ["61593.99000000", "0.00089000"], ["61593.27000000", "0.43560000"], ["61592.01000000", "0.00009000"], ["61591.65000000", "0.00000000"], ["61591.64000000", "0.00018000"], ["61591.46000000", "0.00009000"], ["61591.45000000", "0.08811000"], ["61591.32000000", "0.00027000"], ["61590.75000000", "0.06101000"], ["61589.14000000", "0.00821000"], ["61589.13000000", "0.70108000"], ["61576.68000000", "0.00000000"], ["61573.86000000", "0.01625000"], ["61573.66000000", "0.00009000"], ["61573.47000000", "0.00000000"], ["61399.50000000", "0.02543000"], ["55434.60000000", "0.00430000"], ["49275.20000000", "0.00000000"]], "asks": [["61594.01000000", "1.52354000"], ["61594.02000000", "0.00062000"], ["61594.10000000", "0.05054000"], ["61596.60000000", "0.00923000"], ["61596.61000000", "0.08997000"], ["61597.32000000", "0.00812000"], ["61597.39000000", "0.00018000"], ["61597.40000000", "0.06637000"], ["61597.93000000", "0.07175000"], ["61597.94000000", "0.00000000"], ["61599.20000000", "0.00000000"], ["61600.71000000", "0.00000000"], ["61606.16000000", "0.97399000"], ["61606.42000000", "0.09791000"], ["61608.29000000", "0.00000000"], ["61609.61000000", "0.00000000"], ["61609.85000000", "1.29673000"], ["61609.86000000", "0.97390000"], ["61609.96000000", "0.00000000"], ["61609.97000000", "0.00000000"], ["61610.63000000", "0.00009000"], ["61611.82000000", "0.58488000"], ["61625.41000000", "0.00000000"], ["61715.53000000", "0.02543000"]]}
{"type": "depth", "ts": 1783008098314, "U": 96863163650, "u": 96863163731, "bids": [["61594.00000000", "1.70666000"], ["61593.99000000", "0.00044000"], ["61593.27000000", "0.67342000"], ["61592.00000000", "0.02418000"], ["61591.64000000", "0.00000000"], ["61591.62000000", "0.00009000"], ["61591.61000000", "0.97399000"], ["61591.46000000", "0.00000000"], ["61591.45000000", "0.08811000"], ["61591.32000000", "0.00009000"], ["61590.75000000", "0.06119000"], ["61589.50000000", "0.04727000"], ["61589.14000000", "0.00812000"], ["61589.13000000", "0.70099000"], ["55434.60000000", "0.00430000"], ["49275.00000000", "0.00200000"]], "asks": [["61594.01000000", "1.06108000"], ["61594.02000000", "0.00080000"], ["61596.60000000", "0.00914000"], ["61596.61000000", "0.00027000"], ["61596.86000000", "0.02452000"], ["61597.32000000", "0.00018000"], ["61597.34000000", "0.02018000"], ["61597.91000000", "0.08988000"], ["61597.93000000", "0.07157000"], ["61598.94000000", "0.00812000"], ["61599.20000000", "0.00009000"], ["61599.99000000", "0.00009000"], ["82071.40000000", "0.00000000"]]}
{"type": "depth", "ts": 1783008098414, "U": 96863163732, "u": 96863163771, "bids": [["61592.01000000", "0.00000000"], ["61592.00000000", "0.02418000"], ["61591.61000000", "0.97417000"], ["61589.50000000", "0.04709000"], ["56701.45000000", "0.00018000"], ["55434.60000000", "0.00430000"], ["49275.00000000", "0.00000000"]], "asks": [["61594.01000000", "1.06108000"], ["61594.02000000", "0.00071000"], ["61596.60000000", "0.00914000"], ["61596.61000000", "0.00009000"], ["61596.86000000", "0.02452000"], ["61597.32000000", "0.00000000"], ["61597.40000000", "0.06655000"], ["61597.91000000", "0.09006000"], ["62517.93000000", "0.00030000"]]}
{"type": "depth", "ts": 1783008098514, "U": 96863163772, "u": 96863163812, "bids": [["61594.00000000", "2.68047000"], ["61593.99000000", "0.00035000"], ["61591.62000000", "0.00000000"], ["61591.61000000", "0.97408000"], ["61591.33000000", "0.08515000"], ["61590.75000000", "0.00018000"], ["61590.21000000", "0.00000000"], ["61562.23000000", "0.00000000"], ["55434.60000000", "0.00450000"], ["55434.00000000", "0.00000000"]], "asks": [["61594.01000000", "0.54394000"], ["61596.00000000", "0.00058000"], ["61597.40000000", "0.00018000"], ["61597.90000000", "0.00000000"], ["61597.91000000", "0.00018000"], ["61597.93000000", "0.00000000"], ["61597.97000000", "0.04535000"], ["61598.94000000", "0.00000000"], ["61600.00000000", "0.20981000"], ["61600.71000000", "0.00812000"], ["61603.08000000", "0.28334000"], ["61603.09000000", "0.00000000"], ["61606.16000000", "0.00009000"], ["61608.29000000", "0.08988000"], ["61609.61000000", "0.08988000"], ["61609.84000000", "0.08988000"], ["61610.37000000", "0.00325000"], ["61612.09000000", "0.00000000"], ["61633.70000000", "0.00829000"], ["61643.36000000", "0.00409000"], ["61645.78000000", "0.00000000"]]}
{"type": "depth", "ts": 1783008098614, "U": 96863163813, "u": 96863163864, "bids": [["61594.00000000", "2.68238000"], ["61591.45000000", "0.08811000"], ["61591.33000000", "0.08533000"], ["61590.75000000", "0.00000000"], ["61588.81000000", "0.00030000"], ["61585.66000000", "0.00000000"], ["61573.49000000", "0.09753000"], ["61498.47000000", "0.00009000"], ["55434.60000000", "0.00450000"], ["49275.20000000", "0.00000000"]], "asks": [["61594.01000000", "0.44385000"], ["61594.02000000", "0.00071000"], ["61594.10000000", "0.05027000"], ["61596.61000000", "0.00000000"], ["61597.34000000", "0.02018000"], ["61597.39000000", "0.00009000"], ["61597.40000000", "0.00000000"], ["61597.91000000", "0.00000000"], ["61597.92000000", "0.00000000"], ["61597.96000000", "0.00009000"], ["61597.97000000", "0.04553000"], ["61598.00000000", "0.00618000"], ["61601.80000000", "0.00009000"], ["61603.80000000", "0.08988000"], ["61605.71000000", "0.08527000"], ["61606.42000000", "0.14046000"], ["61607.01000000", "0.08988000"], ["61609.86000000", "0.00000000"]]}
{"type": "depth", "ts": 1783008098714, "U": 96863163865, "u": 96863163988, "bids": [["61594.00000000", "1.69545000"], ["61593.28000000", "0.00000000"], ["61593.27000000", "0.00036000"], ["61592.01000000", "0.00009000"], ["61591.64000000", "0.00009000"], ["61591.63000000", "0.43331000"], ["61591.62000000", "0.00000000"], ["61591.61000000", "0.00027000"], ["61591.60000000", "1.36348000"], ["61591.53000000", "0.00009000"], ["61591.45000000", "0.00036000"], ["61590.57000000", "0.00812000"], ["61590.21000000", "0.00009000"], ["61589.14000000", "0.00000000"], ["61589.12000000", "1.36330000"], ["61588.60000000", "0.00009000"], ["61588.15000000", "0.00000000"], ["61587.84000000", "0.25478000"], ["61587.17000000", "0.66794000"], ["61586.60000000", "0.97390000"], ["61586.59000000", "0.00000000"], ["61585.96000000", "0.00000000"], ["61585.67000000", "0.00009000"], ["61584.78000000", "0.00488000"], ["61583.80000000", "0.00400000"], ["61582.74000000", "0.00009000"], ["61579.83000000", "0.00488000"], ["61579.81000000", "0.00009000"], ["61577.64000000", "0.00400000"], ["61577.02000000", "0.00000000"], ["61576.88000000", "0.00009000"], ["61573.95000000", "0.00009000"], ["61573.49000000", "0.00000000"], ["61573.48000000", "0.09753000"], ["61571.02000000", "0.00009000"], ["61570.83000000", "0.00000000"], ["61568.09000000", "0.00009000"], ["61565.16000000", "0.00009000"], ["61562.23000000", "0.00009000"], ["61559.10000000", "0.00000000"], ["61557.90000000", "0.13540000"], ["61547.23000000", "0.00488000"], ["61470.11000000", "0.04217000"], ["60737.20000000", "0.02724000"], ["55434.60000000", "0.00430000"]], "asks": [["61594.01000000", "0.86108000"], ["61594.02000000", "0.00080000"], ["61594.10000000", "0.05036000"], ["61597.90000000", "0.00009000"], ["61597.91000000", "0.08997000"], ["61597.95000000", "0.00009000"], ["61597.96000000", "0.18740000"], ["61598.00000000", "0.00642000"], ["61599.99000000", "0.00000000"], ["61600.00000000", "0.62873000"], ["61601.80000000", "0.00000000"], ["61603.05000000", "0.08988000"], ["61603.06000000", "1.36330000"], ["61603.07000000", "0.00000000"], ["61603.08000000", "0.59012000"], ["61603.80000000", "0.00000000"], ["61605.70000000", "0.97390000"], ["61605.71000000", "0.00000000"], ["61606.42000000", "0.09791000"], ["61607.01000000", "0.00000000"], ["61608.29000000", "0.00000000"], ["61609.60000000", "0.97390000"], ["61609.61000000", "0.00000000"], ["61609.84000000", "0.00000000"], ["61619.12000000", "0.00024000"]]}
{"type": "depth", "ts": 1783008098814, "U": 96863163989, "u": 96863164061, "bids": [["61594.00000000", "1.69952000"], ["61593.27000000", "0.00018000"], ["61592.00000000", "0.02418000"], ["61591.66000000", "0.00009000"], ["61591.65000000", "0.85482000"], ["61591.64000000", "0.97878000"], ["61591.63000000", "0.00027000"], ["61591.61000000", "0.00009000"], ["61591.60000000", "1.36348000"], ["61591.45000000", "0.00018000"], ["61591.33000000", "0.08533000"], ["61590.57000000", "0.00830000"], ["61589.14000000", "0.00488000"], ["61587.17000000", "0.67143000"], ["61585.45000000", "0.00191000"], ["61573.48000000", "0.00000000"], ["61573.41000000", "0.09753000"], ["61557.90000000", "0.00000000"], ["61506.64000000", "0.00000000"], ["61489.01000000", "0.03115000"], ["61486.49000000", "0.00000000"], ["55434.60000000", "0.00430000"], ["49275.20000000", "0.00000000"]], "asks": [["61594.01000000", "1.06108000"], ["61597.34000000", "0.02018000"], ["61597.91000000", "0.09015000"], ["61597.96000000", "0.18758000"], ["61597.97000000", "0.04535000"], ["61598.00000000", "0.00624000"], ["61681.13000000", "0.00000000"], ["61691.44000000", "0.00000000"], ["61773.77000000", "0.00000000"], ["82071.40000000", "0.00010000"], ["86422.88000000", "0.03782000"]]}
{"type": "depth", "ts": 1783008098914, "U": 96863164062, "u": 96863164102, "bids": [["61594.00000000", "1.69952000"], ["61592.00000000", "0.02418000"], ["61591.66000000", "0.00009000"], ["61591.65000000", "0.85500000"], ["61591.63000000", "0.00009000"], ["61590.21000000", "0.00000000"], ["61587.84000000", "0.25469000"], ["61536.01000000", "0.00000000"], ["61507.04000000", "0.02027000"], ["61498.41000000", "0.05233000"], ["61480.01000000", "0.00000000"], ["55434.60000000", "0.00430000"]], "asks": [["61594.01000000", "1.06091000"], ["61599.99000000", "0.00009000"], ["61603.03000000", "0.08988000"], ["61603.04000000", "1.36330000"], ["61603.05000000", "0.00000000"], ["61603.06000000", "0.00000000"], ["61603.08000000", "0.28334000"], ["61605.70000000", "0.00000000"], ["61609.59000000", "0.08988000"], ["61683.19000000", "0.05037000"], ["86422.88000000", "0.05673000"]]}
{"type": "depth", "ts": 1783008099014, "U": 96863164103, "u": 96863164112, "bids": [["61536.03000000", "0.00095000"], ["61475.27000000", "0.00038000"], ["58000.00000000", "341.70568000"], ["57500.00000000", "187.35730000"], ["56701.45000000", "0.00000000"], ["55434.60000000", "0.00430000"], ["49275.20000000", "0.00040000"]], "asks": [["80298.72000000", "0.02508000"]]}
{"type": "depth", "ts": 1783008099114, "U": 96863164113, "u": 96863164140, "bids": [["61594.00000000", "2.67333000"], ["61592.70000000", "0.08988000"], ["61592.01000000", "0.00000000"], ["61591.66000000", "0.08988000"], ["61591.65000000", "0.85491000"], ["61591.61000000", "0.00000000"], ["61588.13000000", "0.04217000"], ["61470.11000000", "0.00000000"], ["60670.09000000", "0.00441000"], ["55434.60000000", "0.00430000"]], "asks": [["61594.01000000", "0.63558000"], ["61597.91000000", "0.00027000"], ["61597.96000000", "0.00027000"], ["61601.81000000", "0.00000000"], ["61603.04000000", "0.00000000"], ["61603.33000000", "0.04000000"], ["61604.13000000", "0.08000000"], ["61609.59000000", "0.00000000"], ["80298.72000000", "0.05016000"]]}
{"type": "depth", "ts": 1783008099214, "U": 96863164141, "u": 96863164205, "bids": [["61594.00000000", "2.67524000"], ["61593.27000000", "0.00009000"], ["61592.70000000", "0.00027000"], ["61592.00000000", "0.02418000"], ["61590.20000000", "0.25000000"], ["61590.00000000", "0.02887000"], ["61585.45000000", "0.00000000"], ["61562.23000000", "0.00000000"], ["61454.68000000", "0.00000000"], ["61454.67000000", "0.00034000"], ["59500.00000000", "27.45016000"], ["55434.60000000", "0.00450000"], ["49275.20000000", "0.00000000"]], "asks": [["61594.01000000", "0.63473000"], ["61594.02000000", "0.00071000"], ["61597.34000000", "0.02018000"], ["61597.90000000", "0.00000000"], ["61597.91000000", "0.00009000"], ["61597.95000000", "0.00000000"], ["61597.96000000", "0.00009000"], ["61597.97000000", "0.04553000"], ["61598.00000000", "0.00642000"], ["61600.00000000", "0.20981000"], ["61600.01000000", "0.26002000"], ["61601.80000000", "0.00009000"], ["61601.81000000", "0.08988000"], ["61603.80000000", "0.08988000"], ["61605.71000000", "0.08988000"], ["61606.42000000", "0.14046000"], ["61607.01000000", "0.08988000"], ["61608.29000000", "0.08988000"], ["61609.59000000", "0.08988000"], ["79890.03000000", "0.08484000"]]}
{"type": "depth", "ts": 1783008099314, "U": 96863164206, "u": 96863164229, "bids": [["61594.00000000", "2.67524000"], ["61592.74000000", "0.00000000"], ["61592.70000000", "0.00009000"], ["61591.66000000", "0.00018000"], ["61591.64000000", "0.97896000"], ["61590.20000000", "0.25018000"], ["61573.66000000", "0.00009000"], ["55434.60000000", "0.00450000"]], "asks": [["61594.01000000", "0.46535000"], ["61601.80000000", "0.00000000"], ["61610.63000000", "0.00009000"]]}
{"type": "depth", "ts": 1783008099414, "U": 96863164230, "u": 96863164245, "bids": [["61594.00000000", "2.67515000"], ["61592.70000000", "0.00000000"], ["61592.00000000", "0.02418000"], ["61591.66000000", "0.00000000"], ["61590.00000000", "0.02905000"], ["61562.23000000", "0.00009000"], ["55434.60000000", "0.00450000"]], "asks": [["61601.80000000", "0.00009000"], ["62517.93000000", "0.00030000"]]}
{"type": "depth", "ts": 1783008099514, "U": 96863164246, "u": 96863164256, "bids": [["61591.66000000", "0.08587000"], ["61562.23000000", "0.00000000"], ["55434.60000000", "0.00450000"]], "asks": [["61604.13000000", "0.00000000"], ["61607.13000000", "0.08000000"], ["61609.60000000", "0.00000000"], ["61639.01000000", "0.00000000"], ["61713.89000000", "0.00000000"]]}
{"type": "depth", "ts": 1783008099614, "U": 96863164257, "u": 96863164410, "bids": [["61594.00000000", "3.05329000"], ["61592.70000000", "0.08988000"], ["61592.54000000", "0.00000000"], ["61592.50000000", "0.04217000"], ["61592.10000000", "0.00243000"], ["61592.00000000", "0.02418000"], ["61591.71000000", "0.00000000"], ["61591.66000000", "0.08605000"], ["61591.65000000", "0.67690000"], ["61591.33000000", "0.00018000"], ["61590.96000000", "0.00400000"], ["61590.57000000", "0.00018000"], ["61590.00000000", "0.02887000"], ["61588.79000000", "0.04000000"], ["61588.13000000", "0.04217000"], ["61587.72000000", "0.03000000"], ["61584.43000000", "0.00000000"], ["61581.82000000", "0.08760000"], ["61581.32000000", "0.12000000"], ["61580.28000000", "0.08897000"], ["61578.20000000", "0.58520000"], ["61572.37000000", "0.03187000"], ["61567.38000000", "0.00000000"], ["61567.13000000", "1.60960000"], ["61559.68000000", "0.31957000"], ["61559.17000000", "0.00000000"], ["61557.91000000", "0.00000000"], ["61551.90000000", "0.00000000"], ["61542.55000000", "0.00009000"], ["61542.31000000", "0.02478000"], ["61479.34000000", "0.00000000"], ["61350.38000000", "0.00000000"], ["55434.60000000", "0.00450000"]], "asks": [["61594.01000000", "0.02129000"], ["61594.02000000", "0.00071000"], ["61594.10000000", "0.05027000"], ["61594.46000000", "0.00000000"], ["61594.81000000", "0.00000000"], ["61595.24000000", "0.00018000"], ["61596.60000000", "0.00018000"], ["61597.33000000", "0.00000000"], ["61597.34000000", "0.00018000"], ["61597.39000000", "0.00000000"], ["61597.96000000", "0.00000000"], ["61597.97000000", "0.00018000"], ["61598.48000000", "0.00009000"], ["61598.49000000", "0.00000000"], ["61599.20000000", "0.00000000"], ["61599.21000000", "0.00000000"], ["61599.85000000", "0.00000000"], ["61600.00000000", "0.01118000"], ["61600.01000000", "0.24100000"], ["61600.61000000", "0.00000000"], ["61600.64000000", "0.00984000"], ["61600.71000000", "0.00000000"], ["61601.65000000", "0.00000000"], ["61601.74000000", "0.00048000"], ["61601.80000000", "0.08180000"], ["61601.81000000", "0.00000000"], ["61601.88000000", "0.00000000"], ["61602.98000000", "0.00000000"], ["61603.02000000", "0.00009000"], ["61603.08000000", "0.00009000"], ["61603.27000000", "0.00000000"], ["61603.33000000", "0.00000000"], ["61604.08000000", "0.02000000"], ["61604.42000000", "0.00812000"], ["61604.70000000", "0.00400000"], ["61604.84000000", "0.00000000"], ["61605.23000000", "0.00000000"], ["61606.17000000", "0.00000000"], ["61606.33000000", "0.05009000"], ["61608.20000000", "0.00000000"], ["61608.81000000", "0.00323000"], ["61609.83000000", "0.85665000"], ["61609.84000000", "1.45074000"], ["61609.85000000", "0.00000000"], ["61609.98000000", "0.00000000"], ["61610.37000000", "0.00000000"], ["61610.86000000", "0.00400000"], ["61611.82000000", "0.00000000"], ["61613.56000000", "0.00000000"], ["61615.33000000", "0.00000000"], ["61618.51000000", "0.00000000"], ["61626.69000000", "0.00009000"], ["61628.45000000", "0.58472000"], ["61629.98000000", "0.00000000"], ["61633.32000000", "0.00379000"], ["61671.99000000", "0.00000000"], ["61694.87000000", "0.00152000"], ["61715.53000000", "0.00000000"], ["61728.11000000", "0.02543000"], ["61903.66000000", "0.00009000"]]}
{"type": "depth", "ts": 1783008099714, "U": 96863164411, "u": 96863165127, "bids": [["61596.85000000", "4.80798000"], ["61596.84000000", "2.34243000"], ["61596.83000000", "0.00017000"], ["61596.65000000", "0.04217000"], ["61596.59000000", "0.00000000"], ["61596.48000000", "0.00010000"], ["61596.26000000", "0.02191000"], ["61596.00000000", "0.00009000"], ["61595.99000000", "0.00000000"], ["61595.98000000", "0.00000000"], ["61595.79000000", "0.00000000"], ["61595.66000000", "0.00000000"], ["61595.55000000", "0.00000000"], ["61595.23000000", "0.00000000"], ["61594.46000000", "0.00009000"], ["61594.37000000", "1.36330000"], ["61594.25000000", "0.00000000"], ["61594.10000000", "0.07524000"], ["61594.09000000", "3.30573000"], ["61594.08000000", "0.00000000"], ["61594.07000000", "0.00000000"], ["61594.05000000", "0.07527000"], ["61594.04000000", "0.41470000"], ["61594.03000000", "0.00000000"], ["61594.02000000", "0.00000000"], ["61594.01000000", "0.46456000"], ["61594.00000000", "0.32330000"], ["61593.99000000", "0.00000000"], ["61593.98000000", "0.00000000"], ["61592.71000000", "0.00000000"], ["61592.70000000", "0.00018000"], ["61592.50000000", "0.04235000"], ["61592.42000000", "0.00000000"], ["61592.33000000", "0.16235000"], ["61591.66000000", "0.00018000"], ["61591.65000000", "0.00000000"], ["61591.64000000", "0.00488000"], ["61591.60000000", "1.36330000"], ["61591.58000000", "0.00000000"], ["61591.45000000", "0.00009000"], ["61591.33000000", "0.00000000"], ["61590.69000000", "0.00010000"], ["61590.57000000", "0.00000000"], ["61590.20000000", "0.25000000"], ["61589.35000000", "0.00009000"], ["61589.10000000", "0.00000000"], ["61588.20000000", "0.00009000"], ["61587.84000000", "0.25459000"], ["61587.66000000", "0.00912000"], ["61582.92000000", "0.00000000"], ["61581.40000000", "0.58517000"], ["61579.52000000", "0.00016000"], ["61577.53000000", "0.01625000"], ["61573.86000000", "0.00000000"], ["61571.62000000", "0.00000000"], ["61565.16000000", "0.00000000"], ["61563.55000000", "0.00000000"], ["61563.49000000", "0.00000000"], ["61561.36000000", "0.00009000"], ["61555.15000000", "0.00000000"], ["61549.36000000", "0.13796000"], ["61547.23000000", "0.00000000"], ["61544.75000000", "0.00000000"], ["61544.23000000", "0.03269000"], ["61539.47000000", "0.00404000"], ["61536.02000000", "0.00000000"], ["61498.47000000", "0.00000000"], ["61488.57000000", "0.00000000"], ["61286.68000000", "0.00000000"], ["60670.09000000", "0.00411000"], ["55434.64000000", "0.00010000"], ["55434.60000000", "0.00000000"], ["49275.20000000", "0.00000000"]], "asks": [["61594.01000000", "0.00000000"], ["61594.02000000", "0.00000000"], ["61594.03000000", "0.00000000"], ["61594.04000000", "0.00000000"], ["61594.05000000", "0.00000000"], ["61594.06000000", "0.00000000"], ["61594.09000000", "0.00000000"], ["61594.10000000", "0.00000000"], ["61594.11000000", "0.00000000"], ["61595.24000000", "0.00000000"], ["61595.67000000", "0.00000000"], ["61595.80000000", "0.00000000"], ["61595.99000000", "0.00000000"], ["61596.00000000", "0.00000000"], ["61596.01000000", "0.00000000"], ["61596.60000000", "0.00000000"], ["61596.85000000", "0.00000000"], ["61596.86000000", "0.04470000"], ["61596.87000000", "0.00072000"], ["61597.34000000", "0.00000000"], ["61597.91000000", "0.00000000"], ["61597.97000000", "0.00000000"], ["61598.00000000", "0.00642000"], ["61598.42000000", "0.00000000"], ["61598.48000000", "0.00000000"], ["61599.05000000", "0.00009000"], ["61599.06000000", "0.00000000"], ["61599.39000000", "0.00034000"], ["61599.99000000", "0.00009000"], ["61600.00000000", "0.01136000"], ["61600.01000000", "0.20090000"], ["61600.17000000", "0.00300000"], ["61600.32000000", "0.00000000"], ["61600.36000000", "0.00009000"], ["61600.37000000", "0.08777000"], ["61600.64000000", "0.01002000"], ["61601.79000000", "0.00009000"], ["61601.80000000", "0.00027000"], ["61602.00000000", "0.01918000"], ["61603.02000000", "0.00019000"], ["61603.03000000", "0.00027000"], ["61603.10000000", "0.00912000"], ["61603.63000000", "0.00000000"], ["61603.79000000", "0.00009000"], ["61603.80000000", "0.00000000"], ["61603.81000000", "0.00000000"], ["61603.88000000", "0.00070000"], ["61604.16000000", "0.00009000"], ["61604.42000000", "0.00000000"], ["61604.70000000", "0.00000000"], ["61605.70000000", "0.00009000"], ["61605.71000000", "0.00000000"], ["61606.33000000", "0.01009000"], ["61606.42000000", "0.27836000"], ["61606.43000000", "0.00000000"], ["61606.44000000", "0.00000000"], ["61606.67000000", "0.40100000"], ["61607.00000000", "0.00812000"], ["61607.01000000", "0.00000000"], ["61607.13000000", "0.00000000"], ["61607.57000000", "0.00400000"], ["61608.29000000", "0.00000000"], ["61608.81000000", "0.00000000"], ["61609.18000000", "0.00325000"], ["61609.38000000", "0.00000000"], ["61609.82000000", "1.36330000"], ["61609.83000000", "0.18225000"], ["61609.84000000", "0.00000000"], ["61610.00000000", "0.02400000"], ["61610.86000000", "0.00000000"], ["61611.33000000", "0.14000000"], ["61612.80000000", "0.44138000"], ["61613.71000000", "0.00400000"], ["61614.35000000", "0.00000000"], ["61617.26000000", "0.00158000"], ["61617.43000000", "0.81253000"], ["61617.91000000", "0.00400000"], ["61618.50000000", "0.97273000"], ["61625.00000000", "0.00000000"], ["61625.50000000", "0.00009000"], ["61626.26000000", "0.00000000"], ["61628.00000000", "0.03400000"], ["61629.62000000", "0.97399000"], ["61629.66000000", "0.58471000"], ["61640.63000000", "0.00000000"], ["61643.79000000", "0.00404000"], ["61646.60000000", "0.00000000"], ["61648.60000000", "0.00400000"], ["61652.69000000", "0.00000000"], ["61653.84000000", "0.00400000"], ["61654.34000000", "0.00000000"], ["61654.51000000", "0.00016000"], ["61671.66000000", "0.38092000"], ["61681.13000000", "0.30562000"], ["61686.30000000", "0.00009000"], ["61699.99000000", "0.51679000"], ["61702.29000000", "0.00000000"], ["61705.99000000", "0.00162000"], ["61719.13000000", "4.86556000"], ["62517.93000000", "0.00000000"]]}
{"type": "depth", "ts": 1783008099814, "U": 96863165128, "u": 96863165369, "bids": [["61596.85000000", "5.57646000"], ["61596.84000000", "2.34261000"], ["61596.65000000", "0.00018000"], ["61596.26000000", "0.02209000"], ["61596.20000000", "0.00400000"], ["61595.64000000", "0.02000000"], ["61595.28000000", "0.00000000"], ["61595.26000000", "0.00000000"], ["61595.18000000", "0.15051000"], ["61594.39000000", "0.00000000"], ["61594.38000000", "0.38956000"], ["61594.37000000", "1.36348000"], ["61594.10000000", "0.07542000"], ["61594.09000000", "0.15392000"], ["61594.04000000", "0.41405000"], ["61594.01000000", "0.07500000"], ["61594.00000000", "0.26423000"], ["61592.70000000", "0.00000000"], ["61592.50000000", "0.04217000"], ["61592.33000000", "0.00000000"], ["61592.00000000", "0.02400000"], ["61591.66000000", "0.00000000"], ["61591.61000000", "0.40830000"], ["61591.51000000", "0.00000000"], ["61590.33000000", "0.00009000"], ["61588.20000000", "0.00000000"], ["61586.81000000", "0.08759000"], ["61585.27000000", "0.08896000"], ["61581.82000000", "0.00000000"], ["61581.41000000", "0.45216000"], ["61580.54000000", "0.00000000"], ["61580.28000000", "0.00000000"], ["61572.84000000", "0.64226000"], ["61567.84000000", "0.00000000"], ["61566.00000000", "0.03400000"], ["61563.00000000", "0.00000000"], ["61556.90000000", "0.00400000"], ["61556.85000000", "0.00000000"], ["61555.02000000", "0.00429000"], ["61554.73000000", "1.61611000"], ["61554.60000000", "0.00000000"], ["61551.91000000", "0.00429000"], ["61545.71000000", "0.00000000"], ["61545.38000000", "0.00000000"], ["61541.99000000", "0.00000000"], ["61539.59000000", "0.97506000"], ["61532.08000000", "0.31487000"], ["61532.07000000", "0.00000000"], ["61488.57000000", "0.04217000"], ["61432.60000000", "0.00009000"], ["61419.47000000", "0.00000000"], ["55437.17000000", "0.00040000"], ["55434.00000000", "0.00000000"], ["49277.48000000", "0.00000000"]], "asks": [["61596.86000000", "0.01874000"], ["61596.87000000", "0.00081000"], ["61597.99000000", "0.00016000"], ["61598.88000000", "0.00009000"], ["61599.05000000", "0.00000000"], ["61599.35000000", "0.00000000"], ["61599.39000000", "0.00000000"], ["61599.85000000", "0.00034000"], ["61600.01000000", "0.20081000"], ["61600.37000000", "0.08813000"], ["61600.64000000", "0.01002000"], ["61600.88000000", "0.00243000"], ["61601.48000000", "0.00009000"], ["61601.49000000", "0.02358000"], ["61601.79000000", "0.00000000"], ["61601.80000000", "0.00000000"], ["61601.91000000", "0.00000000"], ["61601.99000000", "0.00009000"], ["61602.00000000", "0.01918000"], ["61603.02000000", "0.00010000"], ["61603.03000000", "0.00000000"], ["61603.10000000", "0.00912000"], ["61603.35000000", "0.00009000"], ["61603.36000000", "0.00000000"], ["61603.79000000", "0.00000000"], ["61603.99000000", "0.00009000"], ["61604.00000000", "0.02418000"], ["61604.07000000", "0.00000000"], ["61604.15000000", "0.00009000"], ["61604.16000000", "0.08074000"], ["61605.70000000", "0.00000000"], ["61605.96000000", "0.08966000"], ["61606.35000000", "0.08750000"], ["61606.42000000", "0.18791000"], ["61606.76000000", "0.00000000"], ["61608.30000000", "0.00000000"], ["61608.56000000", "0.08966000"], ["61609.80000000", "0.62970000"], ["61609.81000000", "0.00000000"], ["61609.82000000", "0.00000000"], ["61609.83000000", "0.00009000"], ["61611.33000000", "0.06000000"], ["61612.03000000", "0.08000000"], ["61624.89000000", "0.01000000"], ["61624.93000000", "0.00000000"], ["61625.76000000", "0.00000000"], ["61628.02000000", "0.00000000"], ["61628.18000000", "0.24750000"], ["61632.55000000", "0.00000000"], ["61632.90000000", "0.00619000"], ["61633.23000000", "0.00429000"], ["61636.76000000", "0.00429000"], ["61637.03000000", "0.00430000"], ["61637.47000000", "0.00230000"], ["61640.64000000", "0.00000000"], ["61649.94000000", "0.09406000"], ["61728.11000000", "0.00000000"], ["61735.23000000", "0.02543000"]]}
{"type": "depth", "ts": 1783008099914, "U": 96863165370, "u": 96863165646, "bids": [["61597.99000000", "5.63281000"], ["61597.98000000", "0.98264000"], ["61597.97000000", "0.00017000"], ["61597.39000000", "0.00009000"], ["61596.87000000", "1.23607000"], ["61596.86000000", "0.22865000"], ["61596.85000000", "0.26254000"], ["61596.84000000", "1.36836000"], ["61596.83000000", "0.00000000"], ["61596.65000000", "0.00000000"], ["61596.55000000", "0.00000000"], ["61596.41000000", "0.16234000"], ["61596.26000000", "0.02209000"], ["61595.64000000", "0.02018000"], ["61595.47000000", "0.00000000"], ["61595.18000000", "0.00027000"], ["61594.53000000", "0.00034000"], ["61594.09000000", "0.15374000"], ["61594.05000000", "0.07509000"], ["61594.04000000", "0.41405000"], ["61594.01000000", "0.00000000"], ["61594.00000000", "0.01664000"], ["61591.63000000", "0.69907000"], ["61591.62000000", "0.97390000"], ["61591.61000000", "0.00000000"], ["61590.10000000", "0.00009000"], ["61567.00000000", "0.01000000"], ["61566.50000000", "0.00000000"], ["61566.00000000", "0.02400000"], ["61553.37000000", "0.00432000"], ["61543.18000000", "0.00000000"], ["61501.90000000", "0.00000000"], ["55438.20000000", "0.00040000"], ["55437.17000000", "0.00000000"]], "asks": [["61596.86000000", "0.00000000"], ["61596.87000000", "0.00000000"], ["61597.99000000", "0.00000000"], ["61598.00000000", "0.17707000"], ["61598.01000000", "0.00081000"], ["61598.26000000", "0.00009000"], ["61598.40000000", "0.00000000"], ["61599.85000000", "0.00000000"], ["61600.37000000", "0.08804000"], ["61600.64000000", "0.01002000"], ["61600.72000000", "0.00000000"], ["61601.41000000", "0.00000000"], ["61601.48000000", "0.00000000"], ["61601.49000000", "0.00018000"], ["61601.69000000", "0.00000000"], ["61602.48000000", "0.00000000"], ["61602.67000000", "0.00009000"], ["61602.68000000", "0.02082000"], ["61602.99000000", "0.00000000"], ["61603.23000000", "0.00000000"], ["61603.35000000", "0.00000000"], ["61604.00000000", "0.02427000"], ["61604.07000000", "0.00009000"], ["61604.15000000", "0.00000000"], ["61604.16000000", "0.00009000"], ["61604.54000000", "0.00000000"], ["61605.78000000", "0.00009000"], ["61605.79000000", "0.08967000"], ["61605.95000000", "0.00000000"], ["61609.18000000", "0.00000000"], ["61609.59000000", "0.00000000"], ["61609.80000000", "0.22275000"], ["61609.95000000", "0.00009000"], ["61610.32000000", "0.00324000"], ["61611.00000000", "0.08967000"], ["61611.13000000", "0.00048000"], ["61611.21000000", "0.00048000"], ["61611.91000000", "0.08335000"], ["61612.79000000", "0.08967000"], ["61616.31000000", "0.00000000"], ["61617.42000000", "0.08642000"], ["61628.00000000", "0.02400000"], ["61628.45000000", "0.58481000"], ["61629.00000000", "0.01000000"], ["61635.34000000", "0.00024000"], ["61659.08000000", "1.22962000"], ["61659.09000000", "0.97506000"], ["61661.41000000", "0.00000000"], ["61677.99000000", "0.80368000"], ["61771.45000000", "0.00009000"], ["61774.52000000", "0.00000000"]]}
{"type": "depth", "ts": 1783008100014, "U": 96863165647, "u": 96863165730, "bids": [["61597.99000000", "5.47465000"], ["61597.98000000", "0.98282000"], ["61596.87000000", "1.23625000"], ["61596.86000000", "0.22883000"], ["61596.85000000", "0.25254000"], ["61596.84000000", "1.36836000"], ["61596.54000000", "0.00000000"], ["61596.41000000", "0.00000000"], ["61596.40000000", "0.16234000"], ["61595.64000000", "0.02000000"], ["61595.18000000", "0.00009000"], ["61594.37000000", "1.36330000"], ["61594.10000000", "0.07524000"], ["61594.04000000", "0.16664000"], ["61592.23000000", "0.00000000"], ["61592.01000000", "0.05098000"], ["61591.67000000", "0.00982000"], ["61590.66000000", "0.00909000"], ["61590.56000000", "0.00000000"], ["61590.33000000", "0.00000000"], ["61576.19000000", "0.00000000"], ["61575.68000000", "0.00000000"], ["61559.19000000", "0.00000000"], ["55438.20000000", "0.00080000"], ["49278.40000000", "0.00040000"]], "asks": [["61598.00000000", "0.17706000"], ["61598.01000000", "0.00081000"], ["61599.56000000", "0.00000000"], ["61600.64000000", "0.01002000"], ["61601.49000000", "0.00000000"], ["61602.00000000", "0.01918000"], ["61602.47000000", "0.00000000"], ["61602.67000000", "0.00009000"], ["61602.68000000", "0.02132000"], ["61608.40000000", "0.08967000"], ["61609.80000000", "0.65412000"], ["61610.98000000", "0.08967000"], ["61610.99000000", "1.36330000"], ["61611.00000000", "0.00000000"], ["61611.91000000", "0.00010000"], ["61612.56000000", "0.00188000"], ["61612.79000000", "0.00000000"], ["61617.42000000", "0.00000000"]]}
{"type": "depth", "ts": 1783008100114, "U": 96863165731, "u": 96863165786, "bids": [["61597.99000000", "5.23731000"], ["61596.86000000", "0.15383000"], ["61596.85000000", "0.17254000"], ["61596.84000000", "1.36836000"], ["61596.40000000", "0.00000000"], ["61596.31000000", "0.11460000"], ["61594.53000000", "0.00000000"], ["61570.55000000", "0.00419000"], ["61520.54000000", "0.00030000"], ["61516.56000000", "0.00000000"], ["61363.66000000", "0.00000000"], ["60674.02000000", "0.00030000"], ["55438.20000000", "0.00100000"]], "asks": [["61598.00000000", "0.42483000"], ["61599.78000000", "0.00034000"], ["61600.32000000", "0.00009000"], ["61600.37000000", "0.08822000"], ["61602.37000000", "0.02850000"], ["61602.68000000", "0.00018000"], ["61603.19000000", "0.00009000"], ["61603.20000000", "0.08966000"], ["61603.55000000", "0.00191000"], ["61604.00000000", "0.02418000"], ["61604.07000000", "0.18096000"], ["61604.15000000", "0.00009000"], ["61604.16000000", "0.08975000"], ["61605.78000000", "0.00000000"], ["61606.42000000", "0.59804000"], ["61608.38000000", "0.08966000"], ["61608.39000000", "1.36330000"], ["61608.40000000", "0.00000000"], ["61608.56000000", "0.00000000"], ["61610.98000000", "0.00000000"], ["61612.80000000", "0.67566000"], ["61613.56000000", "0.97390000"], ["61619.94000000", "0.00419000"], ["61624.92000000", "0.00000000"], ["61651.22000000", "0.00400000"], ["61653.84000000", "0.00000000"], ["61670.54000000", "0.00000000"], ["61674.54000000", "0.00030000"], ["61872.36000000", "0.00000000"]]}
{"type": "depth", "ts": 1783008100214, "U": 96863165787, "u": 96863165837, "bids": [["61596.85000000", "0.17254000"], ["61596.84000000", "1.36836000"], ["61596.38000000", "0.16234000"], ["61596.31000000", "0.00000000"], ["61594.33000000", "0.00034000"], ["61592.06000000", "0.01000000"], ["61589.66000000", "0.01000000"], ["61579.52000000", "0.00000000"], ["61578.35000000", "0.00000000"], ["61489.68000000", "0.00000000"], ["61479.52000000", "0.00000000"], ["61454.67000000", "0.00000000"], ["55438.20000000", "0.00140000"], ["49278.40000000", "0.00000000"]], "asks": [["61598.00000000", "0.17715000"], ["61602.00000000", "0.01918000"], ["61602.36000000", "0.00009000"], ["61602.37000000", "0.00018000"], ["61602.67000000", "0.02161000"], ["61602.68000000", "0.00000000"], ["61603.10000000", "0.00912000"], ["61603.20000000", "0.08993000"], ["61604.00000000", "0.02400000"], ["61604.06000000", "0.00009000"], ["61615.26000000", "0.00000000"], ["61627.23000000", "0.00000000"], ["61654.51000000", "0.00000000"], ["61682.33000000", "0.00000000"], ["61685.57000000", "0.00000000"], ["61689.87000000", "0.00000000"], ["61735.23000000", "0.00000000"]]}
{"type": "depth", "ts": 1783008100314, "U": 96863165838, "u": 96863165865, "bids": [["61596.85000000", "0.17254000"], ["61596.84000000", "1.36836000"], ["61581.64000000", "0.00000000"], ["61577.65000000", "0.00009000"], ["61573.66000000", "0.00000000"], ["61486.64000000", "0.02543000"], ["55438.20000000", "0.00180000"], ["43118.59000000", "0.00000000"]], "asks": [["61598.00000000", "0.17724000"], ["61599.78000000", "0.00000000"], ["61602.00000000", "0.01918000"], ["61602.36000000", "0.00000000"], ["61602.37000000", "0.00000000"], ["61602.66000000", "0.00009000"], ["61602.67000000", "0.02179000"], ["61610.63000000", "0.00000000"], ["61614.62000000", "0.00009000"], ["61703.37000000", "0.02543000"]]}
{"type": "depth", "ts": 1783008100414, "U": 96863165866, "u": 96863165880, "bids": [["61597.99000000", "5.23740000"], ["61595.20000000", "0.00009000"], ["61583.94000000", "0.00000000"], ["61582.35000000", "0.00649000"], ["61493.67000000", "0.00016000"], ["61347.62000000", "0.03263000"], ["55438.20000000", "0.00220000"]], "asks": [["61598.00000000", "0.25858000"], ["61598.05000000", "0.05000000"], ["61598.26000000", "0.00000000"], ["61598.88000000", "0.00000000"], ["61619.25000000", "0.00649000"], ["62521.97000000", "0.00030000"]]}
{"type": "depth", "ts": 1783008100514, "U": 96863165881, "u": 96863165899, "bids": [["61594.00000000", "0.01673000"], ["61483.51000000", "0.00024000"], ["55438.20000000", "0.00260000"]], "asks": [["61598.00000000", "0.25867000"], ["61598.04000000", "0.00009000"], ["61598.05000000", "0.05018000"], ["61603.20000000", "0.08975000"], ["61604.16000000", "0.08966000"], ["61639.57000000", "1.04514000"], ["61645.98000000", "0.00400000"], ["61651.22000000", "0.00000000"], ["77803.32000000", "0.00053000"]]}
{"type": "depth", "ts": 1783008100614, "U": 96863165900, "u": 96863165910, "bids": [["61533.54000000", "0.00000000"], ["61515.08000000", "0.00000000"], ["55438.20000000", "0.00280000"], ["33000.00000000", "37.44300000"]], "asks": [["61598.00000000", "0.30859000"], ["61598.01000000", "0.00090000"], ["61600.17000000", "0.00000000"], ["61633.34000000", "0.58468000"]]}
{"type": "depth", "ts": 1783008100714, "U": 96863165911, "u": 96863166001, "bids": [["61597.99000000", "4.57185000"], ["61596.87000000", "0.00018000"], ["61596.86000000", "0.15383000"], ["61596.85000000", "1.31221000"], ["61596.38000000", "0.00018000"], ["61596.33000000", "0.16234000"], ["61596.23000000", "0.00000000"], ["61578.76000000", "0.00000000"], ["61527.95000000", "0.00309000"], ["61509.49000000", "0.00981000"], ["61505.97000000", "0.00009000"], ["61458.66000000", "0.00034000"], ["55438.20000000", "0.00300000"], ["49278.39000000", "0.00000000"]], "asks": [["61598.00000000", "0.10580000"], ["61598.02000000", "0.00009000"], ["61598.03000000", "0.01612000"], ["61602.34000000", "0.00000000"], ["61602.35000000", "0.00000000"], ["61602.66000000", "0.00000000"], ["61602.67000000", "0.00018000"], ["61602.83000000", "0.01963000"], ["61603.19000000", "0.00000000"], ["61603.20000000", "0.00000000"], ["61604.06000000", "0.00000000"], ["61604.07000000", "0.00000000"], ["61604.15000000", "0.00009000"], ["61604.16000000", "0.08975000"], ["61606.35000000", "0.00000000"], ["61606.42000000", "0.18791000"], ["61608.38000000", "0.00000000"], ["61608.39000000", "0.00000000"], ["61609.80000000", "0.22275000"], ["61610.33000000", "0.00300000"], ["61610.98000000", "1.36330000"], ["61610.99000000", "0.00000000"], ["61611.91000000", "0.08977000"], ["61612.80000000", "0.44138000"], ["61613.55000000", "1.36330000"], ["61613.56000000", "0.00000000"], ["61613.57000000", "0.00000000"], ["61686.34000000", "0.00016000"], ["61689.57000000", "0.00024000"]]}
{"type": "depth", "ts": 1783008100814, "U": 96863166002, "u": 96863166073, "bids": [["61597.99000000", "4.57194000"], ["61597.98000000", "0.98282000"], ["61596.87000000", "0.00000000"], ["61596.86000000", "0.15401000"], ["61596.85000000", "1.31212000"], ["61596.84000000", "1.36836000"], ["61596.38000000", "0.00000000"], ["61596.33000000", "0.00018000"], ["61596.29000000", "0.13251000"], ["61594.00000000", "0.01664000"], ["61592.37000000", "0.00009000"], ["61521.66000000", "0.00000000"], ["61509.01000000", "0.00250000"], ["61495.21000000", "0.00092000"], ["55438.20000000", "0.00340000"], ["49278.39000000", "0.00000000"], ["49278.00000000", "0.03314000"]], "asks": [["61598.00000000", "0.25936000"], ["61598.01000000", "0.00090000"], ["61598.03000000", "0.01630000"], ["61600.32000000", "0.00000000"], ["61600.37000000", "0.08813000"], ["61602.00000000", "0.01918000"], ["61602.51000000", "0.00009000"], ["61602.52000000", "0.02599000"], ["61602.67000000", "0.00000000"], ["61602.82000000", "0.00000000"], ["61602.83000000", "0.00018000"], ["61603.10000000", "0.00894000"], ["61604.15000000", "0.00000000"], ["61604.16000000", "0.00009000"], ["61609.70000000", "0.08967000"], ["61609.80000000", "0.63016000"], ["61610.97000000", "1.45297000"], ["61610.98000000", "0.00000000"], ["61611.91000000", "0.00010000"], ["61783.89000000", "0.00581000"]]}
{"type": "depth", "ts": 1783008100914, "U": 96863166074, "u": 96863166099, "bids": [["61596.86000000", "0.15392000"], ["61596.84000000", "1.36836000"], ["61596.33000000", "0.00000000"], ["61596.29000000", "0.13269000"], ["61593.55000000", "0.04000000"], ["61588.79000000", "0.00000000"], ["61458.66000000", "0.00000000"], ["55438.20000000", "0.00380000"], ["49278.00000000", "0.03114000"]], "asks": [["61600.11000000", "0.00009000"], ["61602.00000000", "0.01918000"], ["61602.52000000", "0.02617000"], ["61602.83000000", "0.00000000"], ["61693.87000000", "0.00040000"], ["61764.16000000", "0.00024000"]]}
{"type": "depth", "ts": 1783008101014, "U": 96863166100, "u": 96863166119, "bids": [["61597.99000000", "4.74140000"], ["61452.54000000", "0.00040000"], ["55438.20000000", "0.00420000"], ["55438.00000000", "0.00722000"], ["49278.40000000", "0.00040000"]], "asks": [["61600.32000000", "0.00009000"], ["61600.36000000", "0.00000000"], ["61600.37000000", "0.00036000"], ["61604.00000000", "0.02409000"], ["61604.07000000", "0.00009000"], ["61604.16000000", "0.00009000"], ["61608.40000000", "0.08967000"], ["61629.62000000", "0.97399000"], ["61673.99000000", "0.00000000"], ["61675.99000000", "0.01171000"]]}
{"type": "depth", "ts": 1783008101114, "U": 96863166120, "u": 96863166140, "bids": [["61597.99000000", "4.57185000"], ["61499.56000000", "0.12000000"], ["60674.02000000", "0.00030000"], ["55438.20000000", "0.00420000"]], "asks": [["61600.01000000", "0.20081000"], ["61600.32000000", "0.00000000"], ["61600.37000000", "0.00018000"], ["61600.59000000", "0.08777000"], ["61602.00000000", "0.02418000"], ["61603.10000000", "0.00912000"], ["61606.67000000", "0.00000000"], ["61608.41000000", "0.40100000"]]}
{"type": "depth", "ts": 1783008101214, "U": 96863166141, "u": 96863166176, "bids": [["61597.99000000", "4.57185000"], ["61495.00000000", "0.00250000"], ["61453.95000000", "0.00039000"], ["61452.54000000", "0.00000000"], ["55438.20000000", "0.00440000"], ["49278.40000000", "0.00000000"]], "asks": [["61598.00000000", "0.25953000"], ["61598.01000000", "0.00107000"], ["61598.02000000", "0.00026000"], ["61600.01000000", "0.20090000"], ["61600.58000000", "0.00009000"], ["61600.59000000", "0.08795000"], ["61603.10000000", "0.00894000"], ["61604.00000000", "0.02400000"], ["61604.07000000", "0.00000000"], ["61616.43000000", "0.09752000"], ["61643.80000000", "0.00000000"]]}
{"type": "depth", "ts": 1783008101314, "U": 96863166177, "u": 96863166187, "bids": [["61577.65000000", "0.00000000"], ["55438.20000000", "0.00440000"]], "asks": [["61614.62000000", "0.00000000"], ["61616.43000000", "0.09752000"], ["61627.64000000", "0.00000000"], ["61633.70000000", "0.00000000"]]}
{"type": "depth", "ts": 1783008101414, "U": 96863166188, "u": 96863166203, "bids": [["61577.65000000", "0.00009000"], ["55438.20000000", "0.00420000"]], "asks": [["61614.62000000", "0.00009000"], ["61616.43000000", "0.00000000"], ["62521.97000000", "0.00030000"]]}
{"type": "depth", "ts": 1783008101514, "U": 96863166204, "u": 96863166223, "bids": [["55438.20000000", "0.00420000"]], "asks": [["61616.43000000", "0.09752000"], ["61748.87000000", "0.00000000"]]}
{"type": "depth", "ts": 1783008101714, "U": 96863166253, "u": 96863166293, "bids": [["61597.99000000", "4.61746000"], ["61595.64000000", "0.02018000"], ["61589.50000000", "0.00000000"], ["61534.01000000", "0.82083000"], ["61525.82000000", "0.14843000"], ["61524.01000000", "0.00000000"], ["61454.98000000", "0.00038000"], ["61453.95000000", "0.00000000"], ["55438.20000000", "0.00420000"], ["55438.19000000", "0.00010000"], ["55434.64000000", "0.00000000"], ["49278.39000000", "0.00000000"]], "asks": [["61598.00000000", "0.25935000"], ["61616.43000000", "0.09752000"], ["61754.68000000", "6.48099000"]]}
{"type": "depth", "ts": 1783008101814, "U": 96863166294, "u": 96863166325, "bids": [["55438.20000000", "0.00460000"], ["49278.39000000", "0.00000000"]], "asks": [["61598.00000000", "0.25707000"], ["61601.47000000", "0.01610000"], ["61616.43000000", "0.00000000"], ["61621.93000000", "0.78000000"], ["67757.80000000", "0.00009000"]]}
{"type": "depth", "ts": 1783008101914, "U": 96863166326, "u": 96863166363, "bids": [["61597.99000000", "4.61737000"], ["55438.20000000", "0.00460000"]], "asks": [["61600.64000000", "0.01002000"], ["61601.47000000", "0.01628000"], ["61602.52000000", "0.02599000"], ["61616.43000000", "0.00000000"], ["61621.57000000", "0.58479000"], ["61629.66000000", "0.00000000"], ["67757.80000000", "0.00000000"]]}
{"type": "depth", "ts": 1783008102114, "U": 96863166384, "u": 96863166413, "bids": [["61597.99000000", "4.61746000"], ["61596.00000000", "0.00058000"], ["61595.64000000", "0.00018000"], ["61594.00000000", "0.02264000"], ["61593.04000000", "0.02000000"], ["61590.20000000", "0.00000000"], ["60674.02000000", "0.00030000"], ["55438.20000000", "0.00440000"], ["55438.00000000", "0.00742000"]], "asks": [["61598.00000000", "0.26241000"], ["61600.32000000", "0.00009000"], ["61604.15000000", "0.00009000"], ["61604.16000000", "0.09044000"], ["61606.42000000", "0.57128000"], ["61608.39000000", "1.36330000"], ["61610.97000000", "1.36330000"], ["61616.43000000", "0.00000000"], ["61617.64000000", "0.58482000"], ["61628.45000000", "0.00009000"]]}
{"type": "depth", "ts": 1783008102214, "U": 96863166414, "u": 96863166453, "bids": [["61596.29000000", "0.13278000"], ["61596.26000000", "0.02209000"], ["61595.64000000", "0.00000000"], ["61595.00000000", "0.25000000"], ["61594.38000000", "0.38974000"], ["61591.32000000", "0.00000000"], ["61534.01000000", "0.00000000"], ["61455.99000000", "0.00037000"], ["61454.98000000", "0.00000000"], ["55438.20000000", "0.00440000"], ["55438.00000000", "0.00722000"], ["49278.40000000", "0.00000000"], ["49278.00000000", "0.03114000"]], "asks": [["61604.14000000", "0.00009000"], ["61604.15000000", "0.17526000"], ["61604.16000000", "0.09035000"], ["61608.38000000", "0.09035000"], ["61608.40000000", "0.00000000"], ["61609.70000000", "0.00000000"], ["61612.80000000", "0.67375000"], ["61613.54000000", "0.97390000"], ["61813.59000000", "0.15343000"]]}
{"type": "depth", "ts": 1783008102314, "U": 96863166454, "u": 96863166465, "bids": [["61596.26000000", "0.02209000"], ["55438.20000000", "0.00440000"]], "asks": [["61603.24000000", "0.08190000"], ["61608.41000000", "0.00000000"], ["61609.28000000", "0.40100000"], ["61616.45000000", "0.09752000"]]}
{"type": "depth", "ts": 1783008102414, "U": 96863166466, "u": 96863166488, "bids": [["61591.63000000", "0.69898000"], ["61591.54000000", "0.00000000"], ["61591.45000000", "0.00000000"], ["61577.65000000", "0.00009000"], ["55438.20000000", "0.00440000"], ["49278.00000000", "0.03114000"]], "asks": [["61598.00000000", "0.26250000"], ["61600.59000000", "0.08804000"], ["61603.23000000", "0.00009000"], ["61604.15000000", "0.17517000"], ["61614.62000000", "0.00009000"], ["61616.45000000", "0.00000000"], ["62521.97000000", "0.00030000"]]}
{"type": "depth", "ts": 1783008102514, "U": 96863166489, "u": 96863166505, "bids": [["61597.99000000", "4.20934000"], ["61596.29000000", "0.00027000"], ["61596.01000000", "0.00812000"], ["61594.52000000", "0.11767000"], ["55438.20000000", "0.00460000"]], "asks": [["61598.00000000", "1.26285000"], ["61600.32000000", "0.00000000"], ["61601.55000000", "0.00873000"], ["61602.26000000", "0.04655000"], ["61602.52000000", "0.00000000"], ["61603.24000000", "0.00000000"], ["61604.16000000", "0.00000000"]]}
{"type": "depth", "ts": 1783008102614, "U": 96863166506, "u": 96863166544, "bids": [["61596.84000000", "1.36836000"], ["61596.29000000", "0.00009000"], ["61596.26000000", "0.02209000"], ["61596.01000000", "0.00830000"], ["61595.00000000", "0.25027000"], ["61594.38000000", "0.38956000"], ["55438.20000000", "0.00460000"]], "asks": [["61598.00000000", "1.26276000"], ["61600.32000000", "0.00009000"], ["61600.37000000", "0.00009000"], ["61600.59000000", "0.08804000"], ["61601.47000000", "0.01628000"], ["61601.55000000", "0.00891000"], ["61602.00000000", "0.02400000"], ["61602.25000000", "0.00009000"], ["61602.51000000", "0.00000000"], ["61603.23000000", "0.00000000"]]}
{"type": "depth", "ts": 1783008102714, "U": 96863166545, "u": 96863166553, "bids": [["61456.98000000", "0.00036000"], ["61455.99000000", "0.00000000"], ["55438.20000000", "0.00440000"], ["49278.39000000", "0.00000000"]], "asks": [["61603.81000000", "0.00009000"], ["61748.09000000", "0.04065000"]]}
{"type": "depth", "ts": 1783008102814, "U": 96863166554, "u": 96863166577, "bids": [["61596.85000000", "1.28911000"], ["55438.20000000", "0.00450000"], ["55438.19000000", "0.00000000"], ["49278.39000000", "0.00000000"]], "asks": [["61598.00000000", "1.26260000"], ["61600.58000000", "0.00000000"], ["61600.59000000", "0.00027000"], ["61601.46000000", "0.00009000"], ["61606.42000000", "0.06745000"], ["61608.39000000", "0.00000000"], ["61629.62000000", "0.97390000"], ["61798.42000000", "0.00182000"], ["61822.63000000", "0.00000000"], ["62471.96000000", "0.00135000"]]}
{"type": "depth", "ts": 1783008102914, "U": 96863166578, "u": 96863166604, "bids": [["55438.20000000", "0.00450000"]], "asks": [["61598.00000000", "1.26303000"], ["61598.01000000", "0.00098000"], ["61600.01000000", "0.20090000"], ["61600.59000000", "0.00000000"], ["61601.55000000", "0.00018000"], ["61602.00000000", "0.02418000"], ["61604.07000000", "0.00009000"], ["61604.14000000", "0.00000000"], ["61604.15000000", "0.00000000"], ["61605.79000000", "0.00000000"], ["61605.96000000", "0.00000000"], ["61609.27000000", "0.09035000"], ["61616.39000000", "0.00000000"], ["61629.62000000", "0.97399000"]]}
{"type": "depth", "ts": 1783008103014, "U": 96863166605, "u": 96863167197, "bids": [["61600.00000000", "4.63453000"], ["61599.99000000", "0.06005000"], ["61599.98000000", "0.00017000"], ["61599.74000000", "0.02000000"], ["61599.22000000", "0.00243000"], ["61599.12000000", "0.00400000"], ["61598.95000000", "0.00009000"], ["61598.94000000", "0.00000000"], ["61598.42000000", "0.00000000"], ["61598.30000000", "0.14218000"], ["61598.04000000", "1.36643000"], ["61598.03000000", "0.07500000"], ["61598.02000000", "1.26149000"], ["61598.01000000", "0.00000000"], ["61598.00000000", "0.07500000"], ["61597.99000000", "0.30799000"], ["61597.98000000", "0.00027000"], ["61597.97000000", "0.00000000"], ["61597.40000000", "0.04217000"], ["61596.85000000", "1.18414000"], ["61596.01000000", "0.00018000"], ["61595.18000000", "0.00000000"], ["61595.03000000", "0.03000000"], ["61595.00000000", "0.25009000"], ["61594.52000000", "0.00009000"], ["61594.39000000", "0.38956000"], ["61594.38000000", "0.00000000"], ["61594.05000000", "0.00009000"], ["61594.04000000", "0.16664000"], ["61594.00000000", "0.02255000"], ["61593.84000000", "0.00019000"], ["61593.73000000", "0.12000000"], ["61593.52000000", "0.00000000"], ["61593.27000000", "0.00000000"], ["61593.04000000", "0.00000000"], ["61592.92000000", "0.00903000"], ["61592.32000000", "0.00009000"], ["61592.10000000", "0.00000000"], ["61590.69000000", "0.00000000"], ["61588.81000000", "0.00000000"], ["61587.72000000", "0.00000000"], ["61587.68000000", "0.00019000"], ["61585.38000000", "0.00000000"], ["61584.60000000", "0.00019000"], ["61584.37000000", "0.58514000"], ["61584.18000000", "0.00000000"], ["61581.52000000", "0.00181000"], ["61581.32000000", "0.00000000"], ["61581.26000000", "0.01625000"], ["61581.10000000", "0.00000000"], ["61578.44000000", "0.00019000"], ["61578.02000000", "0.00000000"], ["61577.53000000", "0.00000000"], ["61575.36000000", "0.00419000"], ["61575.10000000", "0.47673000"], ["61574.94000000", "0.00000000"], ["61573.48000000", "1.60943000"], ["61572.28000000", "0.00019000"], ["61571.86000000", "0.00000000"], ["61570.56000000", "0.00000000"], ["61569.20000000", "0.00019000"], ["61568.78000000", "1.36330000"], ["61568.09000000", "0.00000000"], ["61565.70000000", "0.00000000"], ["61565.37000000", "0.53358000"], ["61565.25000000", "0.00000000"], ["61556.90000000", "0.00000000"], ["61549.36000000", "0.00000000"], ["61547.90000000", "0.35130000"], ["61546.89000000", "0.00000000"], ["61544.83000000", "0.00000000"], ["61541.61000000", "0.00000000"], ["61530.54000000", "0.00000000"], ["61525.07000000", "0.00000000"], ["61521.43000000", "0.00000000"], ["61488.57000000", "0.00000000"], ["60674.02000000", "0.00000000"], ["55438.20000000", "0.00010000"], ["49280.00000000", "0.02173000"], ["49278.00000000", "0.03114000"]], "asks": [["61598.00000000", "0.00000000"], ["61598.01000000", "0.00000000"], ["61598.02000000", "0.00000000"], ["61598.03000000", "0.00000000"], ["61598.04000000", "0.00000000"], ["61598.05000000", "0.00000000"], ["61598.43000000", "0.00000000"], ["61598.95000000", "0.00000000"], ["61599.99000000", "0.00000000"], ["61600.00000000", "0.00000000"], ["61600.01000000", "0.21784000"], ["61600.02000000", "0.00063000"], ["61600.32000000", "0.00000000"], ["61600.37000000", "0.00000000"], ["61600.46000000", "0.00000000"], ["61600.63000000", "0.00000000"], ["61600.64000000", "0.00018000"], ["61600.88000000", "0.00000000"], ["61601.47000000", "0.01628000"], ["61601.55000000", "0.00000000"], ["61601.74000000", "0.00000000"], ["61602.26000000", "0.00018000"], ["61602.63000000", "0.00000000"], ["61603.02000000", "0.00000000"], ["61603.10000000", "0.00018000"], ["61603.25000000", "0.00000000"], ["61603.88000000", "0.00000000"], ["61604.00000000", "0.02418000"], ["61604.01000000", "0.00018000"], ["61604.07000000", "0.00000000"], ["61604.08000000", "0.00018000"], ["61604.16000000", "0.00000000"], ["61604.17000000", "0.00000000"], ["61604.59000000", "0.02520000"], ["61604.88000000", "0.00009000"], ["61604.89000000", "0.04046000"], ["61605.73000000", "0.00000000"], ["61605.74000000", "0.00000000"], ["61605.79000000", "0.00000000"], ["61605.80000000", "0.00000000"], ["61605.86000000", "0.00000000"], ["61605.99000000", "0.00009000"], ["61606.01000000", "0.00378000"], ["61606.02000000", "0.00000000"], ["61606.17000000", "0.00010000"], ["61606.18000000", "0.00000000"], ["61606.33000000", "0.00009000"], ["61606.35000000", "0.00009000"], ["61606.36000000", "0.00000000"], ["61606.39000000", "0.00034000"], ["61606.41000000", "0.00000000"], ["61606.42000000", "0.00000000"], ["61607.00000000", "0.00000000"], ["61607.06000000", "0.00243000"], ["61607.08000000", "0.00896000"], ["61607.17000000", "0.00000000"], ["61607.53000000", "0.00000000"], ["61607.57000000", "0.00000000"], ["61607.87000000", "0.08492000"], ["61607.99000000", "0.00009000"], ["61608.21000000", "0.00000000"], ["61608.37000000", "0.00009000"], ["61608.57000000", "0.00000000"], ["61608.59000000", "0.02000000"], ["61608.61000000", "0.00000000"], ["61608.64000000", "0.00000000"], ["61608.82000000", "0.00000000"], ["61608.83000000", "0.00000000"], ["61609.10000000", "0.00812000"], ["61609.11000000", "0.00009000"], ["61609.19000000", "0.00000000"], ["61609.21000000", "0.00000000"], ["61609.27000000", "0.09035000"], ["61609.44000000", "0.00000000"], ["61609.49000000", "0.00000000"], ["61609.80000000", "0.00000000"], ["61609.91000000", "0.00400000"], ["61610.17000000", "0.00911000"], ["61610.32000000", "0.00000000"], ["61610.34000000", "0.00000000"], ["61610.35000000", "0.00000000"], ["61610.43000000", "0.00000000"], ["61610.73000000", "0.00000000"], ["61610.96000000", "0.00000000"], ["61610.97000000", "0.00000000"], ["61611.33000000", "0.02000000"], ["61611.73000000", "0.01000000"], ["61611.80000000", "0.09044000"], ["61611.91000000", "0.08960000"], ["61612.16000000", "0.00000000"], ["61612.33000000", "0.04010000"], ["61612.80000000", "0.03250000"], ["61613.26000000", "0.00884000"], ["61613.53000000", "1.36330000"], ["61613.54000000", "0.00000000"], ["61613.55000000", "0.00000000"], ["61613.71000000", "0.00000000"], ["61614.42000000", "0.09035000"], ["61614.99000000", "0.00000000"], ["61615.41000000", "0.00010000"], ["61615.73000000", "0.09035000"], ["61616.24000000", "0.00400000"], ["61616.35000000", "0.00913000"], ["61617.04000000", "0.09035000"], ["61617.42000000", "0.09035000"], ["61617.44000000", "1.55924000"], ["61617.45000000", "0.00000000"], ["61617.64000000", "0.00000000"], ["61617.91000000", "0.00000000"], ["61617.93000000", "1.36330000"], ["61617.94000000", "0.00000000"], ["61618.07000000", "0.00000000"], ["61618.49000000", "0.00010000"], ["61618.50000000", "0.68584000"], ["61619.44000000", "0.00896000"], ["61621.15000000", "0.00000000"], ["61621.17000000", "1.36330000"], ["61621.18000000", "0.97390000"], ["61621.19000000", "0.00000000"], ["61621.57000000", "0.58489000"], ["61621.81000000", "0.00400000"], ["61621.93000000", "0.00000000"], ["61623.98000000", "1.36330000"], ["61623.99000000", "0.00024000"], ["61624.23000000", "0.00000000"], ["61624.65000000", "0.00010000"], ["61624.89000000", "0.98390000"], ["61624.91000000", "0.00000000"], ["61626.30000000", "0.00000000"], ["61626.58000000", "1.36330000"], ["61626.59000000", "0.00000000"], ["61626.60000000", "0.00000000"], ["61627.31000000", "0.00000000"], ["61627.73000000", "0.00010000"], ["61629.00000000", "0.00000000"], ["61630.09000000", "0.58471000"], ["61630.81000000", "0.91295000"], ["61631.00000000", "0.01000000"], ["61632.55000000", "0.00009000"], ["61633.32000000", "0.00000000"], ["61635.48000000", "0.00000000"], ["61635.89000000", "0.00000000"], ["61637.12000000", "0.00000000"], ["61637.54000000", "0.04711000"], ["61639.47000000", "0.00379000"], ["61643.79000000", "0.00000000"], ["61646.71000000", "0.00414000"], ["61675.99000000", "0.00000000"], ["61677.99000000", "0.00000000"], ["61687.73000000", "0.50078000"], ["61694.87000000", "0.00000000"], ["61701.06000000", "0.00152000"], ["61706.80000000", "0.11631000"], ["61777.97000000", "0.24750000"], ["62521.97000000", "0.00000000"]]}
{"type": "depth", "ts": 1783008103114, "U": 96863167198, "u": 96863167893, "bids": [["61601.99000000", "5.68554000"], ["61601.98000000", "0.97434000"], ["61601.97000000", "0.00017000"], ["61601.90000000", "2.37209000"], ["61601.89000000", "0.00000000"], ["61601.76000000", "0.00400000"], ["61601.47000000", "0.55569000"], ["61601.46000000", "1.10417000"], ["61601.45000000", "1.61943000"], ["61601.44000000", "0.00000000"], ["61601.43000000", "0.00000000"], ["61600.66000000", "0.00034000"], ["61600.63000000", "0.00000000"], ["61600.54000000", "0.16233000"], ["61600.51000000", "0.08639000"], ["61600.50000000", "0.24795000"], ["61600.32000000", "0.00009000"], ["61600.16000000", "0.00000000"], ["61600.10000000", "0.00000000"], ["61600.09000000", "0.00000000"], ["61600.01000000", "0.07500000"], ["61600.00000000", "0.38786000"], ["61599.99000000", "0.00027000"], ["61599.98000000", "0.00000000"], ["61599.74000000", "0.02018000"], ["61598.30000000", "0.00036000"], ["61598.04000000", "0.00018000"], ["61598.03000000", "0.25672000"], ["61598.02000000", "0.28759000"], ["61598.00000000", "0.00000000"], ["61597.99000000", "0.04757000"], ["61597.98000000", "0.00009000"], ["61596.86000000", "0.15374000"], ["61596.85000000", "1.18387000"], ["61596.84000000", "1.36818000"], ["61596.26000000", "0.02191000"], ["61596.01000000", "0.00000000"], ["61595.90000000", "0.00985000"], ["61595.83000000", "0.00010000"], ["61595.39000000", "0.00009000"], ["61595.20000000", "0.00000000"], ["61594.67000000", "0.00871000"], ["61594.10000000", "0.00024000"], ["61594.04000000", "0.08637000"], ["61594.00000000", "0.02237000"], ["61593.84000000", "0.00009000"], ["61593.55000000", "0.00000000"], ["61590.37000000", "0.58508000"], ["61589.73000000", "0.08759000"], ["61588.19000000", "0.08896000"], ["61587.84000000", "0.25450000"], ["61586.81000000", "0.00000000"], ["61585.27000000", "0.00000000"], ["61585.23000000", "0.01625000"], ["61581.84000000", "0.00000000"], ["61581.26000000", "0.00000000"], ["61577.67000000", "0.01016000"], ["61576.78000000", "0.00419000"], ["61574.03000000", "0.00000000"], ["61571.02000000", "0.00000000"], ["61569.45000000", "0.00000000"], ["61569.00000000", "0.01000000"], ["61567.00000000", "0.00000000"], ["61565.35000000", "0.00000000"], ["61559.52000000", "0.00000000"], ["61556.32000000", "0.13721000"], ["61554.83000000", "1.50247000"], ["61549.77000000", "0.97507000"], ["61546.90000000", "0.49507000"], ["61539.59000000", "0.00000000"], ["61538.94000000", "0.25291000"], ["61536.22000000", "0.00111000"], ["61534.79000000", "0.01692000"], ["61532.08000000", "0.00000000"], ["61522.79000000", "0.00034000"], ["61505.97000000", "0.00000000"], ["61504.25000000", "0.12000000"], ["61497.80000000", "0.00000000"], ["61489.01000000", "0.06099000"], ["61486.40000000", "0.09758000"], ["61423.82000000", "0.00000000"], ["61350.00000000", "1.05718000"], ["60677.43000000", "0.00030000"], ["55441.80000000", "0.00020000"], ["55440.00000000", "0.00998000"]], "asks": [["61600.01000000", "0.00000000"], ["61600.02000000", "0.00000000"], ["61600.10000000", "0.00000000"], ["61600.11000000", "0.00000000"], ["61600.64000000", "0.00000000"], ["61601.46000000", "0.00000000"], ["61601.47000000", "0.00000000"], ["61601.90000000", "0.00000000"], ["61601.99000000", "0.00000000"], ["61602.00000000", "0.02572000"], ["61602.01000000", "0.00072000"], ["61602.25000000", "0.00000000"], ["61602.26000000", "0.00000000"], ["61602.56000000", "0.00009000"], ["61602.57000000", "0.00009000"], ["61603.10000000", "0.00000000"], ["61603.85000000", "0.00000000"], ["61604.00000000", "0.02418000"], ["61604.01000000", "0.00000000"], ["61604.08000000", "0.00000000"], ["61604.58000000", "0.00000000"], ["61604.59000000", "0.00018000"], ["61604.88000000", "0.00000000"], ["61604.89000000", "0.00018000"], ["61605.09000000", "0.00000000"], ["61605.34000000", "0.00000000"], ["61606.00000000", "0.02418000"], ["61606.17000000", "0.00000000"], ["61606.20000000", "0.00034000"], ["61606.35000000", "0.00000000"], ["61606.39000000", "0.00000000"], ["61606.48000000", "0.00836000"], ["61607.08000000", "0.00018000"], ["61607.86000000", "0.00000000"], ["61607.87000000", "0.00018000"], ["61607.95000000", "0.00048000"], ["61608.00000000", "0.02418000"], ["61608.06000000", "0.00010000"], ["61608.31000000", "0.00018000"], ["61608.37000000", "0.00000000"], ["61608.38000000", "0.00000000"], ["61608.51000000", "0.00070000"], ["61608.58000000", "0.00000000"], ["61608.59000000", "0.00000000"], ["61608.83000000", "0.01020000"], ["61609.10000000", "0.00000000"], ["61609.11000000", "0.00000000"], ["61609.26000000", "0.00009000"], ["61609.27000000", "0.01610000"], ["61609.28000000", "0.00000000"], ["61609.74000000", "0.00000000"], ["61609.91000000", "0.00000000"], ["61609.99000000", "0.00009000"], ["61610.25000000", "0.00000000"], ["61611.24000000", "0.09104000"], ["61611.29000000", "0.00000000"], ["61611.33000000", "0.00000000"], ["61611.69000000", "0.00000000"], ["61611.93000000", "0.00000000"], ["61612.03000000", "0.01400000"], ["61612.04000000", "0.00000000"], ["61612.12000000", "0.40100000"], ["61612.32000000", "0.02695000"], ["61612.33000000", "0.06010000"], ["61612.36000000", "0.00000000"], ["61612.80000000", "0.00000000"], ["61613.29000000", "0.02000000"], ["61613.52000000", "0.00000000"], ["61613.53000000", "0.00000000"], ["61613.67000000", "0.00400000"], ["61613.91000000", "0.00000000"], ["61613.99000000", "0.00812000"], ["61614.33000000", "0.00323000"], ["61614.42000000", "0.00000000"], ["61615.20000000", "0.09128000"], ["61615.43000000", "0.08000000"], ["61615.51000000", "0.00000000"], ["61615.73000000", "0.00000000"], ["61615.99000000", "0.09104000"], ["61616.24000000", "0.00000000"], ["61616.34000000", "0.00000000"], ["61616.65000000", "0.10102000"], ["61616.86000000", "0.08755000"], ["61617.04000000", "0.00000000"], ["61617.41000000", "0.09104000"], ["61617.42000000", "0.44651000"], ["61617.44000000", "0.00000000"], ["61617.48000000", "0.00000000"], ["61617.93000000", "0.00000000"], ["61618.40000000", "0.08891000"], ["61618.48000000", "1.21167000"], ["61618.49000000", "1.36340000"], ["61618.50000000", "0.00000000"], ["61618.78000000", "0.00400000"], ["61619.94000000", "0.00000000"], ["61620.78000000", "0.00000000"], ["61621.57000000", "0.00010000"], ["61621.81000000", "0.00000000"], ["61621.99000000", "0.42600000"], ["61622.29000000", "0.00000000"], ["61622.66000000", "0.00324000"], ["61624.90000000", "1.51448000"], ["61625.94000000", "0.00400000"], ["61627.45000000", "0.00000000"], ["61631.00000000", "0.00000000"], ["61631.40000000", "0.00009000"], ["61632.74000000", "0.00000000"], ["61633.00000000", "0.01000000"], ["61633.48000000", "0.58467000"], ["61633.99000000", "1.02975000"], ["61635.32000000", "0.28411000"], ["61635.48000000", "0.00009000"], ["61636.62000000", "1.50047000"], ["61638.41000000", "0.00009000"], ["61639.24000000", "0.00000000"], ["61639.55000000", "0.58462000"], ["61640.38000000", "0.00000000"], ["61648.02000000", "0.01692000"], ["61649.25000000", "0.00112000"], ["61652.50000000", "0.00539000"], ["61657.20000000", "0.00400000"], ["61657.61000000", "1.60723000"], ["61659.09000000", "0.00000000"], ["61659.46000000", "0.00846000"], ["61660.09000000", "0.00000000"], ["61662.02000000", "0.00000000"], ["61662.39000000", "0.00000000"], ["61662.91000000", "0.00000000"], ["61669.28000000", "0.97507000"], ["61693.83000000", "0.00009000"], ["61773.78000000", "0.09712000"]]}
{"type": "depth", "ts": 1783008103214, "U": 96863167894, "u": 96863169000, "bids": [["61605.99000000", "6.01935000"], ["61605.98000000", "0.97434000"], ["61605.97000000", "0.00017000"], ["61605.68000000", "0.00000000"], ["61604.88000000", "0.00000000"], ["61604.86000000", "1.53632000"], ["61604.85000000", "0.00009000"], ["61604.84000000", "1.53854000"], ["61604.83000000", "0.00000000"], ["61604.82000000", "0.00000000"], ["61604.77000000", "0.00000000"], ["61604.76000000", "0.00027000"], ["61604.74000000", "0.00018000"], ["61604.58000000", "0.00000000"], ["61604.50000000", "0.16232000"], ["61604.42000000", "0.00000000"], ["61604.40000000", "0.00400000"], ["61604.05000000", "0.00000000"], ["61604.00000000", "0.07509000"], ["61603.99000000", "0.17652000"], ["61603.98000000", "0.04217000"], ["61603.97000000", "0.00000000"], ["61603.80000000", "0.00000000"], ["61603.68000000", "0.00000000"], ["61603.54000000", "0.00000000"], ["61603.25000000", "0.00009000"], ["61603.07000000", "0.00000000"], ["61602.67000000", "0.00000000"], ["61602.57000000", "2.14323000"], ["61602.56000000", "0.07510000"], ["61602.55000000", "0.34977000"], ["61602.54000000", "0.00000000"], ["61602.53000000", "0.00000000"], ["61602.13000000", "0.03000000"], ["61602.01000000", "0.97390000"], ["61602.00000000", "0.32277000"], ["61601.99000000", "0.10062000"], ["61601.98000000", "0.00027000"], ["61601.97000000", "0.00000000"], ["61601.90000000", "0.00009000"], ["61601.76000000", "0.00400000"], ["61601.47000000", "0.38965000"], ["61601.46000000", "0.13009000"], ["61601.45000000", "1.49827000"], ["61601.35000000", "0.00000000"], ["61601.05000000", "0.02000000"], ["61600.67000000", "0.00034000"], ["61600.66000000", "0.00000000"], ["61600.54000000", "0.00000000"], ["61600.51000000", "0.08639000"], ["61600.50000000", "0.24759000"], ["61600.01000000", "0.00000000"], ["61600.00000000", "0.36768000"], ["61599.99000000", "0.00009000"], ["61599.83000000", "0.00010000"], ["61599.74000000", "0.00000000"], ["61598.67000000", "0.00400000"], ["61598.30000000", "0.00009000"], ["61598.04000000", "0.00000000"], ["61598.03000000", "0.00000000"], ["61598.02000000", "0.00009000"], ["61597.83000000", "0.00000000"], ["61597.40000000", "0.00000000"], ["61596.92000000", "0.00009000"], ["61596.87000000", "0.97390000"], ["61596.86000000", "0.15365000"], ["61596.85000000", "1.18369000"], ["61596.38000000", "0.00400000"], ["61596.31000000", "0.00009000"], ["61596.29000000", "0.00000000"], ["61596.27000000", "0.00876000"], ["61596.26000000", "0.00000000"], ["61596.00000000", "0.00071000"], ["61595.83000000", "0.00000000"], ["61595.03000000", "0.00000000"], ["61595.00000000", "0.25000000"], ["61594.52000000", "0.00000000"], ["61594.50000000", "0.00400000"], ["61594.31000000", "0.00009000"], ["61594.09000000", "0.00000000"], ["61594.05000000", "0.00000000"], ["61594.00000000", "0.02219000"], ["61593.31000000", "0.58506000"], ["61591.67000000", "0.00992000"], ["61590.00000000", "0.02896000"], ["61588.59000000", "0.00010000"], ["61587.84000000", "0.25050000"], ["61587.68000000", "0.00009000"], ["61585.51000000", "0.00010000"], ["61585.23000000", "0.00000000"], ["61584.73000000", "0.36504000"], ["61584.60000000", "0.00009000"], ["61583.80000000", "0.00000000"], ["61583.79000000", "0.00059000"], ["61583.47000000", "0.00000000"], ["61582.43000000", "0.00010000"], ["61581.52000000", "0.00171000"], ["61581.40000000", "0.00000000"], ["61579.95000000", "1.60926000"], ["61579.35000000", "0.00010000"], ["61578.44000000", "0.00009000"], ["61578.20000000", "0.00000000"], ["61577.64000000", "0.00000000"], ["61577.15000000", "0.03240000"], ["61576.27000000", "0.00010000"], ["61575.36000000", "0.00409000"], ["61573.95000000", "0.00000000"], ["61573.19000000", "0.00010000"], ["61573.14000000", "0.00000000"], ["61572.40000000", "0.00000000"], ["61572.37000000", "0.00000000"], ["61572.28000000", "0.00009000"], ["61571.00000000", "0.01000000"], ["61570.55000000", "0.00000000"], ["61569.80000000", "0.00000000"], ["61569.20000000", "0.00009000"], ["61569.00000000", "0.00000000"], ["61568.36000000", "0.00000000"], ["61562.19000000", "0.00000000"], ["61555.86000000", "0.00000000"], ["61555.85000000", "0.00000000"], ["61555.02000000", "0.00000000"], ["61554.83000000", "0.00000000"], ["61554.73000000", "0.00000000"], ["61553.24000000", "0.00000000"], ["61542.39000000", "0.00010000"], ["61535.88000000", "0.00000000"], ["61534.99000000", "0.00000000"], ["61507.92000000", "0.00000000"], ["61507.03000000", "0.03795000"], ["61497.67000000", "0.00016000"], ["61493.67000000", "0.00000000"], ["61492.95000000", "0.00000000"], ["61483.51000000", "0.00000000"], ["61480.78000000", "0.00010000"], ["61474.29000000", "0.00000000"], ["61456.98000000", "0.00000000"], ["61427.69000000", "0.00000000"], ["61426.10000000", "0.00000000"], ["61419.18000000", "0.00010000"], ["61412.69000000", "0.00000000"], ["61357.57000000", "0.00029000"], ["61352.47000000", "0.00033000"], ["61350.53000000", "0.00000000"], ["61345.79000000", "0.00000000"], ["61295.97000000", "0.00010000"], ["61295.50000000", "0.00000000"], ["61288.94000000", "0.00000000"], ["61234.37000000", "0.00025000"], ["61227.34000000", "0.00000000"], ["61172.76000000", "0.00010000"], ["61165.74000000", "0.00000000"], ["61111.16000000", "0.00010000"], ["61104.14000000", "0.00000000"], ["59520.00000000", "0.14286000"], ["55445.40000000", "0.00020000"], ["55442.30000000", "0.00000000"], ["55441.80000000", "0.00000000"], ["49280.00000000", "0.02133000"]], "asks": [["61602.00000000", "0.00000000"], ["61602.01000000", "0.00000000"], ["61602.56000000", "0.00000000"], ["61602.57000000", "0.00000000"], ["61603.08000000", "0.00000000"], ["61603.55000000", "0.00000000"], ["61603.69000000", "0.00000000"], ["61603.81000000", "0.00000000"], ["61603.99000000", "0.00000000"], ["61604.00000000", "0.00000000"], ["61604.01000000", "0.00000000"], ["61604.43000000", "0.00000000"], ["61604.59000000", "0.00000000"], ["61604.85000000", "0.00000000"], ["61604.89000000", "0.00000000"], ["61605.69000000", "0.00000000"], ["61605.99000000", "0.00000000"], ["61606.00000000", "0.03738000"], ["61606.01000000", "0.00432000"], ["61606.20000000", "0.00000000"], ["61606.33000000", "0.00000000"], ["61606.34000000", "0.00300000"], ["61606.48000000", "0.00018000"], ["61607.06000000", "0.00000000"], ["61607.08000000", "0.00000000"], ["61607.19000000", "0.00000000"], ["61607.45000000", "0.00000000"], ["61607.82000000", "0.00000000"], ["61607.87000000", "0.00000000"], ["61607.95000000", "0.00000000"], ["61608.00000000", "0.02418000"], ["61608.06000000", "0.00000000"], ["61608.31000000", "0.00000000"], ["61608.34000000", "0.00027000"], ["61608.43000000", "0.00000000"], ["61608.51000000", "0.00000000"], ["61608.82000000", "0.00000000"], ["61608.83000000", "0.00018000"], ["61609.11000000", "0.00000000"], ["61609.27000000", "0.01628000"], ["61609.83000000", "0.00000000"], ["61609.91000000", "0.00000000"], ["61609.92000000", "0.00000000"], ["61610.00000000", "0.02418000"], ["61610.16000000", "0.00000000"], ["61610.17000000", "0.00000000"], ["61611.02000000", "0.00000000"], ["61611.07000000", "0.01250000"], ["61611.13000000", "0.00000000"], ["61611.21000000", "0.00000000"], ["61611.23000000", "0.00000000"], ["61611.24000000", "0.00000000"], ["61611.73000000", "0.00000000"], ["61611.79000000", "0.00000000"], ["61611.80000000", "0.00009000"], ["61611.90000000", "0.00000000"], ["61611.91000000", "0.00000000"], ["61611.92000000", "0.00000000"], ["61611.99000000", "0.00009000"], ["61612.02000000", "0.00009000"], ["61612.04000000", "0.00000000"], ["61612.12000000", "0.00000000"], ["61612.16000000", "0.00010000"], ["61612.17000000", "0.00000000"], ["61612.18000000", "0.00000000"], ["61612.32000000", "0.00009000"], ["61612.33000000", "0.00000000"], ["61612.72000000", "0.00000000"], ["61612.92000000", "0.00000000"], ["61613.29000000", "0.00000000"], ["61613.31000000", "0.00243000"], ["61613.67000000", "0.00000000"], ["61613.88000000", "0.00000000"], ["61613.92000000", "0.08989000"], ["61613.99000000", "0.00009000"], ["61614.33000000", "0.00000000"], ["61614.66000000", "0.00000000"], ["61614.69000000", "0.00009000"], ["61614.70000000", "0.02000000"], ["61614.72000000", "0.00000000"], ["61614.89000000", "0.00000000"], ["61614.97000000", "0.00000000"], ["61615.11000000", "0.00000000"], ["61615.20000000", "0.00024000"], ["61615.24000000", "0.09103000"], ["61615.41000000", "0.00000000"], ["61615.43000000", "0.00000000"], ["61615.99000000", "0.09104000"], ["61616.26000000", "0.00812000"], ["61616.32000000", "0.00019000"], ["61616.64000000", "0.00000000"], ["61616.65000000", "0.00009000"], ["61616.88000000", "0.00000000"], ["61616.97000000", "0.01800000"], ["61617.12000000", "0.01400000"], ["61617.14000000", "0.00000000"], ["61617.26000000", "0.00000000"], ["61617.42000000", "0.00326000"], ["61617.43000000", "0.00000000"], ["61617.58000000", "0.01200000"], ["61617.74000000", "0.01100000"], ["61617.90000000", "0.00000000"], ["61618.13000000", "0.00400000"], ["61618.39000000", "0.09103000"], ["61618.48000000", "0.14110000"], ["61618.49000000", "0.00000000"], ["61618.78000000", "0.00000000"], ["61619.24000000", "0.07000000"], ["61619.40000000", "0.00010000"], ["61619.66000000", "0.00000000"], ["61620.00000000", "0.02400000"], ["61620.05000000", "0.01000000"], ["61620.06000000", "0.00000000"], ["61620.52000000", "0.09103000"], ["61620.64000000", "0.08000000"], ["61620.95000000", "0.00190000"], ["61621.16000000", "0.00000000"], ["61621.17000000", "0.00000000"], ["61621.18000000", "0.00000000"], ["61621.57000000", "0.00000000"], ["61621.84000000", "0.09103000"], ["61621.97000000", "0.09103000"], ["61621.98000000", "0.13905000"], ["61621.99000000", "0.18811000"], ["61622.48000000", "0.00023000"], ["61622.54000000", "0.00012000"], ["61622.66000000", "0.00000000"], ["61622.81000000", "0.00400000"], ["61623.96000000", "0.09103000"], ["61623.97000000", "0.81242000"], ["61623.98000000", "0.00000000"], ["61624.65000000", "0.00000000"], ["61624.87000000", "1.06260000"], ["61624.88000000", "2.33720000"], ["61624.89000000", "0.01000000"], ["61624.90000000", "0.00000000"], ["61625.56000000", "0.00010000"], ["61625.94000000", "0.00000000"], ["61626.30000000", "0.00158000"], ["61626.58000000", "0.00000000"], ["61626.83000000", "0.00000000"], ["61627.56000000", "0.00059000"], ["61627.73000000", "0.00000000"], ["61628.64000000", "0.00010000"], ["61629.61000000", "1.36330000"], ["61629.62000000", "0.00009000"], ["61629.69000000", "0.97390000"], ["61629.70000000", "0.00009000"], ["61630.47000000", "0.00400000"], ["61630.81000000", "0.91285000"], ["61631.72000000", "0.00010000"], ["61632.72000000", "1.36330000"], ["61632.73000000", "0.00000000"], ["61632.90000000", "0.00000000"], ["61633.00000000", "0.00000000"], ["61633.23000000", "0.00000000"], ["61633.93000000", "0.97390000"], ["61633.94000000", "0.00000000"], ["61633.99000000", "0.00000000"], ["61634.00000000", "0.20409000"], ["61634.35000000", "0.00009000"], ["61634.80000000", "0.00010000"], ["61635.00000000", "0.00000000"], ["61635.30000000", "0.00000000"], ["61636.00000000", "0.02400000"], ["61636.62000000", "0.00000000"], ["61636.76000000", "0.00000000"], ["61637.00000000", "0.01000000"], ["61637.03000000", "0.00000000"], ["61637.45000000", "1.36330000"], ["61637.46000000", "0.00000000"], ["61637.83000000", "0.00000000"], ["61637.85000000", "0.00000000"], ["61638.64000000", "0.00000000"], ["61639.47000000", "0.97390000"], ["61639.48000000", "0.00000000"], ["61639.57000000", "0.00000000"], ["61640.59000000", "0.00000000"], ["61641.34000000", "0.00009000"], ["61641.65000000", "0.00000000"], ["61643.22000000", "1.36330000"], ["61643.23000000", "1.02426000"], ["61643.26000000", "0.00000000"], ["61644.27000000", "0.00009000"], ["61644.38000000", "0.00000000"], ["61644.72000000", "0.58457000"], ["61644.88000000", "0.00024000"], ["61646.71000000", "0.00009000"], ["61647.18000000", "0.00000000"], ["61648.77000000", "0.00000000"], ["61651.10000000", "0.00404000"], ["61651.92000000", "0.00400000"], ["61658.11000000", "0.00000000"], ["61659.20000000", "0.01800000"], ["61659.25000000", "0.01400000"], ["61659.81000000", "0.01200000"], ["61659.87000000", "0.01100000"], ["61662.28000000", "0.01000000"], ["61662.95000000", "0.01200000"], ["61663.08000000", "0.00000000"], ["61663.42000000", "0.00000000"], ["61665.11000000", "0.00000000"], ["61665.60000000", "0.00010000"], ["61667.51000000", "0.00000000"], ["61667.99000000", "2.83415000"], ["61668.11000000", "0.00000000"], ["61668.47000000", "0.13780000"], ["61669.28000000", "0.00000000"], ["61670.55000000", "4.86939000"], ["61674.88000000", "1.36330000"], ["61682.28000000", "1.36330000"], ["61686.34000000", "0.00000000"], ["61689.57000000", "0.00000000"], ["61693.87000000", "0.00000000"], ["61695.06000000", "0.00000000"], ["61701.06000000", "0.00000000"], ["61710.00000000", "0.02419000"], ["61719.70000000", "0.00000000"], ["61727.21000000", "0.00010000"], ["61730.93000000", "0.02543000"], ["61773.36000000", "0.00009000"], ["61776.43000000", "0.00009000"], ["61781.30000000", "0.00000000"], ["61784.14000000", "0.24780000"], ["61788.81000000", "0.00010000"], ["61842.90000000", "0.00000000"], ["61850.42000000", "0.00010000"], ["61852.77000000", "4.85505000"], ["61904.49000000", "0.00000000"], ["61912.02000000", "0.00010000"], ["61966.09000000", "0.00000000"], ["61973.62000000", "0.00010000"], ["62027.69000000", "0.00000000"], ["62035.23000000", "0.00010000"], ["62089.28000000", "0.00000000"], ["62096.83000000", "0.00010000"]]}
