{"type": "depth", "ts": 1783008115114, "U": 96863180625, "u": 96863181991, "bids": [["61617.99000000", "4.25427000"], ["61617.98000000", "0.00035000"], ["61617.97000000", "0.00017000"], ["61617.90000000", "0.00009000"], ["61617.40000000", "0.00000000"], ["61617.26000000", "2.51789000"], ["61617.25000000", "0.15392000"], ["61617.24000000", "0.00000000"], ["61617.23000000", "0.00000000"], ["61617.18000000", "0.00000000"], ["61617.08000000", "0.00000000"], ["61616.94000000", "0.00000000"], ["61616.91000000", "0.46456000"], ["61616.90000000", "1.44366000"], ["61616.89000000", "0.00000000"], ["61616.88000000", "0.00000000"], ["61616.87000000", "0.00000000"], ["61616.86000000", "0.00000000"], ["61616.85000000", "0.08036000"], ["61616.65000000", "0.00018000"], ["61616.59000000", "0.00000000"], ["61616.33000000", "0.00009000"], ["61616.31000000", "0.00009000"], ["61616.15000000", "0.00000000"], ["61616.05000000", "0.16229000"], ["61615.99000000", "0.00009000"], ["61615.80000000", "0.08775000"], ["61614.97000000", "0.00043000"], ["61614.81000000", "0.00009000"], ["61614.74000000", "0.00000000"], ["61614.72000000", "0.00010000"], ["61614.36000000", "0.02000000"], ["61614.29000000", "0.00009000"], ["61613.99000000", "0.00009000"], ["61613.70000000", "0.00009000"], ["61613.69000000", "0.00000000"], ["61613.48000000", "0.00009000"], ["61613.31000000", "0.00000000"], ["61613.28000000", "0.00000000"], ["61613.27000000", "0.00000000"], ["61613.17000000", "0.00009000"], ["61612.98000000", "0.00409000"], ["61612.96000000", "0.00000000"], ["61612.86000000", "0.00000000"], ["61612.62000000", "0.00000000"], ["61612.46000000", "0.00009000"], ["61612.26000000", "0.00000000"], ["61612.04000000", "0.00009000"], ["61611.99000000", "0.00009000"], ["61611.98000000", "0.00000000"], ["61611.94000000", "0.00000000"], ["61611.93000000", "0.00000000"], ["61611.68000000", "0.00000000"], ["61611.50000000", "0.00000000"], ["61611.46000000", "0.00000000"], ["61611.28000000", "0.00000000"], ["61611.20000000", "0.00000000"], ["61611.16000000", "0.00000000"], ["61611.15000000", "0.00000000"], ["61611.09000000", "0.03258000"], ["61611.08000000", "0.00009000"], ["61611.07000000", "0.00000000"], ["61610.87000000", "0.00009000"], ["61610.86000000", "3.68569000"], ["61610.85000000", "0.00000000"], ["61610.84000000", "0.00000000"], ["61610.75000000", "0.07509000"], ["61610.74000000", "2.83318000"], ["61610.40000000", "0.00400000"], ["61610.08000000", "0.97399000"], ["61610.07000000", "0.00018000"], ["61610.01000000", "0.00000000"], ["61610.00000000", "0.00018000"], ["61609.99000000", "0.00000000"], ["61609.63000000", "0.00000000"], ["61609.24000000", "0.00009000"], ["61609.12000000", "0.04118000"], ["61609.11000000", "0.00009000"], ["61609.10000000", "0.02158000"], ["61609.09000000", "0.00000000"], ["61609.08000000", "0.00000000"], ["61608.66000000", "0.00000000"], ["61608.64000000", "0.00010000"], ["61608.38000000", "0.00013000"], ["61608.31000000", "0.00153000"], ["61607.82000000", "0.00400000"], ["61607.79000000", "0.00000000"], ["61607.78000000", "0.00018000"], ["61607.77000000", "0.00000000"], ["61607.50000000", "0.04217000"], ["61607.49000000", "0.00034000"], ["61607.46000000", "0.00009000"], ["61607.44000000", "0.00024000"], ["61606.83000000", "0.15000000"], ["61606.60000000", "0.01336000"], ["61606.44000000", "0.00009000"], ["61606.27000000", "0.00009000"], ["61606.06000000", "0.00000000"], ["61606.00000000", "0.01909000"], ["61605.94000000", "0.00000000"], ["61605.36000000", "0.00000000"], ["61605.20000000", "0.00000000"], ["61605.19000000", "0.64863000"], ["61605.18000000", "1.36818000"], ["61605.17000000", "0.00000000"], ["61605.12000000", "0.00000000"], ["61605.11000000", "0.00000000"], ["61605.05000000", "0.00000000"], ["61604.84000000", "0.00000000"], ["61604.58000000", "0.00000000"], ["61604.53000000", "0.00010000"], ["61604.49000000", "0.00000000"], ["61604.13000000", "0.00400000"], ["61603.93000000", "0.58495000"], ["61603.87000000", "0.08733000"], ["61603.80000000", "0.00400000"], ["61603.79000000", "0.00000000"], ["61602.94000000", "0.00000000"], ["61602.50000000", "0.01015000"], ["61602.46000000", "0.00000000"], ["61602.33000000", "0.08894000"], ["61602.23000000", "0.00000000"], ["61601.51000000", "0.00000000"], ["61601.45000000", "0.00010000"], ["61601.41000000", "0.00894000"], ["61601.29000000", "0.00000000"], ["61599.84000000", "0.00000000"], ["61599.74000000", "0.00000000"], ["61599.53000000", "0.00000000"], ["61598.36000000", "0.00010000"], ["61597.68000000", "0.00000000"], ["61596.45000000", "0.00000000"], ["61596.12000000", "0.00000000"], ["61595.28000000", "0.00010000"], ["61594.91000000", "0.00000000"], ["61594.81000000", "0.00162000"], ["61594.60000000", "0.00000000"], ["61593.23000000", "0.00000000"], ["61592.79000000", "0.00000000"], ["61592.20000000", "0.00010000"], ["61591.52000000", "0.00000000"], ["61589.96000000", "0.61738000"], ["61589.88000000", "0.00000000"], ["61589.78000000", "0.00000000"], ["61589.60000000", "0.00000000"], ["61589.32000000", "0.00000000"], ["61589.12000000", "1.36340000"], ["61588.75000000", "0.00000000"], ["61588.44000000", "0.00000000"], ["61587.15000000", "0.00000000"], ["61586.92000000", "1.60908000"], ["61586.48000000", "0.00419000"], ["61586.20000000", "0.00400000"], ["61586.04000000", "0.00010000"], ["61585.67000000", "0.00000000"], ["61585.36000000", "0.00000000"], ["61584.20000000", "0.00000000"], ["61583.07000000", "0.00000000"], ["61582.74000000", "0.00000000"], ["61582.28000000", "0.00000000"], ["61581.63000000", "0.00000000"], ["61581.52000000", "0.00009000"], ["61581.25000000", "0.00000000"], ["61580.48000000", "0.00009000"], ["61579.83000000", "0.00000000"], ["61579.81000000", "0.00000000"], ["61579.62000000", "1.60927000"], ["61579.20000000", "0.00000000"], ["61579.03000000", "0.00000000"], ["61578.82000000", "0.00400000"], ["61578.30000000", "0.00000000"], ["61577.33000000", "0.00000000"], ["61572.72000000", "0.00000000"], ["61570.08000000", "0.00000000"], ["61568.85000000", "0.00000000"], ["61567.61000000", "0.00000000"], ["61567.35000000", "0.13674000"], ["61566.54000000", "0.00000000"], ["61559.33000000", "0.00403000"], ["61559.32000000", "0.00000000"], ["61557.58000000", "0.00000000"], ["61555.85000000", "0.53135000"], ["61555.63000000", "0.00010000"], ["61555.01000000", "0.97494000"], ["61554.88000000", "0.00000000"], ["61549.45000000", "0.00000000"], ["61549.26000000", "0.00000000"], ["61541.07000000", "0.00000000"], ["61534.74000000", "0.25850000"], ["61533.80000000", "0.00000000"], ["61520.98000000", "0.00000000"], ["61513.48000000", "0.00000000"], ["61494.02000000", "0.00010000"], ["61488.57000000", "0.00000000"], ["61487.65000000", "0.00000000"], ["61470.08000000", "0.21803000"], ["61453.72000000", "0.00000000"], ["61445.15000000", "0.00000000"], ["61442.87000000", "0.00969000"], ["61432.40000000", "0.00010000"], ["61426.04000000", "0.00000000"], ["61421.98000000", "0.04094000"], ["61420.75000000", "0.00000000"], ["61388.72000000", "0.00000000"], ["61370.78000000", "0.00019000"], ["61364.43000000", "0.00000000"], ["61353.79000000", "0.00000000"], ["61309.16000000", "0.00010000"], ["61302.82000000", "0.00000000"], ["61247.55000000", "0.00010000"], ["61241.20000000", "0.00000000"], ["61185.93000000", "0.00010000"], ["61179.59000000", "0.00000000"], ["61124.31000000", "0.00010000"], ["61117.98000000", "0.00000000"], ["61002.49000000", "0.00000000"], ["60749.68000000", "0.00000000"], ["60704.04000000", "1.70578000"], ["60684.96000000", "0.00000000"], ["55455.21000000", "0.00000000"], ["55448.19000000", "0.00010000"]], "asks": [["61609.11000000", "0.00000000"], ["61609.12000000", "0.00000000"], ["61609.13000000", "0.00000000"], ["61610.00000000", "0.00000000"], ["61610.01000000", "0.00000000"], ["61610.08000000", "0.00000000"], ["61610.56000000", "0.00000000"], ["61610.75000000", "0.00000000"], ["61610.76000000", "0.00000000"], ["61610.87000000", "0.00000000"], ["61610.88000000", "0.00000000"], ["61611.16000000", "0.00000000"], ["61611.17000000", "0.00000000"], ["61611.22000000", "0.00000000"], ["61611.29000000", "0.00000000"], ["61611.47000000", "0.00000000"], ["61611.93000000", "0.00000000"], ["61611.94000000", "0.00000000"], ["61611.95000000", "0.00000000"], ["61611.99000000", "0.00000000"], ["61612.00000000", "0.00000000"], ["61612.07000000", "0.00000000"], ["61612.32000000", "0.00000000"], ["61612.46000000", "0.00000000"], ["61612.47000000", "0.00000000"], ["61612.62000000", "0.00000000"], ["61612.63000000", "0.00000000"], ["61612.98000000", "0.00000000"], ["61612.99000000", "0.00000000"], ["61613.18000000", "0.00000000"], ["61613.29000000", "0.00000000"], ["61613.32000000", "0.00000000"], ["61613.49000000", "0.00000000"], ["61613.70000000", "0.00000000"], ["61613.99000000", "0.00000000"], ["61614.00000000", "0.00000000"], ["61614.30000000", "0.00000000"], ["61614.32000000", "0.00000000"], ["61614.81000000", "0.00000000"], ["61614.82000000", "0.00000000"], ["61614.97000000", "0.00000000"], ["61615.27000000", "0.00000000"], ["61615.28000000", "0.00000000"], ["61615.40000000", "0.00000000"], ["61615.56000000", "0.00000000"], ["61615.99000000", "0.00000000"], ["61616.00000000", "0.00000000"], ["61616.27000000", "0.00000000"], ["61616.32000000", "0.00000000"], ["61616.33000000", "0.00000000"], ["61616.34000000", "0.00000000"], ["61616.35000000", "0.00000000"], ["61616.47000000", "0.00000000"], ["61616.51000000", "0.00000000"], ["61616.60000000", "0.00000000"], ["61616.65000000", "0.00000000"], ["61616.66000000", "0.00000000"], ["61616.91000000", "0.00000000"], ["61616.92000000", "0.00000000"], ["61616.95000000", "0.00000000"], ["61617.09000000", "0.00000000"], ["61617.19000000", "0.00000000"], ["61617.26000000", "0.00000000"], ["61617.41000000", "0.00000000"], ["61617.42000000", "0.00000000"], ["61617.60000000", "0.00000000"], ["61617.86000000", "0.00000000"], ["61617.90000000", "0.00000000"], ["61617.99000000", "0.00000000"], ["61618.00000000", "0.04408000"], ["61618.01000000", "0.00098000"], ["61618.41000000", "0.00000000"], ["61618.48000000", "0.00009000"], ["61618.49000000", "0.00009000"], ["61618.55000000", "0.00009000"], ["61618.57000000", "0.00499000"], ["61618.58000000", "0.00009000"], ["61618.59000000", "0.00009000"], ["61618.67000000", "0.00009000"], ["61618.68000000", "0.00000000"], ["61619.11000000", "0.00000000"], ["61619.12000000", "0.00000000"], ["61619.17000000", "0.00000000"], ["61619.70000000", "0.00000000"], ["61619.74000000", "0.00000000"], ["61619.75000000", "0.00000000"], ["61619.82000000", "0.00000000"], ["61619.99000000", "0.00009000"], ["61620.24000000", "0.00000000"], ["61620.32000000", "0.00000000"], ["61620.42000000", "0.01297000"], ["61620.43000000", "0.00009000"], ["61620.44000000", "0.00000000"], ["61620.61000000", "0.00000000"], ["61620.79000000", "0.00009000"], ["61620.80000000", "0.00009000"], ["61620.83000000", "0.00000000"], ["61621.05000000", "0.00000000"], ["61621.12000000", "0.00000000"], ["61621.13000000", "0.00000000"], ["61621.14000000", "0.00000000"], ["61621.22000000", "0.00694000"], ["61621.44000000", "0.00000000"], ["61621.63000000", "0.00000000"], ["61621.72000000", "0.00000000"], ["61621.73000000", "0.00000000"], ["61621.80000000", "0.00000000"], ["61621.99000000", "0.00009000"], ["61622.33000000", "0.00000000"], ["61622.53000000", "0.00030000"], ["61622.65000000", "0.00009000"], ["61622.68000000", "0.00000000"], ["61623.08000000", "0.00977000"], ["61623.25000000", "0.00019000"], ["61623.71000000", "0.00009000"], ["61623.72000000", "0.00000000"], ["61623.76000000", "0.00000000"], ["61623.99000000", "0.00000000"], ["61624.05000000", "0.00000000"], ["61624.27000000", "0.00000000"], ["61624.67000000", "0.00000000"], ["61624.94000000", "0.00000000"], ["61624.97000000", "0.12000000"], ["61625.06000000", "0.00000000"], ["61625.41000000", "0.00000000"], ["61625.81000000", "0.00000000"], ["61625.98000000", "0.00000000"], ["61626.19000000", "0.02000000"], ["61626.53000000", "0.00166000"], ["61626.69000000", "0.00000000"], ["61627.04000000", "0.00000000"], ["61627.05000000", "0.00000000"], ["61627.50000000", "0.00000000"], ["61627.68000000", "0.00000000"], ["61627.87000000", "0.00000000"], ["61628.14000000", "0.00000000"], ["61628.40000000", "0.00009000"], ["61628.49000000", "0.00000000"], ["61628.96000000", "0.00000000"], ["61629.21000000", "0.08729000"], ["61629.22000000", "0.00000000"], ["61629.23000000", "0.00009000"], ["61629.25000000", "0.00972000"], ["61629.31000000", "0.00000000"], ["61629.41000000", "0.00010000"], ["61629.60000000", "0.00000000"], ["61629.62000000", "0.00000000"], ["61630.06000000", "0.00000000"], ["61630.07000000", "0.00000000"], ["61630.33000000", "0.00326000"], ["61630.75000000", "0.08890000"], ["61630.86000000", "0.02594000"], ["61631.19000000", "0.00000000"], ["61631.20000000", "0.00000000"], ["61631.21000000", "0.00000000"], ["61631.57000000", "0.00000000"], ["61632.06000000", "0.00400000"], ["61632.14000000", "0.00000000"], ["61632.49000000", "0.00010000"], ["61632.55000000", "0.00000000"], ["61632.72000000", "0.00000000"], ["61633.89000000", "0.00000000"], ["61633.91000000", "0.00000000"], ["61633.92000000", "0.28120000"], ["61633.93000000", "0.00000000"], ["61634.05000000", "0.00400000"], ["61634.12000000", "0.00000000"], ["61634.65000000", "0.00000000"], ["61635.32000000", "0.00000000"], ["61635.42000000", "0.01003000"], ["61635.58000000", "0.00010000"], ["61636.98000000", "0.00000000"], ["61636.99000000", "0.00000000"], ["61637.16000000", "0.00000000"], ["61637.43000000", "0.00000000"], ["61637.44000000", "0.00000000"], ["61637.45000000", "0.00000000"], ["61637.73000000", "0.00000000"], ["61638.64000000", "0.00400000"], ["61638.66000000", "0.00010000"], ["61638.90000000", "0.00000000"], ["61639.47000000", "0.00000000"], ["61640.00000000", "0.02400000"], ["61640.09000000", "0.00000000"], ["61640.25000000", "0.00009000"], ["61640.78000000", "1.01189000"], ["61640.79000000", "0.00000000"], ["61640.80000000", "0.00000000"], ["61640.81000000", "0.00000000"], ["61640.82000000", "0.00000000"], ["61641.34000000", "0.00009000"], ["61641.59000000", "0.01004000"], ["61641.74000000", "0.00010000"], ["61642.00000000", "0.02400000"], ["61642.18000000", "0.00000000"], ["61643.20000000", "0.00009000"], ["61643.21000000", "0.97390000"], ["61643.22000000", "0.00000000"], ["61643.23000000", "0.00000000"], ["61643.24000000", "0.00000000"], ["61643.63000000", "0.58458000"], ["61644.27000000", "0.00009000"], ["61644.82000000", "0.00010000"], ["61644.83000000", "0.00000000"], ["61644.84000000", "0.00000000"], ["61644.88000000", "0.04710000"], ["61644.92000000", "0.00000000"], ["61645.66000000", "0.00000000"], ["61646.15000000", "0.00009000"], ["61646.51000000", "0.00000000"], ["61647.20000000", "0.00009000"], ["61647.53000000", "0.98390000"], ["61647.69000000", "0.00000000"], ["61647.70000000", "0.00000000"], ["61647.74000000", "0.00000000"], ["61647.90000000", "0.00010000"], ["61648.31000000", "0.58453000"], ["61649.00000000", "0.01111000"], ["61649.37000000", "0.00024000"], ["61649.89000000", "0.29542000"], ["61650.28000000", "0.00000000"], ["61650.32000000", "0.00000000"], ["61650.69000000", "0.00000000"], ["61651.68000000", "0.00400000"], ["61651.99000000", "1.36330000"], ["61652.00000000", "0.02400000"], ["61652.78000000", "0.00000000"], ["61652.79000000", "0.97390000"], ["61653.59000000", "0.00230000"], ["61656.68000000", "0.00024000"], ["61657.60000000", "0.00000000"], ["61661.02000000", "0.00024000"], ["61661.62000000", "1.73581000"], ["61661.73000000", "0.01622000"], ["61662.00000000", "0.02800000"], ["61662.08000000", "0.01622000"], ["61662.16000000", "0.01622000"], ["61663.45000000", "0.00000000"], ["61663.99000000", "0.00404000"], ["61664.44000000", "1.60706000"], ["61670.00000000", "0.02400000"], ["61670.11000000", "1.36330000"], ["61672.49000000", "0.00000000"], ["61673.52000000", "0.00000000"], ["61673.98000000", "0.00000000"], ["61674.53000000", "0.97494000"], ["61674.74000000", "0.00000000"], ["61675.26000000", "0.00000000"], ["61675.62000000", "0.13381000"], ["61677.60000000", "1.60671000"], ["61678.71000000", "0.00010000"], ["61687.99000000", "0.00000000"], ["61689.67000000", "0.42945000"], ["61689.68000000", "1.36330000"], ["61689.99000000", "0.00000000"], ["61697.08000000", "1.36330000"], ["61699.97000000", "0.98380000"], ["61699.98000000", "0.97390000"], ["61699.99000000", "0.00000000"], ["61701.36000000", "0.00009000"], ["61704.48000000", "1.36330000"], ["61707.38000000", "0.97390000"], ["61715.76000000", "1.58601000"], ["61716.33000000", "0.00000000"], ["61725.15000000", "0.00162000"], ["61734.10000000", "0.00000000"], ["61740.32000000", "0.00010000"], ["61790.31000000", "0.24750000"], ["61795.71000000", "0.00000000"], ["61801.94000000", "0.00010000"], ["61857.32000000", "0.00000000"], ["61863.56000000", "0.00010000"], ["61918.93000000", "0.00000000"], ["61925.18000000", "0.00010000"], ["61980.55000000", "0.00000000"], ["61986.79000000", "0.00010000"], ["62042.16000000", "0.00000000"], ["62048.41000000", "0.00010000"], ["62103.77000000", "0.00000000"], ["62110.03000000", "0.00010000"], ["62533.25000000", "0.00000000"]]}
{"type": "depth", "ts": 1783008115215, "U": 96863181992, "u": 96863182458, "bids": [["61617.99000000", "5.40996000"], ["61617.28000000", "1.00418000"], ["61617.27000000", "1.36834000"], ["61617.26000000", "0.07518000"], ["61617.25000000", "0.15401000"], ["61616.91000000", "0.07518000"], ["61616.85000000", "0.08054000"], ["61616.49000000", "0.16229000"], ["61616.05000000", "0.00027000"], ["61615.80000000", "0.00027000"], ["61615.56000000", "0.00400000"], ["61615.29000000", "0.00153000"], ["61614.00000000", "0.00000000"], ["61612.76000000", "0.00893000"], ["61612.16000000", "0.01013000"], ["61610.92000000", "0.00894000"], ["61610.87000000", "0.91537000"], ["61610.86000000", "1.12773000"], ["61610.74000000", "1.85910000"], ["61610.08000000", "0.00009000"], ["61610.07000000", "0.00000000"], ["61610.00000000", "0.00000000"], ["61609.12000000", "0.23796000"], ["61609.10000000", "0.00000000"], ["61608.31000000", "0.00000000"], ["61608.07000000", "0.00914000"], ["61607.78000000", "0.00000000"], ["61607.59000000", "0.58492000"], ["61607.21000000", "0.00009000"], ["61607.18000000", "0.01003000"], ["61606.60000000", "0.01300000"], ["61606.48000000", "0.00000000"], ["61606.44000000", "0.00000000"], ["61606.37000000", "0.00871000"], ["61606.15000000", "0.00000000"], ["61606.00000000", "0.01900000"], ["61605.99000000", "0.00000000"], ["61604.13000000", "0.00409000"], ["61603.28000000", "0.00901000"], ["61601.64000000", "0.00000000"], ["61599.37000000", "0.00000000"], ["61597.80000000", "0.00000000"], ["61596.99000000", "0.36300000"], ["61596.96000000", "0.00324000"], ["61596.24000000", "0.00000000"], ["61595.50000000", "0.00000000"], ["61594.64000000", "0.00000000"], ["61594.09000000", "0.00012000"], ["61593.67000000", "0.58505000"], ["61593.20000000", "1.19951000"], ["61593.19000000", "1.60891000"], ["61592.92000000", "0.00000000"], ["61592.85000000", "0.00191000"], ["61591.65000000", "0.00000000"], ["61589.55000000", "0.03191000"], ["61587.17000000", "1.10970000"], ["61587.14000000", "0.00000000"], ["61587.00000000", "0.01000000"], ["61583.83000000", "0.00000000"], ["61583.79000000", "0.00000000"], ["61582.06000000", "0.00000000"], ["61581.47000000", "0.00000000"], ["61579.00000000", "0.00000000"], ["61578.00000000", "0.02400000"], ["61576.68000000", "0.00432000"], ["61576.55000000", "0.00623000"], ["61575.36000000", "0.00009000"], ["61574.71000000", "0.02477000"], ["61574.21000000", "0.00426000"], ["61574.05000000", "0.00000000"], ["61568.83000000", "0.00434000"], ["61567.84000000", "1.50215000"], ["61567.13000000", "0.00000000"], ["61566.15000000", "0.35656000"], ["61565.92000000", "0.00000000"], ["61565.69000000", "0.97494000"], ["61565.56000000", "0.00000000"], ["61563.94000000", "0.00000000"], ["61560.98000000", "0.00405000"], ["61559.33000000", "0.00000000"], ["61558.01000000", "0.00401000"], ["61557.62000000", "0.01154000"], ["61557.59000000", "0.07391000"], ["61557.01000000", "0.00529000"], ["61555.85000000", "0.53135000"], ["61555.01000000", "0.00000000"], ["61554.33000000", "0.00000000"], ["61549.59000000", "0.00109000"], ["61549.21000000", "0.01716000"], ["61547.90000000", "0.00000000"], ["61542.31000000", "0.00000000"], ["61538.94000000", "0.24750000"], ["61537.42000000", "0.00000000"], ["61536.22000000", "0.00000000"], ["61534.79000000", "0.00000000"], ["61499.01000000", "0.00162000"], ["61497.13000000", "0.00162000"], ["61496.96000000", "0.00000000"], ["61492.10000000", "0.00000000"], ["61486.43000000", "0.09326000"], ["61473.48000000", "0.00000000"], ["61454.04000000", "0.00000000"], ["61445.94000000", "0.00000000"], ["61442.86000000", "4.88768000"], ["61441.24000000", "0.00000000"], ["61439.69000000", "0.00000000"], ["61351.27000000", "0.00000000"], ["56682.01000000", "0.00018000"], ["55456.20000000", "0.00020000"], ["49287.28000000", "0.00000000"], ["48000.00000000", "406.83585000"], ["45000.00000000", "269.95308000"], ["41000.00000000", "66.61738000"]], "asks": [["61618.00000000", "0.03435000"], ["61618.01000000", "0.00116000"], ["61618.02000000", "0.00905000"], ["61618.49000000", "0.00000000"], ["61618.58000000", "0.00000000"], ["61618.59000000", "0.00000000"], ["61618.67000000", "0.00000000"], ["61619.43000000", "0.00000000"], ["61619.44000000", "0.00018000"], ["61620.00000000", "0.02418000"], ["61620.26000000", "0.00843000"], ["61620.41000000", "0.00000000"], ["61620.42000000", "0.00018000"], ["61620.43000000", "0.00000000"], ["61620.79000000", "0.00000000"], ["61620.80000000", "0.00000000"], ["61620.95000000", "0.00000000"], ["61621.22000000", "0.00018000"], ["61621.67000000", "0.00000000"], ["61622.00000000", "0.02418000"], ["61622.36000000", "0.00000000"], ["61622.48000000", "0.00000000"], ["61622.54000000", "0.00000000"], ["61622.65000000", "0.00000000"], ["61622.66000000", "0.00018000"], ["61622.70000000", "0.00000000"], ["61622.71000000", "0.00000000"], ["61622.88000000", "0.00000000"], ["61623.02000000", "0.00009000"], ["61623.03000000", "0.01328000"], ["61623.08000000", "0.00000000"], ["61623.25000000", "0.00010000"], ["61623.26000000", "0.00000000"], ["61623.27000000", "0.00000000"], ["61623.28000000", "0.00000000"], ["61623.33000000", "0.00000000"], ["61623.40000000", "0.00989000"], ["61623.66000000", "0.00000000"], ["61623.71000000", "0.00000000"], ["61623.99000000", "0.00009000"], ["61624.69000000", "0.00009000"], ["61624.70000000", "0.09214000"], ["61624.76000000", "0.00907000"], ["61624.89000000", "0.00000000"], ["61624.94000000", "0.00009000"], ["61624.95000000", "0.09214000"], ["61624.97000000", "0.00000000"], ["61625.74000000", "0.00000000"], ["61626.11000000", "0.00000000"], ["61626.41000000", "0.00000000"], ["61626.53000000", "0.00000000"], ["61626.55000000", "0.00034000"], ["61626.58000000", "0.00000000"], ["61626.65000000", "0.00000000"], ["61627.56000000", "0.00000000"], ["61627.78000000", "0.00000000"], ["61627.85000000", "0.00903000"], ["61628.27000000", "0.00048000"], ["61628.77000000", "0.15000000"], ["61629.14000000", "0.00812000"], ["61629.15000000", "0.01800000"], ["61629.20000000", "0.00000000"], ["61629.21000000", "0.10129000"], ["61629.40000000", "0.00812000"], ["61629.77000000", "0.01200000"], ["61629.81000000", "0.00000000"], ["61629.82000000", "0.01100000"], ["61630.23000000", "0.00187000"], ["61630.86000000", "0.06649000"], ["61630.87000000", "0.00000000"], ["61630.94000000", "0.00910000"], ["61631.40000000", "0.09214000"], ["61632.06000000", "0.00000000"], ["61632.24000000", "0.01000000"], ["61632.74000000", "0.09205000"], ["61632.90000000", "0.01200000"], ["61633.33000000", "0.00000000"], ["61633.76000000", "0.00166000"], ["61633.91000000", "0.09205000"], ["61633.92000000", "0.18530000"], ["61634.03000000", "0.00896000"], ["61634.58000000", "0.00400000"], ["61635.41000000", "0.09205000"], ["61635.48000000", "0.00000000"], ["61635.52000000", "0.00000000"], ["61635.82000000", "0.00000000"], ["61636.05000000", "0.00000000"], ["61636.06000000", "0.00190000"], ["61636.76000000", "0.09205000"], ["61636.96000000", "0.09214000"], ["61636.97000000", "1.22086000"], ["61636.98000000", "1.36330000"], ["61637.15000000", "0.00000000"], ["61637.66000000", "0.00012000"], ["61638.10000000", "0.00000000"], ["61638.41000000", "0.00000000"], ["61638.64000000", "0.00000000"], ["61639.44000000", "0.00000000"], ["61639.45000000", "0.00000000"], ["61639.46000000", "2.33720000"], ["61640.77000000", "0.00000000"], ["61640.78000000", "0.52396000"], ["61640.79000000", "0.38956000"], ["61641.34000000", "0.00009000"], ["61641.65000000", "0.00000000"], ["61641.66000000", "0.00000000"], ["61642.02000000", "0.00059000"], ["61642.41000000", "0.00400000"], ["61642.76000000", "1.36330000"], ["61643.20000000", "0.93529000"], ["61644.74000000", "0.00000000"], ["61645.65000000", "1.36330000"], ["61646.57000000", "0.00000000"], ["61646.85000000", "0.00000000"], ["61646.94000000", "0.00000000"], ["61647.14000000", "0.59487000"], ["61647.68000000", "0.00000000"], ["61647.92000000", "0.00431000"], ["61648.23000000", "0.01151000"], ["61649.00000000", "0.01000000"], ["61649.65000000", "1.50015000"], ["61649.81000000", "0.86429000"], ["61650.01000000", "0.00615000"], ["61650.13000000", "0.00009000"], ["61650.29000000", "0.00000000"], ["61652.16000000", "0.00000000"], ["61652.47000000", "0.00000000"], ["61652.78000000", "0.94779000"], ["61653.06000000", "0.00009000"], ["61653.56000000", "0.00847000"], ["61653.59000000", "0.00000000"], ["61655.11000000", "1.36330000"], ["61655.48000000", "0.01130000"], ["61655.99000000", "0.00000000"], ["61658.27000000", "0.00435000"], ["61659.01000000", "0.00434000"], ["61660.92000000", "0.00000000"], ["61662.40000000", "0.01716000"], ["61662.87000000", "0.00109000"], ["61663.99000000", "0.00000000"], ["61664.12000000", "0.00000000"], ["61664.99000000", "0.00404000"], ["61665.17000000", "0.00537000"], ["61667.16000000", "0.00400000"], ["61667.99000000", "0.45126000"], ["61668.96000000", "0.00000000"], ["61669.74000000", "0.00400000"], ["61669.99000000", "0.00380000"], ["61670.12000000", "0.00000000"], ["61670.55000000", "0.00000000"], ["61671.40000000", "0.09182000"], ["61674.53000000", "0.00000000"], ["61674.62000000", "0.01800000"], ["61674.67000000", "0.01400000"], ["61675.23000000", "0.01200000"], ["61675.29000000", "0.01100000"], ["61675.62000000", "0.00000000"], ["61676.18000000", "0.00000000"], ["61676.30000000", "0.13776000"], ["61677.09000000", "1.82063000"], ["61677.70000000", "0.01000000"], ["61678.37000000", "0.01213000"], ["61682.71000000", "0.00230000"], ["61684.19000000", "0.71737000"], ["61685.05000000", "0.04593000"], ["61685.23000000", "0.97494000"], ["61692.29000000", "0.04609000"], ["61696.23000000", "0.45769000"], ["61703.03000000", "0.83175000"], ["61706.80000000", "0.39215000"], ["61710.18000000", "0.07388000"], ["61713.29000000", "0.12704000"], ["61719.12000000", "1.46507000"], ["61721.99000000", "0.08112000"], ["61724.70000000", "1.47302000"], ["61725.15000000", "0.00000000"], ["61726.26000000", "0.00162000"], ["61728.67000000", "0.07388000"], ["61730.69000000", "0.00154000"], ["61735.50000000", "0.00000000"], ["61745.62000000", "0.02543000"], ["61778.71000000", "4.86087000"], ["61789.79000000", "0.00009000"], ["61792.87000000", "0.00009000"], ["61796.11000000", "0.00232000"], ["61799.19000000", "0.00009000"], ["61933.04000000", "0.00000000"], ["62048.84000000", "0.00000000"]]}
{"type": "depth", "ts": 1783008115314, "U": 96863182459, "u": 96863182677, "bids": [["61617.99000000", "6.12216000"], ["61617.28000000", "1.00436000"], ["61617.27000000", "1.36852000"], ["61617.26000000", "0.00018000"], ["61616.85000000", "0.08054000"], ["61616.49000000", "0.16256000"], ["61616.05000000", "0.00009000"], ["61615.80000000", "0.00009000"], ["61615.34000000", "0.03220000"], ["61615.33000000", "0.03000000"], ["61615.29000000", "0.00000000"], ["61614.36000000", "0.06217000"], ["61610.74000000", "1.75783000"], ["61606.83000000", "0.12000000"], ["61604.94000000", "0.00009000"], ["61602.06000000", "0.00000000"], ["61597.85000000", "0.00060000"], ["61594.87000000", "0.03176000"], ["61593.78000000", "0.00419000"], ["61592.53000000", "0.00000000"], ["61589.55000000", "0.00000000"], ["61588.63000000", "0.00000000"], ["61567.84000000", "0.00000000"], ["61562.06000000", "0.00405000"], ["61558.01000000", "0.00000000"], ["61520.17000000", "0.00161000"], ["61517.14000000", "0.04576000"], ["61516.26000000", "0.03373000"], ["61514.25000000", "0.05233000"], ["61507.04000000", "0.00000000"], ["61507.03000000", "0.00000000"], ["61503.88000000", "0.00000000"], ["61500.42000000", "0.00162000"], ["61497.80000000", "0.00000000"], ["61497.13000000", "0.00000000"], ["61496.29000000", "0.00194000"], ["61431.49000000", "0.00000000"], ["61362.23000000", "0.00047000"], ["61260.66000000", "0.00000000"], ["55456.20000000", "0.00040000"]], "asks": [["61618.00000000", "0.02570000"], ["61618.01000000", "0.00107000"], ["61618.02000000", "0.00905000"], ["61619.44000000", "0.00000000"], ["61620.26000000", "0.00843000"], ["61620.42000000", "0.00000000"], ["61621.22000000", "0.00000000"], ["61622.00000000", "0.02418000"], ["61622.53000000", "0.00000000"], ["61622.66000000", "0.00000000"], ["61623.03000000", "0.01346000"], ["61623.40000000", "0.01007000"], ["61623.46000000", "0.04103000"], ["61623.62000000", "0.00174000"], ["61624.00000000", "0.02418000"], ["61624.69000000", "0.00000000"], ["61624.70000000", "0.00027000"], ["61624.94000000", "0.00000000"], ["61624.95000000", "0.00009000"], ["61625.52000000", "0.00000000"], ["61626.69000000", "0.00009000"], ["61628.16000000", "0.00409000"], ["61628.17000000", "0.21434000"], ["61628.77000000", "0.00000000"], ["61629.14000000", "0.00000000"], ["61629.40000000", "0.00000000"], ["61629.62000000", "0.00009000"], ["61629.69000000", "0.00000000"], ["61629.99000000", "0.00000000"], ["61630.78000000", "0.00812000"], ["61631.38000000", "0.07000000"], ["61631.40000000", "0.00009000"], ["61631.48000000", "0.08000000"], ["61632.55000000", "0.00009000"], ["61632.74000000", "0.08891000"], ["61633.51000000", "0.01300000"], ["61633.88000000", "0.59733000"], ["61633.89000000", "0.09277000"], ["61633.90000000", "1.36330000"], ["61633.91000000", "0.00000000"], ["61633.92000000", "0.00000000"], ["61634.26000000", "0.00028000"], ["61634.58000000", "0.00000000"], ["61635.21000000", "0.00000000"], ["61635.41000000", "0.00000000"], ["61635.48000000", "0.00009000"], ["61636.35000000", "0.01000000"], ["61636.76000000", "0.00000000"], ["61636.96000000", "0.00009000"], ["61637.57000000", "0.00400000"], ["61638.41000000", "0.00009000"], ["61640.77000000", "0.38956000"], ["61640.79000000", "0.00000000"], ["61641.03000000", "0.00000000"], ["61641.92000000", "0.00000000"], ["61647.13000000", "0.38956000"], ["61647.15000000", "0.00000000"], ["61647.92000000", "0.00000000"], ["61649.65000000", "0.00000000"], ["61655.10000000", "0.38956000"], ["61655.12000000", "0.00000000"], ["61660.18000000", "0.00000000"], ["61665.99000000", "0.00381000"], ["61667.18000000", "0.00230000"], ["61669.99000000", "0.00000000"], ["61672.32000000", "0.00400000"], ["61672.75000000", "0.01300000"], ["61674.67000000", "0.00000000"], ["61675.23000000", "0.00000000"], ["61675.29000000", "0.02200000"], ["61676.30000000", "0.00000000"], ["61677.09000000", "1.17182000"], ["61678.07000000", "0.01009000"], ["61679.28000000", "0.00000000"], ["61680.62000000", "0.13791000"], ["61682.71000000", "0.00000000"], ["61688.68000000", "0.00000000"], ["61699.00000000", "0.00000000"], ["61699.08000000", "0.05036000"], ["61717.99000000", "0.07298000"], ["61727.87000000", "0.00153000"], ["61727.88000000", "0.00000000"], ["61730.69000000", "0.00000000"], ["61799.19000000", "0.00000000"], ["61933.04000000", "0.00009000"]]}
{"type": "depth", "ts": 1783008115414, "U": 96863182678, "u": 96863182762, "bids": [["61617.99000000", "6.07146000"], ["61617.70000000", "0.04217000"], ["61617.27000000", "1.36852000"], ["61617.26000000", "0.00000000"], ["61616.91000000", "0.00018000"], ["61616.49000000", "0.16256000"], ["61615.34000000", "0.03238000"], ["61608.10000000", "0.08732000"], ["61606.56000000", "0.08893000"], ["61603.87000000", "0.00000000"], ["61602.33000000", "0.00000000"], ["61586.48000000", "0.00000000"], ["61580.63000000", "0.77904000"], ["61569.22000000", "0.00000000"], ["61562.06000000", "0.00000000"], ["61513.64000000", "0.00016000"], ["61507.04000000", "0.02718000"], ["61507.03000000", "0.00844000"], ["61504.76000000", "0.00000000"], ["61494.59000000", "0.00000000"], ["61468.06000000", "0.00000000"], ["55456.20000000", "0.00060000"]], "asks": [["61618.00000000", "0.02937000"], ["61623.40000000", "0.01007000"], ["61623.45000000", "0.00009000"], ["61623.46000000", "0.04121000"], ["61624.00000000", "0.02418000"], ["61624.70000000", "0.00009000"], ["61625.15000000", "0.08775000"], ["61628.16000000", "0.00400000"], ["61628.17000000", "0.00000000"], ["61629.15000000", "0.00000000"], ["61629.21000000", "0.00000000"], ["61629.77000000", "0.00000000"], ["61629.82000000", "0.00000000"], ["61630.75000000", "0.00000000"], ["61632.24000000", "0.00000000"], ["61632.74000000", "0.00000000"], ["61632.90000000", "0.00000000"], ["61633.87000000", "0.09277000"], ["61633.89000000", "0.00000000"], ["61636.65000000", "0.01000000"], ["61639.35000000", "0.02570000"], ["61647.23000000", "0.00000000"], ["61647.53000000", "0.97390000"], ["61649.21000000", "0.61679000"], ["61649.72000000", "0.00000000"], ["61653.56000000", "0.00000000"], ["61655.99000000", "0.00009000"], ["61656.16000000", "0.00429000"], ["61667.83000000", "0.08115000"], ["61675.29000000", "0.01100000"], ["61678.37000000", "0.02213000"], ["61695.98000000", "0.71215000"], ["61695.99000000", "0.80368000"], ["61696.23000000", "0.00000000"], ["61697.46000000", "0.00000000"], ["61700.69000000", "0.00000000"], ["61704.99000000", "0.00000000"], ["61727.87000000", "0.00000000"], ["62542.27000000", "0.00030000"]]}
{"type": "depth", "ts": 1783008115514, "U": 96863182763, "u": 96863182824, "bids": [["61617.99000000", "5.92754000"], ["61617.70000000", "0.04235000"], ["61617.28000000", "0.88910000"], ["61617.25000000", "0.15392000"], ["61616.91000000", "0.00000000"], ["61611.96000000", "0.01000000"], ["61610.87000000", "0.81857000"], ["61610.71000000", "0.01200000"], ["61606.16000000", "0.00009000"], ["61602.18000000", "0.00000000"], ["61573.24000000", "1.50202000"], ["61552.80000000", "0.00000000"], ["61519.57000000", "0.00016000"], ["61507.04000000", "0.00000000"], ["61503.48000000", "0.00024000"], ["61467.30000000", "0.00939000"], ["61442.87000000", "0.00015000"], ["59700.00000000", "24.93878000"], ["55456.20000000", "0.00100000"]], "asks": [["61618.00000000", "0.02928000"], ["61623.45000000", "0.00000000"], ["61623.46000000", "0.00018000"], ["61628.17000000", "0.08958000"], ["61630.86000000", "0.13512000"], ["61631.37000000", "0.09277000"], ["61632.74000000", "0.09277000"], ["61639.35000000", "0.00000000"], ["61640.15000000", "0.01000000"], ["61651.65000000", "0.00230000"], ["61652.78000000", "1.35365000"], ["61655.05000000", "1.50002000"], ["61667.18000000", "0.00000000"], ["61672.04000000", "0.01100000"], ["61678.32000000", "0.01000000"], ["61692.58000000", "0.00000000"], ["61694.28000000", "0.00000000"], ["61695.98000000", "1.55004000"], ["61696.24000000", "0.00000000"], ["61697.12000000", "3.23202000"]]}
{"type": "depth", "ts": 1783008115614, "U": 96863182825, "u": 96863182860, "bids": [["61617.99000000", "6.09709000"], ["61617.33000000", "0.00009000"], ["61611.75000000", "0.01000000"], ["61611.12000000", "0.01300000"], ["61601.10000000", "0.58498000"], ["61551.08000000", "0.00000000"], ["60693.72000000", "0.00030000"], ["55456.20000000", "0.00140000"], ["33000.00000000", "37.44300000"]], "asks": [["61623.40000000", "0.01007000"], ["61623.46000000", "0.00000000"], ["61623.76000000", "0.00009000"], ["61624.76000000", "0.00925000"], ["61625.15000000", "0.00000000"], ["61628.17000000", "0.00000000"], ["61645.23000000", "0.56963000"], ["61647.48000000", "0.00000000"], ["61650.34000000", "0.58451000"], ["61654.64000000", "0.58447000"], ["61655.99000000", "0.00000000"], ["61664.38000000", "1.06388000"], ["61670.35000000", "0.01100000"], ["61670.97000000", "0.01000000"], ["61678.32000000", "0.00000000"], ["61745.62000000", "0.00000000"], ["61933.04000000", "0.00000000"], ["62980.00000000", "3.52240000"]]}
{"type": "depth", "ts": 1783008115714, "U": 96863182861, "u": 96863182893, "bids": [["61617.99000000", "5.92754000"], ["61611.82000000", "0.00300000"], ["61610.87000000", "0.81848000"], ["61610.08000000", "0.00000000"], ["61609.96000000", "0.00009000"], ["61606.27000000", "0.00000000"], ["61605.73000000", "0.01700000"], ["61595.65000000", "0.00000000"], ["61551.53000000", "0.00000000"], ["61514.25000000", "0.00000000"], ["61488.81000000", "0.00000000"], ["61477.93000000", "0.00035000"], ["56682.01000000", "0.00000000"], ["55456.20000000", "0.00190000"], ["55448.19000000", "0.00000000"]], "asks": [["61618.00000000", "0.02652000"], ["61621.02000000", "0.00009000"], ["61623.79000000", "0.00000000"], ["61624.20000000", "0.00009000"], ["61624.21000000", "0.03079000"], ["61628.17000000", "0.00000000"], ["61628.40000000", "0.00000000"], ["61630.33000000", "0.00626000"], ["61643.27000000", "0.00419000"], ["61660.44000000", "0.10000000"], ["61699.08000000", "0.00000000"], ["61706.36000000", "0.00016000"], ["61709.60000000", "0.00024000"], ["61712.41000000", "0.00000000"]]}
{"type": "depth", "ts": 1783008115814, "U": 96863182894, "u": 96863182924, "bids": [["61617.99000000", "5.92354000"], ["61597.64000000", "0.00009000"], ["61588.76000000", "0.00000000"], ["61565.69000000", "0.00000000"], ["61565.06000000", "0.97494000"], ["61551.69000000", "0.00000000"], ["61521.35000000", "0.05719000"], ["61507.16000000", "0.00092000"], ["61495.21000000", "0.00000000"], ["55456.20000000", "0.00230000"]], "asks": [["61618.00000000", "0.02661000"], ["61622.50000000", "0.08775000"], ["61622.81000000", "0.00009000"], ["61622.82000000", "0.03921000"], ["61624.00000000", "0.02418000"], ["61624.20000000", "0.00000000"], ["61624.21000000", "0.00018000"], ["61624.76000000", "0.00907000"], ["61625.73000000", "0.00000000"], ["61634.63000000", "0.00018000"], ["61653.06000000", "0.00000000"], ["61706.20000000", "0.05036000"], ["61730.02000000", "0.00000000"], ["61764.16000000", "0.00000000"], ["61788.16000000", "0.02542000"]]}
{"type": "depth", "ts": 1783008115914, "U": 96863182925, "u": 96863182953, "bids": [["61576.70000000", "0.14032000"], ["61567.35000000", "0.00000000"], ["61477.93000000", "0.00000000"], ["61467.30000000", "0.00953000"], ["61442.87000000", "0.00000000"], ["55456.20000000", "0.00270000"], ["55456.00000000", "0.02704000"], ["49294.39000000", "0.00000000"]], "asks": [["61618.00000000", "0.02679000"], ["61622.00000000", "0.02418000"], ["61622.49000000", "0.00009000"], ["61622.50000000", "0.08793000"], ["61622.82000000", "0.03939000"], ["61624.00000000", "0.02400000"], ["61624.21000000", "0.00000000"], ["61680.62000000", "0.00000000"], ["61682.66000000", "0.13506000"], ["61713.90000000", "0.00040000"], ["61770.73000000", "0.00024000"]]}
{"type": "depth", "ts": 1783008116014, "U": 96863182954, "u": 96863183017, "bids": [["61617.99000000", "6.09318000"], ["61612.77000000", "0.03248000"], ["61611.09000000", "0.00010000"], ["61472.52000000", "0.00040000"], ["61467.30000000", "0.00000000"], ["55456.20000000", "0.00310000"], ["49294.40000000", "0.00109000"], ["49294.39000000", "0.00020000"]], "asks": [["61618.00000000", "0.02676000"], ["61622.81000000", "0.00000000"], ["61622.82000000", "0.00018000"], ["61623.76000000", "0.00000000"], ["61626.19000000", "0.00000000"], ["61626.88000000", "0.00000000"], ["61627.69000000", "0.02000000"], ["61627.71000000", "0.00000000"], ["61628.17000000", "0.00000000"], ["61628.18000000", "0.00000000"], ["61628.26000000", "0.00000000"], ["61629.22000000", "0.00812000"], ["61630.32000000", "0.00000000"], ["61630.78000000", "0.00000000"], ["61631.36000000", "0.00812000"], ["61631.37000000", "0.00000000"], ["61631.38000000", "0.00000000"], ["61631.48000000", "0.00000000"], ["61632.74000000", "0.00000000"], ["61633.08000000", "0.03000000"], ["61633.90000000", "0.00000000"], ["61636.98000000", "0.00000000"], ["61637.28000000", "0.12000000"], ["61639.45000000", "1.36330000"], ["61639.46000000", "0.00000000"], ["61640.76000000", "0.38956000"], ["61640.77000000", "0.00000000"], ["61643.27000000", "0.00000000"], ["61644.88000000", "0.00000000"], ["61649.20000000", "1.36330000"], ["61649.82000000", "0.00000000"], ["61653.06000000", "0.00009000"], ["61660.56000000", "0.04710000"], ["61672.76000000", "0.56529000"], ["61704.41000000", "0.00000000"], ["61788.16000000", "0.00000000"]]}
{"type": "depth", "ts": 1783008116114, "U": 96863183018, "u": 96863183096, "bids": [["61617.99000000", "6.09327000"], ["61615.87000000", "0.00000000"], ["61615.63000000", "0.00995000"], ["61614.89000000", "0.00000000"], ["61614.49000000", "0.00880000"], ["61612.74000000", "0.00024000"], ["61610.86000000", "1.12764000"], ["61610.63000000", "0.58489000"], ["61610.48000000", "0.00009000"], ["61610.00000000", "0.00800000"], ["61608.00000000", "0.00800000"], ["61603.07000000", "0.01624000"], ["61601.41000000", "0.00000000"], ["61593.67000000", "0.00000000"], ["61591.67000000", "0.00000000"], ["61587.20000000", "0.00000000"], ["61574.46000000", "0.00000000"], ["61540.52000000", "0.00030000"], ["61531.64000000", "0.00000000"], ["55456.20000000", "0.00330000"], ["49294.39000000", "0.00000000"]], "asks": [["61618.00000000", "0.02667000"], ["61622.50000000", "0.08793000"], ["61622.82000000", "0.00000000"], ["61623.40000000", "0.00018000"], ["61624.00000000", "0.02418000"], ["61624.76000000", "0.00000000"], ["61626.13000000", "0.00994000"], ["61627.69000000", "0.00000000"], ["61628.16000000", "0.00000000"], ["61630.59000000", "0.00000000"], ["61630.86000000", "0.05484000"], ["61631.36000000", "0.00000000"], ["61631.85000000", "0.00000000"], ["61631.99000000", "0.00000000"], ["61632.00000000", "0.04400000"], ["61632.48000000", "0.00000000"], ["61633.76000000", "0.00000000"], ["61633.88000000", "0.57320000"], ["61635.41000000", "0.09278000"], ["61636.16000000", "0.09278000"], ["61636.95000000", "0.09278000"], ["61636.96000000", "1.36339000"], ["61636.97000000", "0.47663000"], ["61643.63000000", "0.00000000"], ["61647.14000000", "1.00119000"], ["61650.01000000", "0.00000000"], ["61655.14000000", "0.58447000"], ["61658.51000000", "0.00628000"], ["61676.10000000", "0.00400000"], ["61685.66000000", "0.00000000"], ["61694.56000000", "0.00030000"], ["61708.88000000", "0.00009000"], ["61796.48000000", "0.24750000"]]}
{"type": "depth", "ts": 1783008116214, "U": 96863183097, "u": 96863183150, "bids": [["61617.99000000", "6.14196000"], ["61616.85000000", "0.08045000"], ["61616.49000000", "0.16256000"], ["61615.80000000", "0.00000000"], ["61615.78000000", "0.01000000"], ["61615.63000000", "0.01013000"], ["61615.34000000", "0.03220000"], ["61615.10000000", "0.01000000"], ["61611.83000000", "0.04000000"], ["61467.30000000", "0.00015000"], ["55456.20000000", "0.00370000"], ["49294.40000000", "0.00069000"], ["49294.00000000", "0.00800000"]], "asks": [["61618.00000000", "0.02658000"], ["61618.01000000", "0.00124000"], ["61618.02000000", "0.00922000"], ["61619.16000000", "0.00009000"], ["61622.49000000", "0.00000000"], ["61622.50000000", "0.00018000"], ["61623.03000000", "0.01346000"], ["61623.40000000", "0.00000000"], ["61624.00000000", "0.02418000"], ["61624.96000000", "1.99818000"], ["61632.74000000", "0.09278000"], ["61636.36000000", "0.01800000"], ["61636.42000000", "0.01400000"], ["61636.98000000", "0.01200000"], ["61637.03000000", "0.01100000"], ["61639.45000000", "1.37330000"], ["61640.11000000", "0.01200000"], ["61640.90000000", "0.00166000"], ["61644.45000000", "0.00000000"], ["61674.67000000", "0.01400000"], ["61675.23000000", "0.01200000"]]}
{"type": "depth", "ts": 1783008116314, "U": 96863183151, "u": 96863183675, "bids": [["61619.99000000", "5.62087000"], ["61619.98000000", "0.00035000"], ["61619.97000000", "0.00017000"], ["61619.60000000", "3.29954000"], ["61619.59000000", "1.37570000"], ["61619.58000000", "0.00000000"], ["61619.57000000", "0.00000000"], ["61619.52000000", "0.00000000"], ["61619.40000000", "0.00400000"], ["61619.15000000", "0.00000000"], ["61618.95000000", "0.24777000"], ["61618.56000000", "0.00000000"], ["61618.54000000", "0.00000000"], ["61618.47000000", "0.00000000"], ["61618.46000000", "0.00000000"], ["61618.01000000", "0.00024000"], ["61618.00000000", "0.07527000"], ["61617.99000000", "0.26145000"], ["61617.98000000", "0.00000000"], ["61617.97000000", "0.00000000"], ["61617.83000000", "0.00000000"], ["61617.28000000", "0.00018000"], ["61617.27000000", "0.39462000"], ["61617.25000000", "0.00027000"], ["61617.02000000", "0.00889000"], ["61616.90000000", "1.44348000"], ["61616.85000000", "0.08018000"], ["61616.50000000", "0.00000000"], ["61616.49000000", "0.00009000"], ["61616.05000000", "0.00000000"], ["61615.78000000", "0.01000000"], ["61615.63000000", "0.00995000"], ["61615.40000000", "0.01000000"], ["61614.50000000", "0.03247000"], ["61614.36000000", "0.04217000"], ["61612.79000000", "0.00010000"], ["61612.77000000", "0.00000000"], ["61612.46000000", "0.00000000"], ["61612.32000000", "0.00009000"], ["61611.99000000", "0.00000000"], ["61611.83000000", "0.06000000"], ["61611.82000000", "0.00700000"], ["61611.09000000", "0.00000000"], ["61611.08000000", "0.00000000"], ["61610.86000000", "0.97399000"], ["61607.67000000", "0.00010000"], ["61605.35000000", "0.00009000"], ["61604.64000000", "0.00009000"], ["61604.59000000", "0.00010000"], ["61604.53000000", "0.00000000"], ["61603.28000000", "0.00000000"], ["61602.30000000", "0.00499000"], ["61601.50000000", "0.00010000"], ["61601.45000000", "0.00000000"], ["61598.42000000", "0.00010000"], ["61598.36000000", "0.00000000"], ["61595.34000000", "0.00010000"], ["61595.28000000", "0.00000000"], ["61592.26000000", "0.00010000"], ["61592.20000000", "0.00000000"], ["61589.18000000", "0.00010000"], ["61589.12000000", "1.36330000"], ["61588.60000000", "0.00000000"], ["61586.63000000", "0.00016000"], ["61586.04000000", "0.00000000"], ["61578.90000000", "0.00400000"], ["61578.82000000", "0.00000000"], ["61576.86000000", "0.00000000"], ["61563.02000000", "0.00000000"], ["61562.46000000", "0.00000000"], ["61541.22000000", "0.69746000"], ["61541.20000000", "0.00000000"], ["61523.00000000", "0.00009000"], ["61467.30000000", "0.00968000"], ["60693.72000000", "0.00000000"], ["55456.20000000", "0.00010000"]], "asks": [["61618.00000000", "0.00000000"], ["61618.01000000", "0.00000000"], ["61618.02000000", "0.00000000"], ["61618.48000000", "0.00000000"], ["61618.55000000", "0.00000000"], ["61618.57000000", "0.00000000"], ["61618.96000000", "0.00000000"], ["61619.16000000", "0.00000000"], ["61619.53000000", "0.00000000"], ["61619.60000000", "0.00000000"], ["61619.99000000", "0.00000000"], ["61620.00000000", "0.02455000"], ["61620.01000000", "0.00081000"], ["61622.00000000", "0.02418000"], ["61622.50000000", "0.00000000"], ["61622.55000000", "0.00009000"], ["61622.69000000", "0.00000000"], ["61623.03000000", "0.00018000"], ["61623.25000000", "0.00000000"], ["61624.02000000", "0.00000000"], ["61624.65000000", "0.00009000"], ["61624.66000000", "0.08775000"], ["61625.12000000", "0.00010000"], ["61625.14000000", "0.00000000"], ["61625.49000000", "0.00000000"], ["61626.00000000", "0.02418000"], ["61626.13000000", "0.01012000"], ["61627.45000000", "0.04035000"], ["61627.85000000", "0.00921000"], ["61628.88000000", "0.00000000"], ["61629.22000000", "0.00000000"], ["61629.61000000", "0.00812000"], ["61629.98000000", "0.00400000"], ["61630.33000000", "0.00300000"], ["61630.44000000", "0.00000000"], ["61630.86000000", "0.00000000"], ["61631.79000000", "0.00000000"], ["61631.99000000", "0.05390000"], ["61632.74000000", "0.00000000"], ["61633.88000000", "0.20528000"], ["61635.41000000", "0.00000000"], ["61636.95000000", "0.00000000"], ["61636.96000000", "0.00009000"], ["61637.03000000", "0.02200000"], ["61639.44000000", "0.09277000"], ["61643.83000000", "0.00000000"], ["61644.40000000", "0.00000000"], ["61644.46000000", "0.00000000"], ["61644.88000000", "0.00419000"], ["61646.86000000", "0.00000000"], ["61649.00000000", "0.00000000"], ["61649.10000000", "0.00409000"], ["61649.98000000", "0.00000000"], ["61650.00000000", "0.02409000"], ["61651.00000000", "0.01000000"], ["61655.99000000", "0.00009000"], ["61660.44000000", "0.00000000"], ["61664.99000000", "0.00000000"], ["61666.24000000", "0.00405000"], ["61675.23000000", "0.00000000"], ["61675.29000000", "0.02200000"], ["61695.48000000", "0.00009000"], ["61699.99000000", "0.01171000"], ["61719.20000000", "0.00009000"], ["61735.26000000", "0.00000000"], ["61830.57000000", "0.00000000"], ["61854.15000000", "1.19998000"], ["61933.04000000", "0.00009000"], ["62542.27000000", "0.00000000"]]}
{"type": "depth", "ts": 1783008116414, "U": 96863183676, "u": 96863183789, "bids": [["61619.99000000", "5.57374000"], ["61619.60000000", "1.36357000"], ["61618.95000000", "0.24786000"], ["61618.59000000", "0.16228000"], ["61617.99000000", "0.24136000"], ["61617.77000000", "0.02000000"], ["61617.70000000", "0.04235000"], ["61617.67000000", "0.00000000"], ["61617.57000000", "0.00000000"], ["61617.28000000", "0.00000000"], ["61617.27000000", "0.39462000"], ["61617.25000000", "0.00009000"], ["61617.02000000", "0.00018000"], ["61615.09000000", "0.01000000"], ["61614.00000000", "0.00600000"], ["61612.98000000", "0.00400000"], ["61612.00000000", "0.00600000"], ["61610.00000000", "0.01400000"], ["61608.00000000", "0.01400000"], ["61589.00000000", "0.01000000"], ["61587.00000000", "0.00000000"], ["61564.86000000", "0.00000000"], ["61554.61000000", "0.00000000"], ["61475.90000000", "0.00039000"], ["61472.52000000", "0.00000000"], ["55458.00000000", "0.00040000"]], "asks": [["61620.00000000", "0.02437000"], ["61620.01000000", "0.00063000"], ["61622.00000000", "0.02418000"], ["61623.02000000", "0.00000000"], ["61623.03000000", "0.00000000"], ["61624.00000000", "0.02418000"], ["61624.47000000", "0.00806000"], ["61624.65000000", "0.00000000"], ["61624.66000000", "0.00018000"], ["61625.09000000", "0.00000000"], ["61625.68000000", "0.03536000"], ["61626.13000000", "0.01012000"], ["61626.69000000", "0.00009000"], ["61627.45000000", "0.00018000"], ["61627.85000000", "0.00903000"], ["61628.27000000", "0.00000000"], ["61629.99000000", "0.02000000"], ["61631.42000000", "0.00000000"], ["61631.99000000", "0.00000000"], ["61632.00000000", "0.02400000"], ["61632.33000000", "0.00323000"], ["61632.95000000", "0.06311000"], ["61633.40000000", "0.09277000"], ["61633.88000000", "0.61044000"], ["61636.08000000", "0.09277000"], ["61636.23000000", "0.00048000"], ["61636.96000000", "1.36339000"], ["61639.44000000", "0.00000000"], ["61640.76000000", "0.00000000"], ["61642.45000000", "0.00000000"], ["61644.20000000", "0.00000000"], ["61647.54000000", "0.00000000"], ["61669.76000000", "0.07312000"], ["61678.80000000", "0.00400000"], ["61695.99000000", "0.00000000"], ["61719.83000000", "0.00000000"], ["61763.67000000", "0.01827000"], ["61799.30000000", "0.00009000"], ["61802.38000000", "0.00009000"]]}
{"type": "depth", "ts": 1783008116514, "U": 96863183790, "u": 96863183851, "bids": [["61619.99000000", "5.59383000"], ["61619.59000000", "1.32570000"], ["61618.95000000", "0.00036000"], ["61618.59000000", "0.00018000"], ["61618.57000000", "0.16228000"], ["61617.99000000", "0.24136000"], ["61617.77000000", "0.00018000"], ["61617.27000000", "0.39444000"], ["61617.02000000", "0.00000000"], ["61586.63000000", "0.00000000"], ["61553.20000000", "0.00000000"], ["61553.10000000", "0.00000000"], ["61521.35000000", "0.00000000"], ["55458.00000000", "0.00080000"]], "asks": [["61620.00000000", "0.02751000"], ["61620.01000000", "0.00072000"], ["61624.00000000", "0.02418000"], ["61624.47000000", "0.00018000"], ["61624.66000000", "0.00000000"], ["61624.96000000", "1.99818000"], ["61625.12000000", "0.01158000"], ["61625.68000000", "0.00018000"], ["61626.13000000", "0.01012000"], ["61627.45000000", "0.00000000"], ["61636.16000000", "0.00000000"], ["61678.32000000", "0.01000000"], ["61802.38000000", "0.00000000"], ["62544.30000000", "0.00030000"]]}
{"type": "depth", "ts": 1783008116614, "U": 96863183852, "u": 96863183910, "bids": [["61619.99000000", "5.57383000"], ["61619.59000000", "1.32570000"], ["61618.95000000", "0.00009000"], ["61618.59000000", "0.00000000"], ["61618.57000000", "0.16246000"], ["61617.99000000", "0.24136000"], ["61617.78000000", "0.60162000"], ["61617.77000000", "0.02000000"], ["61617.27000000", "0.39462000"], ["61616.90000000", "1.44366000"], ["61598.29000000", "0.58510000"], ["61551.07000000", "0.00000000"], ["61522.16000000", "0.05231000"], ["61467.30000000", "0.01001000"], ["60695.69000000", "0.00030000"], ["55458.00000000", "0.00120000"]], "asks": [["61620.00000000", "0.02769000"], ["61620.01000000", "0.00081000"], ["61624.00000000", "0.02418000"], ["61624.47000000", "0.00000000"], ["61624.96000000", "1.99818000"], ["61625.07000000", "0.08775000"], ["61625.12000000", "0.01176000"], ["61625.68000000", "0.00000000"], ["61627.85000000", "0.00921000"], ["61633.51000000", "0.00000000"], ["61635.86000000", "0.00009000"], ["61636.35000000", "0.00000000"], ["61636.47000000", "0.00000000"], ["61636.65000000", "0.00000000"], ["61640.77000000", "0.38956000"], ["61655.99000000", "0.00000000"], ["61660.75000000", "0.58442000"]]}
